File: Lab/XRD/20170814/cu2o_009-2-1120-2.ras
*RAS_DATA_START
*RAS_HEADER_START
*CORR_POS_DB_NAME "DTEX_11112016"
*CORR_POS_GONIO_RADIUS ""
*CORR_POS_NODE_INDEX01 ""
*CORR_POS_NODE_INDEX02 ""
*CORR_POS_NODE_INDEX03 ""
*CORR_POS_NODE_INDEX04 ""
*CORR_POS_NODE_INDEX05 ""
*CORR_POS_NODE_INDEX06 ""
*CORR_POS_NODE_INDEX07 ""
*CORR_POS_NODE_INDEX08 ""
*CORR_POS_NODE_INDEX09 ""
*CORR_POS_NODE_INDEX10 ""
*CORR_POS_NODE_INDEX11 ""
*CORR_POS_NODE_LABEL01 "Si(111)"
*CORR_POS_NODE_LABEL02 "Si(220)"
*CORR_POS_NODE_LABEL03 "Si(311)"
*CORR_POS_NODE_LABEL04 "Si(400)"
*CORR_POS_NODE_LABEL05 "Si(331)"
*CORR_POS_NODE_LABEL06 "Si(422)"
*CORR_POS_NODE_LABEL07 "Si(511)"
*CORR_POS_NODE_LABEL08 "Si(440)"
*CORR_POS_NODE_LABEL09 "Si(531)"
*CORR_POS_NODE_LABEL10 "Si(620)"
*CORR_POS_NODE_LABEL11 "Si(533)"
*CORR_POS_NODE_POS_CALC01 "28.4137"
*CORR_POS_NODE_POS_CALC02 "47.2707"
*CORR_POS_NODE_POS_CALC03 "56.0883"
*CORR_POS_NODE_POS_CALC04 "69.0934"
*CORR_POS_NODE_POS_CALC05 "76.3385"
*CORR_POS_NODE_POS_CALC06 "87.9915"
*CORR_POS_NODE_POS_CALC07 "94.9137"
*CORR_POS_NODE_POS_CALC08 "106.67"
*CORR_POS_NODE_POS_CALC09 "114.054"
*CORR_POS_NODE_POS_CALC10 "127.508"
*CORR_POS_NODE_POS_CALC11 "136.858"
*CORR_POS_NODE_POS_MEAS01 "28.3712"
*CORR_POS_NODE_POS_MEAS02 "47.2304"
*CORR_POS_NODE_POS_MEAS03 "56.0465"
*CORR_POS_NODE_POS_MEAS04 "69.0523"
*CORR_POS_NODE_POS_MEAS05 "76.2993"
*CORR_POS_NODE_POS_MEAS06 "87.9512"
*CORR_POS_NODE_POS_MEAS07 "94.8772"
*CORR_POS_NODE_POS_MEAS08 "106.636"
*CORR_POS_NODE_POS_MEAS09 "114.028"
*CORR_POS_NODE_POS_MEAS10 "127.48"
*CORR_POS_NODE_POS_MEAS11 "136.839"
*CORR_POS_OPT_ATTR "集中法"
*CORR_POS_PARAM_MU ""
*CORR_POS_PARAM_PL ""
*CORR_POS_SEMODEL_TYPE "0"
*CORR_POS_STANDARD_TYPE ""
*CORR_POS_VALUE_ANALYZER "None"
*CORR_POS_VALUE_CMONO "None"
*CORR_POS_VALUE_IMONO "None"
*CORR_POS_VALUE_IS "0.625deg"
*CORR_POS_VALUE_ISL "10.0mm"
*CORR_POS_VALUE_ISOLLER "2.5deg"
*CORR_POS_VALUE_RS1 "13.0mm"
*CORR_POS_VALUE_RS2 "13.0mm"
*CORR_POS_VALUE_RSOLLER "2.5deg"
*CORR_POS_XG_FOCUS_L ""
*CORR_POS_XG_WAVE_TYPE ""
*CORR_POS_XG_WAVE_VALUE ""
*DISP_FMT_X "%.2f"
*DISP_FMT_Y "%.0f"
*DISP_FULLSCALE "11292.0000000000"
*DISP_LINE_COLOR "255.0000000000"
*DISP_LINE_STYLE "0.0000000000"
*DISP_LINE_WIDTH "0.2500000000"
*DISP_NOTE "Collected Data-2"
*DISP_OFFSET_Y "0.0000000000"
*DISP_PEAKSEARCH_UNIT_Y "COUNTS"
*DISP_RANGE_BOTTOM "0.0000000000"
*DISP_RANGE_LEFT "20.0000000000"
*DISP_RANGE_LOGCUTOFF "0.0100000000"
*DISP_RANGE_RIGHT "90.0000000000"
*DISP_RANGE_TOP "11292.0000000000"
*DISP_SCALE_MODE_Y "0.0000000000"
*DISP_TAB_NAME "Theta/2-Theta"
*DISP_TITLE_Y "Intensity"
*DISP_UNIT_Y "COUNTS"
*DISP_WINDOW_NAME "MSG_MACROENGINE"
*FILE_COMMENT " "
*FILE_MD5 ""
*FILE_MEMO " "
*FILE_OPERATOR "MiniFlex"
*FILE_PART_ID "MEAS_PBEA_00223"
*FILE_SAMPLE "cu2o_009"
*FILE_TYPE "RAS_RAW"
*FILE_USERGROUP "System User"
*FILE_VERSION "1.0000000000"
*HW_ATTACHMENT_ID "ATT1031"
*HW_ATTACHMENT_NAME "6サンプルチェンジャ|ASC-6"
*HW_COUNTER_ID-0 "CUT0025"
*HW_COUNTER_ID-1 "CUT0020"
*HW_COUNTER_ID-2 "CUT0020"
*HW_COUNTER_ID-3 "CMC0021"
*HW_COUNTER_NAME-0 "D/teX Ultra|D/teX Ultra"
*HW_COUNTER_NAME-1 "None|None"
*HW_COUNTER_NAME-2 "None|None"
*HW_COUNTER_NAME-3 "検出器モノクロメータ|Detector monochromator"
*HW_COUNTER_SELECT_NAME "D/teX Ultra|D/teX Ultra"
*HW_GONIOMETER_ID "GON0070"
*HW_GONIOMETER_NAME "MiniFlex 300/600|MiniFlex 300/600"
*HW_GONIOMETER_RADIUS-0 "79.0"
*HW_GONIOMETER_RADIUS-1 "91.5"
*HW_GONIOMETER_RADIUS-2 "150.0"
*HW_GONIOMETER_RADIUS-3 "0"
*HW_GONIOMETER_RADIUS-4 "103.4"
*HW_GONIOMETER_RADIUS-5 "150.0"
*HW_GONIOMETER_RADIUS-6 "46.6"
*HW_GONIOMETER_RADIUS-7 "160.0"
*HW_I_OPT_ID-0 "ISL0021"
*HW_I_OPT_ID-1 "ISO0021"
*HW_I_OPT_NAME-0 "発散スリット|Divergence slit"
*HW_I_OPT_NAME-1 "入射平行スリット|Incident parallel slit"
*HW_R_ATTENUATER_AUTOMODE "0"
*HW_R_OPT_ID-0 "RSS0021"
*HW_R_OPT_ID-1 "RSO0021"
*HW_R_OPT_ID-2 "RRS0021"
*HW_R_OPT_NAME-0 "散乱スリット|Scattering slit"
*HW_R_OPT_NAME-1 "受光平行スリット|Receiving soller slit"
*HW_R_OPT_NAME-2 "受光スリット|Receiving slit"
*HW_SAMPLE_HOLDER_ID "SMP0000"
*HW_SAMPLE_HOLDER_NAME "無し|None"
*HW_XG_CURRENT_MAX "15"
*HW_XG_CURRENT_MIN "2"
*HW_XG_CURRENT_RESOLUTION "1"
*HW_XG_CURRENT_UNIT "mA"
*HW_XG_FOCUS "1mm x 10mm"
*HW_XG_FOCUS_TYPE "Normal"
*HW_XG_ID "1060"
*HW_XG_NAME "300W/600W 封入管-B|300W/600W Sealed tube-B"
*HW_XG_TARGET_ATOMIC_NUMBER "29.0000000000"
*HW_XG_TARGET_NAME "Cu"
*HW_XG_TYPE "Hermetic"
*HW_XG_VOLTAGE_MAX "40"
*HW_XG_VOLTAGE_MIN "20"
*HW_XG_VOLTAGE_RESOLUTION "1"
*HW_XG_VOLTAGE_UNIT "kV"
*HW_XG_WATT_MAX "1"
*HW_XG_WATT_UNIT "kW"
*HW_XG_WAVE_LENGTH_ALPHA1 "1.540593"
*HW_XG_WAVE_LENGTH_ALPHA2 "1.544414"
*HW_XG_WAVE_LENGTH_BETA "1.392250"
*MEAS_COND_AXIS_NAME-0 "Theta/2-Theta"
*MEAS_COND_AXIS_NAME-1 "Spin"
*MEAS_COND_AXIS_NAME-2 "Change"
*MEAS_COND_AXIS_NAME-3 "Soller(inc.)"
*MEAS_COND_AXIS_NAME-4 "IHS"
*MEAS_COND_AXIS_NAME-5 "DS"
*MEAS_COND_AXIS_NAME-6 "SS"
*MEAS_COND_AXIS_NAME-7 "Soller(rec.)"
*MEAS_COND_AXIS_NAME-8 "RS"
*MEAS_COND_AXIS_NAME-9 "Filter"
*MEAS_COND_AXIS_NAME-10 "Monochromator"
*MEAS_COND_AXIS_NAME-11 "PHA"
*MEAS_COND_AXIS_NAME_INTERNAL-0 "TwoThetaTheta"
*MEAS_COND_AXIS_NAME_INTERNAL-1 "Spin"
*MEAS_COND_AXIS_NAME_INTERNAL-2 "Change"
*MEAS_COND_AXIS_NAME_INTERNAL-3 "IncidentSollerSlit"
*MEAS_COND_AXIS_NAME_INTERNAL-4 "IncidentAxdSlit"
*MEAS_COND_AXIS_NAME_INTERNAL-5 "IncidentSlitBox"
*MEAS_COND_AXIS_NAME_INTERNAL-6 "ReceivingSlitBox1"
*MEAS_COND_AXIS_NAME_INTERNAL-7 "ReceivingSollerSlit"
*MEAS_COND_AXIS_NAME_INTERNAL-8 "ReceivingSlitBox2"
*MEAS_COND_AXIS_NAME_INTERNAL-9 "Filter"
*MEAS_COND_AXIS_NAME_INTERNAL-10 "CounterMonochromator"
*MEAS_COND_AXIS_NAME_INTERNAL-11 "PHA"
*MEAS_COND_AXIS_NAME_MAGICNO-0 "268632064.0000000000"
*MEAS_COND_AXIS_NAME_MAGICNO-1 "16842752.0000000000"
*MEAS_COND_AXIS_NAME_MAGICNO-2 "16842752.0000000000"
*MEAS_COND_AXIS_NAME_MAGICNO-3 "20971521.0000000000"
*MEAS_COND_AXIS_NAME_MAGICNO-4 "22020097.0000000000"
*MEAS_COND_AXIS_NAME_MAGICNO-5 "22020097.0000000000"
*MEAS_COND_AXIS_NAME_MAGICNO-6 "23068673.0000000000"
*MEAS_COND_AXIS_NAME_MAGICNO-7 "20971521.0000000000"
*MEAS_COND_AXIS_NAME_MAGICNO-8 "23068673.0000000000"
*MEAS_COND_AXIS_NAME_MAGICNO-9 "20971521.0000000000"
*MEAS_COND_AXIS_NAME_MAGICNO-10 "20971521.0000000000"
*MEAS_COND_AXIS_NAME_MAGICNO-11 "0.0000000000"
*MEAS_COND_AXIS_OFFSET-0 "0.0000000000"
*MEAS_COND_AXIS_OFFSET-1 "-"
*MEAS_COND_AXIS_OFFSET-2 "-"
*MEAS_COND_AXIS_OFFSET-3 "-"
*MEAS_COND_AXIS_OFFSET-4 "-"
*MEAS_COND_AXIS_OFFSET-5 "-"
*MEAS_COND_AXIS_OFFSET-6 "-"
*MEAS_COND_AXIS_OFFSET-7 "-"
*MEAS_COND_AXIS_OFFSET-8 "-"
*MEAS_COND_AXIS_OFFSET-9 "-"
*MEAS_COND_AXIS_OFFSET-10 "-"
*MEAS_COND_AXIS_OFFSET-11 "-"
*MEAS_COND_AXIS_POSITION-0 "92.5150000000"
*MEAS_COND_AXIS_POSITION-1 "0.0000000000"
*MEAS_COND_AXIS_POSITION-2 "2.0000000000"
*MEAS_COND_AXIS_POSITION-3 "2.5deg"
*MEAS_COND_AXIS_POSITION-4 "2.0mm"
*MEAS_COND_AXIS_POSITION-5 "0.625deg"
*MEAS_COND_AXIS_POSITION-6 "13.0mm(Open)"
*MEAS_COND_AXIS_POSITION-7 "2.5deg"
*MEAS_COND_AXIS_POSITION-8 "13.0mm"
*MEAS_COND_AXIS_POSITION-9 "K-beta(x2)"
*MEAS_COND_AXIS_POSITION-10 "None"
*MEAS_COND_AXIS_POSITION-11 "41.0000000000"
*MEAS_COND_AXIS_UNIT-0 "deg"
*MEAS_COND_AXIS_UNIT-1 ""
*MEAS_COND_AXIS_UNIT-2 ""
*MEAS_COND_AXIS_UNIT-3 ""
*MEAS_COND_AXIS_UNIT-4 ""
*MEAS_COND_AXIS_UNIT-5 ""
*MEAS_COND_AXIS_UNIT-6 ""
*MEAS_COND_AXIS_UNIT-7 ""
*MEAS_COND_AXIS_UNIT-8 ""
*MEAS_COND_AXIS_UNIT-9 ""
*MEAS_COND_AXIS_UNIT-10 ""
*MEAS_COND_AXIS_UNIT-11 "div"
*MEAS_COND_CORRECTION_SLIT_COUNTERMONO "None"
*MEAS_COND_CORRECTION_SLIT_DS "0.625deg"
*MEAS_COND_CORRECTION_SLIT_FILTER "None"
*MEAS_COND_CORRECTION_SLIT_IHS "2.0mm"
*MEAS_COND_CORRECTION_SLIT_RS "13.0mm"
*MEAS_COND_CORRECTION_SLIT_SOLLER_INC "2.5deg"
*MEAS_COND_CORRECTION_SLIT_SOLLER_REC "2.5deg"
*MEAS_COND_CORRECTION_SLIT_SS "13.0mm"
*MEAS_COND_COUNTER_CNTLOSS_CORR "0.0000000000"
*MEAS_COND_COUNTER_PHABASE "41.0000000000"
*MEAS_COND_COUNTER_PHAWINDOW "14.0000000000"
*MEAS_COND_COUNTER_PHA_UNIT "div"
*MEAS_COND_COUNTER_TAUDIFF "0.2500000000"
*MEAS_COND_COUNTER_TAUINT "0.7500000000"
*MEAS_COND_IRRADIATION_MODE "OFF"
*MEAS_COND_IRRADIATION_WIDTH ""
*MEAS_COND_OPT_ATTR " "
*MEAS_COND_OPT_NAME ""
*MEAS_COND_UNSYMMETRIC_MODE "OFF"
*MEAS_COND_XG_CURRENT "15.0000000000"
*MEAS_COND_XG_VOLTAGE "40.0000000000"
*MEAS_COND_XG_WAVE_TYPE "Ka"
*MEAS_DATA_COUNT "3501.0000000000"
*MEAS_SCAN_AXIS_X "Theta/2-Theta"
*MEAS_SCAN_AXIS_X_INTERNAL "TwoThetaTheta"
*MEAS_SCAN_END_TIME "08/14/17 11:31:29"
*MEAS_SCAN_MODE "CONTINUOUS"
*MEAS_SCAN_MONITOR "0"
*MEAS_SCAN_RESOLUTION_X "0.005"
*MEAS_SCAN_SPEED "15.000"
*MEAS_SCAN_SPEED_UNIT "deg/min"
*MEAS_SCAN_SPEED_USER "15.000"
*MEAS_SCAN_START "20.0000000000"
*MEAS_SCAN_START_TIME "08/14/17 11:26:05"
*MEAS_SCAN_STEP "0.0200000000"
*MEAS_SCAN_STOP "90.0000000000"
*MEAS_SCAN_UNIT_X "deg"
*MEAS_SCAN_UNIT_Y "counts"
*SLIT_SYSTEM "0"
*RAS_HEADER_END
*RAS_INT_START
20.000 149.000 1.000
20.060 168.000 1.000
20.120 179.000 1.000
20.180 170.000 1.000
20.240 155.000 1.000
20.300 154.000 1.000
20.360 191.000 1.000
20.420 152.000 1.000
20.480 160.000 1.000
20.540 174.000 1.000
20.600 179.000 1.000
20.660 149.000 1.000
20.720 161.000 1.000
20.780 175.000 1.000
20.840 169.000 1.000
20.900 169.000 1.000
20.960 161.000 1.000
21.020 170.000 1.000
21.080 156.000 1.000
21.140 169.000 1.000
21.200 162.000 1.000
21.260 178.000 1.000
21.320 164.000 1.000
21.380 190.000 1.000
21.440 213.000 1.000
21.500 172.000 1.000
21.560 164.000 1.000
21.620 190.000 1.000
21.680 166.000 1.000
21.740 176.000 1.000
21.800 186.000 1.000
21.860 191.000 1.000
21.920 171.000 1.000
21.980 197.000 1.000
22.040 195.000 1.000
22.100 179.000 1.000
22.160 184.000 1.000
22.220 180.000 1.000
22.280 196.000 1.000
22.340 193.000 1.000
22.400 196.000 1.000
22.460 192.000 1.000
22.520 191.000 1.000
22.580 221.000 1.000
22.640 197.000 1.000
22.700 214.000 1.000
22.760 214.000 1.000
22.820 195.000 1.000
22.880 210.000 1.000
22.940 210.000 1.000
23.000 214.000 1.000
23.060 210.000 1.000
23.120 200.000 1.000
23.180 237.000 1.000
23.240 248.000 1.000
23.300 243.000 1.000
23.360 248.000 1.000
23.420 247.000 1.000
23.480 256.000 1.000
23.540 267.000 1.000
23.600 259.000 1.000
23.660 287.000 1.000
23.720 292.000 1.000
23.780 304.000 1.000
23.840 314.000 1.000
23.900 321.000 1.000
23.960 311.000 1.000
24.020 322.000 1.000
24.080 349.000 1.000
24.140 333.000 1.000
24.200 362.000 1.000
24.260 375.000 1.000
24.320 400.000 1.000
24.380 399.000 1.000
24.440 406.000 1.000
24.500 464.000 1.000
24.560 494.000 1.000
24.620 512.000 1.000
24.680 537.000 1.000
24.740 546.000 1.000
24.800 588.000 1.000
24.860 595.000 1.000
24.920 627.000 1.000
24.980 694.000 1.000
25.040 721.000 1.000
25.100 781.000 1.000
25.160 888.000 1.000
25.220 925.000 1.000
25.280 926.000 1.000
25.340 1056.000 1.000
25.400 1135.000 1.000
25.460 1250.000 1.000
25.520 1344.000 1.000
25.580 1417.000 1.000
25.640 1564.000 1.000
25.700 1635.000 1.000
25.760 1709.000 1.000
25.820 1936.000 1.000
25.880 2012.000 1.000
25.940 2109.000 1.000
26.000 2260.000 1.000
26.060 2391.000 1.000
26.120 2426.000 1.000
26.180 2643.000 1.000
26.240 2865.000 1.000
26.300 3332.000 1.000
26.360 4354.000 1.000
26.420 6544.000 1.000
26.480 8792.000 1.000
26.540 9054.000 1.000
26.600 6640.000 1.000
26.660 3657.000 1.000
26.720 2054.000 1.000
26.780 1425.000 1.000
26.840 1070.000 1.000
26.900 981.000 1.000
26.960 888.000 1.000
27.020 732.000 1.000
27.080 629.000 1.000
27.140 606.000 1.000
27.200 531.000 1.000
27.260 502.000 1.000
27.320 468.000 1.000
27.380 440.000 1.000
27.440 404.000 1.000
27.500 371.000 1.000
27.560 352.000 1.000
27.620 319.000 1.000
27.680 332.000 1.000
27.740 315.000 1.000
27.800 315.000 1.000
27.860 281.000 1.000
27.920 275.000 1.000
27.980 260.000 1.000
28.040 264.000 1.000
28.100 266.000 1.000
28.160 247.000 1.000
28.220 215.000 1.000
28.280 212.000 1.000
28.340 237.000 1.000
28.400 219.000 1.000
28.460 226.000 1.000
28.520 205.000 1.000
28.580 204.000 1.000
28.640 204.000 1.000
28.700 198.000 1.000
28.760 177.000 1.000
28.820 210.000 1.000
28.880 198.000 1.000
28.940 193.000 1.000
29.000 175.000 1.000
29.060 187.000 1.000
29.120 176.000 1.000
29.180 172.000 1.000
29.240 181.000 1.000
29.300 161.000 1.000
29.360 202.000 1.000
29.420 194.000 1.000
29.480 179.000 1.000
29.540 176.000 1.000
29.600 168.000 1.000
29.660 170.000 1.000
29.720 174.000 1.000
29.780 194.000 1.000
29.840 179.000 1.000
29.900 182.000 1.000
29.960 167.000 1.000
30.020 151.000 1.000
30.080 160.000 1.000
30.140 150.000 1.000
30.200 139.000 1.000
30.260 141.000 1.000
30.320 128.000 1.000
30.380 116.000 1.000
30.440 129.000 1.000
30.500 131.000 1.000
30.560 142.000 1.000
30.620 140.000 1.000
30.680 121.000 1.000
30.740 125.000 1.000
30.800 145.000 1.000
30.860 149.000 1.000
30.920 156.000 1.000
30.980 119.000 1.000
31.040 138.000 1.000
31.100 122.000 1.000
31.160 117.000 1.000
31.220 126.000 1.000
31.280 130.000 1.000
31.340 117.000 1.000
31.400 115.000 1.000
31.460 129.000 1.000
31.520 110.000 1.000
31.580 117.000 1.000
31.640 131.000 1.000
31.700 115.000 1.000
31.760 122.000 1.000
31.820 112.000 1.000
31.880 109.000 1.000
31.940 121.000 1.000
32.000 109.000 1.000
32.060 126.000 1.000
32.120 115.000 1.000
32.180 113.000 1.000
32.240 109.000 1.000
32.300 109.000 1.000
32.360 104.000 1.000
32.420 124.000 1.000
32.480 101.000 1.000
32.540 115.000 1.000
32.600 125.000 1.000
32.660 105.000 1.000
32.720 106.000 1.000
32.780 117.000 1.000
32.840 119.000 1.000
32.900 106.000 1.000
32.960 107.000 1.000
33.020 101.000 1.000
33.080 109.000 1.000
33.140 104.000 1.000
33.200 100.000 1.000
33.260 95.000 1.000
33.320 117.000 1.000
33.380 109.000 1.000
33.440 98.000 1.000
33.500 101.000 1.000
33.560 99.000 1.000
33.620 102.000 1.000
33.680 108.000 1.000
33.740 114.000 1.000
33.800 104.000 1.000
33.860 108.000 1.000
33.920 104.000 1.000
33.980 99.000 1.000
34.040 113.000 1.000
34.100 98.000 1.000
34.160 100.000 1.000
34.220 94.000 1.000
34.280 106.000 1.000
34.340 109.000 1.000
34.400 115.000 1.000
34.460 126.000 1.000
34.520 101.000 1.000
34.580 108.000 1.000
34.640 128.000 1.000
34.700 126.000 1.000
34.760 140.000 1.000
34.820 138.000 1.000
34.880 132.000 1.000
34.940 133.000 1.000
35.000 108.000 1.000
35.060 114.000 1.000
35.120 130.000 1.000
35.180 130.000 1.000
35.240 118.000 1.000
35.300 140.000 1.000
35.360 144.000 1.000
35.420 125.000 1.000
35.480 142.000 1.000
35.540 144.000 1.000
35.600 143.000 1.000
35.660 138.000 1.000
35.720 117.000 1.000
35.780 136.000 1.000
35.840 119.000 1.000
35.900 118.000 1.000
35.960 127.000 1.000
36.020 140.000 1.000
36.080 124.000 1.000
36.140 126.000 1.000
36.200 128.000 1.000
36.260 132.000 1.000
36.320 139.000 1.000
36.380 144.000 1.000
36.440 165.000 1.000
36.500 217.000 1.000
36.560 341.000 1.000
36.620 533.000 1.000
36.680 634.000 1.000
36.740 654.000 1.000
36.800 440.000 1.000
36.860 336.000 1.000
36.920 236.000 1.000
36.980 157.000 1.000
37.040 146.000 1.000
37.100 134.000 1.000
37.160 121.000 1.000
37.220 125.000 1.000
37.280 132.000 1.000
37.340 114.000 1.000
37.400 108.000 1.000
37.460 119.000 1.000
37.520 110.000 1.000
37.580 110.000 1.000
37.640 107.000 1.000
37.700 101.000 1.000
37.760 112.000 1.000
37.820 107.000 1.000
37.880 94.000 1.000
37.940 98.000 1.000
38.000 108.000 1.000
38.060 102.000 1.000
38.120 111.000 1.000
38.180 96.000 1.000
38.240 101.000 1.000
38.300 97.000 1.000
38.360 100.000 1.000
38.420 101.000 1.000
38.480 98.000 1.000
38.540 83.000 1.000
38.600 101.000 1.000
38.660 96.000 1.000
38.720 94.000 1.000
38.780 97.000 1.000
38.840 95.000 1.000
38.900 103.000 1.000
38.960 100.000 1.000
39.020 95.000 1.000
39.080 82.000 1.000
39.140 102.000 1.000
39.200 102.000 1.000
39.260 100.000 1.000
39.320 119.000 1.000
39.380 107.000 1.000
39.440 98.000 1.000
39.500 95.000 1.000
39.560 109.000 1.000
39.620 104.000 1.000
39.680 91.000 1.000
39.740 105.000 1.000
39.800 101.000 1.000
39.860 94.000 1.000
39.920 94.000 1.000
39.980 102.000 1.000
40.040 94.000 1.000
40.100 106.000 1.000
40.160 85.000 1.000
40.220 100.000 1.000
40.280 109.000 1.000
40.340 84.000 1.000
40.400 89.000 1.000
40.460 102.000 1.000
40.520 99.000 1.000
40.580 96.000 1.000
40.640 106.000 1.000
40.700 97.000 1.000
40.760 98.000 1.000
40.820 96.000 1.000
40.880 94.000 1.000
40.940 109.000 1.000
41.000 94.000 1.000
41.060 92.000 1.000
41.120 91.000 1.000
41.180 110.000 1.000
41.240 92.000 1.000
41.300 87.000 1.000
41.360 101.000 1.000
41.420 101.000 1.000
41.480 103.000 1.000
41.540 87.000 1.000
41.600 114.000 1.000
41.660 110.000 1.000
41.720 96.000 1.000
41.780 106.000 1.000
41.840 89.000 1.000
41.900 90.000 1.000
41.960 105.000 1.000
42.020 106.000 1.000
42.080 85.000 1.000
42.140 107.000 1.000
42.200 113.000 1.000
42.260 107.000 1.000
42.320 111.000 1.000
42.380 141.000 1.000
42.440 150.000 1.000
42.500 179.000 1.000
42.560 249.000 1.000
42.620 252.000 1.000
42.680 258.000 1.000
42.740 202.000 1.000
42.800 191.000 1.000
42.860 144.000 1.000
42.920 126.000 1.000
42.980 108.000 1.000
43.040 118.000 1.000
43.100 101.000 1.000
43.160 123.000 1.000
43.220 115.000 1.000
43.280 121.000 1.000
43.340 138.000 1.000
43.400 101.000 1.000
43.460 115.000 1.000
43.520 106.000 1.000
43.580 109.000 1.000
43.640 107.000 1.000
43.700 111.000 1.000
43.760 105.000 1.000
43.820 93.000 1.000
43.880 103.000 1.000
43.940 97.000 1.000
44.000 108.000 1.000
44.060 110.000 1.000
44.120 103.000 1.000
44.180 108.000 1.000
44.240 103.000 1.000
44.300 113.000 1.000
44.360 114.000 1.000
44.420 101.000 1.000
44.480 104.000 1.000
44.540 92.000 1.000
44.600 104.000 1.000
44.660 90.000 1.000
44.720 103.000 1.000
44.780 117.000 1.000
44.840 114.000 1.000
44.900 100.000 1.000
44.960 92.000 1.000
45.020 89.000 1.000
45.080 101.000 1.000
45.140 110.000 1.000
45.200 99.000 1.000
45.260 103.000 1.000
45.320 91.000 1.000
45.380 87.000 1.000
45.440 103.000 1.000
45.500 95.000 1.000
45.560 90.000 1.000
45.620 87.000 1.000
45.680 106.000 1.000
45.740 94.000 1.000
45.800 93.000 1.000
45.860 78.000 1.000
45.920 97.000 1.000
45.980 95.000 1.000
46.040 88.000 1.000
46.100 95.000 1.000
46.160 86.000 1.000
46.220 82.000 1.000
46.280 90.000 1.000
46.340 96.000 1.000
46.400 95.000 1.000
46.460 86.000 1.000
46.520 99.000 1.000
46.580 96.000 1.000
46.640 88.000 1.000
46.700 99.000 1.000
46.760 97.000 1.000
46.820 99.000 1.000
46.880 94.000 1.000
46.940 77.000 1.000
47.000 93.000 1.000
47.060 87.000 1.000
47.120 96.000 1.000
47.180 92.000 1.000
47.240 110.000 1.000
47.300 94.000 1.000
47.360 85.000 1.000
47.420 92.000 1.000
47.480 90.000 1.000
47.540 115.000 1.000
47.600 89.000 1.000
47.660 99.000 1.000
47.720 89.000 1.000
47.780 75.000 1.000
47.840 93.000 1.000
47.900 100.000 1.000
47.960 88.000 1.000
48.020 83.000 1.000
48.080 73.000 1.000
48.140 80.000 1.000
48.200 85.000 1.000
48.260 84.000 1.000
48.320 80.000 1.000
48.380 94.000 1.000
48.440 76.000 1.000
48.500 84.000 1.000
48.560 94.000 1.000
48.620 96.000 1.000
48.680 108.000 1.000
48.740 99.000 1.000
48.800 81.000 1.000
48.860 76.000 1.000
48.920 87.000 1.000
48.980 78.000 1.000
49.040 81.000 1.000
49.100 76.000 1.000
49.160 93.000 1.000
49.220 86.000 1.000
49.280 82.000 1.000
49.340 97.000 1.000
49.400 87.000 1.000
49.460 69.000 1.000
49.520 91.000 1.000
49.580 80.000 1.000
49.640 81.000 1.000
49.700 83.000 1.000
49.760 91.000 1.000
49.820 81.000 1.000
49.880 93.000 1.000
49.940 83.000 1.000
50.000 102.000 1.000
50.060 87.000 1.000
50.120 97.000 1.000
50.180 81.000 1.000
50.240 91.000 1.000
50.300 76.000 1.000
50.360 93.000 1.000
50.420 88.000 1.000
50.480 91.000 1.000
50.540 93.000 1.000
50.600 79.000 1.000
50.660 101.000 1.000
50.720 89.000 1.000
50.780 87.000 1.000
50.840 118.000 1.000
50.900 104.000 1.000
50.960 104.000 1.000
51.020 103.000 1.000
51.080 82.000 1.000
51.140 96.000 1.000
51.200 97.000 1.000
51.260 87.000 1.000
51.320 97.000 1.000
51.380 89.000 1.000
51.440 82.000 1.000
51.500 103.000 1.000
51.560 94.000 1.000
51.620 89.000 1.000
51.680 87.000 1.000
51.740 101.000 1.000
51.800 99.000 1.000
51.860 80.000 1.000
51.920 108.000 1.000
51.980 89.000 1.000
52.040 97.000 1.000
52.100 104.000 1.000
52.160 99.000 1.000
52.220 112.000 1.000
52.280 104.000 1.000
52.340 92.000 1.000
52.400 92.000 1.000
52.460 102.000 1.000
52.520 116.000 1.000
52.580 97.000 1.000
52.640 107.000 1.000
52.700 112.000 1.000
52.760 105.000 1.000
52.820 125.000 1.000
52.880 116.000 1.000
52.940 132.000 1.000
53.000 112.000 1.000
53.060 138.000 1.000
53.120 122.000 1.000
53.180 129.000 1.000
53.240 105.000 1.000
53.300 109.000 1.000
53.360 131.000 1.000
53.420 128.000 1.000
53.480 120.000 1.000
53.540 131.000 1.000
53.600 138.000 1.000
53.660 140.000 1.000
53.720 125.000 1.000
53.780 145.000 1.000
53.840 138.000 1.000
53.900 150.000 1.000
53.960 147.000 1.000
54.020 167.000 1.000
54.080 148.000 1.000
54.140 152.000 1.000
54.200 167.000 1.000
54.260 146.000 1.000
54.320 199.000 1.000
54.380 251.000 1.000
54.440 245.000 1.000
54.500 285.000 1.000
54.560 296.000 1.000
54.620 284.000 1.000
54.680 238.000 1.000
54.740 208.000 1.000
54.800 173.000 1.000
54.860 150.000 1.000
54.920 135.000 1.000
54.980 127.000 1.000
55.040 121.000 1.000
55.100 104.000 1.000
55.160 98.000 1.000
55.220 94.000 1.000
55.280 84.000 1.000
55.340 107.000 1.000
55.400 102.000 1.000
55.460 93.000 1.000
55.520 82.000 1.000
55.580 77.000 1.000
55.640 97.000 1.000
55.700 86.000 1.000
55.760 92.000 1.000
55.820 84.000 1.000
55.880 83.000 1.000
55.940 91.000 1.000
56.000 88.000 1.000
56.060 80.000 1.000
56.120 85.000 1.000
56.180 101.000 1.000
56.240 87.000 1.000
56.300 78.000 1.000
56.360 95.000 1.000
56.420 75.000 1.000
56.480 89.000 1.000
56.540 83.000 1.000
56.600 79.000 1.000
56.660 67.000 1.000
56.720 89.000 1.000
56.780 82.000 1.000
56.840 94.000 1.000
56.900 86.000 1.000
56.960 91.000 1.000
57.020 85.000 1.000
57.080 75.000 1.000
57.140 76.000 1.000
57.200 79.000 1.000
57.260 85.000 1.000
57.320 77.000 1.000
57.380 84.000 1.000
57.440 86.000 1.000
57.500 64.000 1.000
57.560 87.000 1.000
57.620 86.000 1.000
57.680 86.000 1.000
57.740 74.000 1.000
57.800 82.000 1.000
57.860 82.000 1.000
57.920 70.000 1.000
57.980 87.000 1.000
58.040 89.000 1.000
58.100 76.000 1.000
58.160 77.000 1.000
58.220 80.000 1.000
58.280 76.000 1.000
58.340 84.000 1.000
58.400 70.000 1.000
58.460 77.000 1.000
58.520 82.000 1.000
58.580 71.000 1.000
58.640 77.000 1.000
58.700 71.000 1.000
58.760 73.000 1.000
58.820 88.000 1.000
58.880 77.000 1.000
58.940 66.000 1.000
59.000 71.000 1.000
59.060 84.000 1.000
59.120 91.000 1.000
59.180 82.000 1.000
59.240 69.000 1.000
59.300 70.000 1.000
59.360 78.000 1.000
59.420 82.000 1.000
59.480 80.000 1.000
59.540 73.000 1.000
59.600 74.000 1.000
59.660 76.000 1.000
59.720 74.000 1.000
59.780 75.000 1.000
59.840 76.000 1.000
59.900 76.000 1.000
59.960 88.000 1.000
60.020 86.000 1.000
60.080 64.000 1.000
60.140 75.000 1.000
60.200 75.000 1.000
60.260 73.000 1.000
60.320 72.000 1.000
60.380 72.000 1.000
60.440 76.000 1.000
60.500 84.000 1.000
60.560 66.000 1.000
60.620 77.000 1.000
60.680 81.000 1.000
60.740 79.000 1.000
60.800 77.000 1.000
60.860 79.000 1.000
60.920 91.000 1.000
60.980 95.000 1.000
61.040 88.000 1.000
61.100 81.000 1.000
61.160 79.000 1.000
61.220 82.000 1.000
61.280 74.000 1.000
61.340 96.000 1.000
61.400 90.000 1.000
61.460 92.000 1.000
61.520 94.000 1.000
61.580 123.000 1.000
61.640 132.000 1.000
61.700 137.000 1.000
61.760 166.000 1.000
61.820 179.000 1.000
61.880 169.000 1.000
61.940 176.000 1.000
62.000 139.000 1.000
62.060 122.000 1.000
62.120 98.000 1.000
62.180 89.000 1.000
62.240 81.000 1.000
62.300 89.000 1.000
62.360 82.000 1.000
62.420 89.000 1.000
62.480 83.000 1.000
62.540 86.000 1.000
62.600 82.000 1.000
62.660 84.000 1.000
62.720 84.000 1.000
62.780 63.000 1.000
62.840 73.000 1.000
62.900 71.000 1.000
62.960 84.000 1.000
63.020 66.000 1.000
63.080 75.000 1.000
63.140 69.000 1.000
63.200 72.000 1.000
63.260 78.000 1.000
63.320 87.000 1.000
63.380 80.000 1.000
63.440 59.000 1.000
63.500 75.000 1.000
63.560 59.000 1.000
63.620 65.000 1.000
63.680 73.000 1.000
63.740 69.000 1.000
63.800 75.000 1.000
63.860 74.000 1.000
63.920 69.000 1.000
63.980 76.000 1.000
64.040 70.000 1.000
64.100 64.000 1.000
64.160 63.000 1.000
64.220 69.000 1.000
64.280 68.000 1.000
64.340 80.000 1.000
64.400 69.000 1.000
64.460 76.000 1.000
64.520 82.000 1.000
64.580 75.000 1.000
64.640 85.000 1.000
64.700 78.000 1.000
64.760 58.000 1.000
64.820 79.000 1.000
64.880 63.000 1.000
64.940 71.000 1.000
65.000 63.000 1.000
65.060 72.000 1.000
65.120 69.000 1.000
65.180 63.000 1.000
65.240 61.000 1.000
65.300 73.000 1.000
65.360 83.000 1.000
65.420 63.000 1.000
65.480 73.000 1.000
65.540 69.000 1.000
65.600 71.000 1.000
65.660 66.000 1.000
65.720 70.000 1.000
65.780 70.000 1.000
65.840 74.000 1.000
65.900 75.000 1.000
65.960 78.000 1.000
66.020 53.000 1.000
66.080 60.000 1.000
66.140 61.000 1.000
66.200 63.000 1.000
66.260 73.000 1.000
66.320 61.000 1.000
66.380 87.000 1.000
66.440 75.000 1.000
66.500 75.000 1.000
66.560 56.000 1.000
66.620 72.000 1.000
66.680 63.000 1.000
66.740 60.000 1.000
66.800 73.000 1.000
66.860 64.000 1.000
66.920 72.000 1.000
66.980 81.000 1.000
67.040 69.000 1.000
67.100 73.000 1.000
67.160 74.000 1.000
67.220 71.000 1.000
67.280 57.000 1.000
67.340 63.000 1.000
67.400 53.000 1.000
67.460 60.000 1.000
67.520 69.000 1.000
67.580 80.000 1.000
67.640 74.000 1.000
67.700 71.000 1.000
67.760 78.000 1.000
67.820 65.000 1.000
67.880 52.000 1.000
67.940 61.000 1.000
68.000 74.000 1.000
68.060 66.000 1.000
68.120 71.000 1.000
68.180 67.000 1.000
68.240 71.000 1.000
68.300 68.000 1.000
68.360 72.000 1.000
68.420 74.000 1.000
68.480 69.000 1.000
68.540 64.000 1.000
68.600 76.000 1.000
68.660 61.000 1.000
68.720 59.000 1.000
68.780 75.000 1.000
68.840 75.000 1.000
68.900 68.000 1.000
68.960 72.000 1.000
69.020 65.000 1.000
69.080 57.000 1.000
69.140 72.000 1.000
69.200 62.000 1.000
69.260 61.000 1.000
69.320 65.000 1.000
69.380 77.000 1.000
69.440 83.000 1.000
69.500 62.000 1.000
69.560 70.000 1.000
69.620 76.000 1.000
69.680 73.000 1.000
69.740 66.000 1.000
69.800 56.000 1.000
69.860 65.000 1.000
69.920 64.000 1.000
69.980 68.000 1.000
70.040 67.000 1.000
70.100 74.000 1.000
70.160 69.000 1.000
70.220 60.000 1.000
70.280 64.000 1.000
70.340 72.000 1.000
70.400 70.000 1.000
70.460 61.000 1.000
70.520 65.000 1.000
70.580 66.000 1.000
70.640 61.000 1.000
70.700 76.000 1.000
70.760 51.000 1.000
70.820 73.000 1.000
70.880 52.000 1.000
70.940 68.000 1.000
71.000 66.000 1.000
71.060 63.000 1.000
71.120 65.000 1.000
71.180 65.000 1.000
71.240 73.000 1.000
71.300 72.000 1.000
71.360 62.000 1.000
71.420 58.000 1.000
71.480 58.000 1.000
71.540 78.000 1.000
71.600 55.000 1.000
71.660 70.000 1.000
71.720 68.000 1.000
71.780 65.000 1.000
71.840 83.000 1.000
71.900 54.000 1.000
71.960 62.000 1.000
72.020 61.000 1.000
72.080 72.000 1.000
72.140 62.000 1.000
72.200 67.000 1.000
72.260 63.000 1.000
72.320 54.000 1.000
72.380 62.000 1.000
72.440 66.000 1.000
72.500 74.000 1.000
72.560 54.000 1.000
72.620 68.000 1.000
72.680 81.000 1.000
72.740 75.000 1.000
72.800 77.000 1.000
72.860 77.000 1.000
72.920 65.000 1.000
72.980 72.000 1.000
73.040 75.000 1.000
73.100 79.000 1.000
73.160 76.000 1.000
73.220 63.000 1.000
73.280 86.000 1.000
73.340 82.000 1.000
73.400 77.000 1.000
73.460 67.000 1.000
73.520 83.000 1.000
73.580 78.000 1.000
73.640 78.000 1.000
73.700 86.000 1.000
73.760 79.000 1.000
73.820 60.000 1.000
73.880 82.000 1.000
73.940 111.000 1.000
74.000 114.000 1.000
74.060 121.000 1.000
74.120 121.000 1.000
74.180 110.000 1.000
74.240 106.000 1.000
74.300 105.000 1.000
74.360 81.000 1.000
74.420 75.000 1.000
74.480 71.000 1.000
74.540 79.000 1.000
74.600 85.000 1.000
74.660 64.000 1.000
74.720 67.000 1.000
74.780 70.000 1.000
74.840 63.000 1.000
74.900 62.000 1.000
74.960 68.000 1.000
75.020 61.000 1.000
75.080 67.000 1.000
75.140 78.000 1.000
75.200 69.000 1.000
75.260 79.000 1.000
75.320 63.000 1.000
75.380 67.000 1.000
75.440 80.000 1.000
75.500 77.000 1.000
75.560 67.000 1.000
75.620 70.000 1.000
75.680 58.000 1.000
75.740 80.000 1.000
75.800 81.000 1.000
75.860 58.000 1.000
75.920 63.000 1.000
75.980 72.000 1.000
76.040 65.000 1.000
76.100 79.000 1.000
76.160 62.000 1.000
76.220 67.000 1.000
76.280 64.000 1.000
76.340 60.000 1.000
76.400 65.000 1.000
76.460 66.000 1.000
76.520 71.000 1.000
76.580 59.000 1.000
76.640 64.000 1.000
76.700 71.000 1.000
76.760 77.000 1.000
76.820 76.000 1.000
76.880 58.000 1.000
76.940 56.000 1.000
77.000 79.000 1.000
77.060 68.000 1.000
77.120 70.000 1.000
77.180 73.000 1.000
77.240 59.000 1.000
77.300 71.000 1.000
77.360 64.000 1.000
77.420 70.000 1.000
77.480 67.000 1.000
77.540 65.000 1.000
77.600 68.000 1.000
77.660 74.000 1.000
77.720 67.000 1.000
77.780 59.000 1.000
77.840 74.000 1.000
77.900 65.000 1.000
77.960 68.000 1.000
78.020 77.000 1.000
78.080 85.000 1.000
78.140 70.000 1.000
78.200 66.000 1.000
78.260 71.000 1.000
78.320 59.000 1.000
78.380 57.000 1.000
78.440 69.000 1.000
78.500 60.000 1.000
78.560 60.000 1.000
78.620 48.000 1.000
78.680 58.000 1.000
78.740 68.000 1.000
78.800 63.000 1.000
78.860 81.000 1.000
78.920 64.000 1.000
78.980 55.000 1.000
79.040 55.000 1.000
79.100 62.000 1.000
79.160 58.000 1.000
79.220 55.000 1.000
79.280 62.000 1.000
79.340 52.000 1.000
79.400 65.000 1.000
79.460 54.000 1.000
79.520 71.000 1.000
79.580 67.000 1.000
79.640 73.000 1.000
79.700 68.000 1.000
79.760 55.000 1.000
79.820 65.000 1.000
79.880 76.000 1.000
79.940 60.000 1.000
80.000 61.000 1.000
80.060 57.000 1.000
80.120 65.000 1.000
80.180 66.000 1.000
80.240 53.000 1.000
80.300 63.000 1.000
80.360 62.000 1.000
80.420 53.000 1.000
80.480 66.000 1.000
80.540 67.000 1.000
80.600 58.000 1.000
80.660 60.000 1.000
80.720 78.000 1.000
80.780 64.000 1.000
80.840 61.000 1.000
80.900 49.000 1.000
80.960 73.000 1.000
81.020 54.000 1.000
81.080 73.000 1.000
81.140 66.000 1.000
81.200 51.000 1.000
81.260 63.000 1.000
81.320 71.000 1.000
81.380 71.000 1.000
81.440 57.000 1.000
81.500 59.000 1.000
81.560 60.000 1.000
81.620 65.000 1.000
81.680 64.000 1.000
81.740 55.000 1.000
81.800 56.000 1.000
81.860 68.000 1.000
81.920 67.000 1.000
81.980 67.000 1.000
82.040 73.000 1.000
82.100 50.000 1.000
82.160 62.000 1.000
82.220 59.000 1.000
82.280 66.000 1.000
82.340 62.000 1.000
82.400 53.000 1.000
82.460 68.000 1.000
82.520 63.000 1.000
82.580 61.000 1.000
82.640 59.000 1.000
82.700 65.000 1.000
82.760 53.000 1.000
82.820 77.000 1.000
82.880 59.000 1.000
82.940 60.000 1.000
83.000 59.000 1.000
83.060 53.000 1.000
83.120 49.000 1.000
83.180 67.000 1.000
83.240 61.000 1.000
83.300 71.000 1.000
83.360 62.000 1.000
83.420 47.000 1.000
83.480 58.000 1.000
83.540 54.000 1.000
83.600 59.000 1.000
83.660 67.000 1.000
83.720 65.000 1.000
83.780 74.000 1.000
83.840 74.000 1.000
83.900 57.000 1.000
83.960 77.000 1.000
84.020 67.000 1.000
84.080 55.000 1.000
84.140 52.000 1.000
84.200 55.000 1.000
84.260 47.000 1.000
84.320 70.000 1.000
84.380 63.000 1.000
84.440 56.000 1.000
84.500 58.000 1.000
84.560 70.000 1.000
84.620 66.000 1.000
84.680 57.000 1.000
84.740 62.000 1.000
84.800 74.000 1.000
84.860 58.000 1.000
84.920 55.000 1.000
84.980 71.000 1.000
85.040 60.000 1.000
85.100 50.000 1.000
85.160 60.000 1.000
85.220 76.000 1.000
85.280 73.000 1.000
85.340 81.000 1.000
85.400 61.000 1.000
85.460 60.000 1.000
85.520 50.000 1.000
85.580 71.000 1.000
85.640 50.000 1.000
85.700 78.000 1.000
85.760 57.000 1.000
85.820 62.000 1.000
85.880 77.000 1.000
85.940 66.000 1.000
86.000 61.000 1.000
86.060 61.000 1.000
86.120 63.000 1.000
86.180 60.000 1.000
86.240 77.000 1.000
86.300 51.000 1.000
86.360 63.000 1.000
86.420 78.000 1.000
86.480 58.000 1.000
86.540 48.000 1.000
86.600 65.000 1.000
86.660 90.000 1.000
86.720 69.000 1.000
86.780 67.000 1.000
86.840 68.000 1.000
86.900 57.000 1.000
86.960 80.000 1.000
87.020 75.000 1.000
87.080 60.000 1.000
87.140 64.000 1.000
87.200 64.000 1.000
87.260 56.000 1.000
87.320 61.000 1.000
87.380 59.000 1.000
87.440 66.000 1.000
87.500 54.000 1.000
87.560 63.000 1.000
87.620 66.000 1.000
87.680 50.000 1.000
87.740 57.000 1.000
87.800 71.000 1.000
87.860 59.000 1.000
87.920 63.000 1.000
87.980 60.000 1.000
88.040 65.000 1.000
88.100 51.000 1.000
88.160 55.000 1.000
88.220 54.000 1.000
88.280 59.000 1.000
88.340 48.000 1.000
88.400 74.000 1.000
88.460 54.000 1.000
88.520 54.000 1.000
88.580 57.000 1.000
88.640 58.000 1.000
88.700 59.000 1.000
88.760 63.000 1.000
88.820 76.000 1.000
88.880 75.000 1.000
88.940 50.000 1.000
89.000 46.000 1.000
89.060 68.000 1.000
89.120 54.000 1.000
89.180 68.000 1.000
89.240 65.000 1.000
89.300 55.000 1.000
89.360 46.000 1.000
89.420 55.000 1.000
89.480 55.000 1.000
89.540 51.000 1.000
89.600 63.000 1.000
89.660 61.000 1.000
89.720 64.000 1.000
89.780 61.000 1.000
89.840 60.000 1.000
89.900 52.000 1.000
89.960 53.000 1.000
90.000 54.000 1.000
*RAS_INT_END
*RAS_DATA_END