File: Lab/XRD/all_in_one/cu2o_011.ras
*RAS_DATA_START
*RAS_HEADER_START
*CORR_POS_DB_NAME "DTEX_11112016"
*CORR_POS_GONIO_RADIUS ""
*CORR_POS_NODE_INDEX01 ""
*CORR_POS_NODE_INDEX02 ""
*CORR_POS_NODE_INDEX03 ""
*CORR_POS_NODE_INDEX04 ""
*CORR_POS_NODE_INDEX05 ""
*CORR_POS_NODE_INDEX06 ""
*CORR_POS_NODE_INDEX07 ""
*CORR_POS_NODE_INDEX08 ""
*CORR_POS_NODE_INDEX09 ""
*CORR_POS_NODE_INDEX10 ""
*CORR_POS_NODE_INDEX11 ""
*CORR_POS_NODE_LABEL01 "Si(111)"
*CORR_POS_NODE_LABEL02 "Si(220)"
*CORR_POS_NODE_LABEL03 "Si(311)"
*CORR_POS_NODE_LABEL04 "Si(400)"
*CORR_POS_NODE_LABEL05 "Si(331)"
*CORR_POS_NODE_LABEL06 "Si(422)"
*CORR_POS_NODE_LABEL07 "Si(511)"
*CORR_POS_NODE_LABEL08 "Si(440)"
*CORR_POS_NODE_LABEL09 "Si(531)"
*CORR_POS_NODE_LABEL10 "Si(620)"
*CORR_POS_NODE_LABEL11 "Si(533)"
*CORR_POS_NODE_POS_CALC01 "28.4137"
*CORR_POS_NODE_POS_CALC02 "47.2707"
*CORR_POS_NODE_POS_CALC03 "56.0883"
*CORR_POS_NODE_POS_CALC04 "69.0934"
*CORR_POS_NODE_POS_CALC05 "76.3385"
*CORR_POS_NODE_POS_CALC06 "87.9915"
*CORR_POS_NODE_POS_CALC07 "94.9137"
*CORR_POS_NODE_POS_CALC08 "106.67"
*CORR_POS_NODE_POS_CALC09 "114.054"
*CORR_POS_NODE_POS_CALC10 "127.508"
*CORR_POS_NODE_POS_CALC11 "136.858"
*CORR_POS_NODE_POS_MEAS01 "28.3712"
*CORR_POS_NODE_POS_MEAS02 "47.2304"
*CORR_POS_NODE_POS_MEAS03 "56.0465"
*CORR_POS_NODE_POS_MEAS04 "69.0523"
*CORR_POS_NODE_POS_MEAS05 "76.2993"
*CORR_POS_NODE_POS_MEAS06 "87.9512"
*CORR_POS_NODE_POS_MEAS07 "94.8772"
*CORR_POS_NODE_POS_MEAS08 "106.636"
*CORR_POS_NODE_POS_MEAS09 "114.028"
*CORR_POS_NODE_POS_MEAS10 "127.48"
*CORR_POS_NODE_POS_MEAS11 "136.839"
*CORR_POS_OPT_ATTR "集中法"
*CORR_POS_PARAM_MU ""
*CORR_POS_PARAM_PL ""
*CORR_POS_SEMODEL_TYPE "0"
*CORR_POS_STANDARD_TYPE ""
*CORR_POS_VALUE_ANALYZER "None"
*CORR_POS_VALUE_CMONO "None"
*CORR_POS_VALUE_IMONO "None"
*CORR_POS_VALUE_IS "0.625deg"
*CORR_POS_VALUE_ISL "10.0mm"
*CORR_POS_VALUE_ISOLLER "2.5deg"
*CORR_POS_VALUE_RS1 "13.0mm"
*CORR_POS_VALUE_RS2 "13.0mm"
*CORR_POS_VALUE_RSOLLER "2.5deg"
*CORR_POS_XG_FOCUS_L ""
*CORR_POS_XG_WAVE_TYPE ""
*CORR_POS_XG_WAVE_VALUE ""
*DISP_FMT_X "%.2f"
*DISP_FMT_Y "%.0f"
*DISP_FULLSCALE "6734.4000000000"
*DISP_LINE_COLOR "255.0000000000"
*DISP_LINE_STYLE "0.0000000000"
*DISP_LINE_WIDTH "0.2500000000"
*DISP_NOTE "Collected Data-3"
*DISP_OFFSET_Y "0.0000000000"
*DISP_PEAKSEARCH_UNIT_Y "COUNTS"
*DISP_RANGE_BOTTOM "0.0000000000"
*DISP_RANGE_LEFT "20.0000000000"
*DISP_RANGE_LOGCUTOFF "0.0100000000"
*DISP_RANGE_RIGHT "90.0000000000"
*DISP_RANGE_TOP "6734.4000000000"
*DISP_SCALE_MODE_Y "0.0000000000"
*DISP_TAB_NAME "Theta/2-Theta"
*DISP_TITLE_Y "Intensity"
*DISP_UNIT_Y "COUNTS"
*DISP_WINDOW_NAME "MSG_MACROENGINE"
*FILE_COMMENT " "
*FILE_MD5 ""
*FILE_MEMO " "
*FILE_OPERATOR "MiniFlex"
*FILE_PART_ID "MEAS_PBEA_00223"
*FILE_SAMPLE "cu2o_011_20-90_2theta_speed20_step0.02"
*FILE_TYPE "RAS_RAW"
*FILE_USERGROUP "System User"
*FILE_VERSION "1.0000000000"
*HW_ATTACHMENT_ID "ATT1031"
*HW_ATTACHMENT_NAME "6サンプルチェンジャ|ASC-6"
*HW_COUNTER_ID-0 "CUT0025"
*HW_COUNTER_ID-1 "CUT0020"
*HW_COUNTER_ID-2 "CUT0020"
*HW_COUNTER_ID-3 "CMC0021"
*HW_COUNTER_NAME-0 "D/teX Ultra|D/teX Ultra"
*HW_COUNTER_NAME-1 "None|None"
*HW_COUNTER_NAME-2 "None|None"
*HW_COUNTER_NAME-3 "検出器モノクロメータ|Detector monochromator"
*HW_COUNTER_SELECT_NAME "D/teX Ultra|D/teX Ultra"
*HW_GONIOMETER_ID "GON0070"
*HW_GONIOMETER_NAME "MiniFlex 300/600|MiniFlex 300/600"
*HW_GONIOMETER_RADIUS-0 "79.0"
*HW_GONIOMETER_RADIUS-1 "91.5"
*HW_GONIOMETER_RADIUS-2 "150.0"
*HW_GONIOMETER_RADIUS-3 "0"
*HW_GONIOMETER_RADIUS-4 "103.4"
*HW_GONIOMETER_RADIUS-5 "150.0"
*HW_GONIOMETER_RADIUS-6 "46.6"
*HW_GONIOMETER_RADIUS-7 "160.0"
*HW_I_OPT_ID-0 "ISL0021"
*HW_I_OPT_ID-1 "ISO0021"
*HW_I_OPT_NAME-0 "発散スリット|Divergence slit"
*HW_I_OPT_NAME-1 "入射平行スリット|Incident parallel slit"
*HW_R_ATTENUATER_AUTOMODE "0"
*HW_R_OPT_ID-0 "RSS0021"
*HW_R_OPT_ID-1 "RSO0021"
*HW_R_OPT_ID-2 "RRS0021"
*HW_R_OPT_NAME-0 "散乱スリット|Scattering slit"
*HW_R_OPT_NAME-1 "受光平行スリット|Receiving soller slit"
*HW_R_OPT_NAME-2 "受光スリット|Receiving slit"
*HW_SAMPLE_HOLDER_ID "SMP0000"
*HW_SAMPLE_HOLDER_NAME "無し|None"
*HW_XG_CURRENT_MAX "15"
*HW_XG_CURRENT_MIN "2"
*HW_XG_CURRENT_RESOLUTION "1"
*HW_XG_CURRENT_UNIT "mA"
*HW_XG_FOCUS "1mm x 10mm"
*HW_XG_FOCUS_TYPE "Normal"
*HW_XG_ID "1060"
*HW_XG_NAME "300W/600W 封入管-B|300W/600W Sealed tube-B"
*HW_XG_TARGET_ATOMIC_NUMBER "29.0000000000"
*HW_XG_TARGET_NAME "Cu"
*HW_XG_TYPE "Hermetic"
*HW_XG_VOLTAGE_MAX "40"
*HW_XG_VOLTAGE_MIN "20"
*HW_XG_VOLTAGE_RESOLUTION "1"
*HW_XG_VOLTAGE_UNIT "kV"
*HW_XG_WATT_MAX "1"
*HW_XG_WATT_UNIT "kW"
*HW_XG_WAVE_LENGTH_ALPHA1 "1.540593"
*HW_XG_WAVE_LENGTH_ALPHA2 "1.544414"
*HW_XG_WAVE_LENGTH_BETA "1.392250"
*MEAS_COND_AXIS_NAME-0 "Theta/2-Theta"
*MEAS_COND_AXIS_NAME-1 "Spin"
*MEAS_COND_AXIS_NAME-2 "Change"
*MEAS_COND_AXIS_NAME-3 "Soller(inc.)"
*MEAS_COND_AXIS_NAME-4 "IHS"
*MEAS_COND_AXIS_NAME-5 "DS"
*MEAS_COND_AXIS_NAME-6 "SS"
*MEAS_COND_AXIS_NAME-7 "Soller(rec.)"
*MEAS_COND_AXIS_NAME-8 "RS"
*MEAS_COND_AXIS_NAME-9 "Filter"
*MEAS_COND_AXIS_NAME-10 "Monochromator"
*MEAS_COND_AXIS_NAME-11 "PHA"
*MEAS_COND_AXIS_NAME_INTERNAL-0 "TwoThetaTheta"
*MEAS_COND_AXIS_NAME_INTERNAL-1 "Spin"
*MEAS_COND_AXIS_NAME_INTERNAL-2 "Change"
*MEAS_COND_AXIS_NAME_INTERNAL-3 "IncidentSollerSlit"
*MEAS_COND_AXIS_NAME_INTERNAL-4 "IncidentAxdSlit"
*MEAS_COND_AXIS_NAME_INTERNAL-5 "IncidentSlitBox"
*MEAS_COND_AXIS_NAME_INTERNAL-6 "ReceivingSlitBox1"
*MEAS_COND_AXIS_NAME_INTERNAL-7 "ReceivingSollerSlit"
*MEAS_COND_AXIS_NAME_INTERNAL-8 "ReceivingSlitBox2"
*MEAS_COND_AXIS_NAME_INTERNAL-9 "Filter"
*MEAS_COND_AXIS_NAME_INTERNAL-10 "CounterMonochromator"
*MEAS_COND_AXIS_NAME_INTERNAL-11 "PHA"
*MEAS_COND_AXIS_NAME_MAGICNO-0 "268632064.0000000000"
*MEAS_COND_AXIS_NAME_MAGICNO-1 "16842752.0000000000"
*MEAS_COND_AXIS_NAME_MAGICNO-2 "16842752.0000000000"
*MEAS_COND_AXIS_NAME_MAGICNO-3 "20971521.0000000000"
*MEAS_COND_AXIS_NAME_MAGICNO-4 "22020097.0000000000"
*MEAS_COND_AXIS_NAME_MAGICNO-5 "22020097.0000000000"
*MEAS_COND_AXIS_NAME_MAGICNO-6 "23068673.0000000000"
*MEAS_COND_AXIS_NAME_MAGICNO-7 "20971521.0000000000"
*MEAS_COND_AXIS_NAME_MAGICNO-8 "23068673.0000000000"
*MEAS_COND_AXIS_NAME_MAGICNO-9 "20971521.0000000000"
*MEAS_COND_AXIS_NAME_MAGICNO-10 "20971521.0000000000"
*MEAS_COND_AXIS_NAME_MAGICNO-11 "0.0000000000"
*MEAS_COND_AXIS_OFFSET-0 "0.0000000000"
*MEAS_COND_AXIS_OFFSET-1 "-"
*MEAS_COND_AXIS_OFFSET-2 "-"
*MEAS_COND_AXIS_OFFSET-3 "-"
*MEAS_COND_AXIS_OFFSET-4 "-"
*MEAS_COND_AXIS_OFFSET-5 "-"
*MEAS_COND_AXIS_OFFSET-6 "-"
*MEAS_COND_AXIS_OFFSET-7 "-"
*MEAS_COND_AXIS_OFFSET-8 "-"
*MEAS_COND_AXIS_OFFSET-9 "-"
*MEAS_COND_AXIS_OFFSET-10 "-"
*MEAS_COND_AXIS_OFFSET-11 "-"
*MEAS_COND_AXIS_POSITION-0 "10.0000000000"
*MEAS_COND_AXIS_POSITION-1 "0.0000000000"
*MEAS_COND_AXIS_POSITION-2 "4.0000000000"
*MEAS_COND_AXIS_POSITION-3 "2.5deg"
*MEAS_COND_AXIS_POSITION-4 "2.0mm"
*MEAS_COND_AXIS_POSITION-5 "0.625deg"
*MEAS_COND_AXIS_POSITION-6 "13.0mm(Open)"
*MEAS_COND_AXIS_POSITION-7 "2.5deg"
*MEAS_COND_AXIS_POSITION-8 "13.0mm"
*MEAS_COND_AXIS_POSITION-9 "K-beta(x1)"
*MEAS_COND_AXIS_POSITION-10 "None"
*MEAS_COND_AXIS_POSITION-11 "41.0000000000"
*MEAS_COND_AXIS_UNIT-0 "deg"
*MEAS_COND_AXIS_UNIT-1 ""
*MEAS_COND_AXIS_UNIT-2 ""
*MEAS_COND_AXIS_UNIT-3 ""
*MEAS_COND_AXIS_UNIT-4 ""
*MEAS_COND_AXIS_UNIT-5 ""
*MEAS_COND_AXIS_UNIT-6 ""
*MEAS_COND_AXIS_UNIT-7 ""
*MEAS_COND_AXIS_UNIT-8 ""
*MEAS_COND_AXIS_UNIT-9 ""
*MEAS_COND_AXIS_UNIT-10 ""
*MEAS_COND_AXIS_UNIT-11 "div"
*MEAS_COND_CORRECTION_SLIT_COUNTERMONO "None"
*MEAS_COND_CORRECTION_SLIT_DS "0.625deg"
*MEAS_COND_CORRECTION_SLIT_FILTER "None"
*MEAS_COND_CORRECTION_SLIT_IHS "2.0mm"
*MEAS_COND_CORRECTION_SLIT_RS "13.0mm"
*MEAS_COND_CORRECTION_SLIT_SOLLER_INC "2.5deg"
*MEAS_COND_CORRECTION_SLIT_SOLLER_REC "2.5deg"
*MEAS_COND_CORRECTION_SLIT_SS "13.0mm"
*MEAS_COND_COUNTER_CNTLOSS_CORR "0.0000000000"
*MEAS_COND_COUNTER_PHABASE "41.0000000000"
*MEAS_COND_COUNTER_PHAWINDOW "14.0000000000"
*MEAS_COND_COUNTER_PHA_UNIT "div"
*MEAS_COND_COUNTER_TAUDIFF "0.2500000000"
*MEAS_COND_COUNTER_TAUINT "0.7500000000"
*MEAS_COND_IRRADIATION_MODE "OFF"
*MEAS_COND_IRRADIATION_WIDTH ""
*MEAS_COND_OPT_ATTR " "
*MEAS_COND_OPT_NAME ""
*MEAS_COND_UNSYMMETRIC_MODE "OFF"
*MEAS_COND_XG_CURRENT "15.0000000000"
*MEAS_COND_XG_VOLTAGE "40.0000000000"
*MEAS_COND_XG_WAVE_TYPE "Ka"
*MEAS_DATA_COUNT "3501.0000000000"
*MEAS_SCAN_AXIS_X "Theta/2-Theta"
*MEAS_SCAN_AXIS_X_INTERNAL "TwoThetaTheta"
*MEAS_SCAN_END_TIME "09/06/17 11:49:24"
*MEAS_SCAN_MODE "CONTINUOUS"
*MEAS_SCAN_MONITOR "0"
*MEAS_SCAN_RESOLUTION_X "0.005"
*MEAS_SCAN_SPEED "20.000"
*MEAS_SCAN_SPEED_UNIT "deg/min"
*MEAS_SCAN_SPEED_USER "20.000"
*MEAS_SCAN_START "20.0000000000"
*MEAS_SCAN_START_TIME "09/06/17 11:45:22"
*MEAS_SCAN_STEP "0.0200000000"
*MEAS_SCAN_STOP "90.0000000000"
*MEAS_SCAN_UNIT_X "deg"
*MEAS_SCAN_UNIT_Y "counts"
*SLIT_SYSTEM "0"
*RAS_HEADER_END
*RAS_INT_START
20.000 117.000 1.000
20.060 129.000 1.000
20.120 139.000 1.000
20.180 136.000 1.000
20.240 143.000 1.000
20.300 134.000 1.000
20.360 124.000 1.000
20.420 143.000 1.000
20.480 145.000 1.000
20.540 126.000 1.000
20.600 122.000 1.000
20.660 151.000 1.000
20.720 126.000 1.000
20.780 144.000 1.000
20.840 138.000 1.000
20.900 145.000 1.000
20.960 157.000 1.000
21.020 143.000 1.000
21.080 149.000 1.000
21.140 150.000 1.000
21.200 157.000 1.000
21.260 160.000 1.000
21.320 142.000 1.000
21.380 147.000 1.000
21.440 141.000 1.000
21.500 154.000 1.000
21.560 144.000 1.000
21.620 136.000 1.000
21.680 147.000 1.000
21.740 159.000 1.000
21.800 148.000 1.000
21.860 133.000 1.000
21.920 161.000 1.000
21.980 157.000 1.000
22.040 156.000 1.000
22.100 164.000 1.000
22.160 162.000 1.000
22.220 149.000 1.000
22.280 157.000 1.000
22.340 149.000 1.000
22.400 183.000 1.000
22.460 173.000 1.000
22.520 153.000 1.000
22.580 165.000 1.000
22.640 161.000 1.000
22.700 179.000 1.000
22.760 156.000 1.000
22.820 181.000 1.000
22.880 179.000 1.000
22.940 187.000 1.000
23.000 194.000 1.000
23.060 181.000 1.000
23.120 194.000 1.000
23.180 204.000 1.000
23.240 201.000 1.000
23.300 207.000 1.000
23.360 213.000 1.000
23.420 221.000 1.000
23.480 236.000 1.000
23.540 209.000 1.000
23.600 226.000 1.000
23.660 219.000 1.000
23.720 237.000 1.000
23.780 235.000 1.000
23.840 260.000 1.000
23.900 253.000 1.000
23.960 263.000 1.000
24.020 275.000 1.000
24.080 286.000 1.000
24.140 273.000 1.000
24.200 290.000 1.000
24.260 324.000 1.000
24.320 316.000 1.000
24.380 328.000 1.000
24.440 373.000 1.000
24.500 376.000 1.000
24.560 390.000 1.000
24.620 425.000 1.000
24.680 456.000 1.000
24.740 477.000 1.000
24.800 507.000 1.000
24.860 531.000 1.000
24.920 537.000 1.000
24.980 628.000 1.000
25.040 652.000 1.000
25.100 703.000 1.000
25.160 766.000 1.000
25.220 824.000 1.000
25.280 919.000 1.000
25.340 912.000 1.000
25.400 1006.000 1.000
25.460 1123.000 1.000
25.520 1161.000 1.000
25.580 1209.000 1.000
25.640 1318.000 1.000
25.700 1317.000 1.000
25.760 1425.000 1.000
25.820 1463.000 1.000
25.880 1576.000 1.000
25.940 1637.000 1.000
26.000 1965.000 1.000
26.060 2389.000 1.000
26.120 3296.000 1.000
26.180 4471.000 1.000
26.240 5598.000 1.000
26.300 5103.000 1.000
26.360 3226.000 1.000
26.420 1787.000 1.000
26.480 1073.000 1.000
26.540 782.000 1.000
26.600 676.000 1.000
26.660 550.000 1.000
26.720 497.000 1.000
26.780 424.000 1.000
26.840 439.000 1.000
26.900 384.000 1.000
26.960 355.000 1.000
27.020 336.000 1.000
27.080 291.000 1.000
27.140 296.000 1.000
27.200 262.000 1.000
27.260 263.000 1.000
27.320 261.000 1.000
27.380 238.000 1.000
27.440 227.000 1.000
27.500 227.000 1.000
27.560 236.000 1.000
27.620 224.000 1.000
27.680 215.000 1.000
27.740 212.000 1.000
27.800 193.000 1.000
27.860 189.000 1.000
27.920 194.000 1.000
27.980 174.000 1.000
28.040 189.000 1.000
28.100 182.000 1.000
28.160 168.000 1.000
28.220 169.000 1.000
28.280 189.000 1.000
28.340 186.000 1.000
28.400 172.000 1.000
28.460 148.000 1.000
28.520 183.000 1.000
28.580 167.000 1.000
28.640 160.000 1.000
28.700 155.000 1.000
28.760 150.000 1.000
28.820 170.000 1.000
28.880 142.000 1.000
28.940 137.000 1.000
29.000 160.000 1.000
29.060 176.000 1.000
29.120 165.000 1.000
29.180 178.000 1.000
29.240 160.000 1.000
29.300 138.000 1.000
29.360 161.000 1.000
29.420 177.000 1.000
29.480 208.000 1.000
29.540 240.000 1.000
29.600 216.000 1.000
29.660 202.000 1.000
29.720 158.000 1.000
29.780 122.000 1.000
29.840 140.000 1.000
29.900 127.000 1.000
29.960 129.000 1.000
30.020 140.000 1.000
30.080 138.000 1.000
30.140 115.000 1.000
30.200 113.000 1.000
30.260 129.000 1.000
30.320 117.000 1.000
30.380 125.000 1.000
30.440 135.000 1.000
30.500 140.000 1.000
30.560 131.000 1.000
30.620 136.000 1.000
30.680 131.000 1.000
30.740 116.000 1.000
30.800 123.000 1.000
30.860 120.000 1.000
30.920 120.000 1.000
30.980 122.000 1.000
31.040 129.000 1.000
31.100 119.000 1.000
31.160 109.000 1.000
31.220 132.000 1.000
31.280 133.000 1.000
31.340 113.000 1.000
31.400 108.000 1.000
31.460 120.000 1.000
31.520 115.000 1.000
31.580 119.000 1.000
31.640 123.000 1.000
31.700 135.000 1.000
31.760 121.000 1.000
31.820 118.000 1.000
31.880 126.000 1.000
31.940 126.000 1.000
32.000 107.000 1.000
32.060 119.000 1.000
32.120 108.000 1.000
32.180 118.000 1.000
32.240 113.000 1.000
32.300 112.000 1.000
32.360 121.000 1.000
32.420 105.000 1.000
32.480 115.000 1.000
32.540 114.000 1.000
32.600 96.000 1.000
32.660 110.000 1.000
32.720 109.000 1.000
32.780 109.000 1.000
32.840 120.000 1.000
32.900 111.000 1.000
32.960 111.000 1.000
33.020 117.000 1.000
33.080 114.000 1.000
33.140 116.000 1.000
33.200 106.000 1.000
33.260 111.000 1.000
33.320 130.000 1.000
33.380 98.000 1.000
33.440 118.000 1.000
33.500 128.000 1.000
33.560 104.000 1.000
33.620 123.000 1.000
33.680 121.000 1.000
33.740 123.000 1.000
33.800 107.000 1.000
33.860 115.000 1.000
33.920 118.000 1.000
33.980 109.000 1.000
34.040 107.000 1.000
34.100 131.000 1.000
34.160 99.000 1.000
34.220 141.000 1.000
34.280 137.000 1.000
34.340 135.000 1.000
34.400 143.000 1.000
34.460 137.000 1.000
34.520 131.000 1.000
34.580 130.000 1.000
34.640 123.000 1.000
34.700 145.000 1.000
34.760 142.000 1.000
34.820 133.000 1.000
34.880 162.000 1.000
34.940 134.000 1.000
35.000 132.000 1.000
35.060 143.000 1.000
35.120 145.000 1.000
35.180 142.000 1.000
35.240 153.000 1.000
35.300 151.000 1.000
35.360 161.000 1.000
35.420 141.000 1.000
35.480 145.000 1.000
35.540 167.000 1.000
35.600 150.000 1.000
35.660 149.000 1.000
35.720 173.000 1.000
35.780 158.000 1.000
35.840 166.000 1.000
35.900 172.000 1.000
35.960 184.000 1.000
36.020 161.000 1.000
36.080 215.000 1.000
36.140 224.000 1.000
36.200 269.000 1.000
36.260 427.000 1.000
36.320 686.000 1.000
36.380 1029.000 1.000
36.440 1317.000 1.000
36.500 1218.000 1.000
36.560 820.000 1.000
36.620 437.000 1.000
36.680 261.000 1.000
36.740 195.000 1.000
36.800 177.000 1.000
36.860 162.000 1.000
36.920 154.000 1.000
36.980 120.000 1.000
37.040 128.000 1.000
37.100 114.000 1.000
37.160 127.000 1.000
37.220 112.000 1.000
37.280 131.000 1.000
37.340 133.000 1.000
37.400 118.000 1.000
37.460 119.000 1.000
37.520 112.000 1.000
37.580 135.000 1.000
37.640 121.000 1.000
37.700 120.000 1.000
37.760 120.000 1.000
37.820 134.000 1.000
37.880 105.000 1.000
37.940 121.000 1.000
38.000 109.000 1.000
38.060 127.000 1.000
38.120 106.000 1.000
38.180 117.000 1.000
38.240 115.000 1.000
38.300 121.000 1.000
38.360 122.000 1.000
38.420 105.000 1.000
38.480 108.000 1.000
38.540 114.000 1.000
38.600 105.000 1.000
38.660 92.000 1.000
38.720 108.000 1.000
38.780 113.000 1.000
38.840 103.000 1.000
38.900 95.000 1.000
38.960 110.000 1.000
39.020 121.000 1.000
39.080 109.000 1.000
39.140 131.000 1.000
39.200 125.000 1.000
39.260 101.000 1.000
39.320 105.000 1.000
39.380 122.000 1.000
39.440 108.000 1.000
39.500 116.000 1.000
39.560 95.000 1.000
39.620 78.000 1.000
39.680 114.000 1.000
39.740 103.000 1.000
39.800 93.000 1.000
39.860 126.000 1.000
39.920 111.000 1.000
39.980 121.000 1.000
40.040 105.000 1.000
40.100 120.000 1.000
40.160 105.000 1.000
40.220 117.000 1.000
40.280 105.000 1.000
40.340 110.000 1.000
40.400 120.000 1.000
40.460 94.000 1.000
40.520 132.000 1.000
40.580 110.000 1.000
40.640 106.000 1.000
40.700 103.000 1.000
40.760 103.000 1.000
40.820 109.000 1.000
40.880 115.000 1.000
40.940 107.000 1.000
41.000 106.000 1.000
41.060 101.000 1.000
41.120 103.000 1.000
41.180 114.000 1.000
41.240 118.000 1.000
41.300 125.000 1.000
41.360 125.000 1.000
41.420 102.000 1.000
41.480 109.000 1.000
41.540 122.000 1.000
41.600 112.000 1.000
41.660 127.000 1.000
41.720 138.000 1.000
41.780 125.000 1.000
41.840 123.000 1.000
41.900 123.000 1.000
41.960 138.000 1.000
42.020 155.000 1.000
42.080 163.000 1.000
42.140 179.000 1.000
42.200 237.000 1.000
42.260 310.000 1.000
42.320 443.000 1.000
42.380 515.000 1.000
42.440 450.000 1.000
42.500 365.000 1.000
42.560 277.000 1.000
42.620 188.000 1.000
42.680 129.000 1.000
42.740 157.000 1.000
42.800 132.000 1.000
42.860 132.000 1.000
42.920 127.000 1.000
42.980 132.000 1.000
43.040 137.000 1.000
43.100 123.000 1.000
43.160 106.000 1.000
43.220 119.000 1.000
43.280 123.000 1.000
43.340 122.000 1.000
43.400 122.000 1.000
43.460 110.000 1.000
43.520 110.000 1.000
43.580 114.000 1.000
43.640 114.000 1.000
43.700 105.000 1.000
43.760 119.000 1.000
43.820 107.000 1.000
43.880 117.000 1.000
43.940 104.000 1.000
44.000 122.000 1.000
44.060 114.000 1.000
44.120 104.000 1.000
44.180 110.000 1.000
44.240 124.000 1.000
44.300 107.000 1.000
44.360 92.000 1.000
44.420 110.000 1.000
44.480 104.000 1.000
44.540 122.000 1.000
44.600 111.000 1.000
44.660 111.000 1.000
44.720 117.000 1.000
44.780 106.000 1.000
44.840 108.000 1.000
44.900 108.000 1.000
44.960 94.000 1.000
45.020 98.000 1.000
45.080 91.000 1.000
45.140 112.000 1.000
45.200 107.000 1.000
45.260 116.000 1.000
45.320 100.000 1.000
45.380 92.000 1.000
45.440 104.000 1.000
45.500 105.000 1.000
45.560 95.000 1.000
45.620 111.000 1.000
45.680 96.000 1.000
45.740 94.000 1.000
45.800 94.000 1.000
45.860 104.000 1.000
45.920 102.000 1.000
45.980 95.000 1.000
46.040 103.000 1.000
46.100 95.000 1.000
46.160 112.000 1.000
46.220 88.000 1.000
46.280 100.000 1.000
46.340 112.000 1.000
46.400 91.000 1.000
46.460 103.000 1.000
46.520 75.000 1.000
46.580 105.000 1.000
46.640 86.000 1.000
46.700 94.000 1.000
46.760 96.000 1.000
46.820 82.000 1.000
46.880 110.000 1.000
46.940 86.000 1.000
47.000 103.000 1.000
47.060 99.000 1.000
47.120 96.000 1.000
47.180 102.000 1.000
47.240 96.000 1.000
47.300 104.000 1.000
47.360 105.000 1.000
47.420 105.000 1.000
47.480 88.000 1.000
47.540 94.000 1.000
47.600 91.000 1.000
47.660 101.000 1.000
47.720 100.000 1.000
47.780 94.000 1.000
47.840 87.000 1.000
47.900 94.000 1.000
47.960 100.000 1.000
48.020 113.000 1.000
48.080 93.000 1.000
48.140 78.000 1.000
48.200 98.000 1.000
48.260 99.000 1.000
48.320 111.000 1.000
48.380 108.000 1.000
48.440 96.000 1.000
48.500 105.000 1.000
48.560 88.000 1.000
48.620 103.000 1.000
48.680 108.000 1.000
48.740 109.000 1.000
48.800 82.000 1.000
48.860 99.000 1.000
48.920 103.000 1.000
48.980 108.000 1.000
49.040 97.000 1.000
49.100 78.000 1.000
49.160 92.000 1.000
49.220 95.000 1.000
49.280 93.000 1.000
49.340 103.000 1.000
49.400 98.000 1.000
49.460 84.000 1.000
49.520 80.000 1.000
49.580 84.000 1.000
49.640 85.000 1.000
49.700 95.000 1.000
49.760 92.000 1.000
49.820 98.000 1.000
49.880 105.000 1.000
49.940 88.000 1.000
50.000 92.000 1.000
50.060 99.000 1.000
50.120 104.000 1.000
50.180 104.000 1.000
50.240 86.000 1.000
50.300 104.000 1.000
50.360 92.000 1.000
50.420 96.000 1.000
50.480 87.000 1.000
50.540 101.000 1.000
50.600 95.000 1.000
50.660 87.000 1.000
50.720 99.000 1.000
50.780 75.000 1.000
50.840 98.000 1.000
50.900 105.000 1.000
50.960 91.000 1.000
51.020 95.000 1.000
51.080 88.000 1.000
51.140 98.000 1.000
51.200 100.000 1.000
51.260 85.000 1.000
51.320 105.000 1.000
51.380 99.000 1.000
51.440 122.000 1.000
51.500 100.000 1.000
51.560 98.000 1.000
51.620 107.000 1.000
51.680 98.000 1.000
51.740 89.000 1.000
51.800 95.000 1.000
51.860 128.000 1.000
51.920 112.000 1.000
51.980 96.000 1.000
52.040 105.000 1.000
52.100 114.000 1.000
52.160 120.000 1.000
52.220 97.000 1.000
52.280 101.000 1.000
52.340 103.000 1.000
52.400 102.000 1.000
52.460 106.000 1.000
52.520 119.000 1.000
52.580 116.000 1.000
52.640 126.000 1.000
52.700 110.000 1.000
52.760 107.000 1.000
52.820 137.000 1.000
52.880 111.000 1.000
52.940 115.000 1.000
53.000 125.000 1.000
53.060 114.000 1.000
53.120 132.000 1.000
53.180 146.000 1.000
53.240 131.000 1.000
53.300 125.000 1.000
53.360 127.000 1.000
53.420 132.000 1.000
53.480 123.000 1.000
53.540 120.000 1.000
53.600 139.000 1.000
53.660 165.000 1.000
53.720 141.000 1.000
53.780 156.000 1.000
53.840 146.000 1.000
53.900 123.000 1.000
53.960 142.000 1.000
54.020 169.000 1.000
54.080 167.000 1.000
54.140 184.000 1.000
54.200 208.000 1.000
54.260 252.000 1.000
54.320 239.000 1.000
54.380 220.000 1.000
54.440 205.000 1.000
54.500 172.000 1.000
54.560 128.000 1.000
54.620 140.000 1.000
54.680 101.000 1.000
54.740 102.000 1.000
54.800 125.000 1.000
54.860 109.000 1.000
54.920 93.000 1.000
54.980 88.000 1.000
55.040 110.000 1.000
55.100 102.000 1.000
55.160 101.000 1.000
55.220 97.000 1.000
55.280 98.000 1.000
55.340 91.000 1.000
55.400 102.000 1.000
55.460 107.000 1.000
55.520 103.000 1.000
55.580 82.000 1.000
55.640 100.000 1.000
55.700 79.000 1.000
55.760 103.000 1.000
55.820 81.000 1.000
55.880 93.000 1.000
55.940 94.000 1.000
56.000 104.000 1.000
56.060 104.000 1.000
56.120 99.000 1.000
56.180 103.000 1.000
56.240 109.000 1.000
56.300 90.000 1.000
56.360 91.000 1.000
56.420 83.000 1.000
56.480 97.000 1.000
56.540 82.000 1.000
56.600 89.000 1.000
56.660 98.000 1.000
56.720 89.000 1.000
56.780 95.000 1.000
56.840 76.000 1.000
56.900 86.000 1.000
56.960 87.000 1.000
57.020 89.000 1.000
57.080 77.000 1.000
57.140 109.000 1.000
57.200 84.000 1.000
57.260 93.000 1.000
57.320 108.000 1.000
57.380 99.000 1.000
57.440 74.000 1.000
57.500 79.000 1.000
57.560 90.000 1.000
57.620 79.000 1.000
57.680 83.000 1.000
57.740 99.000 1.000
57.800 98.000 1.000
57.860 89.000 1.000
57.920 99.000 1.000
57.980 91.000 1.000
58.040 80.000 1.000
58.100 84.000 1.000
58.160 86.000 1.000
58.220 70.000 1.000
58.280 90.000 1.000
58.340 84.000 1.000
58.400 86.000 1.000
58.460 81.000 1.000
58.520 84.000 1.000
58.580 87.000 1.000
58.640 76.000 1.000
58.700 100.000 1.000
58.760 88.000 1.000
58.820 83.000 1.000
58.880 77.000 1.000
58.940 86.000 1.000
59.000 84.000 1.000
59.060 84.000 1.000
59.120 79.000 1.000
59.180 82.000 1.000
59.240 95.000 1.000
59.300 94.000 1.000
59.360 80.000 1.000
59.420 92.000 1.000
59.480 86.000 1.000
59.540 92.000 1.000
59.600 92.000 1.000
59.660 90.000 1.000
59.720 103.000 1.000
59.780 87.000 1.000
59.840 89.000 1.000
59.900 96.000 1.000
59.960 82.000 1.000
60.020 78.000 1.000
60.080 84.000 1.000
60.140 81.000 1.000
60.200 100.000 1.000
60.260 93.000 1.000
60.320 96.000 1.000
60.380 93.000 1.000
60.440 90.000 1.000
60.500 99.000 1.000
60.560 98.000 1.000
60.620 103.000 1.000
60.680 100.000 1.000
60.740 101.000 1.000
60.800 107.000 1.000
60.860 88.000 1.000
60.920 102.000 1.000
60.980 91.000 1.000
61.040 90.000 1.000
61.100 110.000 1.000
61.160 125.000 1.000
61.220 117.000 1.000
61.280 124.000 1.000
61.340 137.000 1.000
61.400 175.000 1.000
61.460 193.000 1.000
61.520 262.000 1.000
61.580 273.000 1.000
61.640 264.000 1.000
61.700 246.000 1.000
61.760 200.000 1.000
61.820 175.000 1.000
61.880 134.000 1.000
61.940 136.000 1.000
62.000 118.000 1.000
62.060 110.000 1.000
62.120 110.000 1.000
62.180 89.000 1.000
62.240 110.000 1.000
62.300 99.000 1.000
62.360 97.000 1.000
62.420 80.000 1.000
62.480 90.000 1.000
62.540 87.000 1.000
62.600 103.000 1.000
62.660 98.000 1.000
62.720 79.000 1.000
62.780 84.000 1.000
62.840 88.000 1.000
62.900 93.000 1.000
62.960 84.000 1.000
63.020 87.000 1.000
63.080 94.000 1.000
63.140 78.000 1.000
63.200 75.000 1.000
63.260 69.000 1.000
63.320 83.000 1.000
63.380 78.000 1.000
63.440 84.000 1.000
63.500 87.000 1.000
63.560 87.000 1.000
63.620 86.000 1.000
63.680 83.000 1.000
63.740 90.000 1.000
63.800 93.000 1.000
63.860 97.000 1.000
63.920 90.000 1.000
63.980 85.000 1.000
64.040 83.000 1.000
64.100 89.000 1.000
64.160 84.000 1.000
64.220 87.000 1.000
64.280 73.000 1.000
64.340 94.000 1.000
64.400 80.000 1.000
64.460 83.000 1.000
64.520 86.000 1.000
64.580 83.000 1.000
64.640 85.000 1.000
64.700 76.000 1.000
64.760 77.000 1.000
64.820 87.000 1.000
64.880 82.000 1.000
64.940 79.000 1.000
65.000 81.000 1.000
65.060 76.000 1.000
65.120 73.000 1.000
65.180 81.000 1.000
65.240 86.000 1.000
65.300 79.000 1.000
65.360 80.000 1.000
65.420 83.000 1.000
65.480 87.000 1.000
65.540 64.000 1.000
65.600 80.000 1.000
65.660 75.000 1.000
65.720 80.000 1.000
65.780 83.000 1.000
65.840 87.000 1.000
65.900 74.000 1.000
65.960 65.000 1.000
66.020 68.000 1.000
66.080 71.000 1.000
66.140 86.000 1.000
66.200 71.000 1.000
66.260 79.000 1.000
66.320 86.000 1.000
66.380 68.000 1.000
66.440 95.000 1.000
66.500 63.000 1.000
66.560 97.000 1.000
66.620 87.000 1.000
66.680 74.000 1.000
66.740 81.000 1.000
66.800 90.000 1.000
66.860 77.000 1.000
66.920 82.000 1.000
66.980 67.000 1.000
67.040 77.000 1.000
67.100 68.000 1.000
67.160 96.000 1.000
67.220 78.000 1.000
67.280 76.000 1.000
67.340 77.000 1.000
67.400 71.000 1.000
67.460 82.000 1.000
67.520 72.000 1.000
67.580 75.000 1.000
67.640 90.000 1.000
67.700 88.000 1.000
67.760 74.000 1.000
67.820 77.000 1.000
67.880 63.000 1.000
67.940 70.000 1.000
68.000 73.000 1.000
68.060 74.000 1.000
68.120 77.000 1.000
68.180 87.000 1.000
68.240 86.000 1.000
68.300 67.000 1.000
68.360 84.000 1.000
68.420 84.000 1.000
68.480 82.000 1.000
68.540 86.000 1.000
68.600 70.000 1.000
68.660 83.000 1.000
68.720 76.000 1.000
68.780 82.000 1.000
68.840 75.000 1.000
68.900 93.000 1.000
68.960 69.000 1.000
69.020 80.000 1.000
69.080 76.000 1.000
69.140 86.000 1.000
69.200 74.000 1.000
69.260 77.000 1.000
69.320 89.000 1.000
69.380 82.000 1.000
69.440 79.000 1.000
69.500 71.000 1.000
69.560 77.000 1.000
69.620 68.000 1.000
69.680 73.000 1.000
69.740 94.000 1.000
69.800 76.000 1.000
69.860 77.000 1.000
69.920 71.000 1.000
69.980 75.000 1.000
70.040 84.000 1.000
70.100 90.000 1.000
70.160 63.000 1.000
70.220 66.000 1.000
70.280 75.000 1.000
70.340 70.000 1.000
70.400 65.000 1.000
70.460 81.000 1.000
70.520 69.000 1.000
70.580 88.000 1.000
70.640 76.000 1.000
70.700 71.000 1.000
70.760 71.000 1.000
70.820 72.000 1.000
70.880 78.000 1.000
70.940 80.000 1.000
71.000 72.000 1.000
71.060 78.000 1.000
71.120 79.000 1.000
71.180 72.000 1.000
71.240 71.000 1.000
71.300 71.000 1.000
71.360 79.000 1.000
71.420 78.000 1.000
71.480 80.000 1.000
71.540 84.000 1.000
71.600 83.000 1.000
71.660 81.000 1.000
71.720 77.000 1.000
71.780 85.000 1.000
71.840 71.000 1.000
71.900 85.000 1.000
71.960 75.000 1.000
72.020 74.000 1.000
72.080 83.000 1.000
72.140 68.000 1.000
72.200 77.000 1.000
72.260 77.000 1.000
72.320 90.000 1.000
72.380 73.000 1.000
72.440 73.000 1.000
72.500 99.000 1.000
72.560 87.000 1.000
72.620 93.000 1.000
72.680 93.000 1.000
72.740 83.000 1.000
72.800 95.000 1.000
72.860 99.000 1.000
72.920 89.000 1.000
72.980 92.000 1.000
73.040 85.000 1.000
73.100 83.000 1.000
73.160 84.000 1.000
73.220 92.000 1.000
73.280 100.000 1.000
73.340 95.000 1.000
73.400 85.000 1.000
73.460 97.000 1.000
73.520 107.000 1.000
73.580 113.000 1.000
73.640 127.000 1.000
73.700 136.000 1.000
73.760 158.000 1.000
73.820 171.000 1.000
73.880 159.000 1.000
73.940 161.000 1.000
74.000 125.000 1.000
74.060 154.000 1.000
74.120 116.000 1.000
74.180 102.000 1.000
74.240 108.000 1.000
74.300 86.000 1.000
74.360 81.000 1.000
74.420 83.000 1.000
74.480 100.000 1.000
74.540 94.000 1.000
74.600 73.000 1.000
74.660 79.000 1.000
74.720 82.000 1.000
74.780 78.000 1.000
74.840 87.000 1.000
74.900 80.000 1.000
74.960 85.000 1.000
75.020 81.000 1.000
75.080 67.000 1.000
75.140 83.000 1.000
75.200 82.000 1.000
75.260 76.000 1.000
75.320 82.000 1.000
75.380 78.000 1.000
75.440 77.000 1.000
75.500 85.000 1.000
75.560 64.000 1.000
75.620 80.000 1.000
75.680 76.000 1.000
75.740 80.000 1.000
75.800 87.000 1.000
75.860 72.000 1.000
75.920 82.000 1.000
75.980 75.000 1.000
76.040 86.000 1.000
76.100 84.000 1.000
76.160 83.000 1.000
76.220 84.000 1.000
76.280 81.000 1.000
76.340 86.000 1.000
76.400 82.000 1.000
76.460 84.000 1.000
76.520 79.000 1.000
76.580 84.000 1.000
76.640 85.000 1.000
76.700 75.000 1.000
76.760 83.000 1.000
76.820 76.000 1.000
76.880 84.000 1.000
76.940 77.000 1.000
77.000 71.000 1.000
77.060 71.000 1.000
77.120 75.000 1.000
77.180 81.000 1.000
77.240 74.000 1.000
77.300 75.000 1.000
77.360 91.000 1.000
77.420 87.000 1.000
77.480 79.000 1.000
77.540 102.000 1.000
77.600 83.000 1.000
77.660 90.000 1.000
77.720 107.000 1.000
77.780 107.000 1.000
77.840 95.000 1.000
77.900 99.000 1.000
77.960 84.000 1.000
78.020 81.000 1.000
78.080 96.000 1.000
78.140 70.000 1.000
78.200 83.000 1.000
78.260 85.000 1.000
78.320 76.000 1.000
78.380 78.000 1.000
78.440 87.000 1.000
78.500 71.000 1.000
78.560 76.000 1.000
78.620 72.000 1.000
78.680 87.000 1.000
78.740 79.000 1.000
78.800 69.000 1.000
78.860 77.000 1.000
78.920 72.000 1.000
78.980 87.000 1.000
79.040 62.000 1.000
79.100 69.000 1.000
79.160 78.000 1.000
79.220 80.000 1.000
79.280 73.000 1.000
79.340 96.000 1.000
79.400 71.000 1.000
79.460 73.000 1.000
79.520 76.000 1.000
79.580 80.000 1.000
79.640 76.000 1.000
79.700 83.000 1.000
79.760 81.000 1.000
79.820 72.000 1.000
79.880 72.000 1.000
79.940 76.000 1.000
80.000 80.000 1.000
80.060 67.000 1.000
80.120 77.000 1.000
80.180 71.000 1.000
80.240 75.000 1.000
80.300 72.000 1.000
80.360 70.000 1.000
80.420 71.000 1.000
80.480 75.000 1.000
80.540 79.000 1.000
80.600 69.000 1.000
80.660 66.000 1.000
80.720 70.000 1.000
80.780 78.000 1.000
80.840 81.000 1.000
80.900 82.000 1.000
80.960 75.000 1.000
81.020 66.000 1.000
81.080 73.000 1.000
81.140 75.000 1.000
81.200 81.000 1.000
81.260 60.000 1.000
81.320 76.000 1.000
81.380 77.000 1.000
81.440 85.000 1.000
81.500 77.000 1.000
81.560 84.000 1.000
81.620 68.000 1.000
81.680 79.000 1.000
81.740 59.000 1.000
81.800 72.000 1.000
81.860 77.000 1.000
81.920 77.000 1.000
81.980 69.000 1.000
82.040 81.000 1.000
82.100 70.000 1.000
82.160 75.000 1.000
82.220 72.000 1.000
82.280 62.000 1.000
82.340 70.000 1.000
82.400 84.000 1.000
82.460 81.000 1.000
82.520 65.000 1.000
82.580 75.000 1.000
82.640 80.000 1.000
82.700 77.000 1.000
82.760 60.000 1.000
82.820 69.000 1.000
82.880 78.000 1.000
82.940 91.000 1.000
83.000 64.000 1.000
83.060 72.000 1.000
83.120 72.000 1.000
83.180 71.000 1.000
83.240 73.000 1.000
83.300 70.000 1.000
83.360 70.000 1.000
83.420 73.000 1.000
83.480 63.000 1.000
83.540 68.000 1.000
83.600 71.000 1.000
83.660 81.000 1.000
83.720 62.000 1.000
83.780 63.000 1.000
83.840 82.000 1.000
83.900 71.000 1.000
83.960 81.000 1.000
84.020 78.000 1.000
84.080 75.000 1.000
84.140 80.000 1.000
84.200 78.000 1.000
84.260 59.000 1.000
84.320 69.000 1.000
84.380 77.000 1.000
84.440 79.000 1.000
84.500 63.000 1.000
84.560 76.000 1.000
84.620 68.000 1.000
84.680 72.000 1.000
84.740 65.000 1.000
84.800 79.000 1.000
84.860 75.000 1.000
84.920 73.000 1.000
84.980 67.000 1.000
85.040 79.000 1.000
85.100 79.000 1.000
85.160 74.000 1.000
85.220 74.000 1.000
85.280 73.000 1.000
85.340 81.000 1.000
85.400 77.000 1.000
85.460 78.000 1.000
85.520 63.000 1.000
85.580 79.000 1.000
85.640 83.000 1.000
85.700 75.000 1.000
85.760 67.000 1.000
85.820 83.000 1.000
85.880 74.000 1.000
85.940 68.000 1.000
86.000 74.000 1.000
86.060 74.000 1.000
86.120 77.000 1.000
86.180 73.000 1.000
86.240 68.000 1.000
86.300 80.000 1.000
86.360 84.000 1.000
86.420 68.000 1.000
86.480 84.000 1.000
86.540 71.000 1.000
86.600 81.000 1.000
86.660 86.000 1.000
86.720 84.000 1.000
86.780 77.000 1.000
86.840 75.000 1.000
86.900 79.000 1.000
86.960 87.000 1.000
87.020 73.000 1.000
87.080 67.000 1.000
87.140 72.000 1.000
87.200 73.000 1.000
87.260 80.000 1.000
87.320 66.000 1.000
87.380 67.000 1.000
87.440 80.000 1.000
87.500 69.000 1.000
87.560 61.000 1.000
87.620 74.000 1.000
87.680 59.000 1.000
87.740 65.000 1.000
87.800 70.000 1.000
87.860 72.000 1.000
87.920 75.000 1.000
87.980 80.000 1.000
88.040 67.000 1.000
88.100 77.000 1.000
88.160 74.000 1.000
88.220 58.000 1.000
88.280 52.000 1.000
88.340 63.000 1.000
88.400 63.000 1.000
88.460 69.000 1.000
88.520 61.000 1.000
88.580 80.000 1.000
88.640 67.000 1.000
88.700 64.000 1.000
88.760 61.000 1.000
88.820 82.000 1.000
88.880 70.000 1.000
88.940 54.000 1.000
89.000 72.000 1.000
89.060 77.000 1.000
89.120 72.000 1.000
89.180 78.000 1.000
89.240 64.000 1.000
89.300 72.000 1.000
89.360 71.000 1.000
89.420 59.000 1.000
89.480 59.000 1.000
89.540 71.000 1.000
89.600 56.000 1.000
89.660 65.000 1.000
89.720 69.000 1.000
89.780 63.000 1.000
89.840 76.000 1.000
89.900 67.000 1.000
89.960 71.000 1.000
90.000 82.000 1.000
*RAS_INT_END
*RAS_DATA_END