File: Lab/XRD/all_in_one/cu2o_008.ras
*RAS_DATA_START
*RAS_HEADER_START
*CORR_POS_DB_NAME "DTEX_11112016"
*CORR_POS_GONIO_RADIUS ""
*CORR_POS_NODE_INDEX01 ""
*CORR_POS_NODE_INDEX02 ""
*CORR_POS_NODE_INDEX03 ""
*CORR_POS_NODE_INDEX04 ""
*CORR_POS_NODE_INDEX05 ""
*CORR_POS_NODE_INDEX06 ""
*CORR_POS_NODE_INDEX07 ""
*CORR_POS_NODE_INDEX08 ""
*CORR_POS_NODE_INDEX09 ""
*CORR_POS_NODE_INDEX10 ""
*CORR_POS_NODE_INDEX11 ""
*CORR_POS_NODE_LABEL01 "Si(111)"
*CORR_POS_NODE_LABEL02 "Si(220)"
*CORR_POS_NODE_LABEL03 "Si(311)"
*CORR_POS_NODE_LABEL04 "Si(400)"
*CORR_POS_NODE_LABEL05 "Si(331)"
*CORR_POS_NODE_LABEL06 "Si(422)"
*CORR_POS_NODE_LABEL07 "Si(511)"
*CORR_POS_NODE_LABEL08 "Si(440)"
*CORR_POS_NODE_LABEL09 "Si(531)"
*CORR_POS_NODE_LABEL10 "Si(620)"
*CORR_POS_NODE_LABEL11 "Si(533)"
*CORR_POS_NODE_POS_CALC01 "28.4137"
*CORR_POS_NODE_POS_CALC02 "47.2707"
*CORR_POS_NODE_POS_CALC03 "56.0883"
*CORR_POS_NODE_POS_CALC04 "69.0934"
*CORR_POS_NODE_POS_CALC05 "76.3385"
*CORR_POS_NODE_POS_CALC06 "87.9915"
*CORR_POS_NODE_POS_CALC07 "94.9137"
*CORR_POS_NODE_POS_CALC08 "106.67"
*CORR_POS_NODE_POS_CALC09 "114.054"
*CORR_POS_NODE_POS_CALC10 "127.508"
*CORR_POS_NODE_POS_CALC11 "136.858"
*CORR_POS_NODE_POS_MEAS01 "28.3712"
*CORR_POS_NODE_POS_MEAS02 "47.2304"
*CORR_POS_NODE_POS_MEAS03 "56.0465"
*CORR_POS_NODE_POS_MEAS04 "69.0523"
*CORR_POS_NODE_POS_MEAS05 "76.2993"
*CORR_POS_NODE_POS_MEAS06 "87.9512"
*CORR_POS_NODE_POS_MEAS07 "94.8772"
*CORR_POS_NODE_POS_MEAS08 "106.636"
*CORR_POS_NODE_POS_MEAS09 "114.028"
*CORR_POS_NODE_POS_MEAS10 "127.48"
*CORR_POS_NODE_POS_MEAS11 "136.839"
*CORR_POS_OPT_ATTR "集中法"
*CORR_POS_PARAM_MU ""
*CORR_POS_PARAM_PL ""
*CORR_POS_SEMODEL_TYPE "0"
*CORR_POS_STANDARD_TYPE ""
*CORR_POS_VALUE_ANALYZER "None"
*CORR_POS_VALUE_CMONO "None"
*CORR_POS_VALUE_IMONO "None"
*CORR_POS_VALUE_IS "0.625deg"
*CORR_POS_VALUE_ISL "10.0mm"
*CORR_POS_VALUE_ISOLLER "2.5deg"
*CORR_POS_VALUE_RS1 "13.0mm"
*CORR_POS_VALUE_RS2 "13.0mm"
*CORR_POS_VALUE_RSOLLER "2.5deg"
*CORR_POS_XG_FOCUS_L ""
*CORR_POS_XG_WAVE_TYPE ""
*CORR_POS_XG_WAVE_VALUE ""
*DISP_FMT_X "%.2f"
*DISP_FMT_Y "%.0f"
*DISP_FULLSCALE "8712.0000000000"
*DISP_LINE_COLOR "255.0000000000"
*DISP_LINE_STYLE "0.0000000000"
*DISP_LINE_WIDTH "0.2500000000"
*DISP_NOTE "Collected Data-1"
*DISP_OFFSET_Y "0.0000000000"
*DISP_PEAKSEARCH_UNIT_Y "COUNTS"
*DISP_RANGE_BOTTOM "0.0000000000"
*DISP_RANGE_LEFT "20.0000000000"
*DISP_RANGE_LOGCUTOFF "0.0100000000"
*DISP_RANGE_RIGHT "90.0000000000"
*DISP_RANGE_TOP "8712.0000000000"
*DISP_SCALE_MODE_Y "0.0000000000"
*DISP_TAB_NAME "Theta/2-Theta"
*DISP_TITLE_Y "Intensity"
*DISP_UNIT_Y "COUNTS"
*DISP_WINDOW_NAME "MSG_MACROENGINE"
*FILE_COMMENT " "
*FILE_MD5 ""
*FILE_MEMO " "
*FILE_OPERATOR "MiniFlex"
*FILE_PART_ID "MEAS_PBEA_00223"
*FILE_SAMPLE "cu2o_008"
*FILE_TYPE "RAS_RAW"
*FILE_USERGROUP "System User"
*FILE_VERSION "1.0000000000"
*HW_ATTACHMENT_ID "ATT1031"
*HW_ATTACHMENT_NAME "6サンプルチェンジャ|ASC-6"
*HW_COUNTER_ID-0 "CUT0025"
*HW_COUNTER_ID-1 "CUT0020"
*HW_COUNTER_ID-2 "CUT0020"
*HW_COUNTER_ID-3 "CMC0021"
*HW_COUNTER_NAME-0 "D/teX Ultra|D/teX Ultra"
*HW_COUNTER_NAME-1 "None|None"
*HW_COUNTER_NAME-2 "None|None"
*HW_COUNTER_NAME-3 "検出器モノクロメータ|Detector monochromator"
*HW_COUNTER_SELECT_NAME "D/teX Ultra|D/teX Ultra"
*HW_GONIOMETER_ID "GON0070"
*HW_GONIOMETER_NAME "MiniFlex 300/600|MiniFlex 300/600"
*HW_GONIOMETER_RADIUS-0 "79.0"
*HW_GONIOMETER_RADIUS-1 "91.5"
*HW_GONIOMETER_RADIUS-2 "150.0"
*HW_GONIOMETER_RADIUS-3 "0"
*HW_GONIOMETER_RADIUS-4 "103.4"
*HW_GONIOMETER_RADIUS-5 "150.0"
*HW_GONIOMETER_RADIUS-6 "46.6"
*HW_GONIOMETER_RADIUS-7 "160.0"
*HW_I_OPT_ID-0 "ISL0021"
*HW_I_OPT_ID-1 "ISO0021"
*HW_I_OPT_NAME-0 "発散スリット|Divergence slit"
*HW_I_OPT_NAME-1 "入射平行スリット|Incident parallel slit"
*HW_R_ATTENUATER_AUTOMODE "0"
*HW_R_OPT_ID-0 "RSS0021"
*HW_R_OPT_ID-1 "RSO0021"
*HW_R_OPT_ID-2 "RRS0021"
*HW_R_OPT_NAME-0 "散乱スリット|Scattering slit"
*HW_R_OPT_NAME-1 "受光平行スリット|Receiving soller slit"
*HW_R_OPT_NAME-2 "受光スリット|Receiving slit"
*HW_SAMPLE_HOLDER_ID "SMP0000"
*HW_SAMPLE_HOLDER_NAME "無し|None"
*HW_XG_CURRENT_MAX "15"
*HW_XG_CURRENT_MIN "2"
*HW_XG_CURRENT_RESOLUTION "1"
*HW_XG_CURRENT_UNIT "mA"
*HW_XG_FOCUS "1mm x 10mm"
*HW_XG_FOCUS_TYPE "Normal"
*HW_XG_ID "1060"
*HW_XG_NAME "300W/600W 封入管-B|300W/600W Sealed tube-B"
*HW_XG_TARGET_ATOMIC_NUMBER "29.0000000000"
*HW_XG_TARGET_NAME "Cu"
*HW_XG_TYPE "Hermetic"
*HW_XG_VOLTAGE_MAX "40"
*HW_XG_VOLTAGE_MIN "20"
*HW_XG_VOLTAGE_RESOLUTION "1"
*HW_XG_VOLTAGE_UNIT "kV"
*HW_XG_WATT_MAX "1"
*HW_XG_WATT_UNIT "kW"
*HW_XG_WAVE_LENGTH_ALPHA1 "1.540593"
*HW_XG_WAVE_LENGTH_ALPHA2 "1.544414"
*HW_XG_WAVE_LENGTH_BETA "1.392250"
*MEAS_COND_AXIS_NAME-0 "Theta/2-Theta"
*MEAS_COND_AXIS_NAME-1 "Spin"
*MEAS_COND_AXIS_NAME-2 "Change"
*MEAS_COND_AXIS_NAME-3 "Soller(inc.)"
*MEAS_COND_AXIS_NAME-4 "IHS"
*MEAS_COND_AXIS_NAME-5 "DS"
*MEAS_COND_AXIS_NAME-6 "SS"
*MEAS_COND_AXIS_NAME-7 "Soller(rec.)"
*MEAS_COND_AXIS_NAME-8 "RS"
*MEAS_COND_AXIS_NAME-9 "Filter"
*MEAS_COND_AXIS_NAME-10 "Monochromator"
*MEAS_COND_AXIS_NAME-11 "PHA"
*MEAS_COND_AXIS_NAME_INTERNAL-0 "TwoThetaTheta"
*MEAS_COND_AXIS_NAME_INTERNAL-1 "Spin"
*MEAS_COND_AXIS_NAME_INTERNAL-2 "Change"
*MEAS_COND_AXIS_NAME_INTERNAL-3 "IncidentSollerSlit"
*MEAS_COND_AXIS_NAME_INTERNAL-4 "IncidentAxdSlit"
*MEAS_COND_AXIS_NAME_INTERNAL-5 "IncidentSlitBox"
*MEAS_COND_AXIS_NAME_INTERNAL-6 "ReceivingSlitBox1"
*MEAS_COND_AXIS_NAME_INTERNAL-7 "ReceivingSollerSlit"
*MEAS_COND_AXIS_NAME_INTERNAL-8 "ReceivingSlitBox2"
*MEAS_COND_AXIS_NAME_INTERNAL-9 "Filter"
*MEAS_COND_AXIS_NAME_INTERNAL-10 "CounterMonochromator"
*MEAS_COND_AXIS_NAME_INTERNAL-11 "PHA"
*MEAS_COND_AXIS_NAME_MAGICNO-0 "268632064.0000000000"
*MEAS_COND_AXIS_NAME_MAGICNO-1 "16842752.0000000000"
*MEAS_COND_AXIS_NAME_MAGICNO-2 "16842752.0000000000"
*MEAS_COND_AXIS_NAME_MAGICNO-3 "20971521.0000000000"
*MEAS_COND_AXIS_NAME_MAGICNO-4 "22020097.0000000000"
*MEAS_COND_AXIS_NAME_MAGICNO-5 "22020097.0000000000"
*MEAS_COND_AXIS_NAME_MAGICNO-6 "23068673.0000000000"
*MEAS_COND_AXIS_NAME_MAGICNO-7 "20971521.0000000000"
*MEAS_COND_AXIS_NAME_MAGICNO-8 "23068673.0000000000"
*MEAS_COND_AXIS_NAME_MAGICNO-9 "20971521.0000000000"
*MEAS_COND_AXIS_NAME_MAGICNO-10 "20971521.0000000000"
*MEAS_COND_AXIS_NAME_MAGICNO-11 "0.0000000000"
*MEAS_COND_AXIS_OFFSET-0 "0.0000000000"
*MEAS_COND_AXIS_OFFSET-1 "-"
*MEAS_COND_AXIS_OFFSET-2 "-"
*MEAS_COND_AXIS_OFFSET-3 "-"
*MEAS_COND_AXIS_OFFSET-4 "-"
*MEAS_COND_AXIS_OFFSET-5 "-"
*MEAS_COND_AXIS_OFFSET-6 "-"
*MEAS_COND_AXIS_OFFSET-7 "-"
*MEAS_COND_AXIS_OFFSET-8 "-"
*MEAS_COND_AXIS_OFFSET-9 "-"
*MEAS_COND_AXIS_OFFSET-10 "-"
*MEAS_COND_AXIS_OFFSET-11 "-"
*MEAS_COND_AXIS_POSITION-0 "10.0000000000"
*MEAS_COND_AXIS_POSITION-1 "0.0000000000"
*MEAS_COND_AXIS_POSITION-2 "1.0000000000"
*MEAS_COND_AXIS_POSITION-3 "2.5deg"
*MEAS_COND_AXIS_POSITION-4 "2.0mm"
*MEAS_COND_AXIS_POSITION-5 "0.625deg"
*MEAS_COND_AXIS_POSITION-6 "13.0mm(Open)"
*MEAS_COND_AXIS_POSITION-7 "2.5deg"
*MEAS_COND_AXIS_POSITION-8 "13.0mm"
*MEAS_COND_AXIS_POSITION-9 "K-beta(x2)"
*MEAS_COND_AXIS_POSITION-10 "None"
*MEAS_COND_AXIS_POSITION-11 "41.0000000000"
*MEAS_COND_AXIS_UNIT-0 "deg"
*MEAS_COND_AXIS_UNIT-1 ""
*MEAS_COND_AXIS_UNIT-2 ""
*MEAS_COND_AXIS_UNIT-3 ""
*MEAS_COND_AXIS_UNIT-4 ""
*MEAS_COND_AXIS_UNIT-5 ""
*MEAS_COND_AXIS_UNIT-6 ""
*MEAS_COND_AXIS_UNIT-7 ""
*MEAS_COND_AXIS_UNIT-8 ""
*MEAS_COND_AXIS_UNIT-9 ""
*MEAS_COND_AXIS_UNIT-10 ""
*MEAS_COND_AXIS_UNIT-11 "div"
*MEAS_COND_CORRECTION_SLIT_COUNTERMONO "None"
*MEAS_COND_CORRECTION_SLIT_DS "0.625deg"
*MEAS_COND_CORRECTION_SLIT_FILTER "None"
*MEAS_COND_CORRECTION_SLIT_IHS "2.0mm"
*MEAS_COND_CORRECTION_SLIT_RS "13.0mm"
*MEAS_COND_CORRECTION_SLIT_SOLLER_INC "2.5deg"
*MEAS_COND_CORRECTION_SLIT_SOLLER_REC "2.5deg"
*MEAS_COND_CORRECTION_SLIT_SS "13.0mm"
*MEAS_COND_COUNTER_CNTLOSS_CORR "0.0000000000"
*MEAS_COND_COUNTER_PHABASE "41.0000000000"
*MEAS_COND_COUNTER_PHAWINDOW "14.0000000000"
*MEAS_COND_COUNTER_PHA_UNIT "div"
*MEAS_COND_COUNTER_TAUDIFF "0.2500000000"
*MEAS_COND_COUNTER_TAUINT "0.7500000000"
*MEAS_COND_IRRADIATION_MODE "OFF"
*MEAS_COND_IRRADIATION_WIDTH ""
*MEAS_COND_OPT_ATTR " "
*MEAS_COND_OPT_NAME ""
*MEAS_COND_UNSYMMETRIC_MODE "OFF"
*MEAS_COND_XG_CURRENT "15.0000000000"
*MEAS_COND_XG_VOLTAGE "40.0000000000"
*MEAS_COND_XG_WAVE_TYPE "Ka"
*MEAS_DATA_COUNT "3501.0000000000"
*MEAS_SCAN_AXIS_X "Theta/2-Theta"
*MEAS_SCAN_AXIS_X_INTERNAL "TwoThetaTheta"
*MEAS_SCAN_END_TIME "08/14/17 11:25:52"
*MEAS_SCAN_MODE "CONTINUOUS"
*MEAS_SCAN_MONITOR "0"
*MEAS_SCAN_RESOLUTION_X "0.005"
*MEAS_SCAN_SPEED "15.000"
*MEAS_SCAN_SPEED_UNIT "deg/min"
*MEAS_SCAN_SPEED_USER "15.000"
*MEAS_SCAN_START "20.0000000000"
*MEAS_SCAN_START_TIME "08/14/17 11:20:36"
*MEAS_SCAN_STEP "0.0200000000"
*MEAS_SCAN_STOP "90.0000000000"
*MEAS_SCAN_UNIT_X "deg"
*MEAS_SCAN_UNIT_Y "counts"
*SLIT_SYSTEM "0"
*RAS_HEADER_END
*RAS_INT_START
20.000 186.000 1.000
20.060 185.000 1.000
20.120 198.000 1.000
20.180 192.000 1.000
20.240 184.000 1.000
20.300 188.000 1.000
20.360 192.000 1.000
20.420 192.000 1.000
20.480 192.000 1.000
20.540 177.000 1.000
20.600 181.000 1.000
20.660 194.000 1.000
20.720 188.000 1.000
20.780 195.000 1.000
20.840 199.000 1.000
20.900 219.000 1.000
20.960 186.000 1.000
21.020 208.000 1.000
21.080 203.000 1.000
21.140 211.000 1.000
21.200 199.000 1.000
21.260 189.000 1.000
21.320 192.000 1.000
21.380 202.000 1.000
21.440 210.000 1.000
21.500 205.000 1.000
21.560 186.000 1.000
21.620 188.000 1.000
21.680 210.000 1.000
21.740 202.000 1.000
21.800 198.000 1.000
21.860 215.000 1.000
21.920 218.000 1.000
21.980 203.000 1.000
22.040 208.000 1.000
22.100 208.000 1.000
22.160 227.000 1.000
22.220 205.000 1.000
22.280 234.000 1.000
22.340 207.000 1.000
22.400 185.000 1.000
22.460 241.000 1.000
22.520 211.000 1.000
22.580 208.000 1.000
22.640 220.000 1.000
22.700 224.000 1.000
22.760 235.000 1.000
22.820 239.000 1.000
22.880 260.000 1.000
22.940 233.000 1.000
23.000 226.000 1.000
23.060 243.000 1.000
23.120 254.000 1.000
23.180 279.000 1.000
23.240 259.000 1.000
23.300 279.000 1.000
23.360 285.000 1.000
23.420 292.000 1.000
23.480 305.000 1.000
23.540 293.000 1.000
23.600 318.000 1.000
23.660 318.000 1.000
23.720 347.000 1.000
23.780 332.000 1.000
23.840 330.000 1.000
23.900 340.000 1.000
23.960 361.000 1.000
24.020 377.000 1.000
24.080 348.000 1.000
24.140 405.000 1.000
24.200 404.000 1.000
24.260 414.000 1.000
24.320 436.000 1.000
24.380 487.000 1.000
24.440 508.000 1.000
24.500 540.000 1.000
24.560 579.000 1.000
24.620 591.000 1.000
24.680 647.000 1.000
24.740 659.000 1.000
24.800 721.000 1.000
24.860 721.000 1.000
24.920 782.000 1.000
24.980 833.000 1.000
25.040 923.000 1.000
25.100 923.000 1.000
25.160 1018.000 1.000
25.220 1086.000 1.000
25.280 1181.000 1.000
25.340 1317.000 1.000
25.400 1382.000 1.000
25.460 1443.000 1.000
25.520 1554.000 1.000
25.580 1667.000 1.000
25.640 1782.000 1.000
25.700 1859.000 1.000
25.760 1973.000 1.000
25.820 2123.000 1.000
25.880 2215.000 1.000
25.940 2389.000 1.000
26.000 2578.000 1.000
26.060 3038.000 1.000
26.120 3878.000 1.000
26.180 5140.000 1.000
26.240 6639.000 1.000
26.300 7203.000 1.000
26.360 6415.000 1.000
26.420 4375.000 1.000
26.480 2518.000 1.000
26.540 1515.000 1.000
26.600 1154.000 1.000
26.660 892.000 1.000
26.720 780.000 1.000
26.780 703.000 1.000
26.840 607.000 1.000
26.900 533.000 1.000
26.960 543.000 1.000
27.020 508.000 1.000
27.080 437.000 1.000
27.140 416.000 1.000
27.200 415.000 1.000
27.260 352.000 1.000
27.320 361.000 1.000
27.380 339.000 1.000
27.440 346.000 1.000
27.500 319.000 1.000
27.560 308.000 1.000
27.620 315.000 1.000
27.680 293.000 1.000
27.740 270.000 1.000
27.800 269.000 1.000
27.860 281.000 1.000
27.920 245.000 1.000
27.980 247.000 1.000
28.040 234.000 1.000
28.100 244.000 1.000
28.160 218.000 1.000
28.220 232.000 1.000
28.280 228.000 1.000
28.340 230.000 1.000
28.400 220.000 1.000
28.460 212.000 1.000
28.520 215.000 1.000
28.580 198.000 1.000
28.640 220.000 1.000
28.700 198.000 1.000
28.760 207.000 1.000
28.820 208.000 1.000
28.880 194.000 1.000
28.940 218.000 1.000
29.000 200.000 1.000
29.060 205.000 1.000
29.120 220.000 1.000
29.180 225.000 1.000
29.240 217.000 1.000
29.300 196.000 1.000
29.360 203.000 1.000
29.420 218.000 1.000
29.480 242.000 1.000
29.540 258.000 1.000
29.600 292.000 1.000
29.660 260.000 1.000
29.720 228.000 1.000
29.780 197.000 1.000
29.840 186.000 1.000
29.900 167.000 1.000
29.960 172.000 1.000
30.020 157.000 1.000
30.080 178.000 1.000
30.140 152.000 1.000
30.200 178.000 1.000
30.260 157.000 1.000
30.320 160.000 1.000
30.380 176.000 1.000
30.440 167.000 1.000
30.500 167.000 1.000
30.560 163.000 1.000
30.620 175.000 1.000
30.680 159.000 1.000
30.740 153.000 1.000
30.800 160.000 1.000
30.860 150.000 1.000
30.920 172.000 1.000
30.980 149.000 1.000
31.040 152.000 1.000
31.100 139.000 1.000
31.160 157.000 1.000
31.220 150.000 1.000
31.280 147.000 1.000
31.340 161.000 1.000
31.400 140.000 1.000
31.460 162.000 1.000
31.520 160.000 1.000
31.580 132.000 1.000
31.640 144.000 1.000
31.700 135.000 1.000
31.760 150.000 1.000
31.820 134.000 1.000
31.880 142.000 1.000
31.940 160.000 1.000
32.000 162.000 1.000
32.060 144.000 1.000
32.120 145.000 1.000
32.180 142.000 1.000
32.240 128.000 1.000
32.300 142.000 1.000
32.360 154.000 1.000
32.420 151.000 1.000
32.480 139.000 1.000
32.540 144.000 1.000
32.600 137.000 1.000
32.660 144.000 1.000
32.720 136.000 1.000
32.780 146.000 1.000
32.840 129.000 1.000
32.900 127.000 1.000
32.960 146.000 1.000
33.020 130.000 1.000
33.080 144.000 1.000
33.140 143.000 1.000
33.200 147.000 1.000
33.260 139.000 1.000
33.320 147.000 1.000
33.380 124.000 1.000
33.440 130.000 1.000
33.500 146.000 1.000
33.560 142.000 1.000
33.620 144.000 1.000
33.680 138.000 1.000
33.740 135.000 1.000
33.800 141.000 1.000
33.860 142.000 1.000
33.920 151.000 1.000
33.980 150.000 1.000
34.040 162.000 1.000
34.100 148.000 1.000
34.160 143.000 1.000
34.220 151.000 1.000
34.280 168.000 1.000
34.340 154.000 1.000
34.400 154.000 1.000
34.460 165.000 1.000
34.520 157.000 1.000
34.580 167.000 1.000
34.640 151.000 1.000
34.700 172.000 1.000
34.760 182.000 1.000
34.820 158.000 1.000
34.880 158.000 1.000
34.940 163.000 1.000
35.000 171.000 1.000
35.060 164.000 1.000
35.120 171.000 1.000
35.180 173.000 1.000
35.240 181.000 1.000
35.300 160.000 1.000
35.360 182.000 1.000
35.420 183.000 1.000
35.480 167.000 1.000
35.540 165.000 1.000
35.600 169.000 1.000
35.660 172.000 1.000
35.720 202.000 1.000
35.780 201.000 1.000
35.840 169.000 1.000
35.900 204.000 1.000
35.960 193.000 1.000
36.020 195.000 1.000
36.080 210.000 1.000
36.140 246.000 1.000
36.200 322.000 1.000
36.260 434.000 1.000
36.320 656.000 1.000
36.380 1073.000 1.000
36.440 1418.000 1.000
36.500 1620.000 1.000
36.560 1291.000 1.000
36.620 849.000 1.000
36.680 467.000 1.000
36.740 291.000 1.000
36.800 204.000 1.000
36.860 194.000 1.000
36.920 157.000 1.000
36.980 144.000 1.000
37.040 167.000 1.000
37.100 153.000 1.000
37.160 143.000 1.000
37.220 147.000 1.000
37.280 146.000 1.000
37.340 144.000 1.000
37.400 145.000 1.000
37.460 133.000 1.000
37.520 143.000 1.000
37.580 147.000 1.000
37.640 136.000 1.000
37.700 140.000 1.000
37.760 138.000 1.000
37.820 143.000 1.000
37.880 145.000 1.000
37.940 140.000 1.000
38.000 142.000 1.000
38.060 136.000 1.000
38.120 133.000 1.000
38.180 130.000 1.000
38.240 120.000 1.000
38.300 161.000 1.000
38.360 147.000 1.000
38.420 142.000 1.000
38.480 162.000 1.000
38.540 132.000 1.000
38.600 143.000 1.000
38.660 138.000 1.000
38.720 150.000 1.000
38.780 138.000 1.000
38.840 131.000 1.000
38.900 148.000 1.000
38.960 113.000 1.000
39.020 146.000 1.000
39.080 125.000 1.000
39.140 129.000 1.000
39.200 136.000 1.000
39.260 133.000 1.000
39.320 145.000 1.000
39.380 113.000 1.000
39.440 131.000 1.000
39.500 119.000 1.000
39.560 118.000 1.000
39.620 123.000 1.000
39.680 138.000 1.000
39.740 111.000 1.000
39.800 136.000 1.000
39.860 140.000 1.000
39.920 129.000 1.000
39.980 130.000 1.000
40.040 147.000 1.000
40.100 133.000 1.000
40.160 123.000 1.000
40.220 123.000 1.000
40.280 120.000 1.000
40.340 141.000 1.000
40.400 128.000 1.000
40.460 130.000 1.000
40.520 118.000 1.000
40.580 117.000 1.000
40.640 133.000 1.000
40.700 125.000 1.000
40.760 124.000 1.000
40.820 152.000 1.000
40.880 133.000 1.000
40.940 133.000 1.000
41.000 123.000 1.000
41.060 134.000 1.000
41.120 128.000 1.000
41.180 133.000 1.000
41.240 131.000 1.000
41.300 142.000 1.000
41.360 142.000 1.000
41.420 127.000 1.000
41.480 130.000 1.000
41.540 125.000 1.000
41.600 154.000 1.000
41.660 131.000 1.000
41.720 142.000 1.000
41.780 148.000 1.000
41.840 128.000 1.000
41.900 136.000 1.000
41.960 157.000 1.000
42.020 145.000 1.000
42.080 178.000 1.000
42.140 176.000 1.000
42.200 248.000 1.000
42.260 350.000 1.000
42.320 450.000 1.000
42.380 562.000 1.000
42.440 528.000 1.000
42.500 437.000 1.000
42.560 369.000 1.000
42.620 249.000 1.000
42.680 203.000 1.000
42.740 150.000 1.000
42.800 164.000 1.000
42.860 170.000 1.000
42.920 149.000 1.000
42.980 153.000 1.000
43.040 136.000 1.000
43.100 134.000 1.000
43.160 165.000 1.000
43.220 145.000 1.000
43.280 137.000 1.000
43.340 157.000 1.000
43.400 147.000 1.000
43.460 126.000 1.000
43.520 154.000 1.000
43.580 131.000 1.000
43.640 138.000 1.000
43.700 134.000 1.000
43.760 142.000 1.000
43.820 144.000 1.000
43.880 131.000 1.000
43.940 149.000 1.000
44.000 118.000 1.000
44.060 141.000 1.000
44.120 139.000 1.000
44.180 141.000 1.000
44.240 122.000 1.000
44.300 126.000 1.000
44.360 132.000 1.000
44.420 123.000 1.000
44.480 140.000 1.000
44.540 151.000 1.000
44.600 127.000 1.000
44.660 123.000 1.000
44.720 129.000 1.000
44.780 111.000 1.000
44.840 137.000 1.000
44.900 127.000 1.000
44.960 124.000 1.000
45.020 130.000 1.000
45.080 123.000 1.000
45.140 120.000 1.000
45.200 129.000 1.000
45.260 111.000 1.000
45.320 107.000 1.000
45.380 112.000 1.000
45.440 114.000 1.000
45.500 133.000 1.000
45.560 126.000 1.000
45.620 112.000 1.000
45.680 120.000 1.000
45.740 132.000 1.000
45.800 116.000 1.000
45.860 121.000 1.000
45.920 109.000 1.000
45.980 115.000 1.000
46.040 127.000 1.000
46.100 117.000 1.000
46.160 103.000 1.000
46.220 123.000 1.000
46.280 120.000 1.000
46.340 115.000 1.000
46.400 109.000 1.000
46.460 118.000 1.000
46.520 115.000 1.000
46.580 99.000 1.000
46.640 108.000 1.000
46.700 111.000 1.000
46.760 96.000 1.000
46.820 114.000 1.000
46.880 118.000 1.000
46.940 133.000 1.000
47.000 108.000 1.000
47.060 106.000 1.000
47.120 125.000 1.000
47.180 116.000 1.000
47.240 115.000 1.000
47.300 119.000 1.000
47.360 121.000 1.000
47.420 116.000 1.000
47.480 112.000 1.000
47.540 101.000 1.000
47.600 112.000 1.000
47.660 110.000 1.000
47.720 117.000 1.000
47.780 118.000 1.000
47.840 116.000 1.000
47.900 121.000 1.000
47.960 124.000 1.000
48.020 111.000 1.000
48.080 107.000 1.000
48.140 125.000 1.000
48.200 111.000 1.000
48.260 125.000 1.000
48.320 121.000 1.000
48.380 124.000 1.000
48.440 125.000 1.000
48.500 138.000 1.000
48.560 117.000 1.000
48.620 114.000 1.000
48.680 113.000 1.000
48.740 107.000 1.000
48.800 112.000 1.000
48.860 113.000 1.000
48.920 130.000 1.000
48.980 126.000 1.000
49.040 109.000 1.000
49.100 110.000 1.000
49.160 104.000 1.000
49.220 109.000 1.000
49.280 107.000 1.000
49.340 120.000 1.000
49.400 115.000 1.000
49.460 118.000 1.000
49.520 107.000 1.000
49.580 111.000 1.000
49.640 110.000 1.000
49.700 103.000 1.000
49.760 108.000 1.000
49.820 106.000 1.000
49.880 98.000 1.000
49.940 110.000 1.000
50.000 110.000 1.000
50.060 111.000 1.000
50.120 111.000 1.000
50.180 100.000 1.000
50.240 106.000 1.000
50.300 105.000 1.000
50.360 103.000 1.000
50.420 111.000 1.000
50.480 119.000 1.000
50.540 123.000 1.000
50.600 113.000 1.000
50.660 111.000 1.000
50.720 117.000 1.000
50.780 107.000 1.000
50.840 118.000 1.000
50.900 139.000 1.000
50.960 125.000 1.000
51.020 130.000 1.000
51.080 118.000 1.000
51.140 134.000 1.000
51.200 119.000 1.000
51.260 107.000 1.000
51.320 111.000 1.000
51.380 118.000 1.000
51.440 124.000 1.000
51.500 114.000 1.000
51.560 115.000 1.000
51.620 125.000 1.000
51.680 119.000 1.000
51.740 125.000 1.000
51.800 124.000 1.000
51.860 117.000 1.000
51.920 131.000 1.000
51.980 128.000 1.000
52.040 118.000 1.000
52.100 136.000 1.000
52.160 144.000 1.000
52.220 126.000 1.000
52.280 114.000 1.000
52.340 123.000 1.000
52.400 138.000 1.000
52.460 132.000 1.000
52.520 150.000 1.000
52.580 134.000 1.000
52.640 135.000 1.000
52.700 153.000 1.000
52.760 163.000 1.000
52.820 148.000 1.000
52.880 147.000 1.000
52.940 119.000 1.000
53.000 149.000 1.000
53.060 132.000 1.000
53.120 150.000 1.000
53.180 146.000 1.000
53.240 166.000 1.000
53.300 153.000 1.000
53.360 139.000 1.000
53.420 141.000 1.000
53.480 178.000 1.000
53.540 155.000 1.000
53.600 168.000 1.000
53.660 157.000 1.000
53.720 168.000 1.000
53.780 176.000 1.000
53.840 176.000 1.000
53.900 159.000 1.000
53.960 186.000 1.000
54.020 181.000 1.000
54.080 188.000 1.000
54.140 218.000 1.000
54.200 235.000 1.000
54.260 239.000 1.000
54.320 285.000 1.000
54.380 300.000 1.000
54.440 256.000 1.000
54.500 260.000 1.000
54.560 217.000 1.000
54.620 190.000 1.000
54.680 162.000 1.000
54.740 154.000 1.000
54.800 140.000 1.000
54.860 127.000 1.000
54.920 130.000 1.000
54.980 121.000 1.000
55.040 111.000 1.000
55.100 126.000 1.000
55.160 115.000 1.000
55.220 106.000 1.000
55.280 112.000 1.000
55.340 105.000 1.000
55.400 118.000 1.000
55.460 116.000 1.000
55.520 103.000 1.000
55.580 113.000 1.000
55.640 98.000 1.000
55.700 115.000 1.000
55.760 117.000 1.000
55.820 115.000 1.000
55.880 110.000 1.000
55.940 120.000 1.000
56.000 118.000 1.000
56.060 110.000 1.000
56.120 114.000 1.000
56.180 100.000 1.000
56.240 114.000 1.000
56.300 105.000 1.000
56.360 109.000 1.000
56.420 112.000 1.000
56.480 86.000 1.000
56.540 103.000 1.000
56.600 95.000 1.000
56.660 99.000 1.000
56.720 105.000 1.000
56.780 115.000 1.000
56.840 119.000 1.000
56.900 105.000 1.000
56.960 96.000 1.000
57.020 98.000 1.000
57.080 120.000 1.000
57.140 101.000 1.000
57.200 108.000 1.000
57.260 113.000 1.000
57.320 103.000 1.000
57.380 105.000 1.000
57.440 100.000 1.000
57.500 104.000 1.000
57.560 98.000 1.000
57.620 105.000 1.000
57.680 100.000 1.000
57.740 99.000 1.000
57.800 116.000 1.000
57.860 100.000 1.000
57.920 108.000 1.000
57.980 98.000 1.000
58.040 113.000 1.000
58.100 90.000 1.000
58.160 90.000 1.000
58.220 105.000 1.000
58.280 98.000 1.000
58.340 93.000 1.000
58.400 100.000 1.000
58.460 104.000 1.000
58.520 92.000 1.000
58.580 83.000 1.000
58.640 97.000 1.000
58.700 92.000 1.000
58.760 97.000 1.000
58.820 105.000 1.000
58.880 99.000 1.000
58.940 93.000 1.000
59.000 100.000 1.000
59.060 106.000 1.000
59.120 110.000 1.000
59.180 107.000 1.000
59.240 99.000 1.000
59.300 103.000 1.000
59.360 119.000 1.000
59.420 108.000 1.000
59.480 108.000 1.000
59.540 93.000 1.000
59.600 127.000 1.000
59.660 100.000 1.000
59.720 98.000 1.000
59.780 103.000 1.000
59.840 112.000 1.000
59.900 102.000 1.000
59.960 92.000 1.000
60.020 115.000 1.000
60.080 101.000 1.000
60.140 111.000 1.000
60.200 99.000 1.000
60.260 112.000 1.000
60.320 107.000 1.000
60.380 101.000 1.000
60.440 107.000 1.000
60.500 100.000 1.000
60.560 108.000 1.000
60.620 102.000 1.000
60.680 107.000 1.000
60.740 113.000 1.000
60.800 105.000 1.000
60.860 98.000 1.000
60.920 136.000 1.000
60.980 107.000 1.000
61.040 108.000 1.000
61.100 121.000 1.000
61.160 133.000 1.000
61.220 119.000 1.000
61.280 155.000 1.000
61.340 132.000 1.000
61.400 166.000 1.000
61.460 224.000 1.000
61.520 284.000 1.000
61.580 312.000 1.000
61.640 330.000 1.000
61.700 287.000 1.000
61.760 246.000 1.000
61.820 221.000 1.000
61.880 188.000 1.000
61.940 138.000 1.000
62.000 134.000 1.000
62.060 125.000 1.000
62.120 125.000 1.000
62.180 125.000 1.000
62.240 115.000 1.000
62.300 114.000 1.000
62.360 113.000 1.000
62.420 89.000 1.000
62.480 105.000 1.000
62.540 91.000 1.000
62.600 99.000 1.000
62.660 99.000 1.000
62.720 94.000 1.000
62.780 89.000 1.000
62.840 91.000 1.000
62.900 93.000 1.000
62.960 100.000 1.000
63.020 106.000 1.000
63.080 101.000 1.000
63.140 90.000 1.000
63.200 110.000 1.000
63.260 99.000 1.000
63.320 89.000 1.000
63.380 87.000 1.000
63.440 109.000 1.000
63.500 81.000 1.000
63.560 91.000 1.000
63.620 91.000 1.000
63.680 112.000 1.000
63.740 97.000 1.000
63.800 100.000 1.000
63.860 93.000 1.000
63.920 95.000 1.000
63.980 83.000 1.000
64.040 101.000 1.000
64.100 106.000 1.000
64.160 89.000 1.000
64.220 98.000 1.000
64.280 98.000 1.000
64.340 96.000 1.000
64.400 93.000 1.000
64.460 105.000 1.000
64.520 86.000 1.000
64.580 94.000 1.000
64.640 99.000 1.000
64.700 93.000 1.000
64.760 85.000 1.000
64.820 88.000 1.000
64.880 93.000 1.000
64.940 81.000 1.000
65.000 93.000 1.000
65.060 103.000 1.000
65.120 85.000 1.000
65.180 80.000 1.000
65.240 100.000 1.000
65.300 88.000 1.000
65.360 76.000 1.000
65.420 89.000 1.000
65.480 82.000 1.000
65.540 96.000 1.000
65.600 91.000 1.000
65.660 98.000 1.000
65.720 93.000 1.000
65.780 101.000 1.000
65.840 99.000 1.000
65.900 107.000 1.000
65.960 89.000 1.000
66.020 92.000 1.000
66.080 83.000 1.000
66.140 99.000 1.000
66.200 84.000 1.000
66.260 85.000 1.000
66.320 93.000 1.000
66.380 81.000 1.000
66.440 88.000 1.000
66.500 84.000 1.000
66.560 108.000 1.000
66.620 93.000 1.000
66.680 90.000 1.000
66.740 102.000 1.000
66.800 106.000 1.000
66.860 84.000 1.000
66.920 74.000 1.000
66.980 96.000 1.000
67.040 95.000 1.000
67.100 88.000 1.000
67.160 98.000 1.000
67.220 100.000 1.000
67.280 94.000 1.000
67.340 89.000 1.000
67.400 96.000 1.000
67.460 97.000 1.000
67.520 86.000 1.000
67.580 87.000 1.000
67.640 82.000 1.000
67.700 81.000 1.000
67.760 84.000 1.000
67.820 105.000 1.000
67.880 73.000 1.000
67.940 95.000 1.000
68.000 85.000 1.000
68.060 86.000 1.000
68.120 107.000 1.000
68.180 95.000 1.000
68.240 97.000 1.000
68.300 96.000 1.000
68.360 95.000 1.000
68.420 88.000 1.000
68.480 92.000 1.000
68.540 103.000 1.000
68.600 92.000 1.000
68.660 96.000 1.000
68.720 89.000 1.000
68.780 97.000 1.000
68.840 87.000 1.000
68.900 93.000 1.000
68.960 88.000 1.000
69.020 96.000 1.000
69.080 90.000 1.000
69.140 107.000 1.000
69.200 96.000 1.000
69.260 90.000 1.000
69.320 88.000 1.000
69.380 81.000 1.000
69.440 73.000 1.000
69.500 78.000 1.000
69.560 87.000 1.000
69.620 82.000 1.000
69.680 83.000 1.000
69.740 106.000 1.000
69.800 103.000 1.000
69.860 88.000 1.000
69.920 87.000 1.000
69.980 95.000 1.000
70.040 81.000 1.000
70.100 93.000 1.000
70.160 101.000 1.000
70.220 99.000 1.000
70.280 86.000 1.000
70.340 88.000 1.000
70.400 103.000 1.000
70.460 103.000 1.000
70.520 97.000 1.000
70.580 83.000 1.000
70.640 85.000 1.000
70.700 83.000 1.000
70.760 101.000 1.000
70.820 94.000 1.000
70.880 103.000 1.000
70.940 89.000 1.000
71.000 100.000 1.000
71.060 95.000 1.000
71.120 99.000 1.000
71.180 93.000 1.000
71.240 89.000 1.000
71.300 96.000 1.000
71.360 84.000 1.000
71.420 75.000 1.000
71.480 98.000 1.000
71.540 94.000 1.000
71.600 81.000 1.000
71.660 90.000 1.000
71.720 95.000 1.000
71.780 98.000 1.000
71.840 113.000 1.000
71.900 84.000 1.000
71.960 90.000 1.000
72.020 90.000 1.000
72.080 100.000 1.000
72.140 90.000 1.000
72.200 78.000 1.000
72.260 100.000 1.000
72.320 100.000 1.000
72.380 90.000 1.000
72.440 103.000 1.000
72.500 103.000 1.000
72.560 103.000 1.000
72.620 101.000 1.000
72.680 103.000 1.000
72.740 87.000 1.000
72.800 115.000 1.000
72.860 99.000 1.000
72.920 116.000 1.000
72.980 106.000 1.000
73.040 95.000 1.000
73.100 104.000 1.000
73.160 106.000 1.000
73.220 109.000 1.000
73.280 100.000 1.000
73.340 97.000 1.000
73.400 105.000 1.000
73.460 109.000 1.000
73.520 113.000 1.000
73.580 145.000 1.000
73.640 115.000 1.000
73.700 168.000 1.000
73.760 195.000 1.000
73.820 206.000 1.000
73.880 209.000 1.000
73.940 162.000 1.000
74.000 196.000 1.000
74.060 164.000 1.000
74.120 158.000 1.000
74.180 130.000 1.000
74.240 122.000 1.000
74.300 92.000 1.000
74.360 110.000 1.000
74.420 93.000 1.000
74.480 92.000 1.000
74.540 96.000 1.000
74.600 78.000 1.000
74.660 94.000 1.000
74.720 101.000 1.000
74.780 105.000 1.000
74.840 84.000 1.000
74.900 96.000 1.000
74.960 83.000 1.000
75.020 100.000 1.000
75.080 105.000 1.000
75.140 78.000 1.000
75.200 85.000 1.000
75.260 84.000 1.000
75.320 83.000 1.000
75.380 102.000 1.000
75.440 92.000 1.000
75.500 83.000 1.000
75.560 97.000 1.000
75.620 107.000 1.000
75.680 85.000 1.000
75.740 87.000 1.000
75.800 97.000 1.000
75.860 92.000 1.000
75.920 99.000 1.000
75.980 89.000 1.000
76.040 98.000 1.000
76.100 83.000 1.000
76.160 87.000 1.000
76.220 94.000 1.000
76.280 98.000 1.000
76.340 101.000 1.000
76.400 101.000 1.000
76.460 85.000 1.000
76.520 94.000 1.000
76.580 75.000 1.000
76.640 95.000 1.000
76.700 101.000 1.000
76.760 93.000 1.000
76.820 98.000 1.000
76.880 92.000 1.000
76.940 76.000 1.000
77.000 106.000 1.000
77.060 98.000 1.000
77.120 94.000 1.000
77.180 87.000 1.000
77.240 101.000 1.000
77.300 103.000 1.000
77.360 97.000 1.000
77.420 103.000 1.000
77.480 101.000 1.000
77.540 99.000 1.000
77.600 115.000 1.000
77.660 123.000 1.000
77.720 109.000 1.000
77.780 105.000 1.000
77.840 109.000 1.000
77.900 92.000 1.000
77.960 98.000 1.000
78.020 94.000 1.000
78.080 117.000 1.000
78.140 89.000 1.000
78.200 104.000 1.000
78.260 88.000 1.000
78.320 85.000 1.000
78.380 100.000 1.000
78.440 79.000 1.000
78.500 81.000 1.000
78.560 81.000 1.000
78.620 83.000 1.000
78.680 69.000 1.000
78.740 79.000 1.000
78.800 101.000 1.000
78.860 90.000 1.000
78.920 109.000 1.000
78.980 79.000 1.000
79.040 82.000 1.000
79.100 92.000 1.000
79.160 95.000 1.000
79.220 81.000 1.000
79.280 95.000 1.000
79.340 65.000 1.000
79.400 85.000 1.000
79.460 82.000 1.000
79.520 100.000 1.000
79.580 85.000 1.000
79.640 92.000 1.000
79.700 83.000 1.000
79.760 85.000 1.000
79.820 71.000 1.000
79.880 69.000 1.000
79.940 77.000 1.000
80.000 82.000 1.000
80.060 84.000 1.000
80.120 88.000 1.000
80.180 71.000 1.000
80.240 84.000 1.000
80.300 81.000 1.000
80.360 83.000 1.000
80.420 64.000 1.000
80.480 91.000 1.000
80.540 79.000 1.000
80.600 79.000 1.000
80.660 77.000 1.000
80.720 84.000 1.000
80.780 66.000 1.000
80.840 77.000 1.000
80.900 72.000 1.000
80.960 78.000 1.000
81.020 80.000 1.000
81.080 81.000 1.000
81.140 78.000 1.000
81.200 87.000 1.000
81.260 76.000 1.000
81.320 81.000 1.000
81.380 83.000 1.000
81.440 84.000 1.000
81.500 80.000 1.000
81.560 77.000 1.000
81.620 93.000 1.000
81.680 79.000 1.000
81.740 89.000 1.000
81.800 84.000 1.000
81.860 81.000 1.000
81.920 85.000 1.000
81.980 72.000 1.000
82.040 84.000 1.000
82.100 84.000 1.000
82.160 70.000 1.000
82.220 83.000 1.000
82.280 82.000 1.000
82.340 92.000 1.000
82.400 69.000 1.000
82.460 73.000 1.000
82.520 70.000 1.000
82.580 79.000 1.000
82.640 89.000 1.000
82.700 73.000 1.000
82.760 81.000 1.000
82.820 76.000 1.000
82.880 83.000 1.000
82.940 84.000 1.000
83.000 73.000 1.000
83.060 91.000 1.000
83.120 82.000 1.000
83.180 90.000 1.000
83.240 67.000 1.000
83.300 79.000 1.000
83.360 95.000 1.000
83.420 85.000 1.000
83.480 76.000 1.000
83.540 70.000 1.000
83.600 97.000 1.000
83.660 92.000 1.000
83.720 77.000 1.000
83.780 80.000 1.000
83.840 92.000 1.000
83.900 77.000 1.000
83.960 80.000 1.000
84.020 80.000 1.000
84.080 80.000 1.000
84.140 82.000 1.000
84.200 88.000 1.000
84.260 96.000 1.000
84.320 87.000 1.000
84.380 83.000 1.000
84.440 96.000 1.000
84.500 85.000 1.000
84.560 73.000 1.000
84.620 76.000 1.000
84.680 91.000 1.000
84.740 84.000 1.000
84.800 69.000 1.000
84.860 72.000 1.000
84.920 93.000 1.000
84.980 85.000 1.000
85.040 91.000 1.000
85.100 76.000 1.000
85.160 86.000 1.000
85.220 80.000 1.000
85.280 81.000 1.000
85.340 83.000 1.000
85.400 76.000 1.000
85.460 78.000 1.000
85.520 80.000 1.000
85.580 93.000 1.000
85.640 91.000 1.000
85.700 91.000 1.000
85.760 78.000 1.000
85.820 90.000 1.000
85.880 74.000 1.000
85.940 80.000 1.000
86.000 77.000 1.000
86.060 90.000 1.000
86.120 89.000 1.000
86.180 69.000 1.000
86.240 78.000 1.000
86.300 74.000 1.000
86.360 101.000 1.000
86.420 102.000 1.000
86.480 79.000 1.000
86.540 87.000 1.000
86.600 88.000 1.000
86.660 77.000 1.000
86.720 78.000 1.000
86.780 83.000 1.000
86.840 87.000 1.000
86.900 81.000 1.000
86.960 80.000 1.000
87.020 70.000 1.000
87.080 90.000 1.000
87.140 79.000 1.000
87.200 76.000 1.000
87.260 79.000 1.000
87.320 96.000 1.000
87.380 75.000 1.000
87.440 86.000 1.000
87.500 83.000 1.000
87.560 79.000 1.000
87.620 75.000 1.000
87.680 63.000 1.000
87.740 75.000 1.000
87.800 92.000 1.000
87.860 72.000 1.000
87.920 78.000 1.000
87.980 83.000 1.000
88.040 74.000 1.000
88.100 89.000 1.000
88.160 74.000 1.000
88.220 79.000 1.000
88.280 76.000 1.000
88.340 70.000 1.000
88.400 74.000 1.000
88.460 63.000 1.000
88.520 69.000 1.000
88.580 74.000 1.000
88.640 61.000 1.000
88.700 81.000 1.000
88.760 65.000 1.000
88.820 77.000 1.000
88.880 86.000 1.000
88.940 75.000 1.000
89.000 80.000 1.000
89.060 78.000 1.000
89.120 67.000 1.000
89.180 71.000 1.000
89.240 74.000 1.000
89.300 80.000 1.000
89.360 75.000 1.000
89.420 71.000 1.000
89.480 82.000 1.000
89.540 76.000 1.000
89.600 66.000 1.000
89.660 77.000 1.000
89.720 78.000 1.000
89.780 72.000 1.000
89.840 77.000 1.000
89.900 68.000 1.000
89.960 67.000 1.000
90.000 72.000 1.000
*RAS_INT_END
*RAS_DATA_END