File: Lab/XRD/all_in_one/cu2o_002.ras
*RAS_DATA_START
*RAS_HEADER_START
*CORR_POS_DB_NAME "DTEX_11112016"
*CORR_POS_GONIO_RADIUS ""
*CORR_POS_NODE_INDEX01 ""
*CORR_POS_NODE_INDEX02 ""
*CORR_POS_NODE_INDEX03 ""
*CORR_POS_NODE_INDEX04 ""
*CORR_POS_NODE_INDEX05 ""
*CORR_POS_NODE_INDEX06 ""
*CORR_POS_NODE_INDEX07 ""
*CORR_POS_NODE_INDEX08 ""
*CORR_POS_NODE_INDEX09 ""
*CORR_POS_NODE_INDEX10 ""
*CORR_POS_NODE_INDEX11 ""
*CORR_POS_NODE_LABEL01 "Si(111)"
*CORR_POS_NODE_LABEL02 "Si(220)"
*CORR_POS_NODE_LABEL03 "Si(311)"
*CORR_POS_NODE_LABEL04 "Si(400)"
*CORR_POS_NODE_LABEL05 "Si(331)"
*CORR_POS_NODE_LABEL06 "Si(422)"
*CORR_POS_NODE_LABEL07 "Si(511)"
*CORR_POS_NODE_LABEL08 "Si(440)"
*CORR_POS_NODE_LABEL09 "Si(531)"
*CORR_POS_NODE_LABEL10 "Si(620)"
*CORR_POS_NODE_LABEL11 "Si(533)"
*CORR_POS_NODE_POS_CALC01 "28.4137"
*CORR_POS_NODE_POS_CALC02 "47.2707"
*CORR_POS_NODE_POS_CALC03 "56.0883"
*CORR_POS_NODE_POS_CALC04 "69.0934"
*CORR_POS_NODE_POS_CALC05 "76.3385"
*CORR_POS_NODE_POS_CALC06 "87.9915"
*CORR_POS_NODE_POS_CALC07 "94.9137"
*CORR_POS_NODE_POS_CALC08 "106.67"
*CORR_POS_NODE_POS_CALC09 "114.054"
*CORR_POS_NODE_POS_CALC10 "127.508"
*CORR_POS_NODE_POS_CALC11 "136.858"
*CORR_POS_NODE_POS_MEAS01 "28.3712"
*CORR_POS_NODE_POS_MEAS02 "47.2304"
*CORR_POS_NODE_POS_MEAS03 "56.0465"
*CORR_POS_NODE_POS_MEAS04 "69.0523"
*CORR_POS_NODE_POS_MEAS05 "76.2993"
*CORR_POS_NODE_POS_MEAS06 "87.9512"
*CORR_POS_NODE_POS_MEAS07 "94.8772"
*CORR_POS_NODE_POS_MEAS08 "106.636"
*CORR_POS_NODE_POS_MEAS09 "114.028"
*CORR_POS_NODE_POS_MEAS10 "127.48"
*CORR_POS_NODE_POS_MEAS11 "136.839"
*CORR_POS_OPT_ATTR "集中法"
*CORR_POS_PARAM_MU ""
*CORR_POS_PARAM_PL ""
*CORR_POS_SEMODEL_TYPE "0"
*CORR_POS_STANDARD_TYPE ""
*CORR_POS_VALUE_ANALYZER "None"
*CORR_POS_VALUE_CMONO "None"
*CORR_POS_VALUE_IMONO "None"
*CORR_POS_VALUE_IS "0.625deg"
*CORR_POS_VALUE_ISL "10.0mm"
*CORR_POS_VALUE_ISOLLER "2.5deg"
*CORR_POS_VALUE_RS1 "13.0mm"
*CORR_POS_VALUE_RS2 "13.0mm"
*CORR_POS_VALUE_RSOLLER "2.5deg"
*CORR_POS_XG_FOCUS_L ""
*CORR_POS_XG_WAVE_TYPE ""
*CORR_POS_XG_WAVE_VALUE ""
*DISP_FMT_X "%.2f"
*DISP_FMT_Y "%.0f"
*DISP_FULLSCALE "5745.6000000000"
*DISP_LINE_COLOR "255.0000000000"
*DISP_LINE_STYLE "0.0000000000"
*DISP_LINE_WIDTH "0.2500000000"
*DISP_NOTE "Collected Data-4"
*DISP_OFFSET_Y "0.0000000000"
*DISP_PEAKSEARCH_UNIT_Y "COUNTS"
*DISP_RANGE_BOTTOM "0.0000000000"
*DISP_RANGE_LEFT "10.0000000000"
*DISP_RANGE_LOGCUTOFF "0.0100000000"
*DISP_RANGE_RIGHT "90.0000000000"
*DISP_RANGE_TOP "5745.6000000000"
*DISP_SCALE_MODE_Y "0.0000000000"
*DISP_TAB_NAME "Theta/2-Theta"
*DISP_TITLE_Y "Intensity"
*DISP_UNIT_Y "counts"
*DISP_WINDOW_NAME "MSG_MACROENGINE"
*FILE_COMMENT " "
*FILE_MD5 ""
*FILE_MEMO " "
*FILE_OPERATOR "MiniFlex"
*FILE_PART_ID "MEAS_PBEA_00223"
*FILE_SAMPLE "cu2o_002_test"
*FILE_TYPE "RAS_RAW"
*FILE_USERGROUP "System User"
*FILE_VERSION "1.0000000000"
*HW_ATTACHMENT_ID "ATT1031"
*HW_ATTACHMENT_NAME "6サンプルチェンジャ|ASC-6"
*HW_COUNTER_ID-0 "CUT0025"
*HW_COUNTER_ID-1 "CUT0020"
*HW_COUNTER_ID-2 "CUT0020"
*HW_COUNTER_ID-3 "CMC0021"
*HW_COUNTER_NAME-0 "D/teX Ultra|D/teX Ultra"
*HW_COUNTER_NAME-1 "None|None"
*HW_COUNTER_NAME-2 "None|None"
*HW_COUNTER_NAME-3 "検出器モノクロメータ|Detector monochromator"
*HW_COUNTER_SELECT_NAME "D/teX Ultra|D/teX Ultra"
*HW_GONIOMETER_ID "GON0070"
*HW_GONIOMETER_NAME "MiniFlex 300/600|MiniFlex 300/600"
*HW_GONIOMETER_RADIUS-0 "79.0"
*HW_GONIOMETER_RADIUS-1 "91.5"
*HW_GONIOMETER_RADIUS-2 "150.0"
*HW_GONIOMETER_RADIUS-3 "0"
*HW_GONIOMETER_RADIUS-4 "103.4"
*HW_GONIOMETER_RADIUS-5 "150.0"
*HW_GONIOMETER_RADIUS-6 "46.6"
*HW_GONIOMETER_RADIUS-7 "160.0"
*HW_I_OPT_ID-0 "ISL0021"
*HW_I_OPT_ID-1 "ISO0021"
*HW_I_OPT_NAME-0 "発散スリット|Divergence slit"
*HW_I_OPT_NAME-1 "入射平行スリット|Incident parallel slit"
*HW_R_ATTENUATER_AUTOMODE "0"
*HW_R_OPT_ID-0 "RSS0021"
*HW_R_OPT_ID-1 "RSO0021"
*HW_R_OPT_ID-2 "RRS0021"
*HW_R_OPT_NAME-0 "散乱スリット|Scattering slit"
*HW_R_OPT_NAME-1 "受光平行スリット|Receiving soller slit"
*HW_R_OPT_NAME-2 "受光スリット|Receiving slit"
*HW_SAMPLE_HOLDER_ID "SMP0000"
*HW_SAMPLE_HOLDER_NAME "無し|None"
*HW_XG_CURRENT_MAX "15"
*HW_XG_CURRENT_MIN "2"
*HW_XG_CURRENT_RESOLUTION "1"
*HW_XG_CURRENT_UNIT "mA"
*HW_XG_FOCUS "1mm x 10mm"
*HW_XG_FOCUS_TYPE "Normal"
*HW_XG_ID "1060"
*HW_XG_NAME "300W/600W 封入管-B|300W/600W Sealed tube-B"
*HW_XG_TARGET_ATOMIC_NUMBER "29.0000000000"
*HW_XG_TARGET_NAME "Cu"
*HW_XG_TYPE "Hermetic"
*HW_XG_VOLTAGE_MAX "40"
*HW_XG_VOLTAGE_MIN "20"
*HW_XG_VOLTAGE_RESOLUTION "1"
*HW_XG_VOLTAGE_UNIT "kV"
*HW_XG_WATT_MAX "1"
*HW_XG_WATT_UNIT "kW"
*HW_XG_WAVE_LENGTH_ALPHA1 "1.540593"
*HW_XG_WAVE_LENGTH_ALPHA2 "1.544414"
*HW_XG_WAVE_LENGTH_BETA "1.392250"
*MEAS_COND_AXIS_NAME-0 "Theta/2-Theta"
*MEAS_COND_AXIS_NAME-1 "Spin"
*MEAS_COND_AXIS_NAME-2 "Change"
*MEAS_COND_AXIS_NAME-3 "Soller(inc.)"
*MEAS_COND_AXIS_NAME-4 "IHS"
*MEAS_COND_AXIS_NAME-5 "DS"
*MEAS_COND_AXIS_NAME-6 "SS"
*MEAS_COND_AXIS_NAME-7 "Soller(rec.)"
*MEAS_COND_AXIS_NAME-8 "RS"
*MEAS_COND_AXIS_NAME-9 "Filter"
*MEAS_COND_AXIS_NAME-10 "Monochromator"
*MEAS_COND_AXIS_NAME-11 "PHA"
*MEAS_COND_AXIS_NAME_INTERNAL-0 "TwoThetaTheta"
*MEAS_COND_AXIS_NAME_INTERNAL-1 "Spin"
*MEAS_COND_AXIS_NAME_INTERNAL-2 "Change"
*MEAS_COND_AXIS_NAME_INTERNAL-3 "IncidentSollerSlit"
*MEAS_COND_AXIS_NAME_INTERNAL-4 "IncidentAxdSlit"
*MEAS_COND_AXIS_NAME_INTERNAL-5 "IncidentSlitBox"
*MEAS_COND_AXIS_NAME_INTERNAL-6 "ReceivingSlitBox1"
*MEAS_COND_AXIS_NAME_INTERNAL-7 "ReceivingSollerSlit"
*MEAS_COND_AXIS_NAME_INTERNAL-8 "ReceivingSlitBox2"
*MEAS_COND_AXIS_NAME_INTERNAL-9 "Filter"
*MEAS_COND_AXIS_NAME_INTERNAL-10 "CounterMonochromator"
*MEAS_COND_AXIS_NAME_INTERNAL-11 "PHA"
*MEAS_COND_AXIS_NAME_MAGICNO-0 "268632064.0000000000"
*MEAS_COND_AXIS_NAME_MAGICNO-1 "16842752.0000000000"
*MEAS_COND_AXIS_NAME_MAGICNO-2 "16842752.0000000000"
*MEAS_COND_AXIS_NAME_MAGICNO-3 "20971521.0000000000"
*MEAS_COND_AXIS_NAME_MAGICNO-4 "22020097.0000000000"
*MEAS_COND_AXIS_NAME_MAGICNO-5 "22020097.0000000000"
*MEAS_COND_AXIS_NAME_MAGICNO-6 "23068673.0000000000"
*MEAS_COND_AXIS_NAME_MAGICNO-7 "20971521.0000000000"
*MEAS_COND_AXIS_NAME_MAGICNO-8 "23068673.0000000000"
*MEAS_COND_AXIS_NAME_MAGICNO-9 "20971521.0000000000"
*MEAS_COND_AXIS_NAME_MAGICNO-10 "20971521.0000000000"
*MEAS_COND_AXIS_NAME_MAGICNO-11 "0.0000000000"
*MEAS_COND_AXIS_OFFSET-0 "0.0000000000"
*MEAS_COND_AXIS_OFFSET-1 "-"
*MEAS_COND_AXIS_OFFSET-2 "-"
*MEAS_COND_AXIS_OFFSET-3 "-"
*MEAS_COND_AXIS_OFFSET-4 "-"
*MEAS_COND_AXIS_OFFSET-5 "-"
*MEAS_COND_AXIS_OFFSET-6 "-"
*MEAS_COND_AXIS_OFFSET-7 "-"
*MEAS_COND_AXIS_OFFSET-8 "-"
*MEAS_COND_AXIS_OFFSET-9 "-"
*MEAS_COND_AXIS_OFFSET-10 "-"
*MEAS_COND_AXIS_OFFSET-11 "-"
*MEAS_COND_AXIS_POSITION-0 "10.0000000000"
*MEAS_COND_AXIS_POSITION-1 "0.0000000000"
*MEAS_COND_AXIS_POSITION-2 "1.0000000000"
*MEAS_COND_AXIS_POSITION-3 "2.5deg"
*MEAS_COND_AXIS_POSITION-4 "10.0mm"
*MEAS_COND_AXIS_POSITION-5 "0.625deg"
*MEAS_COND_AXIS_POSITION-6 "13.0mm(Open)"
*MEAS_COND_AXIS_POSITION-7 "2.5deg"
*MEAS_COND_AXIS_POSITION-8 "13.0mm"
*MEAS_COND_AXIS_POSITION-9 "K-beta(x2)"
*MEAS_COND_AXIS_POSITION-10 "None"
*MEAS_COND_AXIS_POSITION-11 "41.0000000000"
*MEAS_COND_AXIS_UNIT-0 "deg"
*MEAS_COND_AXIS_UNIT-1 ""
*MEAS_COND_AXIS_UNIT-2 ""
*MEAS_COND_AXIS_UNIT-3 ""
*MEAS_COND_AXIS_UNIT-4 ""
*MEAS_COND_AXIS_UNIT-5 ""
*MEAS_COND_AXIS_UNIT-6 ""
*MEAS_COND_AXIS_UNIT-7 ""
*MEAS_COND_AXIS_UNIT-8 ""
*MEAS_COND_AXIS_UNIT-9 ""
*MEAS_COND_AXIS_UNIT-10 ""
*MEAS_COND_AXIS_UNIT-11 "div"
*MEAS_COND_CORRECTION_SLIT_COUNTERMONO "None"
*MEAS_COND_CORRECTION_SLIT_DS "0.625deg"
*MEAS_COND_CORRECTION_SLIT_FILTER "None"
*MEAS_COND_CORRECTION_SLIT_IHS "10.0mm"
*MEAS_COND_CORRECTION_SLIT_RS "13.0mm"
*MEAS_COND_CORRECTION_SLIT_SOLLER_INC "2.5deg"
*MEAS_COND_CORRECTION_SLIT_SOLLER_REC "2.5deg"
*MEAS_COND_CORRECTION_SLIT_SS "13.0mm"
*MEAS_COND_COUNTER_CNTLOSS_CORR "0.0000000000"
*MEAS_COND_COUNTER_PHABASE "41.0000000000"
*MEAS_COND_COUNTER_PHAWINDOW "14.0000000000"
*MEAS_COND_COUNTER_PHA_UNIT "div"
*MEAS_COND_COUNTER_TAUDIFF "0.2500000000"
*MEAS_COND_COUNTER_TAUINT "0.7500000000"
*MEAS_COND_IRRADIATION_MODE "OFF"
*MEAS_COND_IRRADIATION_WIDTH ""
*MEAS_COND_OPT_ATTR " "
*MEAS_COND_OPT_NAME ""
*MEAS_COND_UNSYMMETRIC_MODE "OFF"
*MEAS_COND_XG_CURRENT "15.0000000000"
*MEAS_COND_XG_VOLTAGE "40.0000000000"
*MEAS_COND_XG_WAVE_TYPE "Ka"
*MEAS_DATA_COUNT "4001.0000000000"
*MEAS_SCAN_AXIS_X "Theta/2-Theta"
*MEAS_SCAN_AXIS_X_INTERNAL "TwoThetaTheta"
*MEAS_SCAN_END_TIME "02/23/17 13:06:10"
*MEAS_SCAN_MODE "CONTINUOUS"
*MEAS_SCAN_MONITOR "0"
*MEAS_SCAN_RESOLUTION_X "0.005"
*MEAS_SCAN_SPEED "20.000"
*MEAS_SCAN_SPEED_UNIT "deg/min"
*MEAS_SCAN_SPEED_USER "20.000"
*MEAS_SCAN_START "10.0000000000"
*MEAS_SCAN_START_TIME "02/23/17 13:01:38"
*MEAS_SCAN_STEP "0.0200000000"
*MEAS_SCAN_STOP "90.0000000000"
*MEAS_SCAN_UNIT_X "deg"
*MEAS_SCAN_UNIT_Y "counts"
*SLIT_SYSTEM "0"
*RAS_HEADER_END
*RAS_INT_START
10.000 91.000 1.000
10.060 105.000 1.000
10.120 102.000 1.000
10.180 120.000 1.000
10.240 95.000 1.000
10.300 109.000 1.000
10.360 105.000 1.000
10.420 113.000 1.000
10.480 113.000 1.000
10.540 102.000 1.000
10.600 101.000 1.000
10.660 116.000 1.000
10.720 114.000 1.000
10.780 100.000 1.000
10.840 98.000 1.000
10.900 104.000 1.000
10.960 109.000 1.000
11.020 110.000 1.000
11.080 106.000 1.000
11.140 93.000 1.000
11.200 102.000 1.000
11.260 106.000 1.000
11.320 99.000 1.000
11.380 104.000 1.000
11.440 103.000 1.000
11.500 105.000 1.000
11.560 115.000 1.000
11.620 98.000 1.000
11.680 114.000 1.000
11.740 102.000 1.000
11.800 98.000 1.000
11.860 103.000 1.000
11.920 112.000 1.000
11.980 105.000 1.000
12.040 115.000 1.000
12.100 113.000 1.000
12.160 116.000 1.000
12.220 109.000 1.000
12.280 106.000 1.000
12.340 111.000 1.000
12.400 101.000 1.000
12.460 118.000 1.000
12.520 108.000 1.000
12.580 114.000 1.000
12.640 101.000 1.000
12.700 88.000 1.000
12.760 95.000 1.000
12.820 100.000 1.000
12.880 104.000 1.000
12.940 105.000 1.000
13.000 107.000 1.000
13.060 104.000 1.000
13.120 106.000 1.000
13.180 96.000 1.000
13.240 116.000 1.000
13.300 110.000 1.000
13.360 102.000 1.000
13.420 108.000 1.000
13.480 113.000 1.000
13.540 91.000 1.000
13.600 87.000 1.000
13.660 90.000 1.000
13.720 97.000 1.000
13.780 98.000 1.000
13.840 99.000 1.000
13.900 103.000 1.000
13.960 93.000 1.000
14.020 89.000 1.000
14.080 82.000 1.000
14.140 101.000 1.000
14.200 92.000 1.000
14.260 97.000 1.000
14.320 98.000 1.000
14.380 92.000 1.000
14.440 108.000 1.000
14.500 91.000 1.000
14.560 102.000 1.000
14.620 95.000 1.000
14.680 93.000 1.000
14.740 93.000 1.000
14.800 82.000 1.000
14.860 102.000 1.000
14.920 100.000 1.000
14.980 104.000 1.000
15.040 103.000 1.000
15.100 86.000 1.000
15.160 88.000 1.000
15.220 102.000 1.000
15.280 98.000 1.000
15.340 79.000 1.000
15.400 102.000 1.000
15.460 99.000 1.000
15.520 104.000 1.000
15.580 95.000 1.000
15.640 87.000 1.000
15.700 102.000 1.000
15.760 84.000 1.000
15.820 102.000 1.000
15.880 95.000 1.000
15.940 97.000 1.000
16.000 97.000 1.000
16.060 99.000 1.000
16.120 92.000 1.000
16.180 101.000 1.000
16.240 91.000 1.000
16.300 87.000 1.000
16.360 96.000 1.000
16.420 92.000 1.000
16.480 85.000 1.000
16.540 94.000 1.000
16.600 93.000 1.000
16.660 103.000 1.000
16.720 91.000 1.000
16.780 86.000 1.000
16.840 106.000 1.000
16.900 90.000 1.000
16.960 90.000 1.000
17.020 100.000 1.000
17.080 99.000 1.000
17.140 92.000 1.000
17.200 81.000 1.000
17.260 90.000 1.000
17.320 97.000 1.000
17.380 91.000 1.000
17.440 103.000 1.000
17.500 111.000 1.000
17.560 113.000 1.000
17.620 101.000 1.000
17.680 96.000 1.000
17.740 89.000 1.000
17.800 91.000 1.000
17.860 113.000 1.000
17.920 88.000 1.000
17.980 91.000 1.000
18.040 90.000 1.000
18.100 105.000 1.000
18.160 89.000 1.000
18.220 94.000 1.000
18.280 87.000 1.000
18.340 92.000 1.000
18.400 106.000 1.000
18.460 100.000 1.000
18.520 109.000 1.000
18.580 102.000 1.000
18.640 101.000 1.000
18.700 86.000 1.000
18.760 106.000 1.000
18.820 98.000 1.000
18.880 105.000 1.000
18.940 107.000 1.000
19.000 106.000 1.000
19.060 107.000 1.000
19.120 100.000 1.000
19.180 111.000 1.000
19.240 109.000 1.000
19.300 112.000 1.000
19.360 102.000 1.000
19.420 92.000 1.000
19.480 104.000 1.000
19.540 109.000 1.000
19.600 101.000 1.000
19.660 106.000 1.000
19.720 105.000 1.000
19.780 108.000 1.000
19.840 117.000 1.000
19.900 114.000 1.000
19.960 115.000 1.000
20.020 100.000 1.000
20.080 88.000 1.000
20.140 98.000 1.000
20.200 98.000 1.000
20.260 105.000 1.000
20.320 100.000 1.000
20.380 115.000 1.000
20.440 106.000 1.000
20.500 109.000 1.000
20.560 116.000 1.000
20.620 109.000 1.000
20.680 104.000 1.000
20.740 99.000 1.000
20.800 118.000 1.000
20.860 115.000 1.000
20.920 112.000 1.000
20.980 113.000 1.000
21.040 110.000 1.000
21.100 101.000 1.000
21.160 125.000 1.000
21.220 114.000 1.000
21.280 108.000 1.000
21.340 122.000 1.000
21.400 120.000 1.000
21.460 116.000 1.000
21.520 114.000 1.000
21.580 98.000 1.000
21.640 124.000 1.000
21.700 101.000 1.000
21.760 115.000 1.000
21.820 106.000 1.000
21.880 128.000 1.000
21.940 113.000 1.000
22.000 119.000 1.000
22.060 123.000 1.000
22.120 126.000 1.000
22.180 112.000 1.000
22.240 115.000 1.000
22.300 119.000 1.000
22.360 138.000 1.000
22.420 121.000 1.000
22.480 123.000 1.000
22.540 131.000 1.000
22.600 148.000 1.000
22.660 130.000 1.000
22.720 144.000 1.000
22.780 138.000 1.000
22.840 129.000 1.000
22.900 141.000 1.000
22.960 133.000 1.000
23.020 141.000 1.000
23.080 158.000 1.000
23.140 144.000 1.000
23.200 167.000 1.000
23.260 154.000 1.000
23.320 168.000 1.000
23.380 169.000 1.000
23.440 172.000 1.000
23.500 167.000 1.000
23.560 173.000 1.000
23.620 177.000 1.000
23.680 189.000 1.000
23.740 188.000 1.000
23.800 182.000 1.000
23.860 190.000 1.000
23.920 194.000 1.000
23.980 221.000 1.000
24.040 214.000 1.000
24.100 225.000 1.000
24.160 221.000 1.000
24.220 261.000 1.000
24.280 264.000 1.000
24.340 284.000 1.000
24.400 302.000 1.000
24.460 313.000 1.000
24.520 305.000 1.000
24.580 327.000 1.000
24.640 376.000 1.000
24.700 385.000 1.000
24.760 375.000 1.000
24.820 404.000 1.000
24.880 441.000 1.000
24.940 456.000 1.000
25.000 537.000 1.000
25.060 544.000 1.000
25.120 632.000 1.000
25.180 649.000 1.000
25.240 687.000 1.000
25.300 767.000 1.000
25.360 797.000 1.000
25.420 858.000 1.000
25.480 902.000 1.000
25.540 963.000 1.000
25.600 1016.000 1.000
25.660 1120.000 1.000
25.720 1166.000 1.000
25.780 1207.000 1.000
25.840 1306.000 1.000
25.900 1329.000 1.000
25.960 1422.000 1.000
26.020 1598.000 1.000
26.080 2058.000 1.000
26.140 2780.000 1.000
26.200 4022.000 1.000
26.260 4779.000 1.000
26.320 4154.000 1.000
26.380 2828.000 1.000
26.440 1534.000 1.000
26.500 964.000 1.000
26.560 691.000 1.000
26.620 580.000 1.000
26.680 496.000 1.000
26.740 448.000 1.000
26.800 399.000 1.000
26.860 349.000 1.000
26.920 304.000 1.000
26.980 287.000 1.000
27.040 274.000 1.000
27.100 235.000 1.000
27.160 261.000 1.000
27.220 236.000 1.000
27.280 232.000 1.000
27.340 212.000 1.000
27.400 200.000 1.000
27.460 184.000 1.000
27.520 194.000 1.000
27.580 183.000 1.000
27.640 185.000 1.000
27.700 171.000 1.000
27.760 149.000 1.000
27.820 158.000 1.000
27.880 161.000 1.000
27.940 151.000 1.000
28.000 149.000 1.000
28.060 126.000 1.000
28.120 142.000 1.000
28.180 124.000 1.000
28.240 150.000 1.000
28.300 140.000 1.000
28.360 133.000 1.000
28.420 136.000 1.000
28.480 130.000 1.000
28.540 138.000 1.000
28.600 132.000 1.000
28.660 118.000 1.000
28.720 110.000 1.000
28.780 125.000 1.000
28.840 125.000 1.000
28.900 114.000 1.000
28.960 135.000 1.000
29.020 123.000 1.000
29.080 118.000 1.000
29.140 120.000 1.000
29.200 123.000 1.000
29.260 133.000 1.000
29.320 155.000 1.000
29.380 184.000 1.000
29.440 162.000 1.000
29.500 139.000 1.000
29.560 132.000 1.000
29.620 115.000 1.000
29.680 117.000 1.000
29.740 107.000 1.000
29.800 111.000 1.000
29.860 94.000 1.000
29.920 87.000 1.000
29.980 94.000 1.000
30.040 108.000 1.000
30.100 105.000 1.000
30.160 108.000 1.000
30.220 90.000 1.000
30.280 83.000 1.000
30.340 82.000 1.000
30.400 95.000 1.000
30.460 96.000 1.000
30.520 90.000 1.000
30.580 100.000 1.000
30.640 100.000 1.000
30.700 91.000 1.000
30.760 79.000 1.000
30.820 87.000 1.000
30.880 91.000 1.000
30.940 89.000 1.000
31.000 92.000 1.000
31.060 103.000 1.000
31.120 96.000 1.000
31.180 87.000 1.000
31.240 74.000 1.000
31.300 86.000 1.000
31.360 86.000 1.000
31.420 84.000 1.000
31.480 86.000 1.000
31.540 93.000 1.000
31.600 91.000 1.000
31.660 79.000 1.000
31.720 75.000 1.000
31.780 77.000 1.000
31.840 97.000 1.000
31.900 73.000 1.000
31.960 82.000 1.000
32.020 87.000 1.000
32.080 85.000 1.000
32.140 77.000 1.000
32.200 78.000 1.000
32.260 78.000 1.000
32.320 80.000 1.000
32.380 81.000 1.000
32.440 87.000 1.000
32.500 88.000 1.000
32.560 76.000 1.000
32.620 73.000 1.000
32.680 84.000 1.000
32.740 94.000 1.000
32.800 88.000 1.000
32.860 70.000 1.000
32.920 87.000 1.000
32.980 84.000 1.000
33.040 92.000 1.000
33.100 83.000 1.000
33.160 76.000 1.000
33.220 72.000 1.000
33.280 68.000 1.000
33.340 88.000 1.000
33.400 67.000 1.000
33.460 85.000 1.000
33.520 87.000 1.000
33.580 81.000 1.000
33.640 94.000 1.000
33.700 81.000 1.000
33.760 72.000 1.000
33.820 90.000 1.000
33.880 86.000 1.000
33.940 72.000 1.000
34.000 77.000 1.000
34.060 94.000 1.000
34.120 83.000 1.000
34.180 78.000 1.000
34.240 87.000 1.000
34.300 81.000 1.000
34.360 85.000 1.000
34.420 98.000 1.000
34.480 97.000 1.000
34.540 91.000 1.000
34.600 97.000 1.000
34.660 101.000 1.000
34.720 94.000 1.000
34.780 109.000 1.000
34.840 81.000 1.000
34.900 92.000 1.000
34.960 99.000 1.000
35.020 94.000 1.000
35.080 86.000 1.000
35.140 96.000 1.000
35.200 104.000 1.000
35.260 89.000 1.000
35.320 96.000 1.000
35.380 102.000 1.000
35.440 97.000 1.000
35.500 88.000 1.000
35.560 109.000 1.000
35.620 116.000 1.000
35.680 114.000 1.000
35.740 138.000 1.000
35.800 127.000 1.000
35.860 164.000 1.000
35.920 157.000 1.000
35.980 201.000 1.000
36.040 321.000 1.000
36.100 495.000 1.000
36.160 815.000 1.000
36.220 1134.000 1.000
36.280 1107.000 1.000
36.340 864.000 1.000
36.400 540.000 1.000
36.460 373.000 1.000
36.520 266.000 1.000
36.580 187.000 1.000
36.640 144.000 1.000
36.700 116.000 1.000
36.760 100.000 1.000
36.820 111.000 1.000
36.880 111.000 1.000
36.940 93.000 1.000
37.000 91.000 1.000
37.060 89.000 1.000
37.120 102.000 1.000
37.180 92.000 1.000
37.240 104.000 1.000
37.300 93.000 1.000
37.360 86.000 1.000
37.420 89.000 1.000
37.480 95.000 1.000
37.540 76.000 1.000
37.600 93.000 1.000
37.660 86.000 1.000
37.720 94.000 1.000
37.780 78.000 1.000
37.840 88.000 1.000
37.900 91.000 1.000
37.960 92.000 1.000
38.020 88.000 1.000
38.080 76.000 1.000
38.140 95.000 1.000
38.200 79.000 1.000
38.260 97.000 1.000
38.320 80.000 1.000
38.380 89.000 1.000
38.440 82.000 1.000
38.500 79.000 1.000
38.560 95.000 1.000
38.620 86.000 1.000
38.680 89.000 1.000
38.740 90.000 1.000
38.800 67.000 1.000
38.860 68.000 1.000
38.920 104.000 1.000
38.980 97.000 1.000
39.040 83.000 1.000
39.100 91.000 1.000
39.160 87.000 1.000
39.220 93.000 1.000
39.280 89.000 1.000
39.340 88.000 1.000
39.400 80.000 1.000
39.460 80.000 1.000
39.520 85.000 1.000
39.580 92.000 1.000
39.640 81.000 1.000
39.700 78.000 1.000
39.760 89.000 1.000
39.820 94.000 1.000
39.880 86.000 1.000
39.940 83.000 1.000
40.000 79.000 1.000
40.060 86.000 1.000
40.120 76.000 1.000
40.180 71.000 1.000
40.240 84.000 1.000
40.300 82.000 1.000
40.360 74.000 1.000
40.420 72.000 1.000
40.480 93.000 1.000
40.540 95.000 1.000
40.600 84.000 1.000
40.660 93.000 1.000
40.720 92.000 1.000
40.780 84.000 1.000
40.840 81.000 1.000
40.900 84.000 1.000
40.960 77.000 1.000
41.020 85.000 1.000
41.080 87.000 1.000
41.140 92.000 1.000
41.200 90.000 1.000
41.260 99.000 1.000
41.320 91.000 1.000
41.380 97.000 1.000
41.440 80.000 1.000
41.500 84.000 1.000
41.560 100.000 1.000
41.620 82.000 1.000
41.680 97.000 1.000
41.740 103.000 1.000
41.800 131.000 1.000
41.860 158.000 1.000
41.920 178.000 1.000
41.980 222.000 1.000
42.040 282.000 1.000
42.100 349.000 1.000
42.160 346.000 1.000
42.220 320.000 1.000
42.280 250.000 1.000
42.340 202.000 1.000
42.400 200.000 1.000
42.460 143.000 1.000
42.520 127.000 1.000
42.580 155.000 1.000
42.640 123.000 1.000
42.700 109.000 1.000
42.760 117.000 1.000
42.820 117.000 1.000
42.880 148.000 1.000
42.940 121.000 1.000
43.000 148.000 1.000
43.060 175.000 1.000
43.120 161.000 1.000
43.180 161.000 1.000
43.240 166.000 1.000
43.300 163.000 1.000
43.360 133.000 1.000
43.420 122.000 1.000
43.480 104.000 1.000
43.540 109.000 1.000
43.600 102.000 1.000
43.660 90.000 1.000
43.720 98.000 1.000
43.780 89.000 1.000
43.840 95.000 1.000
43.900 95.000 1.000
43.960 93.000 1.000
44.020 99.000 1.000
44.080 104.000 1.000
44.140 97.000 1.000
44.200 112.000 1.000
44.260 110.000 1.000
44.320 107.000 1.000
44.380 95.000 1.000
44.440 78.000 1.000
44.500 108.000 1.000
44.560 94.000 1.000
44.620 90.000 1.000
44.680 77.000 1.000
44.740 94.000 1.000
44.800 97.000 1.000
44.860 92.000 1.000
44.920 85.000 1.000
44.980 88.000 1.000
45.040 92.000 1.000
45.100 93.000 1.000
45.160 83.000 1.000
45.220 93.000 1.000
45.280 91.000 1.000
45.340 88.000 1.000
45.400 74.000 1.000
45.460 99.000 1.000
45.520 86.000 1.000
45.580 106.000 1.000
45.640 74.000 1.000
45.700 100.000 1.000
45.760 84.000 1.000
45.820 97.000 1.000
45.880 91.000 1.000
45.940 85.000 1.000
46.000 84.000 1.000
46.060 88.000 1.000
46.120 80.000 1.000
46.180 82.000 1.000
46.240 101.000 1.000
46.300 73.000 1.000
46.360 84.000 1.000
46.420 80.000 1.000
46.480 87.000 1.000
46.540 83.000 1.000
46.600 91.000 1.000
46.660 83.000 1.000
46.720 97.000 1.000
46.780 72.000 1.000
46.840 77.000 1.000
46.900 84.000 1.000
46.960 83.000 1.000
47.020 89.000 1.000
47.080 88.000 1.000
47.140 87.000 1.000
47.200 83.000 1.000
47.260 81.000 1.000
47.320 97.000 1.000
47.380 81.000 1.000
47.440 75.000 1.000
47.500 85.000 1.000
47.560 83.000 1.000
47.620 82.000 1.000
47.680 92.000 1.000
47.740 95.000 1.000
47.800 76.000 1.000
47.860 86.000 1.000
47.920 72.000 1.000
47.980 78.000 1.000
48.040 80.000 1.000
48.100 83.000 1.000
48.160 91.000 1.000
48.220 88.000 1.000
48.280 79.000 1.000
48.340 91.000 1.000
48.400 62.000 1.000
48.460 77.000 1.000
48.520 81.000 1.000
48.580 76.000 1.000
48.640 82.000 1.000
48.700 84.000 1.000
48.760 67.000 1.000
48.820 93.000 1.000
48.880 74.000 1.000
48.940 75.000 1.000
49.000 88.000 1.000
49.060 90.000 1.000
49.120 75.000 1.000
49.180 82.000 1.000
49.240 83.000 1.000
49.300 77.000 1.000
49.360 95.000 1.000
49.420 69.000 1.000
49.480 84.000 1.000
49.540 86.000 1.000
49.600 87.000 1.000
49.660 83.000 1.000
49.720 89.000 1.000
49.780 85.000 1.000
49.840 85.000 1.000
49.900 87.000 1.000
49.960 93.000 1.000
50.020 92.000 1.000
50.080 100.000 1.000
50.140 100.000 1.000
50.200 89.000 1.000
50.260 100.000 1.000
50.320 115.000 1.000
50.380 94.000 1.000
50.440 95.000 1.000
50.500 89.000 1.000
50.560 100.000 1.000
50.620 85.000 1.000
50.680 97.000 1.000
50.740 94.000 1.000
50.800 87.000 1.000
50.860 80.000 1.000
50.920 84.000 1.000
50.980 88.000 1.000
51.040 77.000 1.000
51.100 94.000 1.000
51.160 84.000 1.000
51.220 96.000 1.000
51.280 81.000 1.000
51.340 84.000 1.000
51.400 86.000 1.000
51.460 66.000 1.000
51.520 78.000 1.000
51.580 64.000 1.000
51.640 86.000 1.000
51.700 80.000 1.000
51.760 84.000 1.000
51.820 79.000 1.000
51.880 98.000 1.000
51.940 88.000 1.000
52.000 76.000 1.000
52.060 91.000 1.000
52.120 95.000 1.000
52.180 101.000 1.000
52.240 92.000 1.000
52.300 115.000 1.000
52.360 93.000 1.000
52.420 93.000 1.000
52.480 88.000 1.000
52.540 105.000 1.000
52.600 95.000 1.000
52.660 103.000 1.000
52.720 83.000 1.000
52.780 112.000 1.000
52.840 96.000 1.000
52.900 108.000 1.000
52.960 95.000 1.000
53.020 105.000 1.000
53.080 106.000 1.000
53.140 103.000 1.000
53.200 106.000 1.000
53.260 106.000 1.000
53.320 124.000 1.000
53.380 117.000 1.000
53.440 116.000 1.000
53.500 125.000 1.000
53.560 119.000 1.000
53.620 116.000 1.000
53.680 115.000 1.000
53.740 135.000 1.000
53.800 130.000 1.000
53.860 129.000 1.000
53.920 137.000 1.000
53.980 120.000 1.000
54.040 142.000 1.000
54.100 161.000 1.000
54.160 176.000 1.000
54.220 189.000 1.000
54.280 221.000 1.000
54.340 221.000 1.000
54.400 182.000 1.000
54.460 166.000 1.000
54.520 155.000 1.000
54.580 139.000 1.000
54.640 113.000 1.000
54.700 98.000 1.000
54.760 92.000 1.000
54.820 96.000 1.000
54.880 79.000 1.000
54.940 94.000 1.000
55.000 90.000 1.000
55.060 81.000 1.000
55.120 83.000 1.000
55.180 81.000 1.000
55.240 77.000 1.000
55.300 79.000 1.000
55.360 86.000 1.000
55.420 95.000 1.000
55.480 83.000 1.000
55.540 79.000 1.000
55.600 76.000 1.000
55.660 62.000 1.000
55.720 74.000 1.000
55.780 73.000 1.000
55.840 89.000 1.000
55.900 81.000 1.000
55.960 67.000 1.000
56.020 68.000 1.000
56.080 69.000 1.000
56.140 77.000 1.000
56.200 73.000 1.000
56.260 67.000 1.000
56.320 67.000 1.000
56.380 78.000 1.000
56.440 70.000 1.000
56.500 65.000 1.000
56.560 66.000 1.000
56.620 87.000 1.000
56.680 71.000 1.000
56.740 77.000 1.000
56.800 66.000 1.000
56.860 86.000 1.000
56.920 75.000 1.000
56.980 84.000 1.000
57.040 73.000 1.000
57.100 79.000 1.000
57.160 79.000 1.000
57.220 75.000 1.000
57.280 65.000 1.000
57.340 90.000 1.000
57.400 59.000 1.000
57.460 74.000 1.000
57.520 65.000 1.000
57.580 86.000 1.000
57.640 59.000 1.000
57.700 74.000 1.000
57.760 82.000 1.000
57.820 71.000 1.000
57.880 84.000 1.000
57.940 81.000 1.000
58.000 83.000 1.000
58.060 61.000 1.000
58.120 75.000 1.000
58.180 83.000 1.000
58.240 77.000 1.000
58.300 79.000 1.000
58.360 76.000 1.000
58.420 83.000 1.000
58.480 78.000 1.000
58.540 76.000 1.000
58.600 78.000 1.000
58.660 64.000 1.000
58.720 77.000 1.000
58.780 64.000 1.000
58.840 77.000 1.000
58.900 78.000 1.000
58.960 80.000 1.000
59.020 79.000 1.000
59.080 70.000 1.000
59.140 87.000 1.000
59.200 68.000 1.000
59.260 77.000 1.000
59.320 77.000 1.000
59.380 74.000 1.000
59.440 74.000 1.000
59.500 73.000 1.000
59.560 70.000 1.000
59.620 82.000 1.000
59.680 78.000 1.000
59.740 75.000 1.000
59.800 96.000 1.000
59.860 69.000 1.000
59.920 63.000 1.000
59.980 81.000 1.000
60.040 59.000 1.000
60.100 60.000 1.000
60.160 77.000 1.000
60.220 67.000 1.000
60.280 86.000 1.000
60.340 78.000 1.000
60.400 73.000 1.000
60.460 94.000 1.000
60.520 86.000 1.000
60.580 80.000 1.000
60.640 88.000 1.000
60.700 85.000 1.000
60.760 91.000 1.000
60.820 96.000 1.000
60.880 107.000 1.000
60.940 108.000 1.000
61.000 127.000 1.000
61.060 177.000 1.000
61.120 183.000 1.000
61.180 211.000 1.000
61.240 223.000 1.000
61.300 218.000 1.000
61.360 197.000 1.000
61.420 177.000 1.000
61.480 146.000 1.000
61.540 122.000 1.000
61.600 117.000 1.000
61.660 107.000 1.000
61.720 90.000 1.000
61.780 101.000 1.000
61.840 78.000 1.000
61.900 88.000 1.000
61.960 90.000 1.000
62.020 92.000 1.000
62.080 83.000 1.000
62.140 90.000 1.000
62.200 89.000 1.000
62.260 71.000 1.000
62.320 68.000 1.000
62.380 76.000 1.000
62.440 85.000 1.000
62.500 67.000 1.000
62.560 63.000 1.000
62.620 66.000 1.000
62.680 66.000 1.000
62.740 73.000 1.000
62.800 72.000 1.000
62.860 85.000 1.000
62.920 78.000 1.000
62.980 68.000 1.000
63.040 68.000 1.000
63.100 83.000 1.000
63.160 65.000 1.000
63.220 68.000 1.000
63.280 65.000 1.000
63.340 69.000 1.000
63.400 70.000 1.000
63.460 60.000 1.000
63.520 79.000 1.000
63.580 61.000 1.000
63.640 82.000 1.000
63.700 67.000 1.000
63.760 80.000 1.000
63.820 72.000 1.000
63.880 67.000 1.000
63.940 70.000 1.000
64.000 76.000 1.000
64.060 62.000 1.000
64.120 61.000 1.000
64.180 68.000 1.000
64.240 66.000 1.000
64.300 78.000 1.000
64.360 64.000 1.000
64.420 70.000 1.000
64.480 56.000 1.000
64.540 72.000 1.000
64.600 82.000 1.000
64.660 74.000 1.000
64.720 66.000 1.000
64.780 73.000 1.000
64.840 69.000 1.000
64.900 73.000 1.000
64.960 76.000 1.000
65.020 82.000 1.000
65.080 60.000 1.000
65.140 79.000 1.000
65.200 68.000 1.000
65.260 64.000 1.000
65.320 61.000 1.000
65.380 69.000 1.000
65.440 72.000 1.000
65.500 66.000 1.000
65.560 67.000 1.000
65.620 74.000 1.000
65.680 64.000 1.000
65.740 62.000 1.000
65.800 75.000 1.000
65.860 67.000 1.000
65.920 65.000 1.000
65.980 69.000 1.000
66.040 64.000 1.000
66.100 68.000 1.000
66.160 58.000 1.000
66.220 85.000 1.000
66.280 69.000 1.000
66.340 65.000 1.000
66.400 72.000 1.000
66.460 65.000 1.000
66.520 83.000 1.000
66.580 63.000 1.000
66.640 71.000 1.000
66.700 55.000 1.000
66.760 68.000 1.000
66.820 73.000 1.000
66.880 64.000 1.000
66.940 67.000 1.000
67.000 61.000 1.000
67.060 59.000 1.000
67.120 56.000 1.000
67.180 74.000 1.000
67.240 67.000 1.000
67.300 75.000 1.000
67.360 62.000 1.000
67.420 71.000 1.000
67.480 67.000 1.000
67.540 69.000 1.000
67.600 66.000 1.000
67.660 51.000 1.000
67.720 53.000 1.000
67.780 65.000 1.000
67.840 67.000 1.000
67.900 69.000 1.000
67.960 66.000 1.000
68.020 67.000 1.000
68.080 61.000 1.000
68.140 66.000 1.000
68.200 69.000 1.000
68.260 65.000 1.000
68.320 73.000 1.000
68.380 71.000 1.000
68.440 65.000 1.000
68.500 75.000 1.000
68.560 81.000 1.000
68.620 69.000 1.000
68.680 63.000 1.000
68.740 58.000 1.000
68.800 72.000 1.000
68.860 62.000 1.000
68.920 63.000 1.000
68.980 73.000 1.000
69.040 75.000 1.000
69.100 61.000 1.000
69.160 70.000 1.000
69.220 66.000 1.000
69.280 74.000 1.000
69.340 79.000 1.000
69.400 54.000 1.000
69.460 67.000 1.000
69.520 70.000 1.000
69.580 75.000 1.000
69.640 63.000 1.000
69.700 68.000 1.000
69.760 60.000 1.000
69.820 71.000 1.000
69.880 65.000 1.000
69.940 81.000 1.000
70.000 73.000 1.000
70.060 72.000 1.000
70.120 70.000 1.000
70.180 63.000 1.000
70.240 82.000 1.000
70.300 70.000 1.000
70.360 64.000 1.000
70.420 64.000 1.000
70.480 62.000 1.000
70.540 73.000 1.000
70.600 67.000 1.000
70.660 75.000 1.000
70.720 69.000 1.000
70.780 60.000 1.000
70.840 68.000 1.000
70.900 67.000 1.000
70.960 57.000 1.000
71.020 63.000 1.000
71.080 60.000 1.000
71.140 71.000 1.000
71.200 65.000 1.000
71.260 54.000 1.000
71.320 72.000 1.000
71.380 82.000 1.000
71.440 74.000 1.000
71.500 66.000 1.000
71.560 67.000 1.000
71.620 53.000 1.000
71.680 58.000 1.000
71.740 59.000 1.000
71.800 65.000 1.000
71.860 75.000 1.000
71.920 82.000 1.000
71.980 66.000 1.000
72.040 84.000 1.000
72.100 65.000 1.000
72.160 66.000 1.000
72.220 71.000 1.000
72.280 78.000 1.000
72.340 71.000 1.000
72.400 84.000 1.000
72.460 78.000 1.000
72.520 72.000 1.000
72.580 69.000 1.000
72.640 98.000 1.000
72.700 78.000 1.000
72.760 77.000 1.000
72.820 92.000 1.000
72.880 76.000 1.000
72.940 95.000 1.000
73.000 93.000 1.000
73.060 110.000 1.000
73.120 97.000 1.000
73.180 135.000 1.000
73.240 116.000 1.000
73.300 154.000 1.000
73.360 138.000 1.000
73.420 157.000 1.000
73.480 139.000 1.000
73.540 134.000 1.000
73.600 132.000 1.000
73.660 115.000 1.000
73.720 91.000 1.000
73.780 99.000 1.000
73.840 82.000 1.000
73.900 101.000 1.000
73.960 89.000 1.000
74.020 83.000 1.000
74.080 83.000 1.000
74.140 77.000 1.000
74.200 86.000 1.000
74.260 74.000 1.000
74.320 73.000 1.000
74.380 71.000 1.000
74.440 70.000 1.000
74.500 58.000 1.000
74.560 67.000 1.000
74.620 66.000 1.000
74.680 73.000 1.000
74.740 63.000 1.000
74.800 55.000 1.000
74.860 78.000 1.000
74.920 70.000 1.000
74.980 73.000 1.000
75.040 62.000 1.000
75.100 68.000 1.000
75.160 69.000 1.000
75.220 59.000 1.000
75.280 69.000 1.000
75.340 72.000 1.000
75.400 64.000 1.000
75.460 78.000 1.000
75.520 66.000 1.000
75.580 64.000 1.000
75.640 67.000 1.000
75.700 64.000 1.000
75.760 80.000 1.000
75.820 67.000 1.000
75.880 59.000 1.000
75.940 65.000 1.000
76.000 79.000 1.000
76.060 78.000 1.000
76.120 84.000 1.000
76.180 68.000 1.000
76.240 78.000 1.000
76.300 77.000 1.000
76.360 61.000 1.000
76.420 69.000 1.000
76.480 71.000 1.000
76.540 75.000 1.000
76.600 59.000 1.000
76.660 68.000 1.000
76.720 69.000 1.000
76.780 65.000 1.000
76.840 68.000 1.000
76.900 69.000 1.000
76.960 65.000 1.000
77.020 69.000 1.000
77.080 73.000 1.000
77.140 79.000 1.000
77.200 78.000 1.000
77.260 80.000 1.000
77.320 89.000 1.000
77.380 61.000 1.000
77.440 77.000 1.000
77.500 81.000 1.000
77.560 72.000 1.000
77.620 69.000 1.000
77.680 69.000 1.000
77.740 72.000 1.000
77.800 71.000 1.000
77.860 60.000 1.000
77.920 69.000 1.000
77.980 60.000 1.000
78.040 65.000 1.000
78.100 63.000 1.000
78.160 61.000 1.000
78.220 52.000 1.000
78.280 58.000 1.000
78.340 60.000 1.000
78.400 80.000 1.000
78.460 69.000 1.000
78.520 48.000 1.000
78.580 57.000 1.000
78.640 53.000 1.000
78.700 62.000 1.000
78.760 64.000 1.000
78.820 53.000 1.000
78.880 64.000 1.000
78.940 58.000 1.000
79.000 62.000 1.000
79.060 66.000 1.000
79.120 71.000 1.000
79.180 60.000 1.000
79.240 61.000 1.000
79.300 63.000 1.000
79.360 72.000 1.000
79.420 59.000 1.000
79.480 70.000 1.000
79.540 62.000 1.000
79.600 70.000 1.000
79.660 53.000 1.000
79.720 57.000 1.000
79.780 62.000 1.000
79.840 65.000 1.000
79.900 65.000 1.000
79.960 68.000 1.000
80.020 67.000 1.000
80.080 54.000 1.000
80.140 59.000 1.000
80.200 57.000 1.000
80.260 58.000 1.000
80.320 60.000 1.000
80.380 55.000 1.000
80.440 70.000 1.000
80.500 65.000 1.000
80.560 62.000 1.000
80.620 70.000 1.000
80.680 71.000 1.000
80.740 63.000 1.000
80.800 55.000 1.000
80.860 70.000 1.000
80.920 69.000 1.000
80.980 71.000 1.000
81.040 59.000 1.000
81.100 61.000 1.000
81.160 59.000 1.000
81.220 54.000 1.000
81.280 47.000 1.000
81.340 71.000 1.000
81.400 58.000 1.000
81.460 77.000 1.000
81.520 64.000 1.000
81.580 60.000 1.000
81.640 54.000 1.000
81.700 53.000 1.000
81.760 52.000 1.000
81.820 66.000 1.000
81.880 63.000 1.000
81.940 58.000 1.000
82.000 56.000 1.000
82.060 56.000 1.000
82.120 65.000 1.000
82.180 61.000 1.000
82.240 66.000 1.000
82.300 63.000 1.000
82.360 61.000 1.000
82.420 59.000 1.000
82.480 73.000 1.000
82.540 62.000 1.000
82.600 61.000 1.000
82.660 67.000 1.000
82.720 77.000 1.000
82.780 57.000 1.000
82.840 50.000 1.000
82.900 61.000 1.000
82.960 56.000 1.000
83.020 54.000 1.000
83.080 65.000 1.000
83.140 62.000 1.000
83.200 56.000 1.000
83.260 59.000 1.000
83.320 72.000 1.000
83.380 64.000 1.000
83.440 65.000 1.000
83.500 64.000 1.000
83.560 63.000 1.000
83.620 63.000 1.000
83.680 61.000 1.000
83.740 63.000 1.000
83.800 66.000 1.000
83.860 61.000 1.000
83.920 67.000 1.000
83.980 68.000 1.000
84.040 77.000 1.000
84.100 68.000 1.000
84.160 61.000 1.000
84.220 58.000 1.000
84.280 62.000 1.000
84.340 55.000 1.000
84.400 67.000 1.000
84.460 66.000 1.000
84.520 69.000 1.000
84.580 48.000 1.000
84.640 72.000 1.000
84.700 52.000 1.000
84.760 50.000 1.000
84.820 63.000 1.000
84.880 80.000 1.000
84.940 62.000 1.000
85.000 75.000 1.000
85.060 54.000 1.000
85.120 57.000 1.000
85.180 53.000 1.000
85.240 52.000 1.000
85.300 66.000 1.000
85.360 79.000 1.000
85.420 65.000 1.000
85.480 74.000 1.000
85.540 55.000 1.000
85.600 63.000 1.000
85.660 63.000 1.000
85.720 64.000 1.000
85.780 63.000 1.000
85.840 53.000 1.000
85.900 53.000 1.000
85.960 67.000 1.000
86.020 60.000 1.000
86.080 60.000 1.000
86.140 50.000 1.000
86.200 66.000 1.000
86.260 55.000 1.000
86.320 60.000 1.000
86.380 79.000 1.000
86.440 56.000 1.000
86.500 56.000 1.000
86.560 71.000 1.000
86.620 71.000 1.000
86.680 69.000 1.000
86.740 68.000 1.000
86.800 63.000 1.000
86.860 58.000 1.000
86.920 63.000 1.000
86.980 67.000 1.000
87.040 69.000 1.000
87.100 80.000 1.000
87.160 62.000 1.000
87.220 58.000 1.000
87.280 62.000 1.000
87.340 67.000 1.000
87.400 49.000 1.000
87.460 62.000 1.000
87.520 56.000 1.000
87.580 66.000 1.000
87.640 75.000 1.000
87.700 60.000 1.000
87.760 54.000 1.000
87.820 58.000 1.000
87.880 59.000 1.000
87.940 56.000 1.000
88.000 57.000 1.000
88.060 57.000 1.000
88.120 65.000 1.000
88.180 58.000 1.000
88.240 54.000 1.000
88.300 60.000 1.000
88.360 65.000 1.000
88.420 53.000 1.000
88.480 63.000 1.000
88.540 58.000 1.000
88.600 62.000 1.000
88.660 53.000 1.000
88.720 66.000 1.000
88.780 59.000 1.000
88.840 69.000 1.000
88.900 61.000 1.000
88.960 52.000 1.000
89.020 64.000 1.000
89.080 52.000 1.000
89.140 67.000 1.000
89.200 54.000 1.000
89.260 58.000 1.000
89.320 58.000 1.000
89.380 59.000 1.000
89.440 48.000 1.000
89.500 55.000 1.000
89.560 50.000 1.000
89.620 56.000 1.000
89.680 62.000 1.000
89.740 64.000 1.000
89.800 72.000 1.000
89.860 68.000 1.000
89.920 59.000 1.000
89.980 58.000 1.000
90.000 61.000 1.000
*RAS_INT_END
*RAS_DATA_END