File: Lab/XRD/all_in_one/cu2o_006.ras
*RAS_DATA_START
*RAS_HEADER_START
*CORR_POS_DB_NAME "DTEX_11112016"
*CORR_POS_GONIO_RADIUS ""
*CORR_POS_NODE_INDEX01 ""
*CORR_POS_NODE_INDEX02 ""
*CORR_POS_NODE_INDEX03 ""
*CORR_POS_NODE_INDEX04 ""
*CORR_POS_NODE_INDEX05 ""
*CORR_POS_NODE_INDEX06 ""
*CORR_POS_NODE_INDEX07 ""
*CORR_POS_NODE_INDEX08 ""
*CORR_POS_NODE_INDEX09 ""
*CORR_POS_NODE_INDEX10 ""
*CORR_POS_NODE_INDEX11 ""
*CORR_POS_NODE_LABEL01 "Si(111)"
*CORR_POS_NODE_LABEL02 "Si(220)"
*CORR_POS_NODE_LABEL03 "Si(311)"
*CORR_POS_NODE_LABEL04 "Si(400)"
*CORR_POS_NODE_LABEL05 "Si(331)"
*CORR_POS_NODE_LABEL06 "Si(422)"
*CORR_POS_NODE_LABEL07 "Si(511)"
*CORR_POS_NODE_LABEL08 "Si(440)"
*CORR_POS_NODE_LABEL09 "Si(531)"
*CORR_POS_NODE_LABEL10 "Si(620)"
*CORR_POS_NODE_LABEL11 "Si(533)"
*CORR_POS_NODE_POS_CALC01 "28.4137"
*CORR_POS_NODE_POS_CALC02 "47.2707"
*CORR_POS_NODE_POS_CALC03 "56.0883"
*CORR_POS_NODE_POS_CALC04 "69.0934"
*CORR_POS_NODE_POS_CALC05 "76.3385"
*CORR_POS_NODE_POS_CALC06 "87.9915"
*CORR_POS_NODE_POS_CALC07 "94.9137"
*CORR_POS_NODE_POS_CALC08 "106.67"
*CORR_POS_NODE_POS_CALC09 "114.054"
*CORR_POS_NODE_POS_CALC10 "127.508"
*CORR_POS_NODE_POS_CALC11 "136.858"
*CORR_POS_NODE_POS_MEAS01 "28.3712"
*CORR_POS_NODE_POS_MEAS02 "47.2304"
*CORR_POS_NODE_POS_MEAS03 "56.0465"
*CORR_POS_NODE_POS_MEAS04 "69.0523"
*CORR_POS_NODE_POS_MEAS05 "76.2993"
*CORR_POS_NODE_POS_MEAS06 "87.9512"
*CORR_POS_NODE_POS_MEAS07 "94.8772"
*CORR_POS_NODE_POS_MEAS08 "106.636"
*CORR_POS_NODE_POS_MEAS09 "114.028"
*CORR_POS_NODE_POS_MEAS10 "127.48"
*CORR_POS_NODE_POS_MEAS11 "136.839"
*CORR_POS_OPT_ATTR "集中法"
*CORR_POS_PARAM_MU ""
*CORR_POS_PARAM_PL ""
*CORR_POS_SEMODEL_TYPE "0"
*CORR_POS_STANDARD_TYPE ""
*CORR_POS_VALUE_ANALYZER "None"
*CORR_POS_VALUE_CMONO "None"
*CORR_POS_VALUE_IMONO "None"
*CORR_POS_VALUE_IS "0.625deg"
*CORR_POS_VALUE_ISL "10.0mm"
*CORR_POS_VALUE_ISOLLER "2.5deg"
*CORR_POS_VALUE_RS1 "13.0mm"
*CORR_POS_VALUE_RS2 "13.0mm"
*CORR_POS_VALUE_RSOLLER "2.5deg"
*CORR_POS_XG_FOCUS_L ""
*CORR_POS_XG_WAVE_TYPE ""
*CORR_POS_XG_WAVE_VALUE ""
*DISP_FMT_X "%.2f"
*DISP_FMT_Y "%.0f"
*DISP_FULLSCALE "9128.4000000000"
*DISP_LINE_COLOR "255.0000000000"
*DISP_LINE_STYLE "0.0000000000"
*DISP_LINE_WIDTH "0.2500000000"
*DISP_NOTE "Collected Data-1"
*DISP_OFFSET_Y "0.0000000000"
*DISP_PEAKSEARCH_UNIT_Y "COUNTS"
*DISP_RANGE_BOTTOM "0.0000000000"
*DISP_RANGE_LEFT "10.0000000000"
*DISP_RANGE_LOGCUTOFF "0.0100000000"
*DISP_RANGE_RIGHT "90.0000000000"
*DISP_RANGE_TOP "9128.4000000000"
*DISP_SCALE_MODE_Y "0.0000000000"
*DISP_TAB_NAME "Theta/2-Theta"
*DISP_TITLE_Y "Intensity"
*DISP_UNIT_Y "COUNTS"
*DISP_WINDOW_NAME "MSG_MACROENGINE"
*FILE_COMMENT " "
*FILE_MD5 ""
*FILE_MEMO "35C"
*FILE_OPERATOR "MiniFlex"
*FILE_PART_ID "MEAS_PBEA_00223"
*FILE_SAMPLE "006"
*FILE_TYPE "RAS_RAW"
*FILE_USERGROUP "System User"
*FILE_VERSION "1.0000000000"
*HW_ATTACHMENT_ID "ATT1031"
*HW_ATTACHMENT_NAME "6サンプルチェンジャ|ASC-6"
*HW_COUNTER_ID-0 "CUT0025"
*HW_COUNTER_ID-1 "CUT0020"
*HW_COUNTER_ID-2 "CUT0020"
*HW_COUNTER_ID-3 "CMC0021"
*HW_COUNTER_NAME-0 "D/teX Ultra|D/teX Ultra"
*HW_COUNTER_NAME-1 "None|None"
*HW_COUNTER_NAME-2 "None|None"
*HW_COUNTER_NAME-3 "検出器モノクロメータ|Detector monochromator"
*HW_COUNTER_SELECT_NAME "D/teX Ultra|D/teX Ultra"
*HW_GONIOMETER_ID "GON0070"
*HW_GONIOMETER_NAME "MiniFlex 300/600|MiniFlex 300/600"
*HW_GONIOMETER_RADIUS-0 "79.0"
*HW_GONIOMETER_RADIUS-1 "91.5"
*HW_GONIOMETER_RADIUS-2 "150.0"
*HW_GONIOMETER_RADIUS-3 "0"
*HW_GONIOMETER_RADIUS-4 "103.4"
*HW_GONIOMETER_RADIUS-5 "150.0"
*HW_GONIOMETER_RADIUS-6 "46.6"
*HW_GONIOMETER_RADIUS-7 "160.0"
*HW_I_OPT_ID-0 "ISL0021"
*HW_I_OPT_ID-1 "ISO0021"
*HW_I_OPT_NAME-0 "発散スリット|Divergence slit"
*HW_I_OPT_NAME-1 "入射平行スリット|Incident parallel slit"
*HW_R_ATTENUATER_AUTOMODE "0"
*HW_R_OPT_ID-0 "RSS0021"
*HW_R_OPT_ID-1 "RSO0021"
*HW_R_OPT_ID-2 "RRS0021"
*HW_R_OPT_NAME-0 "散乱スリット|Scattering slit"
*HW_R_OPT_NAME-1 "受光平行スリット|Receiving soller slit"
*HW_R_OPT_NAME-2 "受光スリット|Receiving slit"
*HW_SAMPLE_HOLDER_ID "SMP0000"
*HW_SAMPLE_HOLDER_NAME "無し|None"
*HW_XG_CURRENT_MAX "15"
*HW_XG_CURRENT_MIN "2"
*HW_XG_CURRENT_RESOLUTION "1"
*HW_XG_CURRENT_UNIT "mA"
*HW_XG_FOCUS "1mm x 10mm"
*HW_XG_FOCUS_TYPE "Normal"
*HW_XG_ID "1060"
*HW_XG_NAME "300W/600W 封入管-B|300W/600W Sealed tube-B"
*HW_XG_TARGET_ATOMIC_NUMBER "29.0000000000"
*HW_XG_TARGET_NAME "Cu"
*HW_XG_TYPE "Hermetic"
*HW_XG_VOLTAGE_MAX "40"
*HW_XG_VOLTAGE_MIN "20"
*HW_XG_VOLTAGE_RESOLUTION "1"
*HW_XG_VOLTAGE_UNIT "kV"
*HW_XG_WATT_MAX "1"
*HW_XG_WATT_UNIT "kW"
*HW_XG_WAVE_LENGTH_ALPHA1 "1.540593"
*HW_XG_WAVE_LENGTH_ALPHA2 "1.544414"
*HW_XG_WAVE_LENGTH_BETA "1.392250"
*MEAS_COND_AXIS_NAME-0 "Theta/2-Theta"
*MEAS_COND_AXIS_NAME-1 "Spin"
*MEAS_COND_AXIS_NAME-2 "Change"
*MEAS_COND_AXIS_NAME-3 "Soller(inc.)"
*MEAS_COND_AXIS_NAME-4 "IHS"
*MEAS_COND_AXIS_NAME-5 "DS"
*MEAS_COND_AXIS_NAME-6 "SS"
*MEAS_COND_AXIS_NAME-7 "Soller(rec.)"
*MEAS_COND_AXIS_NAME-8 "RS"
*MEAS_COND_AXIS_NAME-9 "Filter"
*MEAS_COND_AXIS_NAME-10 "Monochromator"
*MEAS_COND_AXIS_NAME-11 "PHA"
*MEAS_COND_AXIS_NAME_INTERNAL-0 "TwoThetaTheta"
*MEAS_COND_AXIS_NAME_INTERNAL-1 "Spin"
*MEAS_COND_AXIS_NAME_INTERNAL-2 "Change"
*MEAS_COND_AXIS_NAME_INTERNAL-3 "IncidentSollerSlit"
*MEAS_COND_AXIS_NAME_INTERNAL-4 "IncidentAxdSlit"
*MEAS_COND_AXIS_NAME_INTERNAL-5 "IncidentSlitBox"
*MEAS_COND_AXIS_NAME_INTERNAL-6 "ReceivingSlitBox1"
*MEAS_COND_AXIS_NAME_INTERNAL-7 "ReceivingSollerSlit"
*MEAS_COND_AXIS_NAME_INTERNAL-8 "ReceivingSlitBox2"
*MEAS_COND_AXIS_NAME_INTERNAL-9 "Filter"
*MEAS_COND_AXIS_NAME_INTERNAL-10 "CounterMonochromator"
*MEAS_COND_AXIS_NAME_INTERNAL-11 "PHA"
*MEAS_COND_AXIS_NAME_MAGICNO-0 "268632064.0000000000"
*MEAS_COND_AXIS_NAME_MAGICNO-1 "16842752.0000000000"
*MEAS_COND_AXIS_NAME_MAGICNO-2 "16842752.0000000000"
*MEAS_COND_AXIS_NAME_MAGICNO-3 "20971521.0000000000"
*MEAS_COND_AXIS_NAME_MAGICNO-4 "22020097.0000000000"
*MEAS_COND_AXIS_NAME_MAGICNO-5 "22020097.0000000000"
*MEAS_COND_AXIS_NAME_MAGICNO-6 "23068673.0000000000"
*MEAS_COND_AXIS_NAME_MAGICNO-7 "20971521.0000000000"
*MEAS_COND_AXIS_NAME_MAGICNO-8 "23068673.0000000000"
*MEAS_COND_AXIS_NAME_MAGICNO-9 "20971521.0000000000"
*MEAS_COND_AXIS_NAME_MAGICNO-10 "20971521.0000000000"
*MEAS_COND_AXIS_NAME_MAGICNO-11 "0.0000000000"
*MEAS_COND_AXIS_OFFSET-0 "0.0000000000"
*MEAS_COND_AXIS_OFFSET-1 "-"
*MEAS_COND_AXIS_OFFSET-2 "-"
*MEAS_COND_AXIS_OFFSET-3 "-"
*MEAS_COND_AXIS_OFFSET-4 "-"
*MEAS_COND_AXIS_OFFSET-5 "-"
*MEAS_COND_AXIS_OFFSET-6 "-"
*MEAS_COND_AXIS_OFFSET-7 "-"
*MEAS_COND_AXIS_OFFSET-8 "-"
*MEAS_COND_AXIS_OFFSET-9 "-"
*MEAS_COND_AXIS_OFFSET-10 "-"
*MEAS_COND_AXIS_OFFSET-11 "-"
*MEAS_COND_AXIS_POSITION-0 "10.0000000000"
*MEAS_COND_AXIS_POSITION-1 "0.0000000000"
*MEAS_COND_AXIS_POSITION-2 "1.0000000000"
*MEAS_COND_AXIS_POSITION-3 "2.5deg"
*MEAS_COND_AXIS_POSITION-4 "10.0mm"
*MEAS_COND_AXIS_POSITION-5 "0.625deg"
*MEAS_COND_AXIS_POSITION-6 "13.0mm(Open)"
*MEAS_COND_AXIS_POSITION-7 "2.5deg"
*MEAS_COND_AXIS_POSITION-8 "13.0mm"
*MEAS_COND_AXIS_POSITION-9 "K-beta(x2)"
*MEAS_COND_AXIS_POSITION-10 "None"
*MEAS_COND_AXIS_POSITION-11 "41.0000000000"
*MEAS_COND_AXIS_UNIT-0 "deg"
*MEAS_COND_AXIS_UNIT-1 ""
*MEAS_COND_AXIS_UNIT-2 ""
*MEAS_COND_AXIS_UNIT-3 ""
*MEAS_COND_AXIS_UNIT-4 ""
*MEAS_COND_AXIS_UNIT-5 ""
*MEAS_COND_AXIS_UNIT-6 ""
*MEAS_COND_AXIS_UNIT-7 ""
*MEAS_COND_AXIS_UNIT-8 ""
*MEAS_COND_AXIS_UNIT-9 ""
*MEAS_COND_AXIS_UNIT-10 ""
*MEAS_COND_AXIS_UNIT-11 "div"
*MEAS_COND_CORRECTION_SLIT_COUNTERMONO "None"
*MEAS_COND_CORRECTION_SLIT_DS "0.625deg"
*MEAS_COND_CORRECTION_SLIT_FILTER "None"
*MEAS_COND_CORRECTION_SLIT_IHS "10.0mm"
*MEAS_COND_CORRECTION_SLIT_RS "13.0mm"
*MEAS_COND_CORRECTION_SLIT_SOLLER_INC "2.5deg"
*MEAS_COND_CORRECTION_SLIT_SOLLER_REC "2.5deg"
*MEAS_COND_CORRECTION_SLIT_SS "13.0mm"
*MEAS_COND_COUNTER_CNTLOSS_CORR "0.0000000000"
*MEAS_COND_COUNTER_PHABASE "41.0000000000"
*MEAS_COND_COUNTER_PHAWINDOW "14.0000000000"
*MEAS_COND_COUNTER_PHA_UNIT "div"
*MEAS_COND_COUNTER_TAUDIFF "0.2500000000"
*MEAS_COND_COUNTER_TAUINT "0.7500000000"
*MEAS_COND_IRRADIATION_MODE "OFF"
*MEAS_COND_IRRADIATION_WIDTH ""
*MEAS_COND_OPT_ATTR " "
*MEAS_COND_OPT_NAME ""
*MEAS_COND_UNSYMMETRIC_MODE "OFF"
*MEAS_COND_XG_CURRENT "15.0000000000"
*MEAS_COND_XG_VOLTAGE "40.0000000000"
*MEAS_COND_XG_WAVE_TYPE "Ka"
*MEAS_DATA_COUNT "4001.0000000000"
*MEAS_SCAN_AXIS_X "Theta/2-Theta"
*MEAS_SCAN_AXIS_X_INTERNAL "TwoThetaTheta"
*MEAS_SCAN_END_TIME "03/14/17 10:45:12"
*MEAS_SCAN_MODE "CONTINUOUS"
*MEAS_SCAN_MONITOR "0"
*MEAS_SCAN_RESOLUTION_X "0.005"
*MEAS_SCAN_SPEED "10.000"
*MEAS_SCAN_SPEED_UNIT "deg/min"
*MEAS_SCAN_SPEED_USER "10.000"
*MEAS_SCAN_START "10.0000000000"
*MEAS_SCAN_START_TIME "03/14/17 10:36:26"
*MEAS_SCAN_STEP "0.0200000000"
*MEAS_SCAN_STOP "90.0000000000"
*MEAS_SCAN_UNIT_X "deg"
*MEAS_SCAN_UNIT_Y "counts"
*SLIT_SYSTEM "0"
*RAS_HEADER_END
*RAS_INT_START
10.000 168.000 1.000
10.060 160.000 1.000
10.120 197.000 1.000
10.180 200.000 1.000
10.240 195.000 1.000
10.300 172.000 1.000
10.360 173.000 1.000
10.420 185.000 1.000
10.480 175.000 1.000
10.540 202.000 1.000
10.600 197.000 1.000
10.660 168.000 1.000
10.720 184.000 1.000
10.780 176.000 1.000
10.840 184.000 1.000
10.900 191.000 1.000
10.960 180.000 1.000
11.020 196.000 1.000
11.080 173.000 1.000
11.140 185.000 1.000
11.200 171.000 1.000
11.260 193.000 1.000
11.320 167.000 1.000
11.380 192.000 1.000
11.440 172.000 1.000
11.500 195.000 1.000
11.560 171.000 1.000
11.620 193.000 1.000
11.680 179.000 1.000
11.740 188.000 1.000
11.800 184.000 1.000
11.860 201.000 1.000
11.920 199.000 1.000
11.980 200.000 1.000
12.040 195.000 1.000
12.100 171.000 1.000
12.160 176.000 1.000
12.220 207.000 1.000
12.280 186.000 1.000
12.340 183.000 1.000
12.400 199.000 1.000
12.460 181.000 1.000
12.520 198.000 1.000
12.580 195.000 1.000
12.640 184.000 1.000
12.700 181.000 1.000
12.760 173.000 1.000
12.820 175.000 1.000
12.880 187.000 1.000
12.940 205.000 1.000
13.000 174.000 1.000
13.060 191.000 1.000
13.120 191.000 1.000
13.180 186.000 1.000
13.240 193.000 1.000
13.300 191.000 1.000
13.360 193.000 1.000
13.420 189.000 1.000
13.480 167.000 1.000
13.540 181.000 1.000
13.600 179.000 1.000
13.660 190.000 1.000
13.720 190.000 1.000
13.780 180.000 1.000
13.840 179.000 1.000
13.900 189.000 1.000
13.960 189.000 1.000
14.020 181.000 1.000
14.080 167.000 1.000
14.140 216.000 1.000
14.200 169.000 1.000
14.260 183.000 1.000
14.320 179.000 1.000
14.380 178.000 1.000
14.440 185.000 1.000
14.500 166.000 1.000
14.560 172.000 1.000
14.620 178.000 1.000
14.680 166.000 1.000
14.740 163.000 1.000
14.800 183.000 1.000
14.860 170.000 1.000
14.920 186.000 1.000
14.980 193.000 1.000
15.040 193.000 1.000
15.100 180.000 1.000
15.160 215.000 1.000
15.220 184.000 1.000
15.280 197.000 1.000
15.340 170.000 1.000
15.400 188.000 1.000
15.460 180.000 1.000
15.520 168.000 1.000
15.580 170.000 1.000
15.640 183.000 1.000
15.700 164.000 1.000
15.760 172.000 1.000
15.820 180.000 1.000
15.880 177.000 1.000
15.940 178.000 1.000
16.000 174.000 1.000
16.060 184.000 1.000
16.120 187.000 1.000
16.180 174.000 1.000
16.240 179.000 1.000
16.300 192.000 1.000
16.360 190.000 1.000
16.420 170.000 1.000
16.480 168.000 1.000
16.540 192.000 1.000
16.600 183.000 1.000
16.660 200.000 1.000
16.720 188.000 1.000
16.780 198.000 1.000
16.840 183.000 1.000
16.900 170.000 1.000
16.960 184.000 1.000
17.020 181.000 1.000
17.080 189.000 1.000
17.140 189.000 1.000
17.200 188.000 1.000
17.260 179.000 1.000
17.320 199.000 1.000
17.380 169.000 1.000
17.440 195.000 1.000
17.500 188.000 1.000
17.560 189.000 1.000
17.620 187.000 1.000
17.680 198.000 1.000
17.740 179.000 1.000
17.800 195.000 1.000
17.860 189.000 1.000
17.920 178.000 1.000
17.980 199.000 1.000
18.040 209.000 1.000
18.100 175.000 1.000
18.160 199.000 1.000
18.220 196.000 1.000
18.280 186.000 1.000
18.340 164.000 1.000
18.400 185.000 1.000
18.460 185.000 1.000
18.520 197.000 1.000
18.580 177.000 1.000
18.640 185.000 1.000
18.700 199.000 1.000
18.760 203.000 1.000
18.820 194.000 1.000
18.880 213.000 1.000
18.940 199.000 1.000
19.000 211.000 1.000
19.060 193.000 1.000
19.120 197.000 1.000
19.180 209.000 1.000
19.240 206.000 1.000
19.300 202.000 1.000
19.360 196.000 1.000
19.420 208.000 1.000
19.480 221.000 1.000
19.540 205.000 1.000
19.600 213.000 1.000
19.660 231.000 1.000
19.720 229.000 1.000
19.780 205.000 1.000
19.840 218.000 1.000
19.900 203.000 1.000
19.960 219.000 1.000
20.020 212.000 1.000
20.080 222.000 1.000
20.140 229.000 1.000
20.200 226.000 1.000
20.260 222.000 1.000
20.320 211.000 1.000
20.380 233.000 1.000
20.440 223.000 1.000
20.500 216.000 1.000
20.560 215.000 1.000
20.620 226.000 1.000
20.680 223.000 1.000
20.740 211.000 1.000
20.800 206.000 1.000
20.860 213.000 1.000
20.920 234.000 1.000
20.980 214.000 1.000
21.040 220.000 1.000
21.100 197.000 1.000
21.160 240.000 1.000
21.220 225.000 1.000
21.280 217.000 1.000
21.340 242.000 1.000
21.400 210.000 1.000
21.460 227.000 1.000
21.520 217.000 1.000
21.580 224.000 1.000
21.640 223.000 1.000
21.700 232.000 1.000
21.760 232.000 1.000
21.820 245.000 1.000
21.880 219.000 1.000
21.940 241.000 1.000
22.000 246.000 1.000
22.060 241.000 1.000
22.120 237.000 1.000
22.180 221.000 1.000
22.240 241.000 1.000
22.300 259.000 1.000
22.360 228.000 1.000
22.420 246.000 1.000
22.480 265.000 1.000
22.540 251.000 1.000
22.600 255.000 1.000
22.660 261.000 1.000
22.720 256.000 1.000
22.780 263.000 1.000
22.840 270.000 1.000
22.900 268.000 1.000
22.960 277.000 1.000
23.020 287.000 1.000
23.080 296.000 1.000
23.140 279.000 1.000
23.200 275.000 1.000
23.260 264.000 1.000
23.320 330.000 1.000
23.380 291.000 1.000
23.440 295.000 1.000
23.500 290.000 1.000
23.560 310.000 1.000
23.620 338.000 1.000
23.680 347.000 1.000
23.740 336.000 1.000
23.800 344.000 1.000
23.860 356.000 1.000
23.920 370.000 1.000
23.980 357.000 1.000
24.040 389.000 1.000
24.100 434.000 1.000
24.160 424.000 1.000
24.220 435.000 1.000
24.280 447.000 1.000
24.340 414.000 1.000
24.400 451.000 1.000
24.460 497.000 1.000
24.520 539.000 1.000
24.580 540.000 1.000
24.640 587.000 1.000
24.700 594.000 1.000
24.760 592.000 1.000
24.820 642.000 1.000
24.880 725.000 1.000
24.940 736.000 1.000
25.000 782.000 1.000
25.060 829.000 1.000
25.120 884.000 1.000
25.180 956.000 1.000
25.240 1074.000 1.000
25.300 1086.000 1.000
25.360 1159.000 1.000
25.420 1322.000 1.000
25.480 1358.000 1.000
25.540 1464.000 1.000
25.600 1529.000 1.000
25.660 1655.000 1.000
25.720 1812.000 1.000
25.780 1916.000 1.000
25.840 1951.000 1.000
25.900 2069.000 1.000
25.960 2093.000 1.000
26.020 2216.000 1.000
26.080 2416.000 1.000
26.140 2880.000 1.000
26.200 3599.000 1.000
26.260 5171.000 1.000
26.320 7217.000 1.000
26.380 7577.000 1.000
26.440 5600.000 1.000
26.500 3164.000 1.000
26.560 1821.000 1.000
26.620 1262.000 1.000
26.680 992.000 1.000
26.740 866.000 1.000
26.800 760.000 1.000
26.860 709.000 1.000
26.920 619.000 1.000
26.980 590.000 1.000
27.040 530.000 1.000
27.100 494.000 1.000
27.160 476.000 1.000
27.220 420.000 1.000
27.280 420.000 1.000
27.340 405.000 1.000
27.400 385.000 1.000
27.460 365.000 1.000
27.520 346.000 1.000
27.580 331.000 1.000
27.640 347.000 1.000
27.700 301.000 1.000
27.760 353.000 1.000
27.820 300.000 1.000
27.880 313.000 1.000
27.940 313.000 1.000
28.000 291.000 1.000
28.060 283.000 1.000
28.120 253.000 1.000
28.180 292.000 1.000
28.240 269.000 1.000
28.300 258.000 1.000
28.360 234.000 1.000
28.420 245.000 1.000
28.480 275.000 1.000
28.540 286.000 1.000
28.600 270.000 1.000
28.660 252.000 1.000
28.720 231.000 1.000
28.780 242.000 1.000
28.840 253.000 1.000
28.900 250.000 1.000
28.960 239.000 1.000
29.020 248.000 1.000
29.080 220.000 1.000
29.140 228.000 1.000
29.200 248.000 1.000
29.260 253.000 1.000
29.320 243.000 1.000
29.380 262.000 1.000
29.440 343.000 1.000
29.500 370.000 1.000
29.560 376.000 1.000
29.620 321.000 1.000
29.680 246.000 1.000
29.740 253.000 1.000
29.800 250.000 1.000
29.860 230.000 1.000
29.920 256.000 1.000
29.980 232.000 1.000
30.040 208.000 1.000
30.100 235.000 1.000
30.160 223.000 1.000
30.220 183.000 1.000
30.280 212.000 1.000
30.340 193.000 1.000
30.400 196.000 1.000
30.460 211.000 1.000
30.520 197.000 1.000
30.580 195.000 1.000
30.640 211.000 1.000
30.700 200.000 1.000
30.760 207.000 1.000
30.820 232.000 1.000
30.880 232.000 1.000
30.940 227.000 1.000
31.000 230.000 1.000
31.060 221.000 1.000
31.120 215.000 1.000
31.180 218.000 1.000
31.240 206.000 1.000
31.300 200.000 1.000
31.360 192.000 1.000
31.420 202.000 1.000
31.480 183.000 1.000
31.540 170.000 1.000
31.600 192.000 1.000
31.660 183.000 1.000
31.720 185.000 1.000
31.780 198.000 1.000
31.840 176.000 1.000
31.900 196.000 1.000
31.960 176.000 1.000
32.020 194.000 1.000
32.080 179.000 1.000
32.140 184.000 1.000
32.200 168.000 1.000
32.260 176.000 1.000
32.320 171.000 1.000
32.380 183.000 1.000
32.440 174.000 1.000
32.500 188.000 1.000
32.560 189.000 1.000
32.620 177.000 1.000
32.680 181.000 1.000
32.740 171.000 1.000
32.800 205.000 1.000
32.860 170.000 1.000
32.920 168.000 1.000
32.980 168.000 1.000
33.040 176.000 1.000
33.100 185.000 1.000
33.160 176.000 1.000
33.220 170.000 1.000
33.280 178.000 1.000
33.340 181.000 1.000
33.400 174.000 1.000
33.460 180.000 1.000
33.520 167.000 1.000
33.580 183.000 1.000
33.640 165.000 1.000
33.700 171.000 1.000
33.760 178.000 1.000
33.820 186.000 1.000
33.880 167.000 1.000
33.940 158.000 1.000
34.000 182.000 1.000
34.060 184.000 1.000
34.120 183.000 1.000
34.180 180.000 1.000
34.240 187.000 1.000
34.300 180.000 1.000
34.360 203.000 1.000
34.420 178.000 1.000
34.480 184.000 1.000
34.540 176.000 1.000
34.600 207.000 1.000
34.660 182.000 1.000
34.720 188.000 1.000
34.780 202.000 1.000
34.840 202.000 1.000
34.900 189.000 1.000
34.960 206.000 1.000
35.020 212.000 1.000
35.080 192.000 1.000
35.140 201.000 1.000
35.200 203.000 1.000
35.260 217.000 1.000
35.320 229.000 1.000
35.380 200.000 1.000
35.440 206.000 1.000
35.500 195.000 1.000
35.560 229.000 1.000
35.620 243.000 1.000
35.680 204.000 1.000
35.740 252.000 1.000
35.800 260.000 1.000
35.860 245.000 1.000
35.920 263.000 1.000
35.980 266.000 1.000
36.040 292.000 1.000
36.100 391.000 1.000
36.160 518.000 1.000
36.220 960.000 1.000
36.280 1719.000 1.000
36.340 2677.000 1.000
36.400 2890.000 1.000
36.460 2154.000 1.000
36.520 1210.000 1.000
36.580 612.000 1.000
36.640 390.000 1.000
36.700 315.000 1.000
36.760 283.000 1.000
36.820 267.000 1.000
36.880 227.000 1.000
36.940 224.000 1.000
37.000 208.000 1.000
37.060 207.000 1.000
37.120 211.000 1.000
37.180 198.000 1.000
37.240 190.000 1.000
37.300 198.000 1.000
37.360 188.000 1.000
37.420 220.000 1.000
37.480 190.000 1.000
37.540 185.000 1.000
37.600 207.000 1.000
37.660 196.000 1.000
37.720 217.000 1.000
37.780 172.000 1.000
37.840 186.000 1.000
37.900 185.000 1.000
37.960 202.000 1.000
38.020 184.000 1.000
38.080 180.000 1.000
38.140 187.000 1.000
38.200 168.000 1.000
38.260 182.000 1.000
38.320 166.000 1.000
38.380 172.000 1.000
38.440 201.000 1.000
38.500 199.000 1.000
38.560 169.000 1.000
38.620 190.000 1.000
38.680 197.000 1.000
38.740 170.000 1.000
38.800 190.000 1.000
38.860 153.000 1.000
38.920 163.000 1.000
38.980 170.000 1.000
39.040 182.000 1.000
39.100 177.000 1.000
39.160 179.000 1.000
39.220 179.000 1.000
39.280 176.000 1.000
39.340 172.000 1.000
39.400 187.000 1.000
39.460 193.000 1.000
39.520 176.000 1.000
39.580 170.000 1.000
39.640 151.000 1.000
39.700 173.000 1.000
39.760 165.000 1.000
39.820 184.000 1.000
39.880 188.000 1.000
39.940 181.000 1.000
40.000 171.000 1.000
40.060 182.000 1.000
40.120 159.000 1.000
40.180 170.000 1.000
40.240 171.000 1.000
40.300 169.000 1.000
40.360 164.000 1.000
40.420 184.000 1.000
40.480 170.000 1.000
40.540 167.000 1.000
40.600 168.000 1.000
40.660 164.000 1.000
40.720 173.000 1.000
40.780 188.000 1.000
40.840 157.000 1.000
40.900 173.000 1.000
40.960 185.000 1.000
41.020 175.000 1.000
41.080 178.000 1.000
41.140 174.000 1.000
41.200 174.000 1.000
41.260 183.000 1.000
41.320 159.000 1.000
41.380 183.000 1.000
41.440 172.000 1.000
41.500 171.000 1.000
41.560 199.000 1.000
41.620 215.000 1.000
41.680 190.000 1.000
41.740 202.000 1.000
41.800 194.000 1.000
41.860 215.000 1.000
41.920 217.000 1.000
41.980 265.000 1.000
42.040 309.000 1.000
42.100 425.000 1.000
42.160 597.000 1.000
42.220 786.000 1.000
42.280 808.000 1.000
42.340 741.000 1.000
42.400 550.000 1.000
42.460 405.000 1.000
42.520 334.000 1.000
42.580 263.000 1.000
42.640 240.000 1.000
42.700 225.000 1.000
42.760 215.000 1.000
42.820 204.000 1.000
42.880 203.000 1.000
42.940 184.000 1.000
43.000 187.000 1.000
43.060 204.000 1.000
43.120 200.000 1.000
43.180 192.000 1.000
43.240 181.000 1.000
43.300 183.000 1.000
43.360 191.000 1.000
43.420 187.000 1.000
43.480 185.000 1.000
43.540 168.000 1.000
43.600 161.000 1.000
43.660 205.000 1.000
43.720 164.000 1.000
43.780 191.000 1.000
43.840 179.000 1.000
43.900 186.000 1.000
43.960 191.000 1.000
44.020 186.000 1.000
44.080 175.000 1.000
44.140 164.000 1.000
44.200 189.000 1.000
44.260 190.000 1.000
44.320 177.000 1.000
44.380 188.000 1.000
44.440 176.000 1.000
44.500 185.000 1.000
44.560 172.000 1.000
44.620 170.000 1.000
44.680 160.000 1.000
44.740 205.000 1.000
44.800 195.000 1.000
44.860 135.000 1.000
44.920 155.000 1.000
44.980 157.000 1.000
45.040 148.000 1.000
45.100 168.000 1.000
45.160 179.000 1.000
45.220 169.000 1.000
45.280 156.000 1.000
45.340 164.000 1.000
45.400 179.000 1.000
45.460 163.000 1.000
45.520 161.000 1.000
45.580 179.000 1.000
45.640 159.000 1.000
45.700 177.000 1.000
45.760 156.000 1.000
45.820 146.000 1.000
45.880 159.000 1.000
45.940 150.000 1.000
46.000 151.000 1.000
46.060 165.000 1.000
46.120 157.000 1.000
46.180 160.000 1.000
46.240 173.000 1.000
46.300 160.000 1.000
46.360 150.000 1.000
46.420 176.000 1.000
46.480 158.000 1.000
46.540 172.000 1.000
46.600 149.000 1.000
46.660 152.000 1.000
46.720 149.000 1.000
46.780 159.000 1.000
46.840 161.000 1.000
46.900 159.000 1.000
46.960 156.000 1.000
47.020 159.000 1.000
47.080 144.000 1.000
47.140 155.000 1.000
47.200 168.000 1.000
47.260 157.000 1.000
47.320 168.000 1.000
47.380 162.000 1.000
47.440 158.000 1.000
47.500 146.000 1.000
47.560 164.000 1.000
47.620 168.000 1.000
47.680 158.000 1.000
47.740 159.000 1.000
47.800 147.000 1.000
47.860 167.000 1.000
47.920 149.000 1.000
47.980 186.000 1.000
48.040 180.000 1.000
48.100 175.000 1.000
48.160 152.000 1.000
48.220 155.000 1.000
48.280 190.000 1.000
48.340 183.000 1.000
48.400 170.000 1.000
48.460 175.000 1.000
48.520 164.000 1.000
48.580 146.000 1.000
48.640 147.000 1.000
48.700 146.000 1.000
48.760 144.000 1.000
48.820 157.000 1.000
48.880 165.000 1.000
48.940 155.000 1.000
49.000 174.000 1.000
49.060 163.000 1.000
49.120 137.000 1.000
49.180 149.000 1.000
49.240 170.000 1.000
49.300 145.000 1.000
49.360 169.000 1.000
49.420 166.000 1.000
49.480 157.000 1.000
49.540 143.000 1.000
49.600 141.000 1.000
49.660 164.000 1.000
49.720 147.000 1.000
49.780 146.000 1.000
49.840 169.000 1.000
49.900 153.000 1.000
49.960 173.000 1.000
50.020 147.000 1.000
50.080 175.000 1.000
50.140 146.000 1.000
50.200 149.000 1.000
50.260 165.000 1.000
50.320 142.000 1.000
50.380 143.000 1.000
50.440 140.000 1.000
50.500 155.000 1.000
50.560 159.000 1.000
50.620 162.000 1.000
50.680 169.000 1.000
50.740 158.000 1.000
50.800 163.000 1.000
50.860 162.000 1.000
50.920 146.000 1.000
50.980 146.000 1.000
51.040 157.000 1.000
51.100 150.000 1.000
51.160 174.000 1.000
51.220 155.000 1.000
51.280 167.000 1.000
51.340 160.000 1.000
51.400 149.000 1.000
51.460 144.000 1.000
51.520 151.000 1.000
51.580 169.000 1.000
51.640 171.000 1.000
51.700 176.000 1.000
51.760 174.000 1.000
51.820 174.000 1.000
51.880 176.000 1.000
51.940 162.000 1.000
52.000 175.000 1.000
52.060 172.000 1.000
52.120 188.000 1.000
52.180 185.000 1.000
52.240 165.000 1.000
52.300 184.000 1.000
52.360 192.000 1.000
52.420 175.000 1.000
52.480 173.000 1.000
52.540 181.000 1.000
52.600 164.000 1.000
52.660 209.000 1.000
52.720 214.000 1.000
52.780 183.000 1.000
52.840 167.000 1.000
52.900 177.000 1.000
52.960 190.000 1.000
53.020 188.000 1.000
53.080 195.000 1.000
53.140 200.000 1.000
53.200 198.000 1.000
53.260 220.000 1.000
53.320 204.000 1.000
53.380 215.000 1.000
53.440 202.000 1.000
53.500 215.000 1.000
53.560 189.000 1.000
53.620 232.000 1.000
53.680 221.000 1.000
53.740 216.000 1.000
53.800 210.000 1.000
53.860 218.000 1.000
53.920 196.000 1.000
53.980 219.000 1.000
54.040 233.000 1.000
54.100 249.000 1.000
54.160 264.000 1.000
54.220 290.000 1.000
54.280 331.000 1.000
54.340 360.000 1.000
54.400 368.000 1.000
54.460 334.000 1.000
54.520 311.000 1.000
54.580 260.000 1.000
54.640 245.000 1.000
54.700 239.000 1.000
54.760 219.000 1.000
54.820 198.000 1.000
54.880 179.000 1.000
54.940 184.000 1.000
55.000 156.000 1.000
55.060 163.000 1.000
55.120 161.000 1.000
55.180 153.000 1.000
55.240 167.000 1.000
55.300 168.000 1.000
55.360 147.000 1.000
55.420 150.000 1.000
55.480 162.000 1.000
55.540 155.000 1.000
55.600 161.000 1.000
55.660 152.000 1.000
55.720 151.000 1.000
55.780 156.000 1.000
55.840 160.000 1.000
55.900 154.000 1.000
55.960 158.000 1.000
56.020 146.000 1.000
56.080 153.000 1.000
56.140 156.000 1.000
56.200 142.000 1.000
56.260 150.000 1.000
56.320 147.000 1.000
56.380 139.000 1.000
56.440 156.000 1.000
56.500 159.000 1.000
56.560 162.000 1.000
56.620 154.000 1.000
56.680 154.000 1.000
56.740 158.000 1.000
56.800 145.000 1.000
56.860 134.000 1.000
56.920 152.000 1.000
56.980 147.000 1.000
57.040 155.000 1.000
57.100 143.000 1.000
57.160 156.000 1.000
57.220 147.000 1.000
57.280 147.000 1.000
57.340 153.000 1.000
57.400 140.000 1.000
57.460 138.000 1.000
57.520 162.000 1.000
57.580 154.000 1.000
57.640 154.000 1.000
57.700 171.000 1.000
57.760 140.000 1.000
57.820 138.000 1.000
57.880 160.000 1.000
57.940 139.000 1.000
58.000 141.000 1.000
58.060 155.000 1.000
58.120 146.000 1.000
58.180 150.000 1.000
58.240 146.000 1.000
58.300 146.000 1.000
58.360 149.000 1.000
58.420 165.000 1.000
58.480 142.000 1.000
58.540 150.000 1.000
58.600 130.000 1.000
58.660 130.000 1.000
58.720 149.000 1.000
58.780 169.000 1.000
58.840 144.000 1.000
58.900 163.000 1.000
58.960 136.000 1.000
59.020 158.000 1.000
59.080 145.000 1.000
59.140 150.000 1.000
59.200 155.000 1.000
59.260 146.000 1.000
59.320 148.000 1.000
59.380 158.000 1.000
59.440 153.000 1.000
59.500 162.000 1.000
59.560 122.000 1.000
59.620 153.000 1.000
59.680 127.000 1.000
59.740 132.000 1.000
59.800 153.000 1.000
59.860 157.000 1.000
59.920 142.000 1.000
59.980 152.000 1.000
60.040 137.000 1.000
60.100 149.000 1.000
60.160 150.000 1.000
60.220 141.000 1.000
60.280 143.000 1.000
60.340 141.000 1.000
60.400 144.000 1.000
60.460 148.000 1.000
60.520 139.000 1.000
60.580 153.000 1.000
60.640 153.000 1.000
60.700 137.000 1.000
60.760 173.000 1.000
60.820 174.000 1.000
60.880 177.000 1.000
60.940 196.000 1.000
61.000 186.000 1.000
61.060 213.000 1.000
61.120 254.000 1.000
61.180 297.000 1.000
61.240 433.000 1.000
61.300 503.000 1.000
61.360 537.000 1.000
61.420 507.000 1.000
61.480 440.000 1.000
61.540 371.000 1.000
61.600 344.000 1.000
61.660 265.000 1.000
61.720 233.000 1.000
61.780 216.000 1.000
61.840 217.000 1.000
61.900 177.000 1.000
61.960 170.000 1.000
62.020 161.000 1.000
62.080 165.000 1.000
62.140 154.000 1.000
62.200 149.000 1.000
62.260 144.000 1.000
62.320 157.000 1.000
62.380 132.000 1.000
62.440 175.000 1.000
62.500 146.000 1.000
62.560 155.000 1.000
62.620 149.000 1.000
62.680 156.000 1.000
62.740 140.000 1.000
62.800 149.000 1.000
62.860 165.000 1.000
62.920 137.000 1.000
62.980 134.000 1.000
63.040 142.000 1.000
63.100 138.000 1.000
63.160 138.000 1.000
63.220 148.000 1.000
63.280 150.000 1.000
63.340 132.000 1.000
63.400 159.000 1.000
63.460 143.000 1.000
63.520 152.000 1.000
63.580 137.000 1.000
63.640 134.000 1.000
63.700 141.000 1.000
63.760 148.000 1.000
63.820 143.000 1.000
63.880 152.000 1.000
63.940 136.000 1.000
64.000 150.000 1.000
64.060 137.000 1.000
64.120 135.000 1.000
64.180 122.000 1.000
64.240 142.000 1.000
64.300 128.000 1.000
64.360 143.000 1.000
64.420 130.000 1.000
64.480 136.000 1.000
64.540 138.000 1.000
64.600 122.000 1.000
64.660 142.000 1.000
64.720 132.000 1.000
64.780 140.000 1.000
64.840 134.000 1.000
64.900 148.000 1.000
64.960 126.000 1.000
65.020 141.000 1.000
65.080 143.000 1.000
65.140 132.000 1.000
65.200 141.000 1.000
65.260 136.000 1.000
65.320 143.000 1.000
65.380 119.000 1.000
65.440 117.000 1.000
65.500 150.000 1.000
65.560 139.000 1.000
65.620 137.000 1.000
65.680 145.000 1.000
65.740 149.000 1.000
65.800 143.000 1.000
65.860 142.000 1.000
65.920 136.000 1.000
65.980 134.000 1.000
66.040 123.000 1.000
66.100 131.000 1.000
66.160 123.000 1.000
66.220 155.000 1.000
66.280 134.000 1.000
66.340 117.000 1.000
66.400 130.000 1.000
66.460 144.000 1.000
66.520 134.000 1.000
66.580 127.000 1.000
66.640 148.000 1.000
66.700 135.000 1.000
66.760 118.000 1.000
66.820 132.000 1.000
66.880 142.000 1.000
66.940 135.000 1.000
67.000 134.000 1.000
67.060 134.000 1.000
67.120 150.000 1.000
67.180 128.000 1.000
67.240 120.000 1.000
67.300 137.000 1.000
67.360 124.000 1.000
67.420 144.000 1.000
67.480 131.000 1.000
67.540 132.000 1.000
67.600 143.000 1.000
67.660 137.000 1.000
67.720 131.000 1.000
67.780 131.000 1.000
67.840 132.000 1.000
67.900 128.000 1.000
67.960 131.000 1.000
68.020 128.000 1.000
68.080 135.000 1.000
68.140 132.000 1.000
68.200 139.000 1.000
68.260 129.000 1.000
68.320 124.000 1.000
68.380 144.000 1.000
68.440 125.000 1.000
68.500 128.000 1.000
68.560 147.000 1.000
68.620 136.000 1.000
68.680 149.000 1.000
68.740 118.000 1.000
68.800 130.000 1.000
68.860 121.000 1.000
68.920 143.000 1.000
68.980 151.000 1.000
69.040 123.000 1.000
69.100 137.000 1.000
69.160 139.000 1.000
69.220 112.000 1.000
69.280 142.000 1.000
69.340 151.000 1.000
69.400 115.000 1.000
69.460 137.000 1.000
69.520 126.000 1.000
69.580 137.000 1.000
69.640 137.000 1.000
69.700 131.000 1.000
69.760 131.000 1.000
69.820 147.000 1.000
69.880 144.000 1.000
69.940 140.000 1.000
70.000 143.000 1.000
70.060 138.000 1.000
70.120 128.000 1.000
70.180 120.000 1.000
70.240 132.000 1.000
70.300 123.000 1.000
70.360 132.000 1.000
70.420 122.000 1.000
70.480 134.000 1.000
70.540 126.000 1.000
70.600 112.000 1.000
70.660 133.000 1.000
70.720 125.000 1.000
70.780 147.000 1.000
70.840 135.000 1.000
70.900 132.000 1.000
70.960 134.000 1.000
71.020 123.000 1.000
71.080 146.000 1.000
71.140 131.000 1.000
71.200 119.000 1.000
71.260 111.000 1.000
71.320 146.000 1.000
71.380 145.000 1.000
71.440 139.000 1.000
71.500 129.000 1.000
71.560 123.000 1.000
71.620 122.000 1.000
71.680 116.000 1.000
71.740 130.000 1.000
71.800 143.000 1.000
71.860 131.000 1.000
71.920 130.000 1.000
71.980 136.000 1.000
72.040 122.000 1.000
72.100 128.000 1.000
72.160 138.000 1.000
72.220 155.000 1.000
72.280 149.000 1.000
72.340 130.000 1.000
72.400 142.000 1.000
72.460 135.000 1.000
72.520 136.000 1.000
72.580 161.000 1.000
72.640 139.000 1.000
72.700 170.000 1.000
72.760 141.000 1.000
72.820 156.000 1.000
72.880 148.000 1.000
72.940 165.000 1.000
73.000 168.000 1.000
73.060 165.000 1.000
73.120 175.000 1.000
73.180 175.000 1.000
73.240 193.000 1.000
73.300 221.000 1.000
73.360 275.000 1.000
73.420 295.000 1.000
73.480 325.000 1.000
73.540 334.000 1.000
73.600 291.000 1.000
73.660 335.000 1.000
73.720 244.000 1.000
73.780 222.000 1.000
73.840 193.000 1.000
73.900 201.000 1.000
73.960 173.000 1.000
74.020 190.000 1.000
74.080 162.000 1.000
74.140 158.000 1.000
74.200 156.000 1.000
74.260 129.000 1.000
74.320 155.000 1.000
74.380 135.000 1.000
74.440 131.000 1.000
74.500 120.000 1.000
74.560 145.000 1.000
74.620 142.000 1.000
74.680 159.000 1.000
74.740 123.000 1.000
74.800 127.000 1.000
74.860 132.000 1.000
74.920 131.000 1.000
74.980 121.000 1.000
75.040 123.000 1.000
75.100 132.000 1.000
75.160 140.000 1.000
75.220 131.000 1.000
75.280 122.000 1.000
75.340 129.000 1.000
75.400 136.000 1.000
75.460 128.000 1.000
75.520 135.000 1.000
75.580 147.000 1.000
75.640 140.000 1.000
75.700 130.000 1.000
75.760 131.000 1.000
75.820 110.000 1.000
75.880 122.000 1.000
75.940 128.000 1.000
76.000 103.000 1.000
76.060 136.000 1.000
76.120 132.000 1.000
76.180 131.000 1.000
76.240 144.000 1.000
76.300 128.000 1.000
76.360 123.000 1.000
76.420 137.000 1.000
76.480 127.000 1.000
76.540 134.000 1.000
76.600 125.000 1.000
76.660 131.000 1.000
76.720 129.000 1.000
76.780 121.000 1.000
76.840 127.000 1.000
76.900 144.000 1.000
76.960 152.000 1.000
77.020 141.000 1.000
77.080 148.000 1.000
77.140 126.000 1.000
77.200 146.000 1.000
77.260 151.000 1.000
77.320 182.000 1.000
77.380 202.000 1.000
77.440 169.000 1.000
77.500 174.000 1.000
77.560 161.000 1.000
77.620 161.000 1.000
77.680 173.000 1.000
77.740 147.000 1.000
77.800 144.000 1.000
77.860 137.000 1.000
77.920 133.000 1.000
77.980 121.000 1.000
78.040 137.000 1.000
78.100 136.000 1.000
78.160 129.000 1.000
78.220 151.000 1.000
78.280 137.000 1.000
78.340 129.000 1.000
78.400 126.000 1.000
78.460 117.000 1.000
78.520 122.000 1.000
78.580 123.000 1.000
78.640 108.000 1.000
78.700 131.000 1.000
78.760 125.000 1.000
78.820 135.000 1.000
78.880 117.000 1.000
78.940 130.000 1.000
79.000 142.000 1.000
79.060 131.000 1.000
79.120 139.000 1.000
79.180 132.000 1.000
79.240 124.000 1.000
79.300 121.000 1.000
79.360 124.000 1.000
79.420 134.000 1.000
79.480 119.000 1.000
79.540 114.000 1.000
79.600 114.000 1.000
79.660 123.000 1.000
79.720 117.000 1.000
79.780 119.000 1.000
79.840 129.000 1.000
79.900 119.000 1.000
79.960 134.000 1.000
80.020 131.000 1.000
80.080 122.000 1.000
80.140 128.000 1.000
80.200 130.000 1.000
80.260 142.000 1.000
80.320 108.000 1.000
80.380 129.000 1.000
80.440 114.000 1.000
80.500 117.000 1.000
80.560 128.000 1.000
80.620 131.000 1.000
80.680 126.000 1.000
80.740 105.000 1.000
80.800 132.000 1.000
80.860 108.000 1.000
80.920 135.000 1.000
80.980 112.000 1.000
81.040 128.000 1.000
81.100 115.000 1.000
81.160 124.000 1.000
81.220 126.000 1.000
81.280 128.000 1.000
81.340 120.000 1.000
81.400 96.000 1.000
81.460 126.000 1.000
81.520 141.000 1.000
81.580 134.000 1.000
81.640 128.000 1.000
81.700 124.000 1.000
81.760 106.000 1.000
81.820 110.000 1.000
81.880 122.000 1.000
81.940 120.000 1.000
82.000 124.000 1.000
82.060 139.000 1.000
82.120 120.000 1.000
82.180 117.000 1.000
82.240 116.000 1.000
82.300 115.000 1.000
82.360 114.000 1.000
82.420 116.000 1.000
82.480 127.000 1.000
82.540 130.000 1.000
82.600 131.000 1.000
82.660 131.000 1.000
82.720 126.000 1.000
82.780 153.000 1.000
82.840 128.000 1.000
82.900 111.000 1.000
82.960 114.000 1.000
83.020 121.000 1.000
83.080 131.000 1.000
83.140 138.000 1.000
83.200 126.000 1.000
83.260 123.000 1.000
83.320 133.000 1.000
83.380 115.000 1.000
83.440 142.000 1.000
83.500 123.000 1.000
83.560 137.000 1.000
83.620 126.000 1.000
83.680 122.000 1.000
83.740 127.000 1.000
83.800 127.000 1.000
83.860 123.000 1.000
83.920 134.000 1.000
83.980 100.000 1.000
84.040 136.000 1.000
84.100 117.000 1.000
84.160 141.000 1.000
84.220 128.000 1.000
84.280 123.000 1.000
84.340 123.000 1.000
84.400 124.000 1.000
84.460 110.000 1.000
84.520 132.000 1.000
84.580 125.000 1.000
84.640 113.000 1.000
84.700 120.000 1.000
84.760 123.000 1.000
84.820 128.000 1.000
84.880 108.000 1.000
84.940 120.000 1.000
85.000 140.000 1.000
85.060 135.000 1.000
85.120 120.000 1.000
85.180 132.000 1.000
85.240 123.000 1.000
85.300 124.000 1.000
85.360 125.000 1.000
85.420 126.000 1.000
85.480 127.000 1.000
85.540 121.000 1.000
85.600 119.000 1.000
85.660 119.000 1.000
85.720 131.000 1.000
85.780 134.000 1.000
85.840 130.000 1.000
85.900 137.000 1.000
85.960 104.000 1.000
86.020 128.000 1.000
86.080 145.000 1.000
86.140 148.000 1.000
86.200 126.000 1.000
86.260 113.000 1.000
86.320 133.000 1.000
86.380 109.000 1.000
86.440 127.000 1.000
86.500 136.000 1.000
86.560 119.000 1.000
86.620 132.000 1.000
86.680 137.000 1.000
86.740 121.000 1.000
86.800 140.000 1.000
86.860 117.000 1.000
86.920 118.000 1.000
86.980 111.000 1.000
87.040 153.000 1.000
87.100 107.000 1.000
87.160 114.000 1.000
87.220 118.000 1.000
87.280 116.000 1.000
87.340 118.000 1.000
87.400 106.000 1.000
87.460 125.000 1.000
87.520 122.000 1.000
87.580 116.000 1.000
87.640 133.000 1.000
87.700 110.000 1.000
87.760 131.000 1.000
87.820 125.000 1.000
87.880 133.000 1.000
87.940 125.000 1.000
88.000 120.000 1.000
88.060 118.000 1.000
88.120 117.000 1.000
88.180 118.000 1.000
88.240 128.000 1.000
88.300 117.000 1.000
88.360 107.000 1.000
88.420 124.000 1.000
88.480 107.000 1.000
88.540 109.000 1.000
88.600 124.000 1.000
88.660 106.000 1.000
88.720 100.000 1.000
88.780 113.000 1.000
88.840 127.000 1.000
88.900 100.000 1.000
88.960 124.000 1.000
89.020 107.000 1.000
89.080 108.000 1.000
89.140 111.000 1.000
89.200 102.000 1.000
89.260 115.000 1.000
89.320 92.000 1.000
89.380 121.000 1.000
89.440 105.000 1.000
89.500 104.000 1.000
89.560 108.000 1.000
89.620 103.000 1.000
89.680 117.000 1.000
89.740 112.000 1.000
89.800 94.000 1.000
89.860 113.000 1.000
89.920 118.000 1.000
89.980 118.000 1.000
90.000 119.000 1.000
*RAS_INT_END
*RAS_DATA_END