File: Lab/XRD/all_in_one/cu2o_012.ras
*RAS_DATA_START
*RAS_HEADER_START
*CORR_POS_DB_NAME "DTEX_11112016"
*CORR_POS_GONIO_RADIUS ""
*CORR_POS_NODE_INDEX01 ""
*CORR_POS_NODE_INDEX02 ""
*CORR_POS_NODE_INDEX03 ""
*CORR_POS_NODE_INDEX04 ""
*CORR_POS_NODE_INDEX05 ""
*CORR_POS_NODE_INDEX06 ""
*CORR_POS_NODE_INDEX07 ""
*CORR_POS_NODE_INDEX08 ""
*CORR_POS_NODE_INDEX09 ""
*CORR_POS_NODE_INDEX10 ""
*CORR_POS_NODE_INDEX11 ""
*CORR_POS_NODE_LABEL01 "Si(111)"
*CORR_POS_NODE_LABEL02 "Si(220)"
*CORR_POS_NODE_LABEL03 "Si(311)"
*CORR_POS_NODE_LABEL04 "Si(400)"
*CORR_POS_NODE_LABEL05 "Si(331)"
*CORR_POS_NODE_LABEL06 "Si(422)"
*CORR_POS_NODE_LABEL07 "Si(511)"
*CORR_POS_NODE_LABEL08 "Si(440)"
*CORR_POS_NODE_LABEL09 "Si(531)"
*CORR_POS_NODE_LABEL10 "Si(620)"
*CORR_POS_NODE_LABEL11 "Si(533)"
*CORR_POS_NODE_POS_CALC01 "28.4137"
*CORR_POS_NODE_POS_CALC02 "47.2707"
*CORR_POS_NODE_POS_CALC03 "56.0883"
*CORR_POS_NODE_POS_CALC04 "69.0934"
*CORR_POS_NODE_POS_CALC05 "76.3385"
*CORR_POS_NODE_POS_CALC06 "87.9915"
*CORR_POS_NODE_POS_CALC07 "94.9137"
*CORR_POS_NODE_POS_CALC08 "106.67"
*CORR_POS_NODE_POS_CALC09 "114.054"
*CORR_POS_NODE_POS_CALC10 "127.508"
*CORR_POS_NODE_POS_CALC11 "136.858"
*CORR_POS_NODE_POS_MEAS01 "28.3712"
*CORR_POS_NODE_POS_MEAS02 "47.2304"
*CORR_POS_NODE_POS_MEAS03 "56.0465"
*CORR_POS_NODE_POS_MEAS04 "69.0523"
*CORR_POS_NODE_POS_MEAS05 "76.2993"
*CORR_POS_NODE_POS_MEAS06 "87.9512"
*CORR_POS_NODE_POS_MEAS07 "94.8772"
*CORR_POS_NODE_POS_MEAS08 "106.636"
*CORR_POS_NODE_POS_MEAS09 "114.028"
*CORR_POS_NODE_POS_MEAS10 "127.48"
*CORR_POS_NODE_POS_MEAS11 "136.839"
*CORR_POS_OPT_ATTR "集中法"
*CORR_POS_PARAM_MU ""
*CORR_POS_PARAM_PL ""
*CORR_POS_SEMODEL_TYPE "0"
*CORR_POS_STANDARD_TYPE ""
*CORR_POS_VALUE_ANALYZER "None"
*CORR_POS_VALUE_CMONO "None"
*CORR_POS_VALUE_IMONO "None"
*CORR_POS_VALUE_IS "0.625deg"
*CORR_POS_VALUE_ISL "10.0mm"
*CORR_POS_VALUE_ISOLLER "2.5deg"
*CORR_POS_VALUE_RS1 "13.0mm"
*CORR_POS_VALUE_RS2 "13.0mm"
*CORR_POS_VALUE_RSOLLER "2.5deg"
*CORR_POS_XG_FOCUS_L ""
*CORR_POS_XG_WAVE_TYPE ""
*CORR_POS_XG_WAVE_VALUE ""
*DISP_FMT_X "%.2f"
*DISP_FMT_Y "%.0f"
*DISP_FULLSCALE "5376.0000000000"
*DISP_LINE_COLOR "255.0000000000"
*DISP_LINE_STYLE "0.0000000000"
*DISP_LINE_WIDTH "0.2500000000"
*DISP_NOTE "Collected Data-4"
*DISP_OFFSET_Y "0.0000000000"
*DISP_PEAKSEARCH_UNIT_Y "COUNTS"
*DISP_RANGE_BOTTOM "0.0000000000"
*DISP_RANGE_LEFT "20.0000000000"
*DISP_RANGE_LOGCUTOFF "0.0100000000"
*DISP_RANGE_RIGHT "90.0000000000"
*DISP_RANGE_TOP "5376.0000000000"
*DISP_SCALE_MODE_Y "0.0000000000"
*DISP_TAB_NAME "Theta/2-Theta"
*DISP_TITLE_Y "Intensity"
*DISP_UNIT_Y "COUNTS"
*DISP_WINDOW_NAME "MSG_MACROENGINE"
*FILE_COMMENT " "
*FILE_MD5 ""
*FILE_MEMO " "
*FILE_OPERATOR "MiniFlex"
*FILE_PART_ID "MEAS_PBEA_00223"
*FILE_SAMPLE "cu2o_012_20-90_2theta_speed20_step0.02"
*FILE_TYPE "RAS_RAW"
*FILE_USERGROUP "System User"
*FILE_VERSION "1.0000000000"
*HW_ATTACHMENT_ID "ATT1031"
*HW_ATTACHMENT_NAME "6サンプルチェンジャ|ASC-6"
*HW_COUNTER_ID-0 "CUT0025"
*HW_COUNTER_ID-1 "CUT0020"
*HW_COUNTER_ID-2 "CUT0020"
*HW_COUNTER_ID-3 "CMC0021"
*HW_COUNTER_NAME-0 "D/teX Ultra|D/teX Ultra"
*HW_COUNTER_NAME-1 "None|None"
*HW_COUNTER_NAME-2 "None|None"
*HW_COUNTER_NAME-3 "検出器モノクロメータ|Detector monochromator"
*HW_COUNTER_SELECT_NAME "D/teX Ultra|D/teX Ultra"
*HW_GONIOMETER_ID "GON0070"
*HW_GONIOMETER_NAME "MiniFlex 300/600|MiniFlex 300/600"
*HW_GONIOMETER_RADIUS-0 "79.0"
*HW_GONIOMETER_RADIUS-1 "91.5"
*HW_GONIOMETER_RADIUS-2 "150.0"
*HW_GONIOMETER_RADIUS-3 "0"
*HW_GONIOMETER_RADIUS-4 "103.4"
*HW_GONIOMETER_RADIUS-5 "150.0"
*HW_GONIOMETER_RADIUS-6 "46.6"
*HW_GONIOMETER_RADIUS-7 "160.0"
*HW_I_OPT_ID-0 "ISL0021"
*HW_I_OPT_ID-1 "ISO0021"
*HW_I_OPT_NAME-0 "発散スリット|Divergence slit"
*HW_I_OPT_NAME-1 "入射平行スリット|Incident parallel slit"
*HW_R_ATTENUATER_AUTOMODE "0"
*HW_R_OPT_ID-0 "RSS0021"
*HW_R_OPT_ID-1 "RSO0021"
*HW_R_OPT_ID-2 "RRS0021"
*HW_R_OPT_NAME-0 "散乱スリット|Scattering slit"
*HW_R_OPT_NAME-1 "受光平行スリット|Receiving soller slit"
*HW_R_OPT_NAME-2 "受光スリット|Receiving slit"
*HW_SAMPLE_HOLDER_ID "SMP0000"
*HW_SAMPLE_HOLDER_NAME "無し|None"
*HW_XG_CURRENT_MAX "15"
*HW_XG_CURRENT_MIN "2"
*HW_XG_CURRENT_RESOLUTION "1"
*HW_XG_CURRENT_UNIT "mA"
*HW_XG_FOCUS "1mm x 10mm"
*HW_XG_FOCUS_TYPE "Normal"
*HW_XG_ID "1060"
*HW_XG_NAME "300W/600W 封入管-B|300W/600W Sealed tube-B"
*HW_XG_TARGET_ATOMIC_NUMBER "29.0000000000"
*HW_XG_TARGET_NAME "Cu"
*HW_XG_TYPE "Hermetic"
*HW_XG_VOLTAGE_MAX "40"
*HW_XG_VOLTAGE_MIN "20"
*HW_XG_VOLTAGE_RESOLUTION "1"
*HW_XG_VOLTAGE_UNIT "kV"
*HW_XG_WATT_MAX "1"
*HW_XG_WATT_UNIT "kW"
*HW_XG_WAVE_LENGTH_ALPHA1 "1.540593"
*HW_XG_WAVE_LENGTH_ALPHA2 "1.544414"
*HW_XG_WAVE_LENGTH_BETA "1.392250"
*MEAS_COND_AXIS_NAME-0 "Theta/2-Theta"
*MEAS_COND_AXIS_NAME-1 "Spin"
*MEAS_COND_AXIS_NAME-2 "Change"
*MEAS_COND_AXIS_NAME-3 "Soller(inc.)"
*MEAS_COND_AXIS_NAME-4 "IHS"
*MEAS_COND_AXIS_NAME-5 "DS"
*MEAS_COND_AXIS_NAME-6 "SS"
*MEAS_COND_AXIS_NAME-7 "Soller(rec.)"
*MEAS_COND_AXIS_NAME-8 "RS"
*MEAS_COND_AXIS_NAME-9 "Filter"
*MEAS_COND_AXIS_NAME-10 "Monochromator"
*MEAS_COND_AXIS_NAME-11 "PHA"
*MEAS_COND_AXIS_NAME_INTERNAL-0 "TwoThetaTheta"
*MEAS_COND_AXIS_NAME_INTERNAL-1 "Spin"
*MEAS_COND_AXIS_NAME_INTERNAL-2 "Change"
*MEAS_COND_AXIS_NAME_INTERNAL-3 "IncidentSollerSlit"
*MEAS_COND_AXIS_NAME_INTERNAL-4 "IncidentAxdSlit"
*MEAS_COND_AXIS_NAME_INTERNAL-5 "IncidentSlitBox"
*MEAS_COND_AXIS_NAME_INTERNAL-6 "ReceivingSlitBox1"
*MEAS_COND_AXIS_NAME_INTERNAL-7 "ReceivingSollerSlit"
*MEAS_COND_AXIS_NAME_INTERNAL-8 "ReceivingSlitBox2"
*MEAS_COND_AXIS_NAME_INTERNAL-9 "Filter"
*MEAS_COND_AXIS_NAME_INTERNAL-10 "CounterMonochromator"
*MEAS_COND_AXIS_NAME_INTERNAL-11 "PHA"
*MEAS_COND_AXIS_NAME_MAGICNO-0 "268632064.0000000000"
*MEAS_COND_AXIS_NAME_MAGICNO-1 "16842752.0000000000"
*MEAS_COND_AXIS_NAME_MAGICNO-2 "16842752.0000000000"
*MEAS_COND_AXIS_NAME_MAGICNO-3 "20971521.0000000000"
*MEAS_COND_AXIS_NAME_MAGICNO-4 "22020097.0000000000"
*MEAS_COND_AXIS_NAME_MAGICNO-5 "22020097.0000000000"
*MEAS_COND_AXIS_NAME_MAGICNO-6 "23068673.0000000000"
*MEAS_COND_AXIS_NAME_MAGICNO-7 "20971521.0000000000"
*MEAS_COND_AXIS_NAME_MAGICNO-8 "23068673.0000000000"
*MEAS_COND_AXIS_NAME_MAGICNO-9 "20971521.0000000000"
*MEAS_COND_AXIS_NAME_MAGICNO-10 "20971521.0000000000"
*MEAS_COND_AXIS_NAME_MAGICNO-11 "0.0000000000"
*MEAS_COND_AXIS_OFFSET-0 "0.0000000000"
*MEAS_COND_AXIS_OFFSET-1 "-"
*MEAS_COND_AXIS_OFFSET-2 "-"
*MEAS_COND_AXIS_OFFSET-3 "-"
*MEAS_COND_AXIS_OFFSET-4 "-"
*MEAS_COND_AXIS_OFFSET-5 "-"
*MEAS_COND_AXIS_OFFSET-6 "-"
*MEAS_COND_AXIS_OFFSET-7 "-"
*MEAS_COND_AXIS_OFFSET-8 "-"
*MEAS_COND_AXIS_OFFSET-9 "-"
*MEAS_COND_AXIS_OFFSET-10 "-"
*MEAS_COND_AXIS_OFFSET-11 "-"
*MEAS_COND_AXIS_POSITION-0 "10.0000000000"
*MEAS_COND_AXIS_POSITION-1 "0.0000000000"
*MEAS_COND_AXIS_POSITION-2 "4.0000000000"
*MEAS_COND_AXIS_POSITION-3 "2.5deg"
*MEAS_COND_AXIS_POSITION-4 "2.0mm"
*MEAS_COND_AXIS_POSITION-5 "0.625deg"
*MEAS_COND_AXIS_POSITION-6 "13.0mm(Open)"
*MEAS_COND_AXIS_POSITION-7 "2.5deg"
*MEAS_COND_AXIS_POSITION-8 "13.0mm"
*MEAS_COND_AXIS_POSITION-9 "K-beta(x1)"
*MEAS_COND_AXIS_POSITION-10 "None"
*MEAS_COND_AXIS_POSITION-11 "41.0000000000"
*MEAS_COND_AXIS_UNIT-0 "deg"
*MEAS_COND_AXIS_UNIT-1 ""
*MEAS_COND_AXIS_UNIT-2 ""
*MEAS_COND_AXIS_UNIT-3 ""
*MEAS_COND_AXIS_UNIT-4 ""
*MEAS_COND_AXIS_UNIT-5 ""
*MEAS_COND_AXIS_UNIT-6 ""
*MEAS_COND_AXIS_UNIT-7 ""
*MEAS_COND_AXIS_UNIT-8 ""
*MEAS_COND_AXIS_UNIT-9 ""
*MEAS_COND_AXIS_UNIT-10 ""
*MEAS_COND_AXIS_UNIT-11 "div"
*MEAS_COND_CORRECTION_SLIT_COUNTERMONO "None"
*MEAS_COND_CORRECTION_SLIT_DS "0.625deg"
*MEAS_COND_CORRECTION_SLIT_FILTER "None"
*MEAS_COND_CORRECTION_SLIT_IHS "2.0mm"
*MEAS_COND_CORRECTION_SLIT_RS "13.0mm"
*MEAS_COND_CORRECTION_SLIT_SOLLER_INC "2.5deg"
*MEAS_COND_CORRECTION_SLIT_SOLLER_REC "2.5deg"
*MEAS_COND_CORRECTION_SLIT_SS "13.0mm"
*MEAS_COND_COUNTER_CNTLOSS_CORR "0.0000000000"
*MEAS_COND_COUNTER_PHABASE "41.0000000000"
*MEAS_COND_COUNTER_PHAWINDOW "14.0000000000"
*MEAS_COND_COUNTER_PHA_UNIT "div"
*MEAS_COND_COUNTER_TAUDIFF "0.2500000000"
*MEAS_COND_COUNTER_TAUINT "0.7500000000"
*MEAS_COND_IRRADIATION_MODE "OFF"
*MEAS_COND_IRRADIATION_WIDTH ""
*MEAS_COND_OPT_ATTR " "
*MEAS_COND_OPT_NAME ""
*MEAS_COND_UNSYMMETRIC_MODE "OFF"
*MEAS_COND_XG_CURRENT "15.0000000000"
*MEAS_COND_XG_VOLTAGE "40.0000000000"
*MEAS_COND_XG_WAVE_TYPE "Ka"
*MEAS_DATA_COUNT "3501.0000000000"
*MEAS_SCAN_AXIS_X "Theta/2-Theta"
*MEAS_SCAN_AXIS_X_INTERNAL "TwoThetaTheta"
*MEAS_SCAN_END_TIME "09/06/17 11:58:04"
*MEAS_SCAN_MODE "CONTINUOUS"
*MEAS_SCAN_MONITOR "0"
*MEAS_SCAN_RESOLUTION_X "0.005"
*MEAS_SCAN_SPEED "20.000"
*MEAS_SCAN_SPEED_UNIT "deg/min"
*MEAS_SCAN_SPEED_USER "20.000"
*MEAS_SCAN_START "20.0000000000"
*MEAS_SCAN_START_TIME "09/06/17 11:54:02"
*MEAS_SCAN_STEP "0.0200000000"
*MEAS_SCAN_STOP "90.0000000000"
*MEAS_SCAN_UNIT_X "deg"
*MEAS_SCAN_UNIT_Y "counts"
*SLIT_SYSTEM "0"
*RAS_HEADER_END
*RAS_INT_START
20.000 154.000 1.000
20.060 160.000 1.000
20.120 148.000 1.000
20.180 147.000 1.000
20.240 138.000 1.000
20.300 141.000 1.000
20.360 144.000 1.000
20.420 136.000 1.000
20.480 158.000 1.000
20.540 136.000 1.000
20.600 132.000 1.000
20.660 156.000 1.000
20.720 149.000 1.000
20.780 152.000 1.000
20.840 146.000 1.000
20.900 141.000 1.000
20.960 147.000 1.000
21.020 146.000 1.000
21.080 142.000 1.000
21.140 144.000 1.000
21.200 160.000 1.000
21.260 178.000 1.000
21.320 161.000 1.000
21.380 135.000 1.000
21.440 168.000 1.000
21.500 155.000 1.000
21.560 158.000 1.000
21.620 146.000 1.000
21.680 161.000 1.000
21.740 157.000 1.000
21.800 151.000 1.000
21.860 161.000 1.000
21.920 153.000 1.000
21.980 154.000 1.000
22.040 176.000 1.000
22.100 146.000 1.000
22.160 164.000 1.000
22.220 175.000 1.000
22.280 163.000 1.000
22.340 158.000 1.000
22.400 159.000 1.000
22.460 169.000 1.000
22.520 169.000 1.000
22.580 190.000 1.000
22.640 160.000 1.000
22.700 169.000 1.000
22.760 189.000 1.000
22.820 177.000 1.000
22.880 169.000 1.000
22.940 154.000 1.000
23.000 178.000 1.000
23.060 175.000 1.000
23.120 170.000 1.000
23.180 186.000 1.000
23.240 196.000 1.000
23.300 194.000 1.000
23.360 190.000 1.000
23.420 198.000 1.000
23.480 190.000 1.000
23.540 191.000 1.000
23.600 224.000 1.000
23.660 206.000 1.000
23.720 196.000 1.000
23.780 197.000 1.000
23.840 208.000 1.000
23.900 213.000 1.000
23.960 222.000 1.000
24.020 205.000 1.000
24.080 243.000 1.000
24.140 252.000 1.000
24.200 246.000 1.000
24.260 274.000 1.000
24.320 267.000 1.000
24.380 286.000 1.000
24.440 300.000 1.000
24.500 296.000 1.000
24.560 321.000 1.000
24.620 334.000 1.000
24.680 366.000 1.000
24.740 369.000 1.000
24.800 374.000 1.000
24.860 408.000 1.000
24.920 439.000 1.000
24.980 457.000 1.000
25.040 475.000 1.000
25.100 525.000 1.000
25.160 504.000 1.000
25.220 598.000 1.000
25.280 638.000 1.000
25.340 701.000 1.000
25.400 748.000 1.000
25.460 758.000 1.000
25.520 821.000 1.000
25.580 942.000 1.000
25.640 936.000 1.000
25.700 1021.000 1.000
25.760 1041.000 1.000
25.820 1117.000 1.000
25.880 1167.000 1.000
25.940 1217.000 1.000
26.000 1288.000 1.000
26.060 1393.000 1.000
26.120 1619.000 1.000
26.180 2020.000 1.000
26.240 2753.000 1.000
26.300 3757.000 1.000
26.360 4405.000 1.000
26.420 3987.000 1.000
26.480 2447.000 1.000
26.540 1381.000 1.000
26.600 829.000 1.000
26.660 674.000 1.000
26.720 568.000 1.000
26.780 466.000 1.000
26.840 391.000 1.000
26.900 400.000 1.000
26.960 353.000 1.000
27.020 319.000 1.000
27.080 319.000 1.000
27.140 295.000 1.000
27.200 268.000 1.000
27.260 265.000 1.000
27.320 263.000 1.000
27.380 262.000 1.000
27.440 244.000 1.000
27.500 234.000 1.000
27.560 203.000 1.000
27.620 228.000 1.000
27.680 189.000 1.000
27.740 174.000 1.000
27.800 198.000 1.000
27.860 191.000 1.000
27.920 184.000 1.000
27.980 192.000 1.000
28.040 174.000 1.000
28.100 180.000 1.000
28.160 171.000 1.000
28.220 176.000 1.000
28.280 184.000 1.000
28.340 174.000 1.000
28.400 147.000 1.000
28.460 158.000 1.000
28.520 162.000 1.000
28.580 168.000 1.000
28.640 152.000 1.000
28.700 166.000 1.000
28.760 131.000 1.000
28.820 137.000 1.000
28.880 168.000 1.000
28.940 153.000 1.000
29.000 158.000 1.000
29.060 147.000 1.000
29.120 151.000 1.000
29.180 159.000 1.000
29.240 147.000 1.000
29.300 164.000 1.000
29.360 168.000 1.000
29.420 153.000 1.000
29.480 186.000 1.000
29.540 201.000 1.000
29.600 251.000 1.000
29.660 279.000 1.000
29.720 229.000 1.000
29.780 170.000 1.000
29.840 142.000 1.000
29.900 163.000 1.000
29.960 141.000 1.000
30.020 117.000 1.000
30.080 123.000 1.000
30.140 140.000 1.000
30.200 146.000 1.000
30.260 133.000 1.000
30.320 133.000 1.000
30.380 114.000 1.000
30.440 138.000 1.000
30.500 141.000 1.000
30.560 125.000 1.000
30.620 127.000 1.000
30.680 135.000 1.000
30.740 142.000 1.000
30.800 135.000 1.000
30.860 135.000 1.000
30.920 137.000 1.000
30.980 132.000 1.000
31.040 134.000 1.000
31.100 120.000 1.000
31.160 124.000 1.000
31.220 121.000 1.000
31.280 110.000 1.000
31.340 117.000 1.000
31.400 125.000 1.000
31.460 116.000 1.000
31.520 109.000 1.000
31.580 121.000 1.000
31.640 128.000 1.000
31.700 117.000 1.000
31.760 107.000 1.000
31.820 108.000 1.000
31.880 105.000 1.000
31.940 121.000 1.000
32.000 131.000 1.000
32.060 118.000 1.000
32.120 123.000 1.000
32.180 118.000 1.000
32.240 125.000 1.000
32.300 134.000 1.000
32.360 113.000 1.000
32.420 130.000 1.000
32.480 134.000 1.000
32.540 110.000 1.000
32.600 110.000 1.000
32.660 121.000 1.000
32.720 108.000 1.000
32.780 119.000 1.000
32.840 126.000 1.000
32.900 117.000 1.000
32.960 120.000 1.000
33.020 118.000 1.000
33.080 99.000 1.000
33.140 111.000 1.000
33.200 120.000 1.000
33.260 116.000 1.000
33.320 119.000 1.000
33.380 120.000 1.000
33.440 111.000 1.000
33.500 108.000 1.000
33.560 107.000 1.000
33.620 122.000 1.000
33.680 112.000 1.000
33.740 130.000 1.000
33.800 124.000 1.000
33.860 110.000 1.000
33.920 133.000 1.000
33.980 116.000 1.000
34.040 122.000 1.000
34.100 117.000 1.000
34.160 121.000 1.000
34.220 125.000 1.000
34.280 138.000 1.000
34.340 117.000 1.000
34.400 119.000 1.000
34.460 139.000 1.000
34.520 150.000 1.000
34.580 105.000 1.000
34.640 135.000 1.000
34.700 138.000 1.000
34.760 133.000 1.000
34.820 139.000 1.000
34.880 126.000 1.000
34.940 131.000 1.000
35.000 137.000 1.000
35.060 129.000 1.000
35.120 139.000 1.000
35.180 150.000 1.000
35.240 136.000 1.000
35.300 168.000 1.000
35.360 159.000 1.000
35.420 146.000 1.000
35.480 139.000 1.000
35.540 153.000 1.000
35.600 139.000 1.000
35.660 162.000 1.000
35.720 163.000 1.000
35.780 167.000 1.000
35.840 139.000 1.000
35.900 167.000 1.000
35.960 176.000 1.000
36.020 160.000 1.000
36.080 193.000 1.000
36.140 197.000 1.000
36.200 229.000 1.000
36.260 305.000 1.000
36.320 428.000 1.000
36.380 779.000 1.000
36.440 1164.000 1.000
36.500 1707.000 1.000
36.560 2058.000 1.000
36.620 1513.000 1.000
36.680 861.000 1.000
36.740 397.000 1.000
36.800 246.000 1.000
36.860 204.000 1.000
36.920 177.000 1.000
36.980 175.000 1.000
37.040 155.000 1.000
37.100 171.000 1.000
37.160 139.000 1.000
37.220 135.000 1.000
37.280 125.000 1.000
37.340 125.000 1.000
37.400 127.000 1.000
37.460 133.000 1.000
37.520 128.000 1.000
37.580 133.000 1.000
37.640 134.000 1.000
37.700 125.000 1.000
37.760 127.000 1.000
37.820 136.000 1.000
37.880 116.000 1.000
37.940 115.000 1.000
38.000 115.000 1.000
38.060 125.000 1.000
38.120 129.000 1.000
38.180 109.000 1.000
38.240 113.000 1.000
38.300 133.000 1.000
38.360 147.000 1.000
38.420 130.000 1.000
38.480 117.000 1.000
38.540 109.000 1.000
38.600 120.000 1.000
38.660 127.000 1.000
38.720 111.000 1.000
38.780 119.000 1.000
38.840 105.000 1.000
38.900 130.000 1.000
38.960 124.000 1.000
39.020 107.000 1.000
39.080 89.000 1.000
39.140 131.000 1.000
39.200 117.000 1.000
39.260 121.000 1.000
39.320 118.000 1.000
39.380 112.000 1.000
39.440 120.000 1.000
39.500 104.000 1.000
39.560 94.000 1.000
39.620 126.000 1.000
39.680 128.000 1.000
39.740 108.000 1.000
39.800 109.000 1.000
39.860 100.000 1.000
39.920 107.000 1.000
39.980 127.000 1.000
40.040 109.000 1.000
40.100 114.000 1.000
40.160 119.000 1.000
40.220 119.000 1.000
40.280 120.000 1.000
40.340 118.000 1.000
40.400 113.000 1.000
40.460 117.000 1.000
40.520 110.000 1.000
40.580 111.000 1.000
40.640 107.000 1.000
40.700 133.000 1.000
40.760 122.000 1.000
40.820 134.000 1.000
40.880 125.000 1.000
40.940 103.000 1.000
41.000 129.000 1.000
41.060 132.000 1.000
41.120 119.000 1.000
41.180 122.000 1.000
41.240 113.000 1.000
41.300 125.000 1.000
41.360 129.000 1.000
41.420 124.000 1.000
41.480 118.000 1.000
41.540 124.000 1.000
41.600 117.000 1.000
41.660 114.000 1.000
41.720 121.000 1.000
41.780 140.000 1.000
41.840 154.000 1.000
41.900 144.000 1.000
41.960 134.000 1.000
42.020 118.000 1.000
42.080 144.000 1.000
42.140 161.000 1.000
42.200 177.000 1.000
42.260 247.000 1.000
42.320 348.000 1.000
42.380 424.000 1.000
42.440 566.000 1.000
42.500 540.000 1.000
42.560 397.000 1.000
42.620 276.000 1.000
42.680 196.000 1.000
42.740 150.000 1.000
42.800 148.000 1.000
42.860 145.000 1.000
42.920 128.000 1.000
42.980 127.000 1.000
43.040 154.000 1.000
43.100 145.000 1.000
43.160 138.000 1.000
43.220 132.000 1.000
43.280 138.000 1.000
43.340 123.000 1.000
43.400 130.000 1.000
43.460 119.000 1.000
43.520 143.000 1.000
43.580 123.000 1.000
43.640 125.000 1.000
43.700 118.000 1.000
43.760 115.000 1.000
43.820 125.000 1.000
43.880 134.000 1.000
43.940 140.000 1.000
44.000 101.000 1.000
44.060 118.000 1.000
44.120 122.000 1.000
44.180 101.000 1.000
44.240 112.000 1.000
44.300 125.000 1.000
44.360 96.000 1.000
44.420 102.000 1.000
44.480 111.000 1.000
44.540 119.000 1.000
44.600 131.000 1.000
44.660 110.000 1.000
44.720 117.000 1.000
44.780 99.000 1.000
44.840 108.000 1.000
44.900 115.000 1.000
44.960 114.000 1.000
45.020 103.000 1.000
45.080 111.000 1.000
45.140 112.000 1.000
45.200 104.000 1.000
45.260 103.000 1.000
45.320 107.000 1.000
45.380 108.000 1.000
45.440 116.000 1.000
45.500 102.000 1.000
45.560 111.000 1.000
45.620 107.000 1.000
45.680 93.000 1.000
45.740 103.000 1.000
45.800 109.000 1.000
45.860 116.000 1.000
45.920 118.000 1.000
45.980 111.000 1.000
46.040 109.000 1.000
46.100 96.000 1.000
46.160 99.000 1.000
46.220 111.000 1.000
46.280 110.000 1.000
46.340 112.000 1.000
46.400 88.000 1.000
46.460 98.000 1.000
46.520 116.000 1.000
46.580 116.000 1.000
46.640 93.000 1.000
46.700 109.000 1.000
46.760 96.000 1.000
46.820 103.000 1.000
46.880 104.000 1.000
46.940 113.000 1.000
47.000 96.000 1.000
47.060 125.000 1.000
47.120 127.000 1.000
47.180 110.000 1.000
47.240 116.000 1.000
47.300 106.000 1.000
47.360 125.000 1.000
47.420 121.000 1.000
47.480 97.000 1.000
47.540 100.000 1.000
47.600 100.000 1.000
47.660 101.000 1.000
47.720 109.000 1.000
47.780 116.000 1.000
47.840 92.000 1.000
47.900 100.000 1.000
47.960 96.000 1.000
48.020 93.000 1.000
48.080 95.000 1.000
48.140 90.000 1.000
48.200 102.000 1.000
48.260 88.000 1.000
48.320 128.000 1.000
48.380 103.000 1.000
48.440 97.000 1.000
48.500 88.000 1.000
48.560 112.000 1.000
48.620 96.000 1.000
48.680 88.000 1.000
48.740 101.000 1.000
48.800 91.000 1.000
48.860 88.000 1.000
48.920 101.000 1.000
48.980 113.000 1.000
49.040 83.000 1.000
49.100 96.000 1.000
49.160 96.000 1.000
49.220 94.000 1.000
49.280 102.000 1.000
49.340 94.000 1.000
49.400 108.000 1.000
49.460 97.000 1.000
49.520 99.000 1.000
49.580 108.000 1.000
49.640 96.000 1.000
49.700 97.000 1.000
49.760 90.000 1.000
49.820 101.000 1.000
49.880 94.000 1.000
49.940 89.000 1.000
50.000 107.000 1.000
50.060 111.000 1.000
50.120 107.000 1.000
50.180 99.000 1.000
50.240 112.000 1.000
50.300 108.000 1.000
50.360 103.000 1.000
50.420 104.000 1.000
50.480 91.000 1.000
50.540 117.000 1.000
50.600 108.000 1.000
50.660 86.000 1.000
50.720 98.000 1.000
50.780 106.000 1.000
50.840 115.000 1.000
50.900 112.000 1.000
50.960 104.000 1.000
51.020 97.000 1.000
51.080 111.000 1.000
51.140 104.000 1.000
51.200 105.000 1.000
51.260 94.000 1.000
51.320 108.000 1.000
51.380 98.000 1.000
51.440 101.000 1.000
51.500 95.000 1.000
51.560 90.000 1.000
51.620 116.000 1.000
51.680 112.000 1.000
51.740 118.000 1.000
51.800 102.000 1.000
51.860 103.000 1.000
51.920 107.000 1.000
51.980 100.000 1.000
52.040 111.000 1.000
52.100 123.000 1.000
52.160 104.000 1.000
52.220 117.000 1.000
52.280 93.000 1.000
52.340 114.000 1.000
52.400 108.000 1.000
52.460 122.000 1.000
52.520 114.000 1.000
52.580 123.000 1.000
52.640 125.000 1.000
52.700 129.000 1.000
52.760 119.000 1.000
52.820 127.000 1.000
52.880 132.000 1.000
52.940 116.000 1.000
53.000 136.000 1.000
53.060 108.000 1.000
53.120 123.000 1.000
53.180 131.000 1.000
53.240 135.000 1.000
53.300 121.000 1.000
53.360 112.000 1.000
53.420 120.000 1.000
53.480 141.000 1.000
53.540 125.000 1.000
53.600 137.000 1.000
53.660 142.000 1.000
53.720 134.000 1.000
53.780 132.000 1.000
53.840 149.000 1.000
53.900 138.000 1.000
53.960 158.000 1.000
54.020 145.000 1.000
54.080 164.000 1.000
54.140 164.000 1.000
54.200 177.000 1.000
54.260 194.000 1.000
54.320 191.000 1.000
54.380 242.000 1.000
54.440 239.000 1.000
54.500 207.000 1.000
54.560 203.000 1.000
54.620 177.000 1.000
54.680 151.000 1.000
54.740 129.000 1.000
54.800 115.000 1.000
54.860 121.000 1.000
54.920 110.000 1.000
54.980 104.000 1.000
55.040 111.000 1.000
55.100 98.000 1.000
55.160 106.000 1.000
55.220 92.000 1.000
55.280 109.000 1.000
55.340 106.000 1.000
55.400 104.000 1.000
55.460 96.000 1.000
55.520 101.000 1.000
55.580 102.000 1.000
55.640 106.000 1.000
55.700 106.000 1.000
55.760 106.000 1.000
55.820 97.000 1.000
55.880 106.000 1.000
55.940 115.000 1.000
56.000 102.000 1.000
56.060 110.000 1.000
56.120 96.000 1.000
56.180 97.000 1.000
56.240 110.000 1.000
56.300 97.000 1.000
56.360 87.000 1.000
56.420 92.000 1.000
56.480 94.000 1.000
56.540 109.000 1.000
56.600 93.000 1.000
56.660 93.000 1.000
56.720 101.000 1.000
56.780 87.000 1.000
56.840 90.000 1.000
56.900 89.000 1.000
56.960 100.000 1.000
57.020 97.000 1.000
57.080 96.000 1.000
57.140 92.000 1.000
57.200 87.000 1.000
57.260 99.000 1.000
57.320 90.000 1.000
57.380 105.000 1.000
57.440 83.000 1.000
57.500 104.000 1.000
57.560 95.000 1.000
57.620 98.000 1.000
57.680 91.000 1.000
57.740 82.000 1.000
57.800 103.000 1.000
57.860 92.000 1.000
57.920 96.000 1.000
57.980 82.000 1.000
58.040 84.000 1.000
58.100 100.000 1.000
58.160 90.000 1.000
58.220 93.000 1.000
58.280 99.000 1.000
58.340 92.000 1.000
58.400 92.000 1.000
58.460 81.000 1.000
58.520 103.000 1.000
58.580 103.000 1.000
58.640 89.000 1.000
58.700 94.000 1.000
58.760 94.000 1.000
58.820 94.000 1.000
58.880 81.000 1.000
58.940 97.000 1.000
59.000 91.000 1.000
59.060 101.000 1.000
59.120 81.000 1.000
59.180 87.000 1.000
59.240 81.000 1.000
59.300 101.000 1.000
59.360 94.000 1.000
59.420 80.000 1.000
59.480 86.000 1.000
59.540 107.000 1.000
59.600 95.000 1.000
59.660 91.000 1.000
59.720 100.000 1.000
59.780 97.000 1.000
59.840 99.000 1.000
59.900 98.000 1.000
59.960 102.000 1.000
60.020 92.000 1.000
60.080 101.000 1.000
60.140 94.000 1.000
60.200 99.000 1.000
60.260 93.000 1.000
60.320 101.000 1.000
60.380 94.000 1.000
60.440 89.000 1.000
60.500 111.000 1.000
60.560 109.000 1.000
60.620 106.000 1.000
60.680 101.000 1.000
60.740 112.000 1.000
60.800 99.000 1.000
60.860 97.000 1.000
60.920 89.000 1.000
60.980 98.000 1.000
61.040 100.000 1.000
61.100 116.000 1.000
61.160 108.000 1.000
61.220 127.000 1.000
61.280 130.000 1.000
61.340 140.000 1.000
61.400 163.000 1.000
61.460 209.000 1.000
61.520 279.000 1.000
61.580 323.000 1.000
61.640 370.000 1.000
61.700 306.000 1.000
61.760 259.000 1.000
61.820 223.000 1.000
61.880 182.000 1.000
61.940 153.000 1.000
62.000 103.000 1.000
62.060 111.000 1.000
62.120 121.000 1.000
62.180 105.000 1.000
62.240 110.000 1.000
62.300 118.000 1.000
62.360 101.000 1.000
62.420 102.000 1.000
62.480 94.000 1.000
62.540 91.000 1.000
62.600 94.000 1.000
62.660 98.000 1.000
62.720 95.000 1.000
62.780 101.000 1.000
62.840 91.000 1.000
62.900 89.000 1.000
62.960 92.000 1.000
63.020 105.000 1.000
63.080 79.000 1.000
63.140 86.000 1.000
63.200 92.000 1.000
63.260 97.000 1.000
63.320 83.000 1.000
63.380 100.000 1.000
63.440 91.000 1.000
63.500 102.000 1.000
63.560 71.000 1.000
63.620 83.000 1.000
63.680 95.000 1.000
63.740 88.000 1.000
63.800 103.000 1.000
63.860 74.000 1.000
63.920 93.000 1.000
63.980 91.000 1.000
64.040 77.000 1.000
64.100 78.000 1.000
64.160 113.000 1.000
64.220 94.000 1.000
64.280 85.000 1.000
64.340 87.000 1.000
64.400 94.000 1.000
64.460 92.000 1.000
64.520 85.000 1.000
64.580 75.000 1.000
64.640 84.000 1.000
64.700 92.000 1.000
64.760 83.000 1.000
64.820 85.000 1.000
64.880 94.000 1.000
64.940 88.000 1.000
65.000 87.000 1.000
65.060 74.000 1.000
65.120 87.000 1.000
65.180 93.000 1.000
65.240 89.000 1.000
65.300 72.000 1.000
65.360 94.000 1.000
65.420 88.000 1.000
65.480 83.000 1.000
65.540 78.000 1.000
65.600 95.000 1.000
65.660 84.000 1.000
65.720 79.000 1.000
65.780 81.000 1.000
65.840 86.000 1.000
65.900 97.000 1.000
65.960 99.000 1.000
66.020 86.000 1.000
66.080 86.000 1.000
66.140 83.000 1.000
66.200 86.000 1.000
66.260 86.000 1.000
66.320 91.000 1.000
66.380 81.000 1.000
66.440 77.000 1.000
66.500 71.000 1.000
66.560 99.000 1.000
66.620 78.000 1.000
66.680 92.000 1.000
66.740 85.000 1.000
66.800 88.000 1.000
66.860 81.000 1.000
66.920 93.000 1.000
66.980 84.000 1.000
67.040 76.000 1.000
67.100 77.000 1.000
67.160 80.000 1.000
67.220 82.000 1.000
67.280 91.000 1.000
67.340 80.000 1.000
67.400 77.000 1.000
67.460 76.000 1.000
67.520 89.000 1.000
67.580 75.000 1.000
67.640 82.000 1.000
67.700 79.000 1.000
67.760 74.000 1.000
67.820 84.000 1.000
67.880 85.000 1.000
67.940 91.000 1.000
68.000 79.000 1.000
68.060 91.000 1.000
68.120 92.000 1.000
68.180 92.000 1.000
68.240 89.000 1.000
68.300 88.000 1.000
68.360 96.000 1.000
68.420 92.000 1.000
68.480 96.000 1.000
68.540 97.000 1.000
68.600 75.000 1.000
68.660 76.000 1.000
68.720 98.000 1.000
68.780 93.000 1.000
68.840 74.000 1.000
68.900 92.000 1.000
68.960 100.000 1.000
69.020 100.000 1.000
69.080 100.000 1.000
69.140 86.000 1.000
69.200 84.000 1.000
69.260 93.000 1.000
69.320 81.000 1.000
69.380 97.000 1.000
69.440 94.000 1.000
69.500 87.000 1.000
69.560 95.000 1.000
69.620 87.000 1.000
69.680 80.000 1.000
69.740 84.000 1.000
69.800 81.000 1.000
69.860 91.000 1.000
69.920 95.000 1.000
69.980 90.000 1.000
70.040 87.000 1.000
70.100 85.000 1.000
70.160 87.000 1.000
70.220 90.000 1.000
70.280 76.000 1.000
70.340 80.000 1.000
70.400 73.000 1.000
70.460 90.000 1.000
70.520 90.000 1.000
70.580 72.000 1.000
70.640 85.000 1.000
70.700 74.000 1.000
70.760 71.000 1.000
70.820 83.000 1.000
70.880 88.000 1.000
70.940 81.000 1.000
71.000 84.000 1.000
71.060 75.000 1.000
71.120 83.000 1.000
71.180 78.000 1.000
71.240 84.000 1.000
71.300 72.000 1.000
71.360 88.000 1.000
71.420 84.000 1.000
71.480 74.000 1.000
71.540 83.000 1.000
71.600 83.000 1.000
71.660 82.000 1.000
71.720 78.000 1.000
71.780 87.000 1.000
71.840 86.000 1.000
71.900 85.000 1.000
71.960 101.000 1.000
72.020 88.000 1.000
72.080 92.000 1.000
72.140 86.000 1.000
72.200 98.000 1.000
72.260 89.000 1.000
72.320 99.000 1.000
72.380 96.000 1.000
72.440 71.000 1.000
72.500 109.000 1.000
72.560 93.000 1.000
72.620 97.000 1.000
72.680 74.000 1.000
72.740 97.000 1.000
72.800 91.000 1.000
72.860 103.000 1.000
72.920 96.000 1.000
72.980 87.000 1.000
73.040 85.000 1.000
73.100 94.000 1.000
73.160 91.000 1.000
73.220 101.000 1.000
73.280 107.000 1.000
73.340 98.000 1.000
73.400 120.000 1.000
73.460 114.000 1.000
73.520 105.000 1.000
73.580 116.000 1.000
73.640 135.000 1.000
73.700 154.000 1.000
73.760 185.000 1.000
73.820 205.000 1.000
73.880 230.000 1.000
73.940 206.000 1.000
74.000 192.000 1.000
74.060 166.000 1.000
74.120 154.000 1.000
74.180 134.000 1.000
74.240 118.000 1.000
74.300 108.000 1.000
74.360 85.000 1.000
74.420 82.000 1.000
74.480 105.000 1.000
74.540 89.000 1.000
74.600 93.000 1.000
74.660 84.000 1.000
74.720 92.000 1.000
74.780 95.000 1.000
74.840 89.000 1.000
74.900 90.000 1.000
74.960 103.000 1.000
75.020 70.000 1.000
75.080 75.000 1.000
75.140 96.000 1.000
75.200 97.000 1.000
75.260 87.000 1.000
75.320 87.000 1.000
75.380 76.000 1.000
75.440 104.000 1.000
75.500 89.000 1.000
75.560 75.000 1.000
75.620 113.000 1.000
75.680 82.000 1.000
75.740 92.000 1.000
75.800 86.000 1.000
75.860 88.000 1.000
75.920 81.000 1.000
75.980 85.000 1.000
76.040 89.000 1.000
76.100 84.000 1.000
76.160 98.000 1.000
76.220 83.000 1.000
76.280 89.000 1.000
76.340 77.000 1.000
76.400 84.000 1.000
76.460 83.000 1.000
76.520 84.000 1.000
76.580 81.000 1.000
76.640 97.000 1.000
76.700 75.000 1.000
76.760 68.000 1.000
76.820 85.000 1.000
76.880 73.000 1.000
76.940 80.000 1.000
77.000 80.000 1.000
77.060 80.000 1.000
77.120 76.000 1.000
77.180 95.000 1.000
77.240 81.000 1.000
77.300 82.000 1.000
77.360 87.000 1.000
77.420 89.000 1.000
77.480 104.000 1.000
77.540 97.000 1.000
77.600 100.000 1.000
77.660 107.000 1.000
77.720 104.000 1.000
77.780 101.000 1.000
77.840 104.000 1.000
77.900 95.000 1.000
77.960 105.000 1.000
78.020 86.000 1.000
78.080 89.000 1.000
78.140 79.000 1.000
78.200 91.000 1.000
78.260 74.000 1.000
78.320 77.000 1.000
78.380 92.000 1.000
78.440 94.000 1.000
78.500 72.000 1.000
78.560 71.000 1.000
78.620 83.000 1.000
78.680 76.000 1.000
78.740 70.000 1.000
78.800 76.000 1.000
78.860 77.000 1.000
78.920 87.000 1.000
78.980 79.000 1.000
79.040 81.000 1.000
79.100 75.000 1.000
79.160 72.000 1.000
79.220 96.000 1.000
79.280 91.000 1.000
79.340 76.000 1.000
79.400 79.000 1.000
79.460 70.000 1.000
79.520 77.000 1.000
79.580 83.000 1.000
79.640 81.000 1.000
79.700 84.000 1.000
79.760 76.000 1.000
79.820 76.000 1.000
79.880 84.000 1.000
79.940 84.000 1.000
80.000 83.000 1.000
80.060 78.000 1.000
80.120 85.000 1.000
80.180 70.000 1.000
80.240 76.000 1.000
80.300 72.000 1.000
80.360 75.000 1.000
80.420 80.000 1.000
80.480 80.000 1.000
80.540 82.000 1.000
80.600 77.000 1.000
80.660 94.000 1.000
80.720 77.000 1.000
80.780 77.000 1.000
80.840 89.000 1.000
80.900 74.000 1.000
80.960 75.000 1.000
81.020 89.000 1.000
81.080 86.000 1.000
81.140 86.000 1.000
81.200 93.000 1.000
81.260 69.000 1.000
81.320 71.000 1.000
81.380 78.000 1.000
81.440 73.000 1.000
81.500 72.000 1.000
81.560 90.000 1.000
81.620 74.000 1.000
81.680 83.000 1.000
81.740 82.000 1.000
81.800 79.000 1.000
81.860 79.000 1.000
81.920 75.000 1.000
81.980 70.000 1.000
82.040 72.000 1.000
82.100 76.000 1.000
82.160 81.000 1.000
82.220 63.000 1.000
82.280 70.000 1.000
82.340 92.000 1.000
82.400 79.000 1.000
82.460 79.000 1.000
82.520 87.000 1.000
82.580 76.000 1.000
82.640 71.000 1.000
82.700 71.000 1.000
82.760 76.000 1.000
82.820 83.000 1.000
82.880 71.000 1.000
82.940 68.000 1.000
83.000 89.000 1.000
83.060 91.000 1.000
83.120 85.000 1.000
83.180 77.000 1.000
83.240 82.000 1.000
83.300 73.000 1.000
83.360 91.000 1.000
83.420 70.000 1.000
83.480 79.000 1.000
83.540 66.000 1.000
83.600 80.000 1.000
83.660 69.000 1.000
83.720 73.000 1.000
83.780 75.000 1.000
83.840 67.000 1.000
83.900 72.000 1.000
83.960 69.000 1.000
84.020 70.000 1.000
84.080 80.000 1.000
84.140 72.000 1.000
84.200 74.000 1.000
84.260 88.000 1.000
84.320 76.000 1.000
84.380 73.000 1.000
84.440 73.000 1.000
84.500 77.000 1.000
84.560 81.000 1.000
84.620 82.000 1.000
84.680 76.000 1.000
84.740 81.000 1.000
84.800 66.000 1.000
84.860 74.000 1.000
84.920 69.000 1.000
84.980 75.000 1.000
85.040 79.000 1.000
85.100 74.000 1.000
85.160 77.000 1.000
85.220 88.000 1.000
85.280 73.000 1.000
85.340 85.000 1.000
85.400 66.000 1.000
85.460 83.000 1.000
85.520 77.000 1.000
85.580 75.000 1.000
85.640 81.000 1.000
85.700 75.000 1.000
85.760 82.000 1.000
85.820 90.000 1.000
85.880 79.000 1.000
85.940 90.000 1.000
86.000 82.000 1.000
86.060 70.000 1.000
86.120 89.000 1.000
86.180 76.000 1.000
86.240 78.000 1.000
86.300 96.000 1.000
86.360 108.000 1.000
86.420 72.000 1.000
86.480 76.000 1.000
86.540 88.000 1.000
86.600 89.000 1.000
86.660 80.000 1.000
86.720 79.000 1.000
86.780 88.000 1.000
86.840 75.000 1.000
86.900 84.000 1.000
86.960 72.000 1.000
87.020 88.000 1.000
87.080 68.000 1.000
87.140 79.000 1.000
87.200 76.000 1.000
87.260 71.000 1.000
87.320 69.000 1.000
87.380 88.000 1.000
87.440 76.000 1.000
87.500 88.000 1.000
87.560 62.000 1.000
87.620 85.000 1.000
87.680 77.000 1.000
87.740 70.000 1.000
87.800 72.000 1.000
87.860 68.000 1.000
87.920 67.000 1.000
87.980 77.000 1.000
88.040 71.000 1.000
88.100 71.000 1.000
88.160 67.000 1.000
88.220 68.000 1.000
88.280 80.000 1.000
88.340 74.000 1.000
88.400 62.000 1.000
88.460 71.000 1.000
88.520 82.000 1.000
88.580 72.000 1.000
88.640 78.000 1.000
88.700 55.000 1.000
88.760 67.000 1.000
88.820 67.000 1.000
88.880 74.000 1.000
88.940 75.000 1.000
89.000 79.000 1.000
89.060 62.000 1.000
89.120 80.000 1.000
89.180 75.000 1.000
89.240 65.000 1.000
89.300 69.000 1.000
89.360 71.000 1.000
89.420 69.000 1.000
89.480 73.000 1.000
89.540 71.000 1.000
89.600 64.000 1.000
89.660 84.000 1.000
89.720 84.000 1.000
89.780 87.000 1.000
89.840 72.000 1.000
89.900 60.000 1.000
89.960 71.000 1.000
90.000 71.000 1.000
*RAS_INT_END
*RAS_DATA_END