File: Lab/XRD/all_in_one/cu2o_013.ras
*RAS_DATA_START
*RAS_HEADER_START
*CORR_POS_DB_NAME "DTEX_11112016"
*CORR_POS_GONIO_RADIUS ""
*CORR_POS_NODE_INDEX01 ""
*CORR_POS_NODE_INDEX02 ""
*CORR_POS_NODE_INDEX03 ""
*CORR_POS_NODE_INDEX04 ""
*CORR_POS_NODE_INDEX05 ""
*CORR_POS_NODE_INDEX06 ""
*CORR_POS_NODE_INDEX07 ""
*CORR_POS_NODE_INDEX08 ""
*CORR_POS_NODE_INDEX09 ""
*CORR_POS_NODE_INDEX10 ""
*CORR_POS_NODE_INDEX11 ""
*CORR_POS_NODE_LABEL01 "Si(111)"
*CORR_POS_NODE_LABEL02 "Si(220)"
*CORR_POS_NODE_LABEL03 "Si(311)"
*CORR_POS_NODE_LABEL04 "Si(400)"
*CORR_POS_NODE_LABEL05 "Si(331)"
*CORR_POS_NODE_LABEL06 "Si(422)"
*CORR_POS_NODE_LABEL07 "Si(511)"
*CORR_POS_NODE_LABEL08 "Si(440)"
*CORR_POS_NODE_LABEL09 "Si(531)"
*CORR_POS_NODE_LABEL10 "Si(620)"
*CORR_POS_NODE_LABEL11 "Si(533)"
*CORR_POS_NODE_POS_CALC01 "28.4137"
*CORR_POS_NODE_POS_CALC02 "47.2707"
*CORR_POS_NODE_POS_CALC03 "56.0883"
*CORR_POS_NODE_POS_CALC04 "69.0934"
*CORR_POS_NODE_POS_CALC05 "76.3385"
*CORR_POS_NODE_POS_CALC06 "87.9915"
*CORR_POS_NODE_POS_CALC07 "94.9137"
*CORR_POS_NODE_POS_CALC08 "106.67"
*CORR_POS_NODE_POS_CALC09 "114.054"
*CORR_POS_NODE_POS_CALC10 "127.508"
*CORR_POS_NODE_POS_CALC11 "136.858"
*CORR_POS_NODE_POS_MEAS01 "28.3712"
*CORR_POS_NODE_POS_MEAS02 "47.2304"
*CORR_POS_NODE_POS_MEAS03 "56.0465"
*CORR_POS_NODE_POS_MEAS04 "69.0523"
*CORR_POS_NODE_POS_MEAS05 "76.2993"
*CORR_POS_NODE_POS_MEAS06 "87.9512"
*CORR_POS_NODE_POS_MEAS07 "94.8772"
*CORR_POS_NODE_POS_MEAS08 "106.636"
*CORR_POS_NODE_POS_MEAS09 "114.028"
*CORR_POS_NODE_POS_MEAS10 "127.48"
*CORR_POS_NODE_POS_MEAS11 "136.839"
*CORR_POS_OPT_ATTR "集中法"
*CORR_POS_PARAM_MU ""
*CORR_POS_PARAM_PL ""
*CORR_POS_SEMODEL_TYPE "0"
*CORR_POS_STANDARD_TYPE ""
*CORR_POS_VALUE_ANALYZER "None"
*CORR_POS_VALUE_CMONO "None"
*CORR_POS_VALUE_IMONO "None"
*CORR_POS_VALUE_IS "0.625deg"
*CORR_POS_VALUE_ISL "10.0mm"
*CORR_POS_VALUE_ISOLLER "2.5deg"
*CORR_POS_VALUE_RS1 "13.0mm"
*CORR_POS_VALUE_RS2 "13.0mm"
*CORR_POS_VALUE_RSOLLER "2.5deg"
*CORR_POS_XG_FOCUS_L ""
*CORR_POS_XG_WAVE_TYPE ""
*CORR_POS_XG_WAVE_VALUE ""
*DISP_FMT_X "%.2f"
*DISP_FMT_Y "%.0f"
*DISP_FULLSCALE "5856.0000000000"
*DISP_LINE_COLOR "255.0000000000"
*DISP_LINE_STYLE "0.0000000000"
*DISP_LINE_WIDTH "0.2500000000"
*DISP_NOTE "Collected Data-5"
*DISP_OFFSET_Y "0.0000000000"
*DISP_PEAKSEARCH_UNIT_Y "COUNTS"
*DISP_RANGE_BOTTOM "0.0000000000"
*DISP_RANGE_LEFT "20.0000000000"
*DISP_RANGE_LOGCUTOFF "0.0100000000"
*DISP_RANGE_RIGHT "90.0000000000"
*DISP_RANGE_TOP "5856.0000000000"
*DISP_SCALE_MODE_Y "0.0000000000"
*DISP_TAB_NAME "Theta/2-Theta"
*DISP_TITLE_Y "Intensity"
*DISP_UNIT_Y "COUNTS"
*DISP_WINDOW_NAME "MSG_MACROENGINE"
*FILE_COMMENT " "
*FILE_MD5 ""
*FILE_MEMO " "
*FILE_OPERATOR "MiniFlex"
*FILE_PART_ID "MEAS_PBEA_00223"
*FILE_SAMPLE "cu2o_013_20-90_2theta_speed20_step0.02"
*FILE_TYPE "RAS_RAW"
*FILE_USERGROUP "System User"
*FILE_VERSION "1.0000000000"
*HW_ATTACHMENT_ID "ATT1031"
*HW_ATTACHMENT_NAME "6サンプルチェンジャ|ASC-6"
*HW_COUNTER_ID-0 "CUT0025"
*HW_COUNTER_ID-1 "CUT0020"
*HW_COUNTER_ID-2 "CUT0020"
*HW_COUNTER_ID-3 "CMC0021"
*HW_COUNTER_NAME-0 "D/teX Ultra|D/teX Ultra"
*HW_COUNTER_NAME-1 "None|None"
*HW_COUNTER_NAME-2 "None|None"
*HW_COUNTER_NAME-3 "検出器モノクロメータ|Detector monochromator"
*HW_COUNTER_SELECT_NAME "D/teX Ultra|D/teX Ultra"
*HW_GONIOMETER_ID "GON0070"
*HW_GONIOMETER_NAME "MiniFlex 300/600|MiniFlex 300/600"
*HW_GONIOMETER_RADIUS-0 "79.0"
*HW_GONIOMETER_RADIUS-1 "91.5"
*HW_GONIOMETER_RADIUS-2 "150.0"
*HW_GONIOMETER_RADIUS-3 "0"
*HW_GONIOMETER_RADIUS-4 "103.4"
*HW_GONIOMETER_RADIUS-5 "150.0"
*HW_GONIOMETER_RADIUS-6 "46.6"
*HW_GONIOMETER_RADIUS-7 "160.0"
*HW_I_OPT_ID-0 "ISL0021"
*HW_I_OPT_ID-1 "ISO0021"
*HW_I_OPT_NAME-0 "発散スリット|Divergence slit"
*HW_I_OPT_NAME-1 "入射平行スリット|Incident parallel slit"
*HW_R_ATTENUATER_AUTOMODE "0"
*HW_R_OPT_ID-0 "RSS0021"
*HW_R_OPT_ID-1 "RSO0021"
*HW_R_OPT_ID-2 "RRS0021"
*HW_R_OPT_NAME-0 "散乱スリット|Scattering slit"
*HW_R_OPT_NAME-1 "受光平行スリット|Receiving soller slit"
*HW_R_OPT_NAME-2 "受光スリット|Receiving slit"
*HW_SAMPLE_HOLDER_ID "SMP0000"
*HW_SAMPLE_HOLDER_NAME "無し|None"
*HW_XG_CURRENT_MAX "15"
*HW_XG_CURRENT_MIN "2"
*HW_XG_CURRENT_RESOLUTION "1"
*HW_XG_CURRENT_UNIT "mA"
*HW_XG_FOCUS "1mm x 10mm"
*HW_XG_FOCUS_TYPE "Normal"
*HW_XG_ID "1060"
*HW_XG_NAME "300W/600W 封入管-B|300W/600W Sealed tube-B"
*HW_XG_TARGET_ATOMIC_NUMBER "29.0000000000"
*HW_XG_TARGET_NAME "Cu"
*HW_XG_TYPE "Hermetic"
*HW_XG_VOLTAGE_MAX "40"
*HW_XG_VOLTAGE_MIN "20"
*HW_XG_VOLTAGE_RESOLUTION "1"
*HW_XG_VOLTAGE_UNIT "kV"
*HW_XG_WATT_MAX "1"
*HW_XG_WATT_UNIT "kW"
*HW_XG_WAVE_LENGTH_ALPHA1 "1.540593"
*HW_XG_WAVE_LENGTH_ALPHA2 "1.544414"
*HW_XG_WAVE_LENGTH_BETA "1.392250"
*MEAS_COND_AXIS_NAME-0 "Theta/2-Theta"
*MEAS_COND_AXIS_NAME-1 "Spin"
*MEAS_COND_AXIS_NAME-2 "Change"
*MEAS_COND_AXIS_NAME-3 "Soller(inc.)"
*MEAS_COND_AXIS_NAME-4 "IHS"
*MEAS_COND_AXIS_NAME-5 "DS"
*MEAS_COND_AXIS_NAME-6 "SS"
*MEAS_COND_AXIS_NAME-7 "Soller(rec.)"
*MEAS_COND_AXIS_NAME-8 "RS"
*MEAS_COND_AXIS_NAME-9 "Filter"
*MEAS_COND_AXIS_NAME-10 "Monochromator"
*MEAS_COND_AXIS_NAME-11 "PHA"
*MEAS_COND_AXIS_NAME_INTERNAL-0 "TwoThetaTheta"
*MEAS_COND_AXIS_NAME_INTERNAL-1 "Spin"
*MEAS_COND_AXIS_NAME_INTERNAL-2 "Change"
*MEAS_COND_AXIS_NAME_INTERNAL-3 "IncidentSollerSlit"
*MEAS_COND_AXIS_NAME_INTERNAL-4 "IncidentAxdSlit"
*MEAS_COND_AXIS_NAME_INTERNAL-5 "IncidentSlitBox"
*MEAS_COND_AXIS_NAME_INTERNAL-6 "ReceivingSlitBox1"
*MEAS_COND_AXIS_NAME_INTERNAL-7 "ReceivingSollerSlit"
*MEAS_COND_AXIS_NAME_INTERNAL-8 "ReceivingSlitBox2"
*MEAS_COND_AXIS_NAME_INTERNAL-9 "Filter"
*MEAS_COND_AXIS_NAME_INTERNAL-10 "CounterMonochromator"
*MEAS_COND_AXIS_NAME_INTERNAL-11 "PHA"
*MEAS_COND_AXIS_NAME_MAGICNO-0 "268632064.0000000000"
*MEAS_COND_AXIS_NAME_MAGICNO-1 "16842752.0000000000"
*MEAS_COND_AXIS_NAME_MAGICNO-2 "16842752.0000000000"
*MEAS_COND_AXIS_NAME_MAGICNO-3 "20971521.0000000000"
*MEAS_COND_AXIS_NAME_MAGICNO-4 "22020097.0000000000"
*MEAS_COND_AXIS_NAME_MAGICNO-5 "22020097.0000000000"
*MEAS_COND_AXIS_NAME_MAGICNO-6 "23068673.0000000000"
*MEAS_COND_AXIS_NAME_MAGICNO-7 "20971521.0000000000"
*MEAS_COND_AXIS_NAME_MAGICNO-8 "23068673.0000000000"
*MEAS_COND_AXIS_NAME_MAGICNO-9 "20971521.0000000000"
*MEAS_COND_AXIS_NAME_MAGICNO-10 "20971521.0000000000"
*MEAS_COND_AXIS_NAME_MAGICNO-11 "0.0000000000"
*MEAS_COND_AXIS_OFFSET-0 "0.0000000000"
*MEAS_COND_AXIS_OFFSET-1 "-"
*MEAS_COND_AXIS_OFFSET-2 "-"
*MEAS_COND_AXIS_OFFSET-3 "-"
*MEAS_COND_AXIS_OFFSET-4 "-"
*MEAS_COND_AXIS_OFFSET-5 "-"
*MEAS_COND_AXIS_OFFSET-6 "-"
*MEAS_COND_AXIS_OFFSET-7 "-"
*MEAS_COND_AXIS_OFFSET-8 "-"
*MEAS_COND_AXIS_OFFSET-9 "-"
*MEAS_COND_AXIS_OFFSET-10 "-"
*MEAS_COND_AXIS_OFFSET-11 "-"
*MEAS_COND_AXIS_POSITION-0 "10.0000000000"
*MEAS_COND_AXIS_POSITION-1 "0.0000000000"
*MEAS_COND_AXIS_POSITION-2 "4.0000000000"
*MEAS_COND_AXIS_POSITION-3 "2.5deg"
*MEAS_COND_AXIS_POSITION-4 "2.0mm"
*MEAS_COND_AXIS_POSITION-5 "0.625deg"
*MEAS_COND_AXIS_POSITION-6 "13.0mm(Open)"
*MEAS_COND_AXIS_POSITION-7 "2.5deg"
*MEAS_COND_AXIS_POSITION-8 "13.0mm"
*MEAS_COND_AXIS_POSITION-9 "K-beta(x1)"
*MEAS_COND_AXIS_POSITION-10 "None"
*MEAS_COND_AXIS_POSITION-11 "41.0000000000"
*MEAS_COND_AXIS_UNIT-0 "deg"
*MEAS_COND_AXIS_UNIT-1 ""
*MEAS_COND_AXIS_UNIT-2 ""
*MEAS_COND_AXIS_UNIT-3 ""
*MEAS_COND_AXIS_UNIT-4 ""
*MEAS_COND_AXIS_UNIT-5 ""
*MEAS_COND_AXIS_UNIT-6 ""
*MEAS_COND_AXIS_UNIT-7 ""
*MEAS_COND_AXIS_UNIT-8 ""
*MEAS_COND_AXIS_UNIT-9 ""
*MEAS_COND_AXIS_UNIT-10 ""
*MEAS_COND_AXIS_UNIT-11 "div"
*MEAS_COND_CORRECTION_SLIT_COUNTERMONO "None"
*MEAS_COND_CORRECTION_SLIT_DS "0.625deg"
*MEAS_COND_CORRECTION_SLIT_FILTER "None"
*MEAS_COND_CORRECTION_SLIT_IHS "2.0mm"
*MEAS_COND_CORRECTION_SLIT_RS "13.0mm"
*MEAS_COND_CORRECTION_SLIT_SOLLER_INC "2.5deg"
*MEAS_COND_CORRECTION_SLIT_SOLLER_REC "2.5deg"
*MEAS_COND_CORRECTION_SLIT_SS "13.0mm"
*MEAS_COND_COUNTER_CNTLOSS_CORR "0.0000000000"
*MEAS_COND_COUNTER_PHABASE "41.0000000000"
*MEAS_COND_COUNTER_PHAWINDOW "14.0000000000"
*MEAS_COND_COUNTER_PHA_UNIT "div"
*MEAS_COND_COUNTER_TAUDIFF "0.2500000000"
*MEAS_COND_COUNTER_TAUINT "0.7500000000"
*MEAS_COND_IRRADIATION_MODE "OFF"
*MEAS_COND_IRRADIATION_WIDTH ""
*MEAS_COND_OPT_ATTR " "
*MEAS_COND_OPT_NAME ""
*MEAS_COND_UNSYMMETRIC_MODE "OFF"
*MEAS_COND_XG_CURRENT "15.0000000000"
*MEAS_COND_XG_VOLTAGE "40.0000000000"
*MEAS_COND_XG_WAVE_TYPE "Ka"
*MEAS_DATA_COUNT "3501.0000000000"
*MEAS_SCAN_AXIS_X "Theta/2-Theta"
*MEAS_SCAN_AXIS_X_INTERNAL "TwoThetaTheta"
*MEAS_SCAN_END_TIME "09/06/17 12:05:34"
*MEAS_SCAN_MODE "CONTINUOUS"
*MEAS_SCAN_MONITOR "0"
*MEAS_SCAN_RESOLUTION_X "0.005"
*MEAS_SCAN_SPEED "20.000"
*MEAS_SCAN_SPEED_UNIT "deg/min"
*MEAS_SCAN_SPEED_USER "20.000"
*MEAS_SCAN_START "20.0000000000"
*MEAS_SCAN_START_TIME "09/06/17 12:01:34"
*MEAS_SCAN_STEP "0.0200000000"
*MEAS_SCAN_STOP "90.0000000000"
*MEAS_SCAN_UNIT_X "deg"
*MEAS_SCAN_UNIT_Y "counts"
*SLIT_SYSTEM "0"
*RAS_HEADER_END
*RAS_INT_START
20.000 107.000 1.000
20.060 128.000 1.000
20.120 115.000 1.000
20.180 134.000 1.000
20.240 137.000 1.000
20.300 134.000 1.000
20.360 139.000 1.000
20.420 128.000 1.000
20.480 136.000 1.000
20.540 143.000 1.000
20.600 142.000 1.000
20.660 140.000 1.000
20.720 146.000 1.000
20.780 136.000 1.000
20.840 148.000 1.000
20.900 165.000 1.000
20.960 139.000 1.000
21.020 154.000 1.000
21.080 142.000 1.000
21.140 143.000 1.000
21.200 168.000 1.000
21.260 172.000 1.000
21.320 171.000 1.000
21.380 153.000 1.000
21.440 155.000 1.000
21.500 158.000 1.000
21.560 129.000 1.000
21.620 151.000 1.000
21.680 160.000 1.000
21.740 169.000 1.000
21.800 167.000 1.000
21.860 156.000 1.000
21.920 151.000 1.000
21.980 151.000 1.000
22.040 148.000 1.000
22.100 164.000 1.000
22.160 163.000 1.000
22.220 183.000 1.000
22.280 171.000 1.000
22.340 153.000 1.000
22.400 178.000 1.000
22.460 186.000 1.000
22.520 186.000 1.000
22.580 183.000 1.000
22.640 167.000 1.000
22.700 188.000 1.000
22.760 182.000 1.000
22.820 170.000 1.000
22.880 190.000 1.000
22.940 186.000 1.000
23.000 190.000 1.000
23.060 175.000 1.000
23.120 183.000 1.000
23.180 212.000 1.000
23.240 203.000 1.000
23.300 230.000 1.000
23.360 204.000 1.000
23.420 209.000 1.000
23.480 210.000 1.000
23.540 211.000 1.000
23.600 231.000 1.000
23.660 244.000 1.000
23.720 254.000 1.000
23.780 247.000 1.000
23.840 248.000 1.000
23.900 257.000 1.000
23.960 284.000 1.000
24.020 280.000 1.000
24.080 298.000 1.000
24.140 288.000 1.000
24.200 272.000 1.000
24.260 324.000 1.000
24.320 290.000 1.000
24.380 360.000 1.000
24.440 359.000 1.000
24.500 381.000 1.000
24.560 406.000 1.000
24.620 422.000 1.000
24.680 468.000 1.000
24.740 444.000 1.000
24.800 481.000 1.000
24.860 536.000 1.000
24.920 572.000 1.000
24.980 587.000 1.000
25.040 651.000 1.000
25.100 692.000 1.000
25.160 737.000 1.000
25.220 759.000 1.000
25.280 819.000 1.000
25.340 917.000 1.000
25.400 939.000 1.000
25.460 1059.000 1.000
25.520 1091.000 1.000
25.580 1130.000 1.000
25.640 1274.000 1.000
25.700 1355.000 1.000
25.760 1396.000 1.000
25.820 1482.000 1.000
25.880 1452.000 1.000
25.940 1666.000 1.000
26.000 1812.000 1.000
26.060 2137.000 1.000
26.120 2809.000 1.000
26.180 3693.000 1.000
26.240 4575.000 1.000
26.300 4858.000 1.000
26.360 4304.000 1.000
26.420 2759.000 1.000
26.480 1606.000 1.000
26.540 1039.000 1.000
26.600 769.000 1.000
26.660 621.000 1.000
26.720 571.000 1.000
26.780 509.000 1.000
26.840 469.000 1.000
26.900 430.000 1.000
26.960 390.000 1.000
27.020 391.000 1.000
27.080 335.000 1.000
27.140 329.000 1.000
27.200 325.000 1.000
27.260 285.000 1.000
27.320 251.000 1.000
27.380 238.000 1.000
27.440 268.000 1.000
27.500 252.000 1.000
27.560 237.000 1.000
27.620 227.000 1.000
27.680 210.000 1.000
27.740 226.000 1.000
27.800 210.000 1.000
27.860 186.000 1.000
27.920 198.000 1.000
27.980 200.000 1.000
28.040 188.000 1.000
28.100 185.000 1.000
28.160 181.000 1.000
28.220 190.000 1.000
28.280 197.000 1.000
28.340 202.000 1.000
28.400 185.000 1.000
28.460 188.000 1.000
28.520 167.000 1.000
28.580 162.000 1.000
28.640 173.000 1.000
28.700 160.000 1.000
28.760 161.000 1.000
28.820 150.000 1.000
28.880 171.000 1.000
28.940 159.000 1.000
29.000 165.000 1.000
29.060 164.000 1.000
29.120 163.000 1.000
29.180 187.000 1.000
29.240 205.000 1.000
29.300 219.000 1.000
29.360 218.000 1.000
29.420 229.000 1.000
29.480 255.000 1.000
29.540 236.000 1.000
29.600 207.000 1.000
29.660 159.000 1.000
29.720 158.000 1.000
29.780 157.000 1.000
29.840 134.000 1.000
29.900 123.000 1.000
29.960 151.000 1.000
30.020 136.000 1.000
30.080 141.000 1.000
30.140 143.000 1.000
30.200 151.000 1.000
30.260 131.000 1.000
30.320 129.000 1.000
30.380 158.000 1.000
30.440 135.000 1.000
30.500 111.000 1.000
30.560 144.000 1.000
30.620 139.000 1.000
30.680 144.000 1.000
30.740 131.000 1.000
30.800 131.000 1.000
30.860 143.000 1.000
30.920 131.000 1.000
30.980 129.000 1.000
31.040 119.000 1.000
31.100 134.000 1.000
31.160 142.000 1.000
31.220 100.000 1.000
31.280 121.000 1.000
31.340 131.000 1.000
31.400 142.000 1.000
31.460 130.000 1.000
31.520 127.000 1.000
31.580 132.000 1.000
31.640 128.000 1.000
31.700 126.000 1.000
31.760 127.000 1.000
31.820 112.000 1.000
31.880 120.000 1.000
31.940 116.000 1.000
32.000 132.000 1.000
32.060 110.000 1.000
32.120 107.000 1.000
32.180 117.000 1.000
32.240 123.000 1.000
32.300 104.000 1.000
32.360 107.000 1.000
32.420 119.000 1.000
32.480 116.000 1.000
32.540 125.000 1.000
32.600 115.000 1.000
32.660 119.000 1.000
32.720 112.000 1.000
32.780 116.000 1.000
32.840 115.000 1.000
32.900 121.000 1.000
32.960 110.000 1.000
33.020 124.000 1.000
33.080 120.000 1.000
33.140 112.000 1.000
33.200 119.000 1.000
33.260 113.000 1.000
33.320 104.000 1.000
33.380 105.000 1.000
33.440 115.000 1.000
33.500 119.000 1.000
33.560 116.000 1.000
33.620 118.000 1.000
33.680 123.000 1.000
33.740 131.000 1.000
33.800 123.000 1.000
33.860 126.000 1.000
33.920 120.000 1.000
33.980 115.000 1.000
34.040 104.000 1.000
34.100 114.000 1.000
34.160 106.000 1.000
34.220 120.000 1.000
34.280 117.000 1.000
34.340 131.000 1.000
34.400 114.000 1.000
34.460 117.000 1.000
34.520 129.000 1.000
34.580 117.000 1.000
34.640 133.000 1.000
34.700 137.000 1.000
34.760 135.000 1.000
34.820 116.000 1.000
34.880 128.000 1.000
34.940 131.000 1.000
35.000 137.000 1.000
35.060 135.000 1.000
35.120 137.000 1.000
35.180 138.000 1.000
35.240 153.000 1.000
35.300 139.000 1.000
35.360 127.000 1.000
35.420 147.000 1.000
35.480 156.000 1.000
35.540 135.000 1.000
35.600 154.000 1.000
35.660 168.000 1.000
35.720 159.000 1.000
35.780 167.000 1.000
35.840 182.000 1.000
35.900 194.000 1.000
35.960 213.000 1.000
36.020 250.000 1.000
36.080 348.000 1.000
36.140 544.000 1.000
36.200 825.000 1.000
36.260 1158.000 1.000
36.320 1495.000 1.000
36.380 1385.000 1.000
36.440 1065.000 1.000
36.500 673.000 1.000
36.560 390.000 1.000
36.620 272.000 1.000
36.680 184.000 1.000
36.740 162.000 1.000
36.800 183.000 1.000
36.860 134.000 1.000
36.920 162.000 1.000
36.980 125.000 1.000
37.040 141.000 1.000
37.100 147.000 1.000
37.160 122.000 1.000
37.220 130.000 1.000
37.280 127.000 1.000
37.340 133.000 1.000
37.400 127.000 1.000
37.460 104.000 1.000
37.520 115.000 1.000
37.580 129.000 1.000
37.640 113.000 1.000
37.700 132.000 1.000
37.760 134.000 1.000
37.820 126.000 1.000
37.880 122.000 1.000
37.940 110.000 1.000
38.000 119.000 1.000
38.060 118.000 1.000
38.120 101.000 1.000
38.180 119.000 1.000
38.240 117.000 1.000
38.300 118.000 1.000
38.360 126.000 1.000
38.420 120.000 1.000
38.480 119.000 1.000
38.540 112.000 1.000
38.600 107.000 1.000
38.660 106.000 1.000
38.720 109.000 1.000
38.780 112.000 1.000
38.840 118.000 1.000
38.900 100.000 1.000
38.960 108.000 1.000
39.020 103.000 1.000
39.080 109.000 1.000
39.140 119.000 1.000
39.200 116.000 1.000
39.260 114.000 1.000
39.320 122.000 1.000
39.380 105.000 1.000
39.440 113.000 1.000
39.500 100.000 1.000
39.560 119.000 1.000
39.620 110.000 1.000
39.680 126.000 1.000
39.740 108.000 1.000
39.800 100.000 1.000
39.860 118.000 1.000
39.920 106.000 1.000
39.980 105.000 1.000
40.040 122.000 1.000
40.100 111.000 1.000
40.160 115.000 1.000
40.220 107.000 1.000
40.280 95.000 1.000
40.340 94.000 1.000
40.400 118.000 1.000
40.460 94.000 1.000
40.520 120.000 1.000
40.580 116.000 1.000
40.640 111.000 1.000
40.700 109.000 1.000
40.760 114.000 1.000
40.820 104.000 1.000
40.880 104.000 1.000
40.940 121.000 1.000
41.000 110.000 1.000
41.060 110.000 1.000
41.120 124.000 1.000
41.180 108.000 1.000
41.240 109.000 1.000
41.300 115.000 1.000
41.360 111.000 1.000
41.420 106.000 1.000
41.480 100.000 1.000
41.540 120.000 1.000
41.600 118.000 1.000
41.660 136.000 1.000
41.720 122.000 1.000
41.780 146.000 1.000
41.840 138.000 1.000
41.900 162.000 1.000
41.960 190.000 1.000
42.020 215.000 1.000
42.080 310.000 1.000
42.140 394.000 1.000
42.200 440.000 1.000
42.260 453.000 1.000
42.320 367.000 1.000
42.380 324.000 1.000
42.440 231.000 1.000
42.500 215.000 1.000
42.560 165.000 1.000
42.620 154.000 1.000
42.680 152.000 1.000
42.740 133.000 1.000
42.800 144.000 1.000
42.860 121.000 1.000
42.920 150.000 1.000
42.980 149.000 1.000
43.040 146.000 1.000
43.100 148.000 1.000
43.160 166.000 1.000
43.220 150.000 1.000
43.280 148.000 1.000
43.340 145.000 1.000
43.400 147.000 1.000
43.460 127.000 1.000
43.520 116.000 1.000
43.580 128.000 1.000
43.640 131.000 1.000
43.700 119.000 1.000
43.760 122.000 1.000
43.820 120.000 1.000
43.880 118.000 1.000
43.940 110.000 1.000
44.000 111.000 1.000
44.060 105.000 1.000
44.120 111.000 1.000
44.180 121.000 1.000
44.240 117.000 1.000
44.300 108.000 1.000
44.360 120.000 1.000
44.420 126.000 1.000
44.480 120.000 1.000
44.540 114.000 1.000
44.600 118.000 1.000
44.660 116.000 1.000
44.720 109.000 1.000
44.780 117.000 1.000
44.840 101.000 1.000
44.900 99.000 1.000
44.960 97.000 1.000
45.020 109.000 1.000
45.080 111.000 1.000
45.140 98.000 1.000
45.200 93.000 1.000
45.260 106.000 1.000
45.320 99.000 1.000
45.380 94.000 1.000
45.440 103.000 1.000
45.500 99.000 1.000
45.560 97.000 1.000
45.620 119.000 1.000
45.680 99.000 1.000
45.740 115.000 1.000
45.800 96.000 1.000
45.860 101.000 1.000
45.920 104.000 1.000
45.980 98.000 1.000
46.040 87.000 1.000
46.100 107.000 1.000
46.160 87.000 1.000
46.220 107.000 1.000
46.280 99.000 1.000
46.340 89.000 1.000
46.400 104.000 1.000
46.460 117.000 1.000
46.520 119.000 1.000
46.580 99.000 1.000
46.640 93.000 1.000
46.700 91.000 1.000
46.760 86.000 1.000
46.820 97.000 1.000
46.880 105.000 1.000
46.940 95.000 1.000
47.000 101.000 1.000
47.060 109.000 1.000
47.120 112.000 1.000
47.180 92.000 1.000
47.240 108.000 1.000
47.300 135.000 1.000
47.360 101.000 1.000
47.420 111.000 1.000
47.480 105.000 1.000
47.540 99.000 1.000
47.600 90.000 1.000
47.660 85.000 1.000
47.720 78.000 1.000
47.780 103.000 1.000
47.840 104.000 1.000
47.900 97.000 1.000
47.960 97.000 1.000
48.020 112.000 1.000
48.080 73.000 1.000
48.140 98.000 1.000
48.200 103.000 1.000
48.260 103.000 1.000
48.320 109.000 1.000
48.380 92.000 1.000
48.440 102.000 1.000
48.500 92.000 1.000
48.560 105.000 1.000
48.620 103.000 1.000
48.680 90.000 1.000
48.740 97.000 1.000
48.800 87.000 1.000
48.860 102.000 1.000
48.920 100.000 1.000
48.980 100.000 1.000
49.040 118.000 1.000
49.100 97.000 1.000
49.160 98.000 1.000
49.220 87.000 1.000
49.280 99.000 1.000
49.340 98.000 1.000
49.400 92.000 1.000
49.460 94.000 1.000
49.520 102.000 1.000
49.580 97.000 1.000
49.640 97.000 1.000
49.700 96.000 1.000
49.760 90.000 1.000
49.820 77.000 1.000
49.880 74.000 1.000
49.940 106.000 1.000
50.000 98.000 1.000
50.060 114.000 1.000
50.120 92.000 1.000
50.180 106.000 1.000
50.240 104.000 1.000
50.300 98.000 1.000
50.360 103.000 1.000
50.420 99.000 1.000
50.480 113.000 1.000
50.540 107.000 1.000
50.600 87.000 1.000
50.660 100.000 1.000
50.720 107.000 1.000
50.780 99.000 1.000
50.840 95.000 1.000
50.900 95.000 1.000
50.960 93.000 1.000
51.020 100.000 1.000
51.080 101.000 1.000
51.140 112.000 1.000
51.200 88.000 1.000
51.260 98.000 1.000
51.320 116.000 1.000
51.380 87.000 1.000
51.440 105.000 1.000
51.500 111.000 1.000
51.560 86.000 1.000
51.620 96.000 1.000
51.680 103.000 1.000
51.740 95.000 1.000
51.800 97.000 1.000
51.860 110.000 1.000
51.920 103.000 1.000
51.980 80.000 1.000
52.040 96.000 1.000
52.100 97.000 1.000
52.160 115.000 1.000
52.220 107.000 1.000
52.280 127.000 1.000
52.340 121.000 1.000
52.400 119.000 1.000
52.460 128.000 1.000
52.520 122.000 1.000
52.580 102.000 1.000
52.640 120.000 1.000
52.700 119.000 1.000
52.760 124.000 1.000
52.820 108.000 1.000
52.880 108.000 1.000
52.940 104.000 1.000
53.000 112.000 1.000
53.060 108.000 1.000
53.120 107.000 1.000
53.180 108.000 1.000
53.240 114.000 1.000
53.300 125.000 1.000
53.360 129.000 1.000
53.420 130.000 1.000
53.480 130.000 1.000
53.540 131.000 1.000
53.600 137.000 1.000
53.660 143.000 1.000
53.720 129.000 1.000
53.780 138.000 1.000
53.840 134.000 1.000
53.900 124.000 1.000
53.960 159.000 1.000
54.020 149.000 1.000
54.080 152.000 1.000
54.140 156.000 1.000
54.200 191.000 1.000
54.260 204.000 1.000
54.320 231.000 1.000
54.380 201.000 1.000
54.440 210.000 1.000
54.500 172.000 1.000
54.560 177.000 1.000
54.620 107.000 1.000
54.680 122.000 1.000
54.740 101.000 1.000
54.800 123.000 1.000
54.860 116.000 1.000
54.920 115.000 1.000
54.980 92.000 1.000
55.040 99.000 1.000
55.100 117.000 1.000
55.160 112.000 1.000
55.220 86.000 1.000
55.280 90.000 1.000
55.340 96.000 1.000
55.400 88.000 1.000
55.460 114.000 1.000
55.520 103.000 1.000
55.580 86.000 1.000
55.640 85.000 1.000
55.700 103.000 1.000
55.760 97.000 1.000
55.820 105.000 1.000
55.880 100.000 1.000
55.940 93.000 1.000
56.000 87.000 1.000
56.060 87.000 1.000
56.120 78.000 1.000
56.180 84.000 1.000
56.240 104.000 1.000
56.300 88.000 1.000
56.360 91.000 1.000
56.420 93.000 1.000
56.480 83.000 1.000
56.540 92.000 1.000
56.600 102.000 1.000
56.660 92.000 1.000
56.720 91.000 1.000
56.780 89.000 1.000
56.840 81.000 1.000
56.900 83.000 1.000
56.960 88.000 1.000
57.020 78.000 1.000
57.080 87.000 1.000
57.140 69.000 1.000
57.200 88.000 1.000
57.260 81.000 1.000
57.320 81.000 1.000
57.380 86.000 1.000
57.440 78.000 1.000
57.500 80.000 1.000
57.560 79.000 1.000
57.620 92.000 1.000
57.680 85.000 1.000
57.740 82.000 1.000
57.800 98.000 1.000
57.860 80.000 1.000
57.920 83.000 1.000
57.980 86.000 1.000
58.040 85.000 1.000
58.100 87.000 1.000
58.160 91.000 1.000
58.220 87.000 1.000
58.280 98.000 1.000
58.340 87.000 1.000
58.400 94.000 1.000
58.460 88.000 1.000
58.520 81.000 1.000
58.580 97.000 1.000
58.640 81.000 1.000
58.700 88.000 1.000
58.760 96.000 1.000
58.820 81.000 1.000
58.880 93.000 1.000
58.940 87.000 1.000
59.000 89.000 1.000
59.060 86.000 1.000
59.120 86.000 1.000
59.180 95.000 1.000
59.240 81.000 1.000
59.300 91.000 1.000
59.360 87.000 1.000
59.420 84.000 1.000
59.480 101.000 1.000
59.540 93.000 1.000
59.600 85.000 1.000
59.660 89.000 1.000
59.720 90.000 1.000
59.780 99.000 1.000
59.840 88.000 1.000
59.900 81.000 1.000
59.960 87.000 1.000
60.020 84.000 1.000
60.080 91.000 1.000
60.140 91.000 1.000
60.200 87.000 1.000
60.260 84.000 1.000
60.320 79.000 1.000
60.380 77.000 1.000
60.440 81.000 1.000
60.500 89.000 1.000
60.560 79.000 1.000
60.620 104.000 1.000
60.680 101.000 1.000
60.740 93.000 1.000
60.800 86.000 1.000
60.860 92.000 1.000
60.920 112.000 1.000
60.980 109.000 1.000
61.040 138.000 1.000
61.100 135.000 1.000
61.160 177.000 1.000
61.220 220.000 1.000
61.280 254.000 1.000
61.340 279.000 1.000
61.400 251.000 1.000
61.460 216.000 1.000
61.520 198.000 1.000
61.580 170.000 1.000
61.640 140.000 1.000
61.700 142.000 1.000
61.760 135.000 1.000
61.820 114.000 1.000
61.880 102.000 1.000
61.940 105.000 1.000
62.000 107.000 1.000
62.060 101.000 1.000
62.120 102.000 1.000
62.180 96.000 1.000
62.240 91.000 1.000
62.300 103.000 1.000
62.360 99.000 1.000
62.420 88.000 1.000
62.480 91.000 1.000
62.540 86.000 1.000
62.600 82.000 1.000
62.660 81.000 1.000
62.720 94.000 1.000
62.780 96.000 1.000
62.840 88.000 1.000
62.900 75.000 1.000
62.960 77.000 1.000
63.020 90.000 1.000
63.080 73.000 1.000
63.140 83.000 1.000
63.200 70.000 1.000
63.260 71.000 1.000
63.320 89.000 1.000
63.380 88.000 1.000
63.440 88.000 1.000
63.500 85.000 1.000
63.560 87.000 1.000
63.620 77.000 1.000
63.680 67.000 1.000
63.740 73.000 1.000
63.800 79.000 1.000
63.860 74.000 1.000
63.920 73.000 1.000
63.980 81.000 1.000
64.040 84.000 1.000
64.100 78.000 1.000
64.160 95.000 1.000
64.220 76.000 1.000
64.280 67.000 1.000
64.340 76.000 1.000
64.400 80.000 1.000
64.460 80.000 1.000
64.520 76.000 1.000
64.580 89.000 1.000
64.640 90.000 1.000
64.700 71.000 1.000
64.760 84.000 1.000
64.820 82.000 1.000
64.880 78.000 1.000
64.940 82.000 1.000
65.000 73.000 1.000
65.060 74.000 1.000
65.120 80.000 1.000
65.180 86.000 1.000
65.240 75.000 1.000
65.300 75.000 1.000
65.360 80.000 1.000
65.420 63.000 1.000
65.480 80.000 1.000
65.540 72.000 1.000
65.600 72.000 1.000
65.660 83.000 1.000
65.720 71.000 1.000
65.780 76.000 1.000
65.840 77.000 1.000
65.900 75.000 1.000
65.960 75.000 1.000
66.020 85.000 1.000
66.080 86.000 1.000
66.140 82.000 1.000
66.200 72.000 1.000
66.260 83.000 1.000
66.320 76.000 1.000
66.380 84.000 1.000
66.440 86.000 1.000
66.500 64.000 1.000
66.560 80.000 1.000
66.620 75.000 1.000
66.680 77.000 1.000
66.740 72.000 1.000
66.800 92.000 1.000
66.860 80.000 1.000
66.920 69.000 1.000
66.980 72.000 1.000
67.040 81.000 1.000
67.100 72.000 1.000
67.160 74.000 1.000
67.220 83.000 1.000
67.280 81.000 1.000
67.340 78.000 1.000
67.400 75.000 1.000
67.460 81.000 1.000
67.520 94.000 1.000
67.580 89.000 1.000
67.640 80.000 1.000
67.700 64.000 1.000
67.760 81.000 1.000
67.820 78.000 1.000
67.880 81.000 1.000
67.940 80.000 1.000
68.000 83.000 1.000
68.060 75.000 1.000
68.120 69.000 1.000
68.180 86.000 1.000
68.240 68.000 1.000
68.300 84.000 1.000
68.360 75.000 1.000
68.420 67.000 1.000
68.480 83.000 1.000
68.540 75.000 1.000
68.600 63.000 1.000
68.660 82.000 1.000
68.720 85.000 1.000
68.780 80.000 1.000
68.840 68.000 1.000
68.900 78.000 1.000
68.960 71.000 1.000
69.020 74.000 1.000
69.080 65.000 1.000
69.140 83.000 1.000
69.200 74.000 1.000
69.260 88.000 1.000
69.320 73.000 1.000
69.380 78.000 1.000
69.440 73.000 1.000
69.500 90.000 1.000
69.560 83.000 1.000
69.620 88.000 1.000
69.680 77.000 1.000
69.740 75.000 1.000
69.800 91.000 1.000
69.860 81.000 1.000
69.920 68.000 1.000
69.980 91.000 1.000
70.040 75.000 1.000
70.100 74.000 1.000
70.160 72.000 1.000
70.220 75.000 1.000
70.280 70.000 1.000
70.340 65.000 1.000
70.400 65.000 1.000
70.460 72.000 1.000
70.520 76.000 1.000
70.580 74.000 1.000
70.640 76.000 1.000
70.700 75.000 1.000
70.760 79.000 1.000
70.820 64.000 1.000
70.880 87.000 1.000
70.940 86.000 1.000
71.000 68.000 1.000
71.060 79.000 1.000
71.120 74.000 1.000
71.180 83.000 1.000
71.240 81.000 1.000
71.300 79.000 1.000
71.360 72.000 1.000
71.420 71.000 1.000
71.480 81.000 1.000
71.540 75.000 1.000
71.600 75.000 1.000
71.660 92.000 1.000
71.720 78.000 1.000
71.780 73.000 1.000
71.840 72.000 1.000
71.900 74.000 1.000
71.960 86.000 1.000
72.020 81.000 1.000
72.080 85.000 1.000
72.140 85.000 1.000
72.200 97.000 1.000
72.260 75.000 1.000
72.320 68.000 1.000
72.380 93.000 1.000
72.440 65.000 1.000
72.500 85.000 1.000
72.560 89.000 1.000
72.620 91.000 1.000
72.680 93.000 1.000
72.740 87.000 1.000
72.800 101.000 1.000
72.860 95.000 1.000
72.920 97.000 1.000
72.980 93.000 1.000
73.040 96.000 1.000
73.100 95.000 1.000
73.160 120.000 1.000
73.220 122.000 1.000
73.280 137.000 1.000
73.340 149.000 1.000
73.400 147.000 1.000
73.460 182.000 1.000
73.520 168.000 1.000
73.580 197.000 1.000
73.640 157.000 1.000
73.700 136.000 1.000
73.760 140.000 1.000
73.820 118.000 1.000
73.880 116.000 1.000
73.940 103.000 1.000
74.000 93.000 1.000
74.060 113.000 1.000
74.120 88.000 1.000
74.180 88.000 1.000
74.240 82.000 1.000
74.300 87.000 1.000
74.360 87.000 1.000
74.420 86.000 1.000
74.480 81.000 1.000
74.540 84.000 1.000
74.600 81.000 1.000
74.660 77.000 1.000
74.720 73.000 1.000
74.780 74.000 1.000
74.840 82.000 1.000
74.900 65.000 1.000
74.960 81.000 1.000
75.020 89.000 1.000
75.080 76.000 1.000
75.140 74.000 1.000
75.200 76.000 1.000
75.260 72.000 1.000
75.320 79.000 1.000
75.380 86.000 1.000
75.440 74.000 1.000
75.500 85.000 1.000
75.560 81.000 1.000
75.620 78.000 1.000
75.680 74.000 1.000
75.740 84.000 1.000
75.800 77.000 1.000
75.860 59.000 1.000
75.920 83.000 1.000
75.980 79.000 1.000
76.040 89.000 1.000
76.100 61.000 1.000
76.160 78.000 1.000
76.220 69.000 1.000
76.280 70.000 1.000
76.340 84.000 1.000
76.400 77.000 1.000
76.460 89.000 1.000
76.520 65.000 1.000
76.580 69.000 1.000
76.640 80.000 1.000
76.700 73.000 1.000
76.760 79.000 1.000
76.820 83.000 1.000
76.880 85.000 1.000
76.940 80.000 1.000
77.000 86.000 1.000
77.060 81.000 1.000
77.120 85.000 1.000
77.180 86.000 1.000
77.240 95.000 1.000
77.300 95.000 1.000
77.360 92.000 1.000
77.420 102.000 1.000
77.480 102.000 1.000
77.540 88.000 1.000
77.600 90.000 1.000
77.660 85.000 1.000
77.720 76.000 1.000
77.780 74.000 1.000
77.840 79.000 1.000
77.900 81.000 1.000
77.960 70.000 1.000
78.020 75.000 1.000
78.080 75.000 1.000
78.140 80.000 1.000
78.200 75.000 1.000
78.260 90.000 1.000
78.320 80.000 1.000
78.380 61.000 1.000
78.440 68.000 1.000
78.500 80.000 1.000
78.560 56.000 1.000
78.620 74.000 1.000
78.680 82.000 1.000
78.740 72.000 1.000
78.800 69.000 1.000
78.860 84.000 1.000
78.920 74.000 1.000
78.980 73.000 1.000
79.040 73.000 1.000
79.100 86.000 1.000
79.160 72.000 1.000
79.220 63.000 1.000
79.280 68.000 1.000
79.340 77.000 1.000
79.400 83.000 1.000
79.460 68.000 1.000
79.520 63.000 1.000
79.580 64.000 1.000
79.640 81.000 1.000
79.700 59.000 1.000
79.760 75.000 1.000
79.820 67.000 1.000
79.880 69.000 1.000
79.940 73.000 1.000
80.000 59.000 1.000
80.060 65.000 1.000
80.120 71.000 1.000
80.180 60.000 1.000
80.240 69.000 1.000
80.300 80.000 1.000
80.360 74.000 1.000
80.420 80.000 1.000
80.480 68.000 1.000
80.540 72.000 1.000
80.600 60.000 1.000
80.660 75.000 1.000
80.720 61.000 1.000
80.780 76.000 1.000
80.840 69.000 1.000
80.900 75.000 1.000
80.960 81.000 1.000
81.020 85.000 1.000
81.080 59.000 1.000
81.140 67.000 1.000
81.200 62.000 1.000
81.260 70.000 1.000
81.320 72.000 1.000
81.380 75.000 1.000
81.440 65.000 1.000
81.500 80.000 1.000
81.560 72.000 1.000
81.620 76.000 1.000
81.680 71.000 1.000
81.740 49.000 1.000
81.800 73.000 1.000
81.860 62.000 1.000
81.920 62.000 1.000
81.980 61.000 1.000
82.040 69.000 1.000
82.100 81.000 1.000
82.160 83.000 1.000
82.220 64.000 1.000
82.280 76.000 1.000
82.340 65.000 1.000
82.400 67.000 1.000
82.460 71.000 1.000
82.520 74.000 1.000
82.580 64.000 1.000
82.640 77.000 1.000
82.700 67.000 1.000
82.760 63.000 1.000
82.820 62.000 1.000
82.880 71.000 1.000
82.940 60.000 1.000
83.000 57.000 1.000
83.060 79.000 1.000
83.120 85.000 1.000
83.180 64.000 1.000
83.240 79.000 1.000
83.300 79.000 1.000
83.360 72.000 1.000
83.420 74.000 1.000
83.480 72.000 1.000
83.540 59.000 1.000
83.600 86.000 1.000
83.660 65.000 1.000
83.720 72.000 1.000
83.780 61.000 1.000
83.840 57.000 1.000
83.900 67.000 1.000
83.960 84.000 1.000
84.020 66.000 1.000
84.080 59.000 1.000
84.140 64.000 1.000
84.200 67.000 1.000
84.260 64.000 1.000
84.320 73.000 1.000
84.380 76.000 1.000
84.440 60.000 1.000
84.500 74.000 1.000
84.560 74.000 1.000
84.620 75.000 1.000
84.680 68.000 1.000
84.740 60.000 1.000
84.800 76.000 1.000
84.860 64.000 1.000
84.920 75.000 1.000
84.980 72.000 1.000
85.040 68.000 1.000
85.100 68.000 1.000
85.160 70.000 1.000
85.220 76.000 1.000
85.280 71.000 1.000
85.340 69.000 1.000
85.400 69.000 1.000
85.460 68.000 1.000
85.520 75.000 1.000
85.580 82.000 1.000
85.640 70.000 1.000
85.700 88.000 1.000
85.760 64.000 1.000
85.820 63.000 1.000
85.880 83.000 1.000
85.940 89.000 1.000
86.000 66.000 1.000
86.060 71.000 1.000
86.120 73.000 1.000
86.180 70.000 1.000
86.240 76.000 1.000
86.300 78.000 1.000
86.360 69.000 1.000
86.420 73.000 1.000
86.480 65.000 1.000
86.540 89.000 1.000
86.600 71.000 1.000
86.660 91.000 1.000
86.720 79.000 1.000
86.780 83.000 1.000
86.840 67.000 1.000
86.900 81.000 1.000
86.960 70.000 1.000
87.020 79.000 1.000
87.080 73.000 1.000
87.140 66.000 1.000
87.200 67.000 1.000
87.260 73.000 1.000
87.320 71.000 1.000
87.380 65.000 1.000
87.440 68.000 1.000
87.500 66.000 1.000
87.560 85.000 1.000
87.620 71.000 1.000
87.680 86.000 1.000
87.740 72.000 1.000
87.800 61.000 1.000
87.860 72.000 1.000
87.920 79.000 1.000
87.980 64.000 1.000
88.040 64.000 1.000
88.100 76.000 1.000
88.160 68.000 1.000
88.220 58.000 1.000
88.280 67.000 1.000
88.340 50.000 1.000
88.400 63.000 1.000
88.460 54.000 1.000
88.520 55.000 1.000
88.580 63.000 1.000
88.640 70.000 1.000
88.700 64.000 1.000
88.760 76.000 1.000
88.820 67.000 1.000
88.880 83.000 1.000
88.940 61.000 1.000
89.000 58.000 1.000
89.060 70.000 1.000
89.120 70.000 1.000
89.180 54.000 1.000
89.240 56.000 1.000
89.300 65.000 1.000
89.360 67.000 1.000
89.420 58.000 1.000
89.480 63.000 1.000
89.540 71.000 1.000
89.600 61.000 1.000
89.660 61.000 1.000
89.720 64.000 1.000
89.780 75.000 1.000
89.840 88.000 1.000
89.900 65.000 1.000
89.960 63.000 1.000
90.000 90.000 1.000
*RAS_INT_END
*RAS_DATA_END