File: Lab/XRD/20170314/007-2-1036-2.ras
*RAS_DATA_START
*RAS_HEADER_START
*CORR_POS_DB_NAME "DTEX_11112016"
*CORR_POS_GONIO_RADIUS ""
*CORR_POS_NODE_INDEX01 ""
*CORR_POS_NODE_INDEX02 ""
*CORR_POS_NODE_INDEX03 ""
*CORR_POS_NODE_INDEX04 ""
*CORR_POS_NODE_INDEX05 ""
*CORR_POS_NODE_INDEX06 ""
*CORR_POS_NODE_INDEX07 ""
*CORR_POS_NODE_INDEX08 ""
*CORR_POS_NODE_INDEX09 ""
*CORR_POS_NODE_INDEX10 ""
*CORR_POS_NODE_INDEX11 ""
*CORR_POS_NODE_LABEL01 "Si(111)"
*CORR_POS_NODE_LABEL02 "Si(220)"
*CORR_POS_NODE_LABEL03 "Si(311)"
*CORR_POS_NODE_LABEL04 "Si(400)"
*CORR_POS_NODE_LABEL05 "Si(331)"
*CORR_POS_NODE_LABEL06 "Si(422)"
*CORR_POS_NODE_LABEL07 "Si(511)"
*CORR_POS_NODE_LABEL08 "Si(440)"
*CORR_POS_NODE_LABEL09 "Si(531)"
*CORR_POS_NODE_LABEL10 "Si(620)"
*CORR_POS_NODE_LABEL11 "Si(533)"
*CORR_POS_NODE_POS_CALC01 "28.4137"
*CORR_POS_NODE_POS_CALC02 "47.2707"
*CORR_POS_NODE_POS_CALC03 "56.0883"
*CORR_POS_NODE_POS_CALC04 "69.0934"
*CORR_POS_NODE_POS_CALC05 "76.3385"
*CORR_POS_NODE_POS_CALC06 "87.9915"
*CORR_POS_NODE_POS_CALC07 "94.9137"
*CORR_POS_NODE_POS_CALC08 "106.67"
*CORR_POS_NODE_POS_CALC09 "114.054"
*CORR_POS_NODE_POS_CALC10 "127.508"
*CORR_POS_NODE_POS_CALC11 "136.858"
*CORR_POS_NODE_POS_MEAS01 "28.3712"
*CORR_POS_NODE_POS_MEAS02 "47.2304"
*CORR_POS_NODE_POS_MEAS03 "56.0465"
*CORR_POS_NODE_POS_MEAS04 "69.0523"
*CORR_POS_NODE_POS_MEAS05 "76.2993"
*CORR_POS_NODE_POS_MEAS06 "87.9512"
*CORR_POS_NODE_POS_MEAS07 "94.8772"
*CORR_POS_NODE_POS_MEAS08 "106.636"
*CORR_POS_NODE_POS_MEAS09 "114.028"
*CORR_POS_NODE_POS_MEAS10 "127.48"
*CORR_POS_NODE_POS_MEAS11 "136.839"
*CORR_POS_OPT_ATTR "集中法"
*CORR_POS_PARAM_MU ""
*CORR_POS_PARAM_PL ""
*CORR_POS_SEMODEL_TYPE "0"
*CORR_POS_STANDARD_TYPE ""
*CORR_POS_VALUE_ANALYZER "None"
*CORR_POS_VALUE_CMONO "None"
*CORR_POS_VALUE_IMONO "None"
*CORR_POS_VALUE_IS "0.625deg"
*CORR_POS_VALUE_ISL "10.0mm"
*CORR_POS_VALUE_ISOLLER "2.5deg"
*CORR_POS_VALUE_RS1 "13.0mm"
*CORR_POS_VALUE_RS2 "13.0mm"
*CORR_POS_VALUE_RSOLLER "2.5deg"
*CORR_POS_XG_FOCUS_L ""
*CORR_POS_XG_WAVE_TYPE ""
*CORR_POS_XG_WAVE_VALUE ""
*DISP_FMT_X "%.2f"
*DISP_FMT_Y "%.0f"
*DISP_FULLSCALE "10119.6000000000"
*DISP_LINE_COLOR "255.0000000000"
*DISP_LINE_STYLE "0.0000000000"
*DISP_LINE_WIDTH "0.2500000000"
*DISP_NOTE "Collected Data-2"
*DISP_OFFSET_Y "0.0000000000"
*DISP_PEAKSEARCH_UNIT_Y "COUNTS"
*DISP_RANGE_BOTTOM "0.0000000000"
*DISP_RANGE_LEFT "10.0000000000"
*DISP_RANGE_LOGCUTOFF "0.0100000000"
*DISP_RANGE_RIGHT "90.0000000000"
*DISP_RANGE_TOP "10119.6000000000"
*DISP_SCALE_MODE_Y "0.0000000000"
*DISP_TAB_NAME "Theta/2-Theta"
*DISP_TITLE_Y "Intensity"
*DISP_UNIT_Y "COUNTS"
*DISP_WINDOW_NAME "MSG_MACROENGINE"
*FILE_COMMENT " "
*FILE_MD5 ""
*FILE_MEMO "45C"
*FILE_OPERATOR "MiniFlex"
*FILE_PART_ID "MEAS_PBEA_00223"
*FILE_SAMPLE "007"
*FILE_TYPE "RAS_RAW"
*FILE_USERGROUP "System User"
*FILE_VERSION "1.0000000000"
*HW_ATTACHMENT_ID "ATT1031"
*HW_ATTACHMENT_NAME "6サンプルチェンジャ|ASC-6"
*HW_COUNTER_ID-0 "CUT0025"
*HW_COUNTER_ID-1 "CUT0020"
*HW_COUNTER_ID-2 "CUT0020"
*HW_COUNTER_ID-3 "CMC0021"
*HW_COUNTER_NAME-0 "D/teX Ultra|D/teX Ultra"
*HW_COUNTER_NAME-1 "None|None"
*HW_COUNTER_NAME-2 "None|None"
*HW_COUNTER_NAME-3 "検出器モノクロメータ|Detector monochromator"
*HW_COUNTER_SELECT_NAME "D/teX Ultra|D/teX Ultra"
*HW_GONIOMETER_ID "GON0070"
*HW_GONIOMETER_NAME "MiniFlex 300/600|MiniFlex 300/600"
*HW_GONIOMETER_RADIUS-0 "79.0"
*HW_GONIOMETER_RADIUS-1 "91.5"
*HW_GONIOMETER_RADIUS-2 "150.0"
*HW_GONIOMETER_RADIUS-3 "0"
*HW_GONIOMETER_RADIUS-4 "103.4"
*HW_GONIOMETER_RADIUS-5 "150.0"
*HW_GONIOMETER_RADIUS-6 "46.6"
*HW_GONIOMETER_RADIUS-7 "160.0"
*HW_I_OPT_ID-0 "ISL0021"
*HW_I_OPT_ID-1 "ISO0021"
*HW_I_OPT_NAME-0 "発散スリット|Divergence slit"
*HW_I_OPT_NAME-1 "入射平行スリット|Incident parallel slit"
*HW_R_ATTENUATER_AUTOMODE "0"
*HW_R_OPT_ID-0 "RSS0021"
*HW_R_OPT_ID-1 "RSO0021"
*HW_R_OPT_ID-2 "RRS0021"
*HW_R_OPT_NAME-0 "散乱スリット|Scattering slit"
*HW_R_OPT_NAME-1 "受光平行スリット|Receiving soller slit"
*HW_R_OPT_NAME-2 "受光スリット|Receiving slit"
*HW_SAMPLE_HOLDER_ID "SMP0000"
*HW_SAMPLE_HOLDER_NAME "無し|None"
*HW_XG_CURRENT_MAX "15"
*HW_XG_CURRENT_MIN "2"
*HW_XG_CURRENT_RESOLUTION "1"
*HW_XG_CURRENT_UNIT "mA"
*HW_XG_FOCUS "1mm x 10mm"
*HW_XG_FOCUS_TYPE "Normal"
*HW_XG_ID "1060"
*HW_XG_NAME "300W/600W 封入管-B|300W/600W Sealed tube-B"
*HW_XG_TARGET_ATOMIC_NUMBER "29.0000000000"
*HW_XG_TARGET_NAME "Cu"
*HW_XG_TYPE "Hermetic"
*HW_XG_VOLTAGE_MAX "40"
*HW_XG_VOLTAGE_MIN "20"
*HW_XG_VOLTAGE_RESOLUTION "1"
*HW_XG_VOLTAGE_UNIT "kV"
*HW_XG_WATT_MAX "1"
*HW_XG_WATT_UNIT "kW"
*HW_XG_WAVE_LENGTH_ALPHA1 "1.540593"
*HW_XG_WAVE_LENGTH_ALPHA2 "1.544414"
*HW_XG_WAVE_LENGTH_BETA "1.392250"
*MEAS_COND_AXIS_NAME-0 "Theta/2-Theta"
*MEAS_COND_AXIS_NAME-1 "Spin"
*MEAS_COND_AXIS_NAME-2 "Change"
*MEAS_COND_AXIS_NAME-3 "Soller(inc.)"
*MEAS_COND_AXIS_NAME-4 "IHS"
*MEAS_COND_AXIS_NAME-5 "DS"
*MEAS_COND_AXIS_NAME-6 "SS"
*MEAS_COND_AXIS_NAME-7 "Soller(rec.)"
*MEAS_COND_AXIS_NAME-8 "RS"
*MEAS_COND_AXIS_NAME-9 "Filter"
*MEAS_COND_AXIS_NAME-10 "Monochromator"
*MEAS_COND_AXIS_NAME-11 "PHA"
*MEAS_COND_AXIS_NAME_INTERNAL-0 "TwoThetaTheta"
*MEAS_COND_AXIS_NAME_INTERNAL-1 "Spin"
*MEAS_COND_AXIS_NAME_INTERNAL-2 "Change"
*MEAS_COND_AXIS_NAME_INTERNAL-3 "IncidentSollerSlit"
*MEAS_COND_AXIS_NAME_INTERNAL-4 "IncidentAxdSlit"
*MEAS_COND_AXIS_NAME_INTERNAL-5 "IncidentSlitBox"
*MEAS_COND_AXIS_NAME_INTERNAL-6 "ReceivingSlitBox1"
*MEAS_COND_AXIS_NAME_INTERNAL-7 "ReceivingSollerSlit"
*MEAS_COND_AXIS_NAME_INTERNAL-8 "ReceivingSlitBox2"
*MEAS_COND_AXIS_NAME_INTERNAL-9 "Filter"
*MEAS_COND_AXIS_NAME_INTERNAL-10 "CounterMonochromator"
*MEAS_COND_AXIS_NAME_INTERNAL-11 "PHA"
*MEAS_COND_AXIS_NAME_MAGICNO-0 "268632064.0000000000"
*MEAS_COND_AXIS_NAME_MAGICNO-1 "16842752.0000000000"
*MEAS_COND_AXIS_NAME_MAGICNO-2 "16842752.0000000000"
*MEAS_COND_AXIS_NAME_MAGICNO-3 "20971521.0000000000"
*MEAS_COND_AXIS_NAME_MAGICNO-4 "22020097.0000000000"
*MEAS_COND_AXIS_NAME_MAGICNO-5 "22020097.0000000000"
*MEAS_COND_AXIS_NAME_MAGICNO-6 "23068673.0000000000"
*MEAS_COND_AXIS_NAME_MAGICNO-7 "20971521.0000000000"
*MEAS_COND_AXIS_NAME_MAGICNO-8 "23068673.0000000000"
*MEAS_COND_AXIS_NAME_MAGICNO-9 "20971521.0000000000"
*MEAS_COND_AXIS_NAME_MAGICNO-10 "20971521.0000000000"
*MEAS_COND_AXIS_NAME_MAGICNO-11 "0.0000000000"
*MEAS_COND_AXIS_OFFSET-0 "0.0000000000"
*MEAS_COND_AXIS_OFFSET-1 "-"
*MEAS_COND_AXIS_OFFSET-2 "-"
*MEAS_COND_AXIS_OFFSET-3 "-"
*MEAS_COND_AXIS_OFFSET-4 "-"
*MEAS_COND_AXIS_OFFSET-5 "-"
*MEAS_COND_AXIS_OFFSET-6 "-"
*MEAS_COND_AXIS_OFFSET-7 "-"
*MEAS_COND_AXIS_OFFSET-8 "-"
*MEAS_COND_AXIS_OFFSET-9 "-"
*MEAS_COND_AXIS_OFFSET-10 "-"
*MEAS_COND_AXIS_OFFSET-11 "-"
*MEAS_COND_AXIS_POSITION-0 "92.5150000000"
*MEAS_COND_AXIS_POSITION-1 "0.0000000000"
*MEAS_COND_AXIS_POSITION-2 "2.0000000000"
*MEAS_COND_AXIS_POSITION-3 "2.5deg"
*MEAS_COND_AXIS_POSITION-4 "10.0mm"
*MEAS_COND_AXIS_POSITION-5 "0.625deg"
*MEAS_COND_AXIS_POSITION-6 "13.0mm(Open)"
*MEAS_COND_AXIS_POSITION-7 "2.5deg"
*MEAS_COND_AXIS_POSITION-8 "13.0mm"
*MEAS_COND_AXIS_POSITION-9 "K-beta(x2)"
*MEAS_COND_AXIS_POSITION-10 "None"
*MEAS_COND_AXIS_POSITION-11 "41.0000000000"
*MEAS_COND_AXIS_UNIT-0 "deg"
*MEAS_COND_AXIS_UNIT-1 ""
*MEAS_COND_AXIS_UNIT-2 ""
*MEAS_COND_AXIS_UNIT-3 ""
*MEAS_COND_AXIS_UNIT-4 ""
*MEAS_COND_AXIS_UNIT-5 ""
*MEAS_COND_AXIS_UNIT-6 ""
*MEAS_COND_AXIS_UNIT-7 ""
*MEAS_COND_AXIS_UNIT-8 ""
*MEAS_COND_AXIS_UNIT-9 ""
*MEAS_COND_AXIS_UNIT-10 ""
*MEAS_COND_AXIS_UNIT-11 "div"
*MEAS_COND_CORRECTION_SLIT_COUNTERMONO "None"
*MEAS_COND_CORRECTION_SLIT_DS "0.625deg"
*MEAS_COND_CORRECTION_SLIT_FILTER "None"
*MEAS_COND_CORRECTION_SLIT_IHS "10.0mm"
*MEAS_COND_CORRECTION_SLIT_RS "13.0mm"
*MEAS_COND_CORRECTION_SLIT_SOLLER_INC "2.5deg"
*MEAS_COND_CORRECTION_SLIT_SOLLER_REC "2.5deg"
*MEAS_COND_CORRECTION_SLIT_SS "13.0mm"
*MEAS_COND_COUNTER_CNTLOSS_CORR "0.0000000000"
*MEAS_COND_COUNTER_PHABASE "41.0000000000"
*MEAS_COND_COUNTER_PHAWINDOW "14.0000000000"
*MEAS_COND_COUNTER_PHA_UNIT "div"
*MEAS_COND_COUNTER_TAUDIFF "0.2500000000"
*MEAS_COND_COUNTER_TAUINT "0.7500000000"
*MEAS_COND_IRRADIATION_MODE "OFF"
*MEAS_COND_IRRADIATION_WIDTH ""
*MEAS_COND_OPT_ATTR " "
*MEAS_COND_OPT_NAME ""
*MEAS_COND_UNSYMMETRIC_MODE "OFF"
*MEAS_COND_XG_CURRENT "15.0000000000"
*MEAS_COND_XG_VOLTAGE "40.0000000000"
*MEAS_COND_XG_WAVE_TYPE "Ka"
*MEAS_DATA_COUNT "4001.0000000000"
*MEAS_SCAN_AXIS_X "Theta/2-Theta"
*MEAS_SCAN_AXIS_X_INTERNAL "TwoThetaTheta"
*MEAS_SCAN_END_TIME "03/14/17 10:54:22"
*MEAS_SCAN_MODE "CONTINUOUS"
*MEAS_SCAN_MONITOR "0"
*MEAS_SCAN_RESOLUTION_X "0.005"
*MEAS_SCAN_SPEED "10.000"
*MEAS_SCAN_SPEED_UNIT "deg/min"
*MEAS_SCAN_SPEED_USER "10.000"
*MEAS_SCAN_START "10.0000000000"
*MEAS_SCAN_START_TIME "03/14/17 10:45:26"
*MEAS_SCAN_STEP "0.0200000000"
*MEAS_SCAN_STOP "90.0000000000"
*MEAS_SCAN_UNIT_X "deg"
*MEAS_SCAN_UNIT_Y "counts"
*SLIT_SYSTEM "0"
*RAS_HEADER_END
*RAS_INT_START
10.000 179.000 1.000
10.060 187.000 1.000
10.120 194.000 1.000
10.180 191.000 1.000
10.240 195.000 1.000
10.300 210.000 1.000
10.360 206.000 1.000
10.420 181.000 1.000
10.480 205.000 1.000
10.540 219.000 1.000
10.600 216.000 1.000
10.660 210.000 1.000
10.720 198.000 1.000
10.780 210.000 1.000
10.840 220.000 1.000
10.900 210.000 1.000
10.960 219.000 1.000
11.020 193.000 1.000
11.080 192.000 1.000
11.140 209.000 1.000
11.200 223.000 1.000
11.260 206.000 1.000
11.320 218.000 1.000
11.380 215.000 1.000
11.440 223.000 1.000
11.500 205.000 1.000
11.560 219.000 1.000
11.620 214.000 1.000
11.680 225.000 1.000
11.740 194.000 1.000
11.800 211.000 1.000
11.860 220.000 1.000
11.920 209.000 1.000
11.980 211.000 1.000
12.040 205.000 1.000
12.100 216.000 1.000
12.160 211.000 1.000
12.220 199.000 1.000
12.280 225.000 1.000
12.340 206.000 1.000
12.400 210.000 1.000
12.460 212.000 1.000
12.520 216.000 1.000
12.580 201.000 1.000
12.640 214.000 1.000
12.700 212.000 1.000
12.760 224.000 1.000
12.820 231.000 1.000
12.880 206.000 1.000
12.940 199.000 1.000
13.000 213.000 1.000
13.060 206.000 1.000
13.120 239.000 1.000
13.180 221.000 1.000
13.240 239.000 1.000
13.300 205.000 1.000
13.360 225.000 1.000
13.420 209.000 1.000
13.480 219.000 1.000
13.540 221.000 1.000
13.600 207.000 1.000
13.660 205.000 1.000
13.720 244.000 1.000
13.780 225.000 1.000
13.840 207.000 1.000
13.900 230.000 1.000
13.960 219.000 1.000
14.020 224.000 1.000
14.080 220.000 1.000
14.140 228.000 1.000
14.200 211.000 1.000
14.260 216.000 1.000
14.320 228.000 1.000
14.380 230.000 1.000
14.440 224.000 1.000
14.500 223.000 1.000
14.560 214.000 1.000
14.620 206.000 1.000
14.680 220.000 1.000
14.740 208.000 1.000
14.800 209.000 1.000
14.860 213.000 1.000
14.920 202.000 1.000
14.980 189.000 1.000
15.040 220.000 1.000
15.100 202.000 1.000
15.160 220.000 1.000
15.220 229.000 1.000
15.280 238.000 1.000
15.340 210.000 1.000
15.400 239.000 1.000
15.460 214.000 1.000
15.520 236.000 1.000
15.580 223.000 1.000
15.640 209.000 1.000
15.700 227.000 1.000
15.760 231.000 1.000
15.820 208.000 1.000
15.880 233.000 1.000
15.940 233.000 1.000
16.000 207.000 1.000
16.060 220.000 1.000
16.120 217.000 1.000
16.180 216.000 1.000
16.240 221.000 1.000
16.300 207.000 1.000
16.360 223.000 1.000
16.420 236.000 1.000
16.480 224.000 1.000
16.540 224.000 1.000
16.600 204.000 1.000
16.660 241.000 1.000
16.720 230.000 1.000
16.780 225.000 1.000
16.840 224.000 1.000
16.900 223.000 1.000
16.960 226.000 1.000
17.020 234.000 1.000
17.080 211.000 1.000
17.140 248.000 1.000
17.200 244.000 1.000
17.260 249.000 1.000
17.320 202.000 1.000
17.380 218.000 1.000
17.440 203.000 1.000
17.500 229.000 1.000
17.560 234.000 1.000
17.620 217.000 1.000
17.680 220.000 1.000
17.740 218.000 1.000
17.800 220.000 1.000
17.860 226.000 1.000
17.920 229.000 1.000
17.980 210.000 1.000
18.040 226.000 1.000
18.100 220.000 1.000
18.160 227.000 1.000
18.220 214.000 1.000
18.280 212.000 1.000
18.340 218.000 1.000
18.400 222.000 1.000
18.460 233.000 1.000
18.520 206.000 1.000
18.580 235.000 1.000
18.640 253.000 1.000
18.700 231.000 1.000
18.760 220.000 1.000
18.820 236.000 1.000
18.880 243.000 1.000
18.940 229.000 1.000
19.000 248.000 1.000
19.060 243.000 1.000
19.120 264.000 1.000
19.180 249.000 1.000
19.240 232.000 1.000
19.300 225.000 1.000
19.360 246.000 1.000
19.420 209.000 1.000
19.480 248.000 1.000
19.540 255.000 1.000
19.600 234.000 1.000
19.660 236.000 1.000
19.720 238.000 1.000
19.780 241.000 1.000
19.840 231.000 1.000
19.900 241.000 1.000
19.960 242.000 1.000
20.020 247.000 1.000
20.080 236.000 1.000
20.140 230.000 1.000
20.200 231.000 1.000
20.260 213.000 1.000
20.320 258.000 1.000
20.380 239.000 1.000
20.440 246.000 1.000
20.500 228.000 1.000
20.560 236.000 1.000
20.620 241.000 1.000
20.680 237.000 1.000
20.740 235.000 1.000
20.800 261.000 1.000
20.860 242.000 1.000
20.920 224.000 1.000
20.980 238.000 1.000
21.040 231.000 1.000
21.100 251.000 1.000
21.160 258.000 1.000
21.220 282.000 1.000
21.280 285.000 1.000
21.340 285.000 1.000
21.400 285.000 1.000
21.460 260.000 1.000
21.520 246.000 1.000
21.580 253.000 1.000
21.640 262.000 1.000
21.700 240.000 1.000
21.760 255.000 1.000
21.820 254.000 1.000
21.880 268.000 1.000
21.940 275.000 1.000
22.000 263.000 1.000
22.060 260.000 1.000
22.120 262.000 1.000
22.180 273.000 1.000
22.240 271.000 1.000
22.300 258.000 1.000
22.360 277.000 1.000
22.420 263.000 1.000
22.480 258.000 1.000
22.540 296.000 1.000
22.600 281.000 1.000
22.660 256.000 1.000
22.720 285.000 1.000
22.780 285.000 1.000
22.840 289.000 1.000
22.900 278.000 1.000
22.960 300.000 1.000
23.020 308.000 1.000
23.080 286.000 1.000
23.140 330.000 1.000
23.200 342.000 1.000
23.260 322.000 1.000
23.320 309.000 1.000
23.380 312.000 1.000
23.440 333.000 1.000
23.500 341.000 1.000
23.560 331.000 1.000
23.620 369.000 1.000
23.680 392.000 1.000
23.740 420.000 1.000
23.800 373.000 1.000
23.860 411.000 1.000
23.920 385.000 1.000
23.980 415.000 1.000
24.040 421.000 1.000
24.100 421.000 1.000
24.160 458.000 1.000
24.220 431.000 1.000
24.280 448.000 1.000
24.340 453.000 1.000
24.400 533.000 1.000
24.460 518.000 1.000
24.520 552.000 1.000
24.580 566.000 1.000
24.640 569.000 1.000
24.700 609.000 1.000
24.760 653.000 1.000
24.820 685.000 1.000
24.880 727.000 1.000
24.940 764.000 1.000
25.000 832.000 1.000
25.060 804.000 1.000
25.120 917.000 1.000
25.180 931.000 1.000
25.240 1061.000 1.000
25.300 1145.000 1.000
25.360 1212.000 1.000
25.420 1335.000 1.000
25.480 1344.000 1.000
25.540 1480.000 1.000
25.600 1558.000 1.000
25.660 1690.000 1.000
25.720 1843.000 1.000
25.780 1922.000 1.000
25.840 1977.000 1.000
25.900 2130.000 1.000
25.960 2227.000 1.000
26.020 2293.000 1.000
26.080 2485.000 1.000
26.140 2666.000 1.000
26.200 2984.000 1.000
26.260 3596.000 1.000
26.320 5038.000 1.000
26.380 7344.000 1.000
26.440 8433.000 1.000
26.500 6998.000 1.000
26.560 4223.000 1.000
26.620 2362.000 1.000
26.680 1569.000 1.000
26.740 1226.000 1.000
26.800 1014.000 1.000
26.860 929.000 1.000
26.920 783.000 1.000
26.980 738.000 1.000
27.040 633.000 1.000
27.100 640.000 1.000
27.160 546.000 1.000
27.220 521.000 1.000
27.280 513.000 1.000
27.340 465.000 1.000
27.400 467.000 1.000
27.460 436.000 1.000
27.520 440.000 1.000
27.580 402.000 1.000
27.640 376.000 1.000
27.700 372.000 1.000
27.760 361.000 1.000
27.820 350.000 1.000
27.880 345.000 1.000
27.940 312.000 1.000
28.000 336.000 1.000
28.060 338.000 1.000
28.120 313.000 1.000
28.180 309.000 1.000
28.240 305.000 1.000
28.300 280.000 1.000
28.360 278.000 1.000
28.420 291.000 1.000
28.480 301.000 1.000
28.540 279.000 1.000
28.600 272.000 1.000
28.660 272.000 1.000
28.720 293.000 1.000
28.780 271.000 1.000
28.840 273.000 1.000
28.900 264.000 1.000
28.960 235.000 1.000
29.020 235.000 1.000
29.080 262.000 1.000
29.140 273.000 1.000
29.200 263.000 1.000
29.260 286.000 1.000
29.320 270.000 1.000
29.380 273.000 1.000
29.440 304.000 1.000
29.500 339.000 1.000
29.560 437.000 1.000
29.620 524.000 1.000
29.680 497.000 1.000
29.740 373.000 1.000
29.800 332.000 1.000
29.860 274.000 1.000
29.920 258.000 1.000
29.980 232.000 1.000
30.040 229.000 1.000
30.100 224.000 1.000
30.160 247.000 1.000
30.220 234.000 1.000
30.280 238.000 1.000
30.340 239.000 1.000
30.400 208.000 1.000
30.460 245.000 1.000
30.520 225.000 1.000
30.580 225.000 1.000
30.640 216.000 1.000
30.700 258.000 1.000
30.760 349.000 1.000
30.820 285.000 1.000
30.880 265.000 1.000
30.940 218.000 1.000
31.000 242.000 1.000
31.060 196.000 1.000
31.120 213.000 1.000
31.180 228.000 1.000
31.240 203.000 1.000
31.300 217.000 1.000
31.360 200.000 1.000
31.420 230.000 1.000
31.480 203.000 1.000
31.540 213.000 1.000
31.600 228.000 1.000
31.660 223.000 1.000
31.720 205.000 1.000
31.780 206.000 1.000
31.840 212.000 1.000
31.900 180.000 1.000
31.960 199.000 1.000
32.020 192.000 1.000
32.080 208.000 1.000
32.140 190.000 1.000
32.200 208.000 1.000
32.260 203.000 1.000
32.320 190.000 1.000
32.380 202.000 1.000
32.440 196.000 1.000
32.500 204.000 1.000
32.560 206.000 1.000
32.620 215.000 1.000
32.680 197.000 1.000
32.740 201.000 1.000
32.800 193.000 1.000
32.860 208.000 1.000
32.920 199.000 1.000
32.980 184.000 1.000
33.040 196.000 1.000
33.100 199.000 1.000
33.160 184.000 1.000
33.220 210.000 1.000
33.280 224.000 1.000
33.340 196.000 1.000
33.400 201.000 1.000
33.460 213.000 1.000
33.520 221.000 1.000
33.580 214.000 1.000
33.640 213.000 1.000
33.700 191.000 1.000
33.760 189.000 1.000
33.820 206.000 1.000
33.880 219.000 1.000
33.940 178.000 1.000
34.000 182.000 1.000
34.060 219.000 1.000
34.120 189.000 1.000
34.180 204.000 1.000
34.240 224.000 1.000
34.300 215.000 1.000
34.360 221.000 1.000
34.420 189.000 1.000
34.480 219.000 1.000
34.540 221.000 1.000
34.600 211.000 1.000
34.660 248.000 1.000
34.720 219.000 1.000
34.780 225.000 1.000
34.840 227.000 1.000
34.900 228.000 1.000
34.960 229.000 1.000
35.020 237.000 1.000
35.080 220.000 1.000
35.140 221.000 1.000
35.200 244.000 1.000
35.260 268.000 1.000
35.320 227.000 1.000
35.380 218.000 1.000
35.440 224.000 1.000
35.500 241.000 1.000
35.560 257.000 1.000
35.620 276.000 1.000
35.680 246.000 1.000
35.740 265.000 1.000
35.800 254.000 1.000
35.860 297.000 1.000
35.920 324.000 1.000
35.980 258.000 1.000
36.040 314.000 1.000
36.100 336.000 1.000
36.160 361.000 1.000
36.220 473.000 1.000
36.280 711.000 1.000
36.340 1470.000 1.000
36.400 2712.000 1.000
36.460 4164.000 1.000
36.520 3820.000 1.000
36.580 2648.000 1.000
36.640 1430.000 1.000
36.700 672.000 1.000
36.760 445.000 1.000
36.820 342.000 1.000
36.880 297.000 1.000
36.940 252.000 1.000
37.000 271.000 1.000
37.060 288.000 1.000
37.120 249.000 1.000
37.180 247.000 1.000
37.240 239.000 1.000
37.300 218.000 1.000
37.360 225.000 1.000
37.420 226.000 1.000
37.480 220.000 1.000
37.540 219.000 1.000
37.600 216.000 1.000
37.660 214.000 1.000
37.720 219.000 1.000
37.780 205.000 1.000
37.840 211.000 1.000
37.900 226.000 1.000
37.960 215.000 1.000
38.020 219.000 1.000
38.080 226.000 1.000
38.140 213.000 1.000
38.200 203.000 1.000
38.260 209.000 1.000
38.320 220.000 1.000
38.380 224.000 1.000
38.440 215.000 1.000
38.500 232.000 1.000
38.560 234.000 1.000
38.620 191.000 1.000
38.680 205.000 1.000
38.740 201.000 1.000
38.800 190.000 1.000
38.860 177.000 1.000
38.920 202.000 1.000
38.980 205.000 1.000
39.040 207.000 1.000
39.100 193.000 1.000
39.160 200.000 1.000
39.220 197.000 1.000
39.280 209.000 1.000
39.340 228.000 1.000
39.400 186.000 1.000
39.460 229.000 1.000
39.520 198.000 1.000
39.580 210.000 1.000
39.640 191.000 1.000
39.700 205.000 1.000
39.760 200.000 1.000
39.820 220.000 1.000
39.880 221.000 1.000
39.940 181.000 1.000
40.000 210.000 1.000
40.060 190.000 1.000
40.120 216.000 1.000
40.180 204.000 1.000
40.240 192.000 1.000
40.300 219.000 1.000
40.360 211.000 1.000
40.420 202.000 1.000
40.480 208.000 1.000
40.540 185.000 1.000
40.600 206.000 1.000
40.660 205.000 1.000
40.720 196.000 1.000
40.780 221.000 1.000
40.840 235.000 1.000
40.900 215.000 1.000
40.960 200.000 1.000
41.020 214.000 1.000
41.080 211.000 1.000
41.140 206.000 1.000
41.200 235.000 1.000
41.260 224.000 1.000
41.320 224.000 1.000
41.380 213.000 1.000
41.440 202.000 1.000
41.500 231.000 1.000
41.560 200.000 1.000
41.620 215.000 1.000
41.680 204.000 1.000
41.740 198.000 1.000
41.800 223.000 1.000
41.860 246.000 1.000
41.920 264.000 1.000
41.980 248.000 1.000
42.040 264.000 1.000
42.100 323.000 1.000
42.160 387.000 1.000
42.220 610.000 1.000
42.280 861.000 1.000
42.340 1159.000 1.000
42.400 1176.000 1.000
42.460 979.000 1.000
42.520 735.000 1.000
42.580 454.000 1.000
42.640 332.000 1.000
42.700 290.000 1.000
42.760 237.000 1.000
42.820 248.000 1.000
42.880 249.000 1.000
42.940 250.000 1.000
43.000 223.000 1.000
43.060 230.000 1.000
43.120 230.000 1.000
43.180 213.000 1.000
43.240 218.000 1.000
43.300 229.000 1.000
43.360 223.000 1.000
43.420 232.000 1.000
43.480 276.000 1.000
43.540 235.000 1.000
43.600 237.000 1.000
43.660 219.000 1.000
43.720 201.000 1.000
43.780 234.000 1.000
43.840 225.000 1.000
43.900 243.000 1.000
43.960 238.000 1.000
44.020 219.000 1.000
44.080 218.000 1.000
44.140 209.000 1.000
44.200 222.000 1.000
44.260 221.000 1.000
44.320 205.000 1.000
44.380 206.000 1.000
44.440 204.000 1.000
44.500 204.000 1.000
44.560 198.000 1.000
44.620 222.000 1.000
44.680 205.000 1.000
44.740 193.000 1.000
44.800 210.000 1.000
44.860 211.000 1.000
44.920 216.000 1.000
44.980 196.000 1.000
45.040 211.000 1.000
45.100 182.000 1.000
45.160 175.000 1.000
45.220 202.000 1.000
45.280 228.000 1.000
45.340 182.000 1.000
45.400 194.000 1.000
45.460 185.000 1.000
45.520 192.000 1.000
45.580 191.000 1.000
45.640 178.000 1.000
45.700 179.000 1.000
45.760 192.000 1.000
45.820 210.000 1.000
45.880 188.000 1.000
45.940 182.000 1.000
46.000 187.000 1.000
46.060 184.000 1.000
46.120 186.000 1.000
46.180 185.000 1.000
46.240 174.000 1.000
46.300 154.000 1.000
46.360 190.000 1.000
46.420 199.000 1.000
46.480 203.000 1.000
46.540 163.000 1.000
46.600 190.000 1.000
46.660 179.000 1.000
46.720 196.000 1.000
46.780 182.000 1.000
46.840 198.000 1.000
46.900 201.000 1.000
46.960 186.000 1.000
47.020 207.000 1.000
47.080 164.000 1.000
47.140 194.000 1.000
47.200 184.000 1.000
47.260 172.000 1.000
47.320 201.000 1.000
47.380 226.000 1.000
47.440 199.000 1.000
47.500 193.000 1.000
47.560 194.000 1.000
47.620 193.000 1.000
47.680 171.000 1.000
47.740 167.000 1.000
47.800 159.000 1.000
47.860 191.000 1.000
47.920 195.000 1.000
47.980 204.000 1.000
48.040 189.000 1.000
48.100 173.000 1.000
48.160 167.000 1.000
48.220 177.000 1.000
48.280 171.000 1.000
48.340 159.000 1.000
48.400 179.000 1.000
48.460 186.000 1.000
48.520 189.000 1.000
48.580 199.000 1.000
48.640 173.000 1.000
48.700 195.000 1.000
48.760 189.000 1.000
48.820 189.000 1.000
48.880 174.000 1.000
48.940 187.000 1.000
49.000 178.000 1.000
49.060 183.000 1.000
49.120 169.000 1.000
49.180 180.000 1.000
49.240 197.000 1.000
49.300 176.000 1.000
49.360 178.000 1.000
49.420 167.000 1.000
49.480 170.000 1.000
49.540 206.000 1.000
49.600 184.000 1.000
49.660 180.000 1.000
49.720 179.000 1.000
49.780 182.000 1.000
49.840 180.000 1.000
49.900 169.000 1.000
49.960 192.000 1.000
50.020 155.000 1.000
50.080 170.000 1.000
50.140 186.000 1.000
50.200 187.000 1.000
50.260 186.000 1.000
50.320 189.000 1.000
50.380 185.000 1.000
50.440 168.000 1.000
50.500 201.000 1.000
50.560 166.000 1.000
50.620 167.000 1.000
50.680 200.000 1.000
50.740 178.000 1.000
50.800 182.000 1.000
50.860 183.000 1.000
50.920 181.000 1.000
50.980 169.000 1.000
51.040 175.000 1.000
51.100 188.000 1.000
51.160 180.000 1.000
51.220 202.000 1.000
51.280 174.000 1.000
51.340 199.000 1.000
51.400 187.000 1.000
51.460 206.000 1.000
51.520 177.000 1.000
51.580 188.000 1.000
51.640 200.000 1.000
51.700 189.000 1.000
51.760 201.000 1.000
51.820 192.000 1.000
51.880 190.000 1.000
51.940 210.000 1.000
52.000 201.000 1.000
52.060 211.000 1.000
52.120 198.000 1.000
52.180 191.000 1.000
52.240 201.000 1.000
52.300 205.000 1.000
52.360 186.000 1.000
52.420 202.000 1.000
52.480 231.000 1.000
52.540 232.000 1.000
52.600 246.000 1.000
52.660 251.000 1.000
52.720 201.000 1.000
52.780 245.000 1.000
52.840 209.000 1.000
52.900 222.000 1.000
52.960 216.000 1.000
53.020 226.000 1.000
53.080 208.000 1.000
53.140 217.000 1.000
53.200 224.000 1.000
53.260 223.000 1.000
53.320 241.000 1.000
53.380 219.000 1.000
53.440 256.000 1.000
53.500 244.000 1.000
53.560 259.000 1.000
53.620 262.000 1.000
53.680 240.000 1.000
53.740 259.000 1.000
53.800 268.000 1.000
53.860 240.000 1.000
53.920 246.000 1.000
53.980 260.000 1.000
54.040 250.000 1.000
54.100 266.000 1.000
54.160 269.000 1.000
54.220 281.000 1.000
54.280 304.000 1.000
54.340 367.000 1.000
54.400 388.000 1.000
54.460 413.000 1.000
54.520 400.000 1.000
54.580 388.000 1.000
54.640 309.000 1.000
54.700 294.000 1.000
54.760 278.000 1.000
54.820 237.000 1.000
54.880 217.000 1.000
54.940 206.000 1.000
55.000 200.000 1.000
55.060 207.000 1.000
55.120 200.000 1.000
55.180 191.000 1.000
55.240 173.000 1.000
55.300 175.000 1.000
55.360 186.000 1.000
55.420 185.000 1.000
55.480 194.000 1.000
55.540 185.000 1.000
55.600 186.000 1.000
55.660 183.000 1.000
55.720 184.000 1.000
55.780 183.000 1.000
55.840 170.000 1.000
55.900 175.000 1.000
55.960 162.000 1.000
56.020 171.000 1.000
56.080 185.000 1.000
56.140 170.000 1.000
56.200 175.000 1.000
56.260 176.000 1.000
56.320 190.000 1.000
56.380 183.000 1.000
56.440 185.000 1.000
56.500 191.000 1.000
56.560 182.000 1.000
56.620 173.000 1.000
56.680 181.000 1.000
56.740 153.000 1.000
56.800 163.000 1.000
56.860 147.000 1.000
56.920 168.000 1.000
56.980 144.000 1.000
57.040 181.000 1.000
57.100 168.000 1.000
57.160 170.000 1.000
57.220 183.000 1.000
57.280 180.000 1.000
57.340 179.000 1.000
57.400 168.000 1.000
57.460 169.000 1.000
57.520 170.000 1.000
57.580 152.000 1.000
57.640 172.000 1.000
57.700 172.000 1.000
57.760 179.000 1.000
57.820 178.000 1.000
57.880 176.000 1.000
57.940 174.000 1.000
58.000 179.000 1.000
58.060 172.000 1.000
58.120 163.000 1.000
58.180 174.000 1.000
58.240 156.000 1.000
58.300 177.000 1.000
58.360 154.000 1.000
58.420 165.000 1.000
58.480 180.000 1.000
58.540 161.000 1.000
58.600 158.000 1.000
58.660 174.000 1.000
58.720 170.000 1.000
58.780 173.000 1.000
58.840 166.000 1.000
58.900 178.000 1.000
58.960 180.000 1.000
59.020 176.000 1.000
59.080 178.000 1.000
59.140 188.000 1.000
59.200 169.000 1.000
59.260 168.000 1.000
59.320 172.000 1.000
59.380 166.000 1.000
59.440 160.000 1.000
59.500 182.000 1.000
59.560 159.000 1.000
59.620 180.000 1.000
59.680 169.000 1.000
59.740 162.000 1.000
59.800 172.000 1.000
59.860 167.000 1.000
59.920 169.000 1.000
59.980 182.000 1.000
60.040 176.000 1.000
60.100 175.000 1.000
60.160 177.000 1.000
60.220 170.000 1.000
60.280 173.000 1.000
60.340 159.000 1.000
60.400 169.000 1.000
60.460 182.000 1.000
60.520 171.000 1.000
60.580 172.000 1.000
60.640 179.000 1.000
60.700 190.000 1.000
60.760 170.000 1.000
60.820 184.000 1.000
60.880 178.000 1.000
60.940 189.000 1.000
61.000 204.000 1.000
61.060 197.000 1.000
61.120 220.000 1.000
61.180 255.000 1.000
61.240 295.000 1.000
61.300 406.000 1.000
61.360 543.000 1.000
61.420 638.000 1.000
61.480 717.000 1.000
61.540 682.000 1.000
61.600 606.000 1.000
61.660 537.000 1.000
61.720 392.000 1.000
61.780 307.000 1.000
61.840 284.000 1.000
61.900 244.000 1.000
61.960 204.000 1.000
62.020 204.000 1.000
62.080 192.000 1.000
62.140 193.000 1.000
62.200 213.000 1.000
62.260 180.000 1.000
62.320 175.000 1.000
62.380 165.000 1.000
62.440 174.000 1.000
62.500 181.000 1.000
62.560 178.000 1.000
62.620 165.000 1.000
62.680 152.000 1.000
62.740 155.000 1.000
62.800 158.000 1.000
62.860 157.000 1.000
62.920 159.000 1.000
62.980 160.000 1.000
63.040 183.000 1.000
63.100 167.000 1.000
63.160 177.000 1.000
63.220 167.000 1.000
63.280 184.000 1.000
63.340 169.000 1.000
63.400 154.000 1.000
63.460 161.000 1.000
63.520 174.000 1.000
63.580 147.000 1.000
63.640 165.000 1.000
63.700 175.000 1.000
63.760 185.000 1.000
63.820 175.000 1.000
63.880 171.000 1.000
63.940 153.000 1.000
64.000 161.000 1.000
64.060 169.000 1.000
64.120 165.000 1.000
64.180 177.000 1.000
64.240 154.000 1.000
64.300 167.000 1.000
64.360 161.000 1.000
64.420 169.000 1.000
64.480 146.000 1.000
64.540 168.000 1.000
64.600 145.000 1.000
64.660 180.000 1.000
64.720 152.000 1.000
64.780 173.000 1.000
64.840 157.000 1.000
64.900 173.000 1.000
64.960 161.000 1.000
65.020 156.000 1.000
65.080 136.000 1.000
65.140 156.000 1.000
65.200 152.000 1.000
65.260 157.000 1.000
65.320 158.000 1.000
65.380 169.000 1.000
65.440 159.000 1.000
65.500 161.000 1.000
65.560 138.000 1.000
65.620 168.000 1.000
65.680 169.000 1.000
65.740 147.000 1.000
65.800 164.000 1.000
65.860 166.000 1.000
65.920 172.000 1.000
65.980 142.000 1.000
66.040 165.000 1.000
66.100 153.000 1.000
66.160 144.000 1.000
66.220 150.000 1.000
66.280 157.000 1.000
66.340 146.000 1.000
66.400 160.000 1.000
66.460 158.000 1.000
66.520 150.000 1.000
66.580 155.000 1.000
66.640 148.000 1.000
66.700 150.000 1.000
66.760 162.000 1.000
66.820 139.000 1.000
66.880 148.000 1.000
66.940 144.000 1.000
67.000 158.000 1.000
67.060 167.000 1.000
67.120 160.000 1.000
67.180 165.000 1.000
67.240 152.000 1.000
67.300 139.000 1.000
67.360 161.000 1.000
67.420 160.000 1.000
67.480 158.000 1.000
67.540 146.000 1.000
67.600 162.000 1.000
67.660 157.000 1.000
67.720 149.000 1.000
67.780 148.000 1.000
67.840 164.000 1.000
67.900 183.000 1.000
67.960 135.000 1.000
68.020 165.000 1.000
68.080 146.000 1.000
68.140 150.000 1.000
68.200 157.000 1.000
68.260 162.000 1.000
68.320 149.000 1.000
68.380 151.000 1.000
68.440 144.000 1.000
68.500 147.000 1.000
68.560 162.000 1.000
68.620 144.000 1.000
68.680 154.000 1.000
68.740 141.000 1.000
68.800 158.000 1.000
68.860 168.000 1.000
68.920 157.000 1.000
68.980 166.000 1.000
69.040 144.000 1.000
69.100 156.000 1.000
69.160 152.000 1.000
69.220 149.000 1.000
69.280 170.000 1.000
69.340 168.000 1.000
69.400 154.000 1.000
69.460 158.000 1.000
69.520 176.000 1.000
69.580 157.000 1.000
69.640 161.000 1.000
69.700 153.000 1.000
69.760 163.000 1.000
69.820 151.000 1.000
69.880 172.000 1.000
69.940 162.000 1.000
70.000 172.000 1.000
70.060 142.000 1.000
70.120 148.000 1.000
70.180 157.000 1.000
70.240 144.000 1.000
70.300 145.000 1.000
70.360 147.000 1.000
70.420 147.000 1.000
70.480 145.000 1.000
70.540 155.000 1.000
70.600 151.000 1.000
70.660 148.000 1.000
70.720 147.000 1.000
70.780 149.000 1.000
70.840 151.000 1.000
70.900 151.000 1.000
70.960 164.000 1.000
71.020 168.000 1.000
71.080 163.000 1.000
71.140 141.000 1.000
71.200 159.000 1.000
71.260 144.000 1.000
71.320 155.000 1.000
71.380 138.000 1.000
71.440 169.000 1.000
71.500 183.000 1.000
71.560 150.000 1.000
71.620 167.000 1.000
71.680 165.000 1.000
71.740 140.000 1.000
71.800 152.000 1.000
71.860 152.000 1.000
71.920 164.000 1.000
71.980 158.000 1.000
72.040 146.000 1.000
72.100 187.000 1.000
72.160 160.000 1.000
72.220 154.000 1.000
72.280 158.000 1.000
72.340 151.000 1.000
72.400 153.000 1.000
72.460 185.000 1.000
72.520 174.000 1.000
72.580 164.000 1.000
72.640 177.000 1.000
72.700 168.000 1.000
72.760 162.000 1.000
72.820 160.000 1.000
72.880 179.000 1.000
72.940 152.000 1.000
73.000 170.000 1.000
73.060 165.000 1.000
73.120 181.000 1.000
73.180 195.000 1.000
73.240 214.000 1.000
73.300 202.000 1.000
73.360 230.000 1.000
73.420 277.000 1.000
73.480 326.000 1.000
73.540 388.000 1.000
73.600 436.000 1.000
73.660 448.000 1.000
73.720 409.000 1.000
73.780 420.000 1.000
73.840 379.000 1.000
73.900 320.000 1.000
73.960 282.000 1.000
74.020 220.000 1.000
74.080 208.000 1.000
74.140 175.000 1.000
74.200 177.000 1.000
74.260 190.000 1.000
74.320 158.000 1.000
74.380 185.000 1.000
74.440 173.000 1.000
74.500 163.000 1.000
74.560 158.000 1.000
74.620 159.000 1.000
74.680 158.000 1.000
74.740 159.000 1.000
74.800 158.000 1.000
74.860 136.000 1.000
74.920 166.000 1.000
74.980 160.000 1.000
75.040 152.000 1.000
75.100 157.000 1.000
75.160 157.000 1.000
75.220 161.000 1.000
75.280 131.000 1.000
75.340 151.000 1.000
75.400 159.000 1.000
75.460 181.000 1.000
75.520 158.000 1.000
75.580 161.000 1.000
75.640 167.000 1.000
75.700 160.000 1.000
75.760 169.000 1.000
75.820 172.000 1.000
75.880 142.000 1.000
75.940 150.000 1.000
76.000 171.000 1.000
76.060 165.000 1.000
76.120 165.000 1.000
76.180 162.000 1.000
76.240 144.000 1.000
76.300 158.000 1.000
76.360 152.000 1.000
76.420 158.000 1.000
76.480 178.000 1.000
76.540 159.000 1.000
76.600 136.000 1.000
76.660 159.000 1.000
76.720 149.000 1.000
76.780 160.000 1.000
76.840 148.000 1.000
76.900 152.000 1.000
76.960 178.000 1.000
77.020 162.000 1.000
77.080 161.000 1.000
77.140 158.000 1.000
77.200 155.000 1.000
77.260 189.000 1.000
77.320 169.000 1.000
77.380 180.000 1.000
77.440 235.000 1.000
77.500 202.000 1.000
77.560 205.000 1.000
77.620 198.000 1.000
77.680 199.000 1.000
77.740 205.000 1.000
77.800 199.000 1.000
77.860 177.000 1.000
77.920 166.000 1.000
77.980 156.000 1.000
78.040 149.000 1.000
78.100 154.000 1.000
78.160 149.000 1.000
78.220 163.000 1.000
78.280 151.000 1.000
78.340 151.000 1.000
78.400 137.000 1.000
78.460 155.000 1.000
78.520 156.000 1.000
78.580 156.000 1.000
78.640 163.000 1.000
78.700 163.000 1.000
78.760 149.000 1.000
78.820 157.000 1.000
78.880 139.000 1.000
78.940 143.000 1.000
79.000 146.000 1.000
79.060 155.000 1.000
79.120 128.000 1.000
79.180 146.000 1.000
79.240 131.000 1.000
79.300 160.000 1.000
79.360 151.000 1.000
79.420 148.000 1.000
79.480 165.000 1.000
79.540 135.000 1.000
79.600 153.000 1.000
79.660 142.000 1.000
79.720 144.000 1.000
79.780 138.000 1.000
79.840 158.000 1.000
79.900 133.000 1.000
79.960 155.000 1.000
80.020 142.000 1.000
80.080 153.000 1.000
80.140 143.000 1.000
80.200 143.000 1.000
80.260 131.000 1.000
80.320 148.000 1.000
80.380 137.000 1.000
80.440 131.000 1.000
80.500 142.000 1.000
80.560 152.000 1.000
80.620 128.000 1.000
80.680 136.000 1.000
80.740 152.000 1.000
80.800 135.000 1.000
80.860 150.000 1.000
80.920 148.000 1.000
80.980 133.000 1.000
81.040 139.000 1.000
81.100 155.000 1.000
81.160 150.000 1.000
81.220 133.000 1.000
81.280 140.000 1.000
81.340 142.000 1.000
81.400 143.000 1.000
81.460 142.000 1.000
81.520 147.000 1.000
81.580 140.000 1.000
81.640 153.000 1.000
81.700 135.000 1.000
81.760 149.000 1.000
81.820 167.000 1.000
81.880 146.000 1.000
81.940 127.000 1.000
82.000 145.000 1.000
82.060 156.000 1.000
82.120 155.000 1.000
82.180 152.000 1.000
82.240 149.000 1.000
82.300 141.000 1.000
82.360 147.000 1.000
82.420 163.000 1.000
82.480 140.000 1.000
82.540 134.000 1.000
82.600 136.000 1.000
82.660 129.000 1.000
82.720 128.000 1.000
82.780 142.000 1.000
82.840 154.000 1.000
82.900 158.000 1.000
82.960 135.000 1.000
83.020 153.000 1.000
83.080 130.000 1.000
83.140 128.000 1.000
83.200 156.000 1.000
83.260 156.000 1.000
83.320 156.000 1.000
83.380 151.000 1.000
83.440 151.000 1.000
83.500 146.000 1.000
83.560 125.000 1.000
83.620 136.000 1.000
83.680 127.000 1.000
83.740 146.000 1.000
83.800 160.000 1.000
83.860 130.000 1.000
83.920 168.000 1.000
83.980 148.000 1.000
84.040 141.000 1.000
84.100 144.000 1.000
84.160 154.000 1.000
84.220 160.000 1.000
84.280 143.000 1.000
84.340 125.000 1.000
84.400 137.000 1.000
84.460 169.000 1.000
84.520 143.000 1.000
84.580 157.000 1.000
84.640 140.000 1.000
84.700 130.000 1.000
84.760 154.000 1.000
84.820 140.000 1.000
84.880 155.000 1.000
84.940 144.000 1.000
85.000 144.000 1.000
85.060 146.000 1.000
85.120 159.000 1.000
85.180 156.000 1.000
85.240 152.000 1.000
85.300 141.000 1.000
85.360 138.000 1.000
85.420 149.000 1.000
85.480 159.000 1.000
85.540 142.000 1.000
85.600 139.000 1.000
85.660 155.000 1.000
85.720 147.000 1.000
85.780 144.000 1.000
85.840 157.000 1.000
85.900 161.000 1.000
85.960 162.000 1.000
86.020 144.000 1.000
86.080 154.000 1.000
86.140 133.000 1.000
86.200 143.000 1.000
86.260 166.000 1.000
86.320 152.000 1.000
86.380 159.000 1.000
86.440 155.000 1.000
86.500 155.000 1.000
86.560 166.000 1.000
86.620 169.000 1.000
86.680 159.000 1.000
86.740 155.000 1.000
86.800 150.000 1.000
86.860 140.000 1.000
86.920 150.000 1.000
86.980 154.000 1.000
87.040 146.000 1.000
87.100 137.000 1.000
87.160 162.000 1.000
87.220 131.000 1.000
87.280 140.000 1.000
87.340 142.000 1.000
87.400 141.000 1.000
87.460 130.000 1.000
87.520 137.000 1.000
87.580 152.000 1.000
87.640 126.000 1.000
87.700 128.000 1.000
87.760 124.000 1.000
87.820 126.000 1.000
87.880 125.000 1.000
87.940 140.000 1.000
88.000 143.000 1.000
88.060 135.000 1.000
88.120 124.000 1.000
88.180 148.000 1.000
88.240 138.000 1.000
88.300 157.000 1.000
88.360 121.000 1.000
88.420 148.000 1.000
88.480 136.000 1.000
88.540 130.000 1.000
88.600 138.000 1.000
88.660 136.000 1.000
88.720 117.000 1.000
88.780 129.000 1.000
88.840 136.000 1.000
88.900 142.000 1.000
88.960 130.000 1.000
89.020 146.000 1.000
89.080 135.000 1.000
89.140 131.000 1.000
89.200 146.000 1.000
89.260 139.000 1.000
89.320 135.000 1.000
89.380 139.000 1.000
89.440 146.000 1.000
89.500 126.000 1.000
89.560 136.000 1.000
89.620 146.000 1.000
89.680 136.000 1.000
89.740 147.000 1.000
89.800 133.000 1.000
89.860 134.000 1.000
89.920 140.000 1.000
89.980 122.000 1.000
90.000 125.000 1.000
*RAS_INT_END
*RAS_DATA_END