File: Lab/XRD/20170906/cu2o_010-4-1122-1.ras
*RAS_DATA_START
*RAS_HEADER_START
*CORR_POS_DB_NAME "DTEX_11112016"
*CORR_POS_GONIO_RADIUS ""
*CORR_POS_NODE_INDEX01 ""
*CORR_POS_NODE_INDEX02 ""
*CORR_POS_NODE_INDEX03 ""
*CORR_POS_NODE_INDEX04 ""
*CORR_POS_NODE_INDEX05 ""
*CORR_POS_NODE_INDEX06 ""
*CORR_POS_NODE_INDEX07 ""
*CORR_POS_NODE_INDEX08 ""
*CORR_POS_NODE_INDEX09 ""
*CORR_POS_NODE_INDEX10 ""
*CORR_POS_NODE_INDEX11 ""
*CORR_POS_NODE_LABEL01 "Si(111)"
*CORR_POS_NODE_LABEL02 "Si(220)"
*CORR_POS_NODE_LABEL03 "Si(311)"
*CORR_POS_NODE_LABEL04 "Si(400)"
*CORR_POS_NODE_LABEL05 "Si(331)"
*CORR_POS_NODE_LABEL06 "Si(422)"
*CORR_POS_NODE_LABEL07 "Si(511)"
*CORR_POS_NODE_LABEL08 "Si(440)"
*CORR_POS_NODE_LABEL09 "Si(531)"
*CORR_POS_NODE_LABEL10 "Si(620)"
*CORR_POS_NODE_LABEL11 "Si(533)"
*CORR_POS_NODE_POS_CALC01 "28.4137"
*CORR_POS_NODE_POS_CALC02 "47.2707"
*CORR_POS_NODE_POS_CALC03 "56.0883"
*CORR_POS_NODE_POS_CALC04 "69.0934"
*CORR_POS_NODE_POS_CALC05 "76.3385"
*CORR_POS_NODE_POS_CALC06 "87.9915"
*CORR_POS_NODE_POS_CALC07 "94.9137"
*CORR_POS_NODE_POS_CALC08 "106.67"
*CORR_POS_NODE_POS_CALC09 "114.054"
*CORR_POS_NODE_POS_CALC10 "127.508"
*CORR_POS_NODE_POS_CALC11 "136.858"
*CORR_POS_NODE_POS_MEAS01 "28.3712"
*CORR_POS_NODE_POS_MEAS02 "47.2304"
*CORR_POS_NODE_POS_MEAS03 "56.0465"
*CORR_POS_NODE_POS_MEAS04 "69.0523"
*CORR_POS_NODE_POS_MEAS05 "76.2993"
*CORR_POS_NODE_POS_MEAS06 "87.9512"
*CORR_POS_NODE_POS_MEAS07 "94.8772"
*CORR_POS_NODE_POS_MEAS08 "106.636"
*CORR_POS_NODE_POS_MEAS09 "114.028"
*CORR_POS_NODE_POS_MEAS10 "127.48"
*CORR_POS_NODE_POS_MEAS11 "136.839"
*CORR_POS_OPT_ATTR "集中法"
*CORR_POS_PARAM_MU ""
*CORR_POS_PARAM_PL ""
*CORR_POS_SEMODEL_TYPE "0"
*CORR_POS_STANDARD_TYPE ""
*CORR_POS_VALUE_ANALYZER "None"
*CORR_POS_VALUE_CMONO "None"
*CORR_POS_VALUE_IMONO "None"
*CORR_POS_VALUE_IS "0.625deg"
*CORR_POS_VALUE_ISL "10.0mm"
*CORR_POS_VALUE_ISOLLER "2.5deg"
*CORR_POS_VALUE_RS1 "13.0mm"
*CORR_POS_VALUE_RS2 "13.0mm"
*CORR_POS_VALUE_RSOLLER "2.5deg"
*CORR_POS_XG_FOCUS_L ""
*CORR_POS_XG_WAVE_TYPE ""
*CORR_POS_XG_WAVE_VALUE ""
*DISP_FMT_X "%.2f"
*DISP_FMT_Y "%.0f"
*DISP_FULLSCALE "17755.2000000000"
*DISP_LINE_COLOR "255.0000000000"
*DISP_LINE_STYLE "0.0000000000"
*DISP_LINE_WIDTH "0.2500000000"
*DISP_NOTE "Collected Data-1"
*DISP_OFFSET_Y "0.0000000000"
*DISP_PEAKSEARCH_UNIT_Y "COUNTS"
*DISP_RANGE_BOTTOM "0.0000000000"
*DISP_RANGE_LEFT "20.0000000000"
*DISP_RANGE_LOGCUTOFF "0.0100000000"
*DISP_RANGE_RIGHT "90.0000000000"
*DISP_RANGE_TOP "17755.2000000000"
*DISP_SCALE_MODE_Y "0.0000000000"
*DISP_TAB_NAME "Theta/2-Theta"
*DISP_TITLE_Y "Intensity"
*DISP_UNIT_Y "COUNTS"
*DISP_WINDOW_NAME "MSG_MACROENGINE"
*FILE_COMMENT " "
*FILE_MD5 ""
*FILE_MEMO " "
*FILE_OPERATOR "MiniFlex"
*FILE_PART_ID "MEAS_PBEA_00223"
*FILE_SAMPLE "cu2o_010"
*FILE_TYPE "RAS_RAW"
*FILE_USERGROUP "System User"
*FILE_VERSION "1.0000000000"
*HW_ATTACHMENT_ID "ATT1031"
*HW_ATTACHMENT_NAME "6サンプルチェンジャ|ASC-6"
*HW_COUNTER_ID-0 "CUT0025"
*HW_COUNTER_ID-1 "CUT0020"
*HW_COUNTER_ID-2 "CUT0020"
*HW_COUNTER_ID-3 "CMC0021"
*HW_COUNTER_NAME-0 "D/teX Ultra|D/teX Ultra"
*HW_COUNTER_NAME-1 "None|None"
*HW_COUNTER_NAME-2 "None|None"
*HW_COUNTER_NAME-3 "検出器モノクロメータ|Detector monochromator"
*HW_COUNTER_SELECT_NAME "D/teX Ultra|D/teX Ultra"
*HW_GONIOMETER_ID "GON0070"
*HW_GONIOMETER_NAME "MiniFlex 300/600|MiniFlex 300/600"
*HW_GONIOMETER_RADIUS-0 "79.0"
*HW_GONIOMETER_RADIUS-1 "91.5"
*HW_GONIOMETER_RADIUS-2 "150.0"
*HW_GONIOMETER_RADIUS-3 "0"
*HW_GONIOMETER_RADIUS-4 "103.4"
*HW_GONIOMETER_RADIUS-5 "150.0"
*HW_GONIOMETER_RADIUS-6 "46.6"
*HW_GONIOMETER_RADIUS-7 "160.0"
*HW_I_OPT_ID-0 "ISL0021"
*HW_I_OPT_ID-1 "ISO0021"
*HW_I_OPT_NAME-0 "発散スリット|Divergence slit"
*HW_I_OPT_NAME-1 "入射平行スリット|Incident parallel slit"
*HW_R_ATTENUATER_AUTOMODE "0"
*HW_R_OPT_ID-0 "RSS0021"
*HW_R_OPT_ID-1 "RSO0021"
*HW_R_OPT_ID-2 "RRS0021"
*HW_R_OPT_NAME-0 "散乱スリット|Scattering slit"
*HW_R_OPT_NAME-1 "受光平行スリット|Receiving soller slit"
*HW_R_OPT_NAME-2 "受光スリット|Receiving slit"
*HW_SAMPLE_HOLDER_ID "SMP0000"
*HW_SAMPLE_HOLDER_NAME "無し|None"
*HW_XG_CURRENT_MAX "15"
*HW_XG_CURRENT_MIN "2"
*HW_XG_CURRENT_RESOLUTION "1"
*HW_XG_CURRENT_UNIT "mA"
*HW_XG_FOCUS "1mm x 10mm"
*HW_XG_FOCUS_TYPE "Normal"
*HW_XG_ID "1060"
*HW_XG_NAME "300W/600W 封入管-B|300W/600W Sealed tube-B"
*HW_XG_TARGET_ATOMIC_NUMBER "29.0000000000"
*HW_XG_TARGET_NAME "Cu"
*HW_XG_TYPE "Hermetic"
*HW_XG_VOLTAGE_MAX "40"
*HW_XG_VOLTAGE_MIN "20"
*HW_XG_VOLTAGE_RESOLUTION "1"
*HW_XG_VOLTAGE_UNIT "kV"
*HW_XG_WATT_MAX "1"
*HW_XG_WATT_UNIT "kW"
*HW_XG_WAVE_LENGTH_ALPHA1 "1.540593"
*HW_XG_WAVE_LENGTH_ALPHA2 "1.544414"
*HW_XG_WAVE_LENGTH_BETA "1.392250"
*MEAS_COND_AXIS_NAME-0 "Theta/2-Theta"
*MEAS_COND_AXIS_NAME-1 "Spin"
*MEAS_COND_AXIS_NAME-2 "Change"
*MEAS_COND_AXIS_NAME-3 "Soller(inc.)"
*MEAS_COND_AXIS_NAME-4 "IHS"
*MEAS_COND_AXIS_NAME-5 "DS"
*MEAS_COND_AXIS_NAME-6 "SS"
*MEAS_COND_AXIS_NAME-7 "Soller(rec.)"
*MEAS_COND_AXIS_NAME-8 "RS"
*MEAS_COND_AXIS_NAME-9 "Filter"
*MEAS_COND_AXIS_NAME-10 "Monochromator"
*MEAS_COND_AXIS_NAME-11 "PHA"
*MEAS_COND_AXIS_NAME_INTERNAL-0 "TwoThetaTheta"
*MEAS_COND_AXIS_NAME_INTERNAL-1 "Spin"
*MEAS_COND_AXIS_NAME_INTERNAL-2 "Change"
*MEAS_COND_AXIS_NAME_INTERNAL-3 "IncidentSollerSlit"
*MEAS_COND_AXIS_NAME_INTERNAL-4 "IncidentAxdSlit"
*MEAS_COND_AXIS_NAME_INTERNAL-5 "IncidentSlitBox"
*MEAS_COND_AXIS_NAME_INTERNAL-6 "ReceivingSlitBox1"
*MEAS_COND_AXIS_NAME_INTERNAL-7 "ReceivingSollerSlit"
*MEAS_COND_AXIS_NAME_INTERNAL-8 "ReceivingSlitBox2"
*MEAS_COND_AXIS_NAME_INTERNAL-9 "Filter"
*MEAS_COND_AXIS_NAME_INTERNAL-10 "CounterMonochromator"
*MEAS_COND_AXIS_NAME_INTERNAL-11 "PHA"
*MEAS_COND_AXIS_NAME_MAGICNO-0 "268632064.0000000000"
*MEAS_COND_AXIS_NAME_MAGICNO-1 "16842752.0000000000"
*MEAS_COND_AXIS_NAME_MAGICNO-2 "16842752.0000000000"
*MEAS_COND_AXIS_NAME_MAGICNO-3 "20971521.0000000000"
*MEAS_COND_AXIS_NAME_MAGICNO-4 "22020097.0000000000"
*MEAS_COND_AXIS_NAME_MAGICNO-5 "22020097.0000000000"
*MEAS_COND_AXIS_NAME_MAGICNO-6 "23068673.0000000000"
*MEAS_COND_AXIS_NAME_MAGICNO-7 "20971521.0000000000"
*MEAS_COND_AXIS_NAME_MAGICNO-8 "23068673.0000000000"
*MEAS_COND_AXIS_NAME_MAGICNO-9 "20971521.0000000000"
*MEAS_COND_AXIS_NAME_MAGICNO-10 "20971521.0000000000"
*MEAS_COND_AXIS_NAME_MAGICNO-11 "0.0000000000"
*MEAS_COND_AXIS_OFFSET-0 "0.0000000000"
*MEAS_COND_AXIS_OFFSET-1 "-"
*MEAS_COND_AXIS_OFFSET-2 "-"
*MEAS_COND_AXIS_OFFSET-3 "-"
*MEAS_COND_AXIS_OFFSET-4 "-"
*MEAS_COND_AXIS_OFFSET-5 "-"
*MEAS_COND_AXIS_OFFSET-6 "-"
*MEAS_COND_AXIS_OFFSET-7 "-"
*MEAS_COND_AXIS_OFFSET-8 "-"
*MEAS_COND_AXIS_OFFSET-9 "-"
*MEAS_COND_AXIS_OFFSET-10 "-"
*MEAS_COND_AXIS_OFFSET-11 "-"
*MEAS_COND_AXIS_POSITION-0 "10.0000000000"
*MEAS_COND_AXIS_POSITION-1 "0.0000000000"
*MEAS_COND_AXIS_POSITION-2 "4.0000000000"
*MEAS_COND_AXIS_POSITION-3 "2.5deg"
*MEAS_COND_AXIS_POSITION-4 "2.0mm"
*MEAS_COND_AXIS_POSITION-5 "0.625deg"
*MEAS_COND_AXIS_POSITION-6 "13.0mm(Open)"
*MEAS_COND_AXIS_POSITION-7 "2.5deg"
*MEAS_COND_AXIS_POSITION-8 "13.0mm"
*MEAS_COND_AXIS_POSITION-9 "K-beta(x1)"
*MEAS_COND_AXIS_POSITION-10 "None"
*MEAS_COND_AXIS_POSITION-11 "41.0000000000"
*MEAS_COND_AXIS_UNIT-0 "deg"
*MEAS_COND_AXIS_UNIT-1 ""
*MEAS_COND_AXIS_UNIT-2 ""
*MEAS_COND_AXIS_UNIT-3 ""
*MEAS_COND_AXIS_UNIT-4 ""
*MEAS_COND_AXIS_UNIT-5 ""
*MEAS_COND_AXIS_UNIT-6 ""
*MEAS_COND_AXIS_UNIT-7 ""
*MEAS_COND_AXIS_UNIT-8 ""
*MEAS_COND_AXIS_UNIT-9 ""
*MEAS_COND_AXIS_UNIT-10 ""
*MEAS_COND_AXIS_UNIT-11 "div"
*MEAS_COND_CORRECTION_SLIT_COUNTERMONO "None"
*MEAS_COND_CORRECTION_SLIT_DS "0.625deg"
*MEAS_COND_CORRECTION_SLIT_FILTER "None"
*MEAS_COND_CORRECTION_SLIT_IHS "2.0mm"
*MEAS_COND_CORRECTION_SLIT_RS "13.0mm"
*MEAS_COND_CORRECTION_SLIT_SOLLER_INC "2.5deg"
*MEAS_COND_CORRECTION_SLIT_SOLLER_REC "2.5deg"
*MEAS_COND_CORRECTION_SLIT_SS "13.0mm"
*MEAS_COND_COUNTER_CNTLOSS_CORR "0.0000000000"
*MEAS_COND_COUNTER_PHABASE "41.0000000000"
*MEAS_COND_COUNTER_PHAWINDOW "14.0000000000"
*MEAS_COND_COUNTER_PHA_UNIT "div"
*MEAS_COND_COUNTER_TAUDIFF "0.2500000000"
*MEAS_COND_COUNTER_TAUINT "0.7500000000"
*MEAS_COND_IRRADIATION_MODE "OFF"
*MEAS_COND_IRRADIATION_WIDTH ""
*MEAS_COND_OPT_ATTR " "
*MEAS_COND_OPT_NAME ""
*MEAS_COND_UNSYMMETRIC_MODE "OFF"
*MEAS_COND_XG_CURRENT "15.0000000000"
*MEAS_COND_XG_VOLTAGE "40.0000000000"
*MEAS_COND_XG_WAVE_TYPE "Ka"
*MEAS_DATA_COUNT "3501.0000000000"
*MEAS_SCAN_AXIS_X "Theta/2-Theta"
*MEAS_SCAN_AXIS_X_INTERNAL "TwoThetaTheta"
*MEAS_SCAN_END_TIME "09/06/17 11:32:11"
*MEAS_SCAN_MODE "CONTINUOUS"
*MEAS_SCAN_MONITOR "0"
*MEAS_SCAN_RESOLUTION_X "0.005"
*MEAS_SCAN_SPEED "10.000"
*MEAS_SCAN_SPEED_UNIT "deg/min"
*MEAS_SCAN_SPEED_USER "10.000"
*MEAS_SCAN_START "20.0000000000"
*MEAS_SCAN_START_TIME "09/06/17 11:24:25"
*MEAS_SCAN_STEP "0.0200000000"
*MEAS_SCAN_STOP "90.0000000000"
*MEAS_SCAN_UNIT_X "deg"
*MEAS_SCAN_UNIT_Y "counts"
*SLIT_SYSTEM "0"
*RAS_HEADER_END
*RAS_INT_START
20.000 286.000 1.000
20.060 288.000 1.000
20.120 306.000 1.000
20.180 308.000 1.000
20.240 302.000 1.000
20.300 268.000 1.000
20.360 278.000 1.000
20.420 313.000 1.000
20.480 306.000 1.000
20.540 307.000 1.000
20.600 311.000 1.000
20.660 285.000 1.000
20.720 290.000 1.000
20.780 313.000 1.000
20.840 295.000 1.000
20.900 299.000 1.000
20.960 286.000 1.000
21.020 314.000 1.000
21.080 312.000 1.000
21.140 283.000 1.000
21.200 344.000 1.000
21.260 356.000 1.000
21.320 356.000 1.000
21.380 330.000 1.000
21.440 339.000 1.000
21.500 327.000 1.000
21.560 319.000 1.000
21.620 320.000 1.000
21.680 329.000 1.000
21.740 307.000 1.000
21.800 311.000 1.000
21.860 317.000 1.000
21.920 333.000 1.000
21.980 340.000 1.000
22.040 335.000 1.000
22.100 351.000 1.000
22.160 349.000 1.000
22.220 314.000 1.000
22.280 342.000 1.000
22.340 341.000 1.000
22.400 364.000 1.000
22.460 350.000 1.000
22.520 356.000 1.000
22.580 361.000 1.000
22.640 368.000 1.000
22.700 358.000 1.000
22.760 377.000 1.000
22.820 391.000 1.000
22.880 390.000 1.000
22.940 379.000 1.000
23.000 414.000 1.000
23.060 409.000 1.000
23.120 401.000 1.000
23.180 421.000 1.000
23.240 417.000 1.000
23.300 439.000 1.000
23.360 464.000 1.000
23.420 425.000 1.000
23.480 468.000 1.000
23.540 477.000 1.000
23.600 492.000 1.000
23.660 525.000 1.000
23.720 513.000 1.000
23.780 497.000 1.000
23.840 548.000 1.000
23.900 542.000 1.000
23.960 585.000 1.000
24.020 572.000 1.000
24.080 603.000 1.000
24.140 629.000 1.000
24.200 619.000 1.000
24.260 705.000 1.000
24.320 655.000 1.000
24.380 724.000 1.000
24.440 746.000 1.000
24.500 828.000 1.000
24.560 836.000 1.000
24.620 892.000 1.000
24.680 915.000 1.000
24.740 983.000 1.000
24.800 1006.000 1.000
24.860 1089.000 1.000
24.920 1141.000 1.000
24.980 1241.000 1.000
25.040 1347.000 1.000
25.100 1455.000 1.000
25.160 1480.000 1.000
25.220 1626.000 1.000
25.280 1704.000 1.000
25.340 1862.000 1.000
25.400 2080.000 1.000
25.460 2208.000 1.000
25.520 2322.000 1.000
25.580 2546.000 1.000
25.640 2785.000 1.000
25.700 2935.000 1.000
25.760 3090.000 1.000
25.820 3209.000 1.000
25.880 3414.000 1.000
25.940 3548.000 1.000
26.000 3738.000 1.000
26.060 3958.000 1.000
26.120 4262.000 1.000
26.180 4941.000 1.000
26.240 6217.000 1.000
26.300 9077.000 1.000
26.360 12804.000 1.000
26.420 14796.000 1.000
26.480 12059.000 1.000
26.540 7150.000 1.000
26.600 3775.000 1.000
26.660 2404.000 1.000
26.720 1773.000 1.000
26.780 1573.000 1.000
26.840 1354.000 1.000
26.900 1145.000 1.000
26.960 1050.000 1.000
27.020 942.000 1.000
27.080 876.000 1.000
27.140 778.000 1.000
27.200 755.000 1.000
27.260 674.000 1.000
27.320 666.000 1.000
27.380 655.000 1.000
27.440 597.000 1.000
27.500 565.000 1.000
27.560 552.000 1.000
27.620 520.000 1.000
27.680 510.000 1.000
27.740 489.000 1.000
27.800 474.000 1.000
27.860 466.000 1.000
27.920 429.000 1.000
27.980 434.000 1.000
28.040 405.000 1.000
28.100 416.000 1.000
28.160 424.000 1.000
28.220 396.000 1.000
28.280 408.000 1.000
28.340 392.000 1.000
28.400 335.000 1.000
28.460 365.000 1.000
28.520 375.000 1.000
28.580 335.000 1.000
28.640 323.000 1.000
28.700 348.000 1.000
28.760 337.000 1.000
28.820 335.000 1.000
28.880 322.000 1.000
28.940 290.000 1.000
29.000 340.000 1.000
29.060 318.000 1.000
29.120 303.000 1.000
29.180 337.000 1.000
29.240 378.000 1.000
29.300 357.000 1.000
29.360 321.000 1.000
29.420 328.000 1.000
29.480 326.000 1.000
29.540 343.000 1.000
29.600 311.000 1.000
29.660 305.000 1.000
29.720 311.000 1.000
29.780 310.000 1.000
29.840 336.000 1.000
29.900 280.000 1.000
29.960 269.000 1.000
30.020 285.000 1.000
30.080 287.000 1.000
30.140 270.000 1.000
30.200 282.000 1.000
30.260 248.000 1.000
30.320 264.000 1.000
30.380 223.000 1.000
30.440 243.000 1.000
30.500 265.000 1.000
30.560 275.000 1.000
30.620 276.000 1.000
30.680 309.000 1.000
30.740 304.000 1.000
30.800 279.000 1.000
30.860 248.000 1.000
30.920 264.000 1.000
30.980 250.000 1.000
31.040 225.000 1.000
31.100 212.000 1.000
31.160 227.000 1.000
31.220 221.000 1.000
31.280 216.000 1.000
31.340 236.000 1.000
31.400 230.000 1.000
31.460 210.000 1.000
31.520 201.000 1.000
31.580 211.000 1.000
31.640 227.000 1.000
31.700 208.000 1.000
31.760 204.000 1.000
31.820 201.000 1.000
31.880 234.000 1.000
31.940 218.000 1.000
32.000 209.000 1.000
32.060 190.000 1.000
32.120 211.000 1.000
32.180 248.000 1.000
32.240 211.000 1.000
32.300 183.000 1.000
32.360 220.000 1.000
32.420 195.000 1.000
32.480 205.000 1.000
32.540 207.000 1.000
32.600 223.000 1.000
32.660 206.000 1.000
32.720 218.000 1.000
32.780 189.000 1.000
32.840 200.000 1.000
32.900 218.000 1.000
32.960 205.000 1.000
33.020 210.000 1.000
33.080 199.000 1.000
33.140 210.000 1.000
33.200 200.000 1.000
33.260 207.000 1.000
33.320 183.000 1.000
33.380 204.000 1.000
33.440 206.000 1.000
33.500 194.000 1.000
33.560 202.000 1.000
33.620 191.000 1.000
33.680 209.000 1.000
33.740 215.000 1.000
33.800 186.000 1.000
33.860 205.000 1.000
33.920 198.000 1.000
33.980 228.000 1.000
34.040 215.000 1.000
34.100 207.000 1.000
34.160 231.000 1.000
34.220 225.000 1.000
34.280 199.000 1.000
34.340 248.000 1.000
34.400 229.000 1.000
34.460 209.000 1.000
34.520 257.000 1.000
34.580 242.000 1.000
34.640 237.000 1.000
34.700 239.000 1.000
34.760 253.000 1.000
34.820 255.000 1.000
34.880 243.000 1.000
34.940 251.000 1.000
35.000 248.000 1.000
35.060 270.000 1.000
35.120 287.000 1.000
35.180 289.000 1.000
35.240 261.000 1.000
35.300 244.000 1.000
35.360 298.000 1.000
35.420 269.000 1.000
35.480 293.000 1.000
35.540 279.000 1.000
35.600 283.000 1.000
35.660 287.000 1.000
35.720 297.000 1.000
35.780 330.000 1.000
35.840 348.000 1.000
35.900 328.000 1.000
35.960 336.000 1.000
36.020 348.000 1.000
36.080 398.000 1.000
36.140 395.000 1.000
36.200 408.000 1.000
36.260 409.000 1.000
36.320 433.000 1.000
36.380 447.000 1.000
36.440 502.000 1.000
36.500 524.000 1.000
36.560 598.000 1.000
36.620 569.000 1.000
36.680 655.000 1.000
36.740 593.000 1.000
36.800 595.000 1.000
36.860 539.000 1.000
36.920 520.000 1.000
36.980 487.000 1.000
37.040 402.000 1.000
37.100 426.000 1.000
37.160 344.000 1.000
37.220 379.000 1.000
37.280 330.000 1.000
37.340 308.000 1.000
37.400 295.000 1.000
37.460 275.000 1.000
37.520 295.000 1.000
37.580 278.000 1.000
37.640 250.000 1.000
37.700 269.000 1.000
37.760 250.000 1.000
37.820 235.000 1.000
37.880 240.000 1.000
37.940 235.000 1.000
38.000 212.000 1.000
38.060 202.000 1.000
38.120 198.000 1.000
38.180 208.000 1.000
38.240 210.000 1.000
38.300 228.000 1.000
38.360 210.000 1.000
38.420 235.000 1.000
38.480 217.000 1.000
38.540 220.000 1.000
38.600 175.000 1.000
38.660 197.000 1.000
38.720 194.000 1.000
38.780 194.000 1.000
38.840 204.000 1.000
38.900 179.000 1.000
38.960 203.000 1.000
39.020 195.000 1.000
39.080 208.000 1.000
39.140 210.000 1.000
39.200 235.000 1.000
39.260 212.000 1.000
39.320 214.000 1.000
39.380 196.000 1.000
39.440 180.000 1.000
39.500 206.000 1.000
39.560 207.000 1.000
39.620 200.000 1.000
39.680 203.000 1.000
39.740 197.000 1.000
39.800 191.000 1.000
39.860 191.000 1.000
39.920 201.000 1.000
39.980 191.000 1.000
40.040 200.000 1.000
40.100 188.000 1.000
40.160 178.000 1.000
40.220 196.000 1.000
40.280 178.000 1.000
40.340 179.000 1.000
40.400 205.000 1.000
40.460 183.000 1.000
40.520 207.000 1.000
40.580 199.000 1.000
40.640 200.000 1.000
40.700 198.000 1.000
40.760 201.000 1.000
40.820 208.000 1.000
40.880 204.000 1.000
40.940 224.000 1.000
41.000 205.000 1.000
41.060 202.000 1.000
41.120 224.000 1.000
41.180 211.000 1.000
41.240 204.000 1.000
41.300 212.000 1.000
41.360 212.000 1.000
41.420 195.000 1.000
41.480 213.000 1.000
41.540 199.000 1.000
41.600 213.000 1.000
41.660 218.000 1.000
41.720 184.000 1.000
41.780 218.000 1.000
41.840 238.000 1.000
41.900 242.000 1.000
41.960 232.000 1.000
42.020 231.000 1.000
42.080 236.000 1.000
42.140 244.000 1.000
42.200 256.000 1.000
42.260 247.000 1.000
42.320 266.000 1.000
42.380 284.000 1.000
42.440 305.000 1.000
42.500 301.000 1.000
42.560 300.000 1.000
42.620 331.000 1.000
42.680 304.000 1.000
42.740 322.000 1.000
42.800 332.000 1.000
42.860 293.000 1.000
42.920 295.000 1.000
42.980 273.000 1.000
43.040 293.000 1.000
43.100 275.000 1.000
43.160 287.000 1.000
43.220 282.000 1.000
43.280 297.000 1.000
43.340 246.000 1.000
43.400 236.000 1.000
43.460 258.000 1.000
43.520 222.000 1.000
43.580 214.000 1.000
43.640 216.000 1.000
43.700 223.000 1.000
43.760 209.000 1.000
43.820 218.000 1.000
43.880 208.000 1.000
43.940 210.000 1.000
44.000 224.000 1.000
44.060 204.000 1.000
44.120 218.000 1.000
44.180 233.000 1.000
44.240 189.000 1.000
44.300 190.000 1.000
44.360 201.000 1.000
44.420 190.000 1.000
44.480 190.000 1.000
44.540 207.000 1.000
44.600 191.000 1.000
44.660 224.000 1.000
44.720 186.000 1.000
44.780 208.000 1.000
44.840 212.000 1.000
44.900 191.000 1.000
44.960 208.000 1.000
45.020 207.000 1.000
45.080 188.000 1.000
45.140 192.000 1.000
45.200 199.000 1.000
45.260 191.000 1.000
45.320 189.000 1.000
45.380 179.000 1.000
45.440 190.000 1.000
45.500 178.000 1.000
45.560 204.000 1.000
45.620 188.000 1.000
45.680 175.000 1.000
45.740 181.000 1.000
45.800 181.000 1.000
45.860 164.000 1.000
45.920 180.000 1.000
45.980 183.000 1.000
46.040 188.000 1.000
46.100 187.000 1.000
46.160 193.000 1.000
46.220 180.000 1.000
46.280 193.000 1.000
46.340 193.000 1.000
46.400 186.000 1.000
46.460 158.000 1.000
46.520 185.000 1.000
46.580 176.000 1.000
46.640 178.000 1.000
46.700 177.000 1.000
46.760 174.000 1.000
46.820 162.000 1.000
46.880 188.000 1.000
46.940 161.000 1.000
47.000 174.000 1.000
47.060 174.000 1.000
47.120 171.000 1.000
47.180 203.000 1.000
47.240 158.000 1.000
47.300 193.000 1.000
47.360 196.000 1.000
47.420 204.000 1.000
47.480 180.000 1.000
47.540 165.000 1.000
47.600 150.000 1.000
47.660 168.000 1.000
47.720 179.000 1.000
47.780 168.000 1.000
47.840 152.000 1.000
47.900 172.000 1.000
47.960 186.000 1.000
48.020 143.000 1.000
48.080 146.000 1.000
48.140 174.000 1.000
48.200 177.000 1.000
48.260 189.000 1.000
48.320 162.000 1.000
48.380 184.000 1.000
48.440 173.000 1.000
48.500 163.000 1.000
48.560 152.000 1.000
48.620 155.000 1.000
48.680 153.000 1.000
48.740 158.000 1.000
48.800 176.000 1.000
48.860 172.000 1.000
48.920 156.000 1.000
48.980 169.000 1.000
49.040 149.000 1.000
49.100 149.000 1.000
49.160 178.000 1.000
49.220 156.000 1.000
49.280 175.000 1.000
49.340 166.000 1.000
49.400 164.000 1.000
49.460 158.000 1.000
49.520 164.000 1.000
49.580 156.000 1.000
49.640 181.000 1.000
49.700 168.000 1.000
49.760 150.000 1.000
49.820 178.000 1.000
49.880 164.000 1.000
49.940 152.000 1.000
50.000 168.000 1.000
50.060 137.000 1.000
50.120 164.000 1.000
50.180 176.000 1.000
50.240 191.000 1.000
50.300 161.000 1.000
50.360 186.000 1.000
50.420 181.000 1.000
50.480 168.000 1.000
50.540 182.000 1.000
50.600 151.000 1.000
50.660 176.000 1.000
50.720 149.000 1.000
50.780 167.000 1.000
50.840 187.000 1.000
50.900 185.000 1.000
50.960 165.000 1.000
51.020 174.000 1.000
51.080 180.000 1.000
51.140 164.000 1.000
51.200 193.000 1.000
51.260 182.000 1.000
51.320 154.000 1.000
51.380 173.000 1.000
51.440 168.000 1.000
51.500 177.000 1.000
51.560 180.000 1.000
51.620 169.000 1.000
51.680 195.000 1.000
51.740 187.000 1.000
51.800 200.000 1.000
51.860 164.000 1.000
51.920 187.000 1.000
51.980 176.000 1.000
52.040 186.000 1.000
52.100 188.000 1.000
52.160 189.000 1.000
52.220 218.000 1.000
52.280 181.000 1.000
52.340 195.000 1.000
52.400 220.000 1.000
52.460 177.000 1.000
52.520 179.000 1.000
52.580 207.000 1.000
52.640 200.000 1.000
52.700 202.000 1.000
52.760 193.000 1.000
52.820 201.000 1.000
52.880 208.000 1.000
52.940 196.000 1.000
53.000 215.000 1.000
53.060 250.000 1.000
53.120 232.000 1.000
53.180 233.000 1.000
53.240 213.000 1.000
53.300 210.000 1.000
53.360 230.000 1.000
53.420 212.000 1.000
53.480 256.000 1.000
53.540 266.000 1.000
53.600 246.000 1.000
53.660 237.000 1.000
53.720 258.000 1.000
53.780 241.000 1.000
53.840 245.000 1.000
53.900 266.000 1.000
53.960 271.000 1.000
54.020 252.000 1.000
54.080 273.000 1.000
54.140 281.000 1.000
54.200 321.000 1.000
54.260 357.000 1.000
54.320 393.000 1.000
54.380 451.000 1.000
54.440 475.000 1.000
54.500 468.000 1.000
54.560 439.000 1.000
54.620 392.000 1.000
54.680 317.000 1.000
54.740 293.000 1.000
54.800 244.000 1.000
54.860 206.000 1.000
54.920 209.000 1.000
54.980 216.000 1.000
55.040 186.000 1.000
55.100 174.000 1.000
55.160 179.000 1.000
55.220 163.000 1.000
55.280 178.000 1.000
55.340 182.000 1.000
55.400 157.000 1.000
55.460 169.000 1.000
55.520 193.000 1.000
55.580 171.000 1.000
55.640 168.000 1.000
55.700 175.000 1.000
55.760 162.000 1.000
55.820 161.000 1.000
55.880 148.000 1.000
55.940 164.000 1.000
56.000 157.000 1.000
56.060 154.000 1.000
56.120 167.000 1.000
56.180 167.000 1.000
56.240 167.000 1.000
56.300 162.000 1.000
56.360 164.000 1.000
56.420 160.000 1.000
56.480 160.000 1.000
56.540 153.000 1.000
56.600 141.000 1.000
56.660 144.000 1.000
56.720 167.000 1.000
56.780 160.000 1.000
56.840 147.000 1.000
56.900 145.000 1.000
56.960 141.000 1.000
57.020 151.000 1.000
57.080 158.000 1.000
57.140 161.000 1.000
57.200 160.000 1.000
57.260 144.000 1.000
57.320 159.000 1.000
57.380 149.000 1.000
57.440 147.000 1.000
57.500 148.000 1.000
57.560 157.000 1.000
57.620 152.000 1.000
57.680 134.000 1.000
57.740 146.000 1.000
57.800 144.000 1.000
57.860 136.000 1.000
57.920 153.000 1.000
57.980 142.000 1.000
58.040 155.000 1.000
58.100 141.000 1.000
58.160 154.000 1.000
58.220 164.000 1.000
58.280 146.000 1.000
58.340 150.000 1.000
58.400 156.000 1.000
58.460 134.000 1.000
58.520 159.000 1.000
58.580 168.000 1.000
58.640 146.000 1.000
58.700 149.000 1.000
58.760 140.000 1.000
58.820 149.000 1.000
58.880 149.000 1.000
58.940 153.000 1.000
59.000 145.000 1.000
59.060 157.000 1.000
59.120 154.000 1.000
59.180 154.000 1.000
59.240 144.000 1.000
59.300 138.000 1.000
59.360 140.000 1.000
59.420 153.000 1.000
59.480 154.000 1.000
59.540 149.000 1.000
59.600 159.000 1.000
59.660 146.000 1.000
59.720 152.000 1.000
59.780 130.000 1.000
59.840 158.000 1.000
59.900 159.000 1.000
59.960 154.000 1.000
60.020 167.000 1.000
60.080 142.000 1.000
60.140 137.000 1.000
60.200 177.000 1.000
60.260 153.000 1.000
60.320 174.000 1.000
60.380 156.000 1.000
60.440 158.000 1.000
60.500 169.000 1.000
60.560 144.000 1.000
60.620 168.000 1.000
60.680 163.000 1.000
60.740 159.000 1.000
60.800 156.000 1.000
60.860 157.000 1.000
60.920 148.000 1.000
60.980 186.000 1.000
61.040 179.000 1.000
61.100 155.000 1.000
61.160 188.000 1.000
61.220 167.000 1.000
61.280 200.000 1.000
61.340 190.000 1.000
61.400 197.000 1.000
61.460 200.000 1.000
61.520 210.000 1.000
61.580 217.000 1.000
61.640 222.000 1.000
61.700 198.000 1.000
61.760 224.000 1.000
61.820 237.000 1.000
61.880 236.000 1.000
61.940 214.000 1.000
62.000 221.000 1.000
62.060 208.000 1.000
62.120 190.000 1.000
62.180 214.000 1.000
62.240 196.000 1.000
62.300 181.000 1.000
62.360 174.000 1.000
62.420 178.000 1.000
62.480 179.000 1.000
62.540 190.000 1.000
62.600 161.000 1.000
62.660 164.000 1.000
62.720 175.000 1.000
62.780 155.000 1.000
62.840 156.000 1.000
62.900 144.000 1.000
62.960 189.000 1.000
63.020 148.000 1.000
63.080 155.000 1.000
63.140 159.000 1.000
63.200 154.000 1.000
63.260 148.000 1.000
63.320 143.000 1.000
63.380 145.000 1.000
63.440 144.000 1.000
63.500 131.000 1.000
63.560 148.000 1.000
63.620 127.000 1.000
63.680 132.000 1.000
63.740 134.000 1.000
63.800 126.000 1.000
63.860 145.000 1.000
63.920 150.000 1.000
63.980 161.000 1.000
64.040 130.000 1.000
64.100 150.000 1.000
64.160 142.000 1.000
64.220 144.000 1.000
64.280 154.000 1.000
64.340 127.000 1.000
64.400 123.000 1.000
64.460 137.000 1.000
64.520 120.000 1.000
64.580 149.000 1.000
64.640 139.000 1.000
64.700 136.000 1.000
64.760 150.000 1.000
64.820 130.000 1.000
64.880 126.000 1.000
64.940 134.000 1.000
65.000 145.000 1.000
65.060 145.000 1.000
65.120 119.000 1.000
65.180 126.000 1.000
65.240 144.000 1.000
65.300 147.000 1.000
65.360 125.000 1.000
65.420 152.000 1.000
65.480 144.000 1.000
65.540 127.000 1.000
65.600 128.000 1.000
65.660 139.000 1.000
65.720 135.000 1.000
65.780 130.000 1.000
65.840 145.000 1.000
65.900 125.000 1.000
65.960 136.000 1.000
66.020 128.000 1.000
66.080 134.000 1.000
66.140 129.000 1.000
66.200 127.000 1.000
66.260 138.000 1.000
66.320 140.000 1.000
66.380 133.000 1.000
66.440 131.000 1.000
66.500 128.000 1.000
66.560 136.000 1.000
66.620 124.000 1.000
66.680 134.000 1.000
66.740 142.000 1.000
66.800 138.000 1.000
66.860 122.000 1.000
66.920 110.000 1.000
66.980 130.000 1.000
67.040 136.000 1.000
67.100 130.000 1.000
67.160 127.000 1.000
67.220 132.000 1.000
67.280 139.000 1.000
67.340 115.000 1.000
67.400 135.000 1.000
67.460 130.000 1.000
67.520 129.000 1.000
67.580 132.000 1.000
67.640 117.000 1.000
67.700 119.000 1.000
67.760 128.000 1.000
67.820 137.000 1.000
67.880 120.000 1.000
67.940 147.000 1.000
68.000 112.000 1.000
68.060 138.000 1.000
68.120 134.000 1.000
68.180 133.000 1.000
68.240 122.000 1.000
68.300 132.000 1.000
68.360 133.000 1.000
68.420 140.000 1.000
68.480 129.000 1.000
68.540 126.000 1.000
68.600 150.000 1.000
68.660 123.000 1.000
68.720 138.000 1.000
68.780 137.000 1.000
68.840 123.000 1.000
68.900 125.000 1.000
68.960 125.000 1.000
69.020 131.000 1.000
69.080 161.000 1.000
69.140 127.000 1.000
69.200 130.000 1.000
69.260 130.000 1.000
69.320 142.000 1.000
69.380 133.000 1.000
69.440 144.000 1.000
69.500 128.000 1.000
69.560 137.000 1.000
69.620 135.000 1.000
69.680 138.000 1.000
69.740 138.000 1.000
69.800 107.000 1.000
69.860 128.000 1.000
69.920 125.000 1.000
69.980 126.000 1.000
70.040 139.000 1.000
70.100 128.000 1.000
70.160 131.000 1.000
70.220 128.000 1.000
70.280 136.000 1.000
70.340 136.000 1.000
70.400 119.000 1.000
70.460 141.000 1.000
70.520 137.000 1.000
70.580 136.000 1.000
70.640 123.000 1.000
70.700 142.000 1.000
70.760 137.000 1.000
70.820 116.000 1.000
70.880 126.000 1.000
70.940 122.000 1.000
71.000 120.000 1.000
71.060 131.000 1.000
71.120 141.000 1.000
71.180 108.000 1.000
71.240 132.000 1.000
71.300 124.000 1.000
71.360 134.000 1.000
71.420 129.000 1.000
71.480 131.000 1.000
71.540 143.000 1.000
71.600 135.000 1.000
71.660 115.000 1.000
71.720 131.000 1.000
71.780 123.000 1.000
71.840 135.000 1.000
71.900 121.000 1.000
71.960 134.000 1.000
72.020 160.000 1.000
72.080 135.000 1.000
72.140 145.000 1.000
72.200 136.000 1.000
72.260 148.000 1.000
72.320 131.000 1.000
72.380 128.000 1.000
72.440 145.000 1.000
72.500 134.000 1.000
72.560 139.000 1.000
72.620 155.000 1.000
72.680 138.000 1.000
72.740 164.000 1.000
72.800 134.000 1.000
72.860 157.000 1.000
72.920 147.000 1.000
72.980 153.000 1.000
73.040 158.000 1.000
73.100 132.000 1.000
73.160 165.000 1.000
73.220 159.000 1.000
73.280 158.000 1.000
73.340 129.000 1.000
73.400 140.000 1.000
73.460 148.000 1.000
73.520 153.000 1.000
73.580 152.000 1.000
73.640 162.000 1.000
73.700 154.000 1.000
73.760 165.000 1.000
73.820 166.000 1.000
73.880 163.000 1.000
73.940 179.000 1.000
74.000 161.000 1.000
74.060 173.000 1.000
74.120 151.000 1.000
74.180 160.000 1.000
74.240 163.000 1.000
74.300 148.000 1.000
74.360 162.000 1.000
74.420 165.000 1.000
74.480 156.000 1.000
74.540 157.000 1.000
74.600 162.000 1.000
74.660 168.000 1.000
74.720 147.000 1.000
74.780 142.000 1.000
74.840 151.000 1.000
74.900 155.000 1.000
74.960 148.000 1.000
75.020 139.000 1.000
75.080 122.000 1.000
75.140 128.000 1.000
75.200 134.000 1.000
75.260 144.000 1.000
75.320 123.000 1.000
75.380 152.000 1.000
75.440 142.000 1.000
75.500 138.000 1.000
75.560 145.000 1.000
75.620 133.000 1.000
75.680 122.000 1.000
75.740 131.000 1.000
75.800 130.000 1.000
75.860 124.000 1.000
75.920 139.000 1.000
75.980 125.000 1.000
76.040 135.000 1.000
76.100 134.000 1.000
76.160 123.000 1.000
76.220 138.000 1.000
76.280 139.000 1.000
76.340 139.000 1.000
76.400 137.000 1.000
76.460 151.000 1.000
76.520 144.000 1.000
76.580 133.000 1.000
76.640 136.000 1.000
76.700 130.000 1.000
76.760 112.000 1.000
76.820 119.000 1.000
76.880 130.000 1.000
76.940 158.000 1.000
77.000 133.000 1.000
77.060 138.000 1.000
77.120 149.000 1.000
77.180 126.000 1.000
77.240 142.000 1.000
77.300 135.000 1.000
77.360 149.000 1.000
77.420 148.000 1.000
77.480 134.000 1.000
77.540 129.000 1.000
77.600 132.000 1.000
77.660 141.000 1.000
77.720 137.000 1.000
77.780 135.000 1.000
77.840 132.000 1.000
77.900 138.000 1.000
77.960 134.000 1.000
78.020 134.000 1.000
78.080 138.000 1.000
78.140 107.000 1.000
78.200 142.000 1.000
78.260 140.000 1.000
78.320 147.000 1.000
78.380 142.000 1.000
78.440 141.000 1.000
78.500 130.000 1.000
78.560 123.000 1.000
78.620 123.000 1.000
78.680 111.000 1.000
78.740 127.000 1.000
78.800 127.000 1.000
78.860 116.000 1.000
78.920 120.000 1.000
78.980 142.000 1.000
79.040 131.000 1.000
79.100 123.000 1.000
79.160 122.000 1.000
79.220 138.000 1.000
79.280 112.000 1.000
79.340 131.000 1.000
79.400 119.000 1.000
79.460 102.000 1.000
79.520 111.000 1.000
79.580 114.000 1.000
79.640 132.000 1.000
79.700 122.000 1.000
79.760 111.000 1.000
79.820 135.000 1.000
79.880 122.000 1.000
79.940 120.000 1.000
80.000 116.000 1.000
80.060 96.000 1.000
80.120 108.000 1.000
80.180 117.000 1.000
80.240 116.000 1.000
80.300 116.000 1.000
80.360 118.000 1.000
80.420 134.000 1.000
80.480 113.000 1.000
80.540 118.000 1.000
80.600 104.000 1.000
80.660 110.000 1.000
80.720 117.000 1.000
80.780 119.000 1.000
80.840 117.000 1.000
80.900 104.000 1.000
80.960 111.000 1.000
81.020 128.000 1.000
81.080 110.000 1.000
81.140 119.000 1.000
81.200 125.000 1.000
81.260 113.000 1.000
81.320 115.000 1.000
81.380 116.000 1.000
81.440 108.000 1.000
81.500 108.000 1.000
81.560 116.000 1.000
81.620 123.000 1.000
81.680 100.000 1.000
81.740 110.000 1.000
81.800 109.000 1.000
81.860 118.000 1.000
81.920 127.000 1.000
81.980 124.000 1.000
82.040 128.000 1.000
82.100 109.000 1.000
82.160 114.000 1.000
82.220 114.000 1.000
82.280 109.000 1.000
82.340 127.000 1.000
82.400 118.000 1.000
82.460 115.000 1.000
82.520 133.000 1.000
82.580 118.000 1.000
82.640 97.000 1.000
82.700 114.000 1.000
82.760 113.000 1.000
82.820 112.000 1.000
82.880 107.000 1.000
82.940 109.000 1.000
83.000 105.000 1.000
83.060 129.000 1.000
83.120 113.000 1.000
83.180 109.000 1.000
83.240 99.000 1.000
83.300 106.000 1.000
83.360 106.000 1.000
83.420 130.000 1.000
83.480 120.000 1.000
83.540 112.000 1.000
83.600 114.000 1.000
83.660 101.000 1.000
83.720 120.000 1.000
83.780 108.000 1.000
83.840 108.000 1.000
83.900 142.000 1.000
83.960 130.000 1.000
84.020 123.000 1.000
84.080 117.000 1.000
84.140 124.000 1.000
84.200 125.000 1.000
84.260 116.000 1.000
84.320 119.000 1.000
84.380 108.000 1.000
84.440 112.000 1.000
84.500 119.000 1.000
84.560 116.000 1.000
84.620 119.000 1.000
84.680 118.000 1.000
84.740 119.000 1.000
84.800 104.000 1.000
84.860 128.000 1.000
84.920 125.000 1.000
84.980 123.000 1.000
85.040 106.000 1.000
85.100 117.000 1.000
85.160 111.000 1.000
85.220 114.000 1.000
85.280 125.000 1.000
85.340 108.000 1.000
85.400 111.000 1.000
85.460 105.000 1.000
85.520 98.000 1.000
85.580 108.000 1.000
85.640 126.000 1.000
85.700 99.000 1.000
85.760 111.000 1.000
85.820 102.000 1.000
85.880 98.000 1.000
85.940 142.000 1.000
86.000 121.000 1.000
86.060 140.000 1.000
86.120 129.000 1.000
86.180 128.000 1.000
86.240 133.000 1.000
86.300 135.000 1.000
86.360 128.000 1.000
86.420 129.000 1.000
86.480 137.000 1.000
86.540 105.000 1.000
86.600 133.000 1.000
86.660 144.000 1.000
86.720 132.000 1.000
86.780 106.000 1.000
86.840 123.000 1.000
86.900 113.000 1.000
86.960 119.000 1.000
87.020 138.000 1.000
87.080 123.000 1.000
87.140 115.000 1.000
87.200 132.000 1.000
87.260 118.000 1.000
87.320 121.000 1.000
87.380 109.000 1.000
87.440 113.000 1.000
87.500 122.000 1.000
87.560 120.000 1.000
87.620 118.000 1.000
87.680 106.000 1.000
87.740 119.000 1.000
87.800 106.000 1.000
87.860 100.000 1.000
87.920 101.000 1.000
87.980 104.000 1.000
88.040 108.000 1.000
88.100 102.000 1.000
88.160 115.000 1.000
88.220 96.000 1.000
88.280 91.000 1.000
88.340 119.000 1.000
88.400 110.000 1.000
88.460 105.000 1.000
88.520 95.000 1.000
88.580 120.000 1.000
88.640 127.000 1.000
88.700 117.000 1.000
88.760 121.000 1.000
88.820 111.000 1.000
88.880 91.000 1.000
88.940 125.000 1.000
89.000 106.000 1.000
89.060 102.000 1.000
89.120 106.000 1.000
89.180 110.000 1.000
89.240 100.000 1.000
89.300 103.000 1.000
89.360 94.000 1.000
89.420 107.000 1.000
89.480 122.000 1.000
89.540 118.000 1.000
89.600 92.000 1.000
89.660 97.000 1.000
89.720 112.000 1.000
89.780 109.000 1.000
89.840 134.000 1.000
89.900 112.000 1.000
89.960 108.000 1.000
90.000 112.000 1.000
*RAS_INT_END
*RAS_DATA_END