File: Lab/XRD/20170223/Grafittpapir_test_glassholder-1-1256-1.ras
*RAS_DATA_START
*RAS_HEADER_START
*CORR_POS_DB_NAME "DTEX_11112016"
*CORR_POS_GONIO_RADIUS ""
*CORR_POS_NODE_INDEX01 ""
*CORR_POS_NODE_INDEX02 ""
*CORR_POS_NODE_INDEX03 ""
*CORR_POS_NODE_INDEX04 ""
*CORR_POS_NODE_INDEX05 ""
*CORR_POS_NODE_INDEX06 ""
*CORR_POS_NODE_INDEX07 ""
*CORR_POS_NODE_INDEX08 ""
*CORR_POS_NODE_INDEX09 ""
*CORR_POS_NODE_INDEX10 ""
*CORR_POS_NODE_INDEX11 ""
*CORR_POS_NODE_LABEL01 "Si(111)"
*CORR_POS_NODE_LABEL02 "Si(220)"
*CORR_POS_NODE_LABEL03 "Si(311)"
*CORR_POS_NODE_LABEL04 "Si(400)"
*CORR_POS_NODE_LABEL05 "Si(331)"
*CORR_POS_NODE_LABEL06 "Si(422)"
*CORR_POS_NODE_LABEL07 "Si(511)"
*CORR_POS_NODE_LABEL08 "Si(440)"
*CORR_POS_NODE_LABEL09 "Si(531)"
*CORR_POS_NODE_LABEL10 "Si(620)"
*CORR_POS_NODE_LABEL11 "Si(533)"
*CORR_POS_NODE_POS_CALC01 "28.4137"
*CORR_POS_NODE_POS_CALC02 "47.2707"
*CORR_POS_NODE_POS_CALC03 "56.0883"
*CORR_POS_NODE_POS_CALC04 "69.0934"
*CORR_POS_NODE_POS_CALC05 "76.3385"
*CORR_POS_NODE_POS_CALC06 "87.9915"
*CORR_POS_NODE_POS_CALC07 "94.9137"
*CORR_POS_NODE_POS_CALC08 "106.67"
*CORR_POS_NODE_POS_CALC09 "114.054"
*CORR_POS_NODE_POS_CALC10 "127.508"
*CORR_POS_NODE_POS_CALC11 "136.858"
*CORR_POS_NODE_POS_MEAS01 "28.3712"
*CORR_POS_NODE_POS_MEAS02 "47.2304"
*CORR_POS_NODE_POS_MEAS03 "56.0465"
*CORR_POS_NODE_POS_MEAS04 "69.0523"
*CORR_POS_NODE_POS_MEAS05 "76.2993"
*CORR_POS_NODE_POS_MEAS06 "87.9512"
*CORR_POS_NODE_POS_MEAS07 "94.8772"
*CORR_POS_NODE_POS_MEAS08 "106.636"
*CORR_POS_NODE_POS_MEAS09 "114.028"
*CORR_POS_NODE_POS_MEAS10 "127.48"
*CORR_POS_NODE_POS_MEAS11 "136.839"
*CORR_POS_OPT_ATTR "集中法"
*CORR_POS_PARAM_MU ""
*CORR_POS_PARAM_PL ""
*CORR_POS_SEMODEL_TYPE "0"
*CORR_POS_STANDARD_TYPE ""
*CORR_POS_VALUE_ANALYZER "None"
*CORR_POS_VALUE_CMONO "None"
*CORR_POS_VALUE_IMONO "None"
*CORR_POS_VALUE_IS "0.625deg"
*CORR_POS_VALUE_ISL "10.0mm"
*CORR_POS_VALUE_ISOLLER "2.5deg"
*CORR_POS_VALUE_RS1 "13.0mm"
*CORR_POS_VALUE_RS2 "13.0mm"
*CORR_POS_VALUE_RSOLLER "2.5deg"
*CORR_POS_XG_FOCUS_L ""
*CORR_POS_XG_WAVE_TYPE ""
*CORR_POS_XG_WAVE_VALUE ""
*DISP_FMT_X "%.2f"
*DISP_FMT_Y "%.0f"
*DISP_FULLSCALE "1974.0000000000"
*DISP_LINE_COLOR "255.0000000000"
*DISP_LINE_STYLE "0.0000000000"
*DISP_LINE_WIDTH "0.2500000000"
*DISP_NOTE "Collected Data-2"
*DISP_OFFSET_Y "0.0000000000"
*DISP_PEAKSEARCH_UNIT_Y "COUNTS"
*DISP_RANGE_BOTTOM "0.0000000000"
*DISP_RANGE_LEFT "10.0000000000"
*DISP_RANGE_LOGCUTOFF "0.0100000000"
*DISP_RANGE_RIGHT "90.0000000000"
*DISP_RANGE_TOP "1974.0000000000"
*DISP_SCALE_MODE_Y "0.0000000000"
*DISP_TAB_NAME "Theta/2-Theta"
*DISP_TITLE_Y "Intensity"
*DISP_UNIT_Y "COUNTS"
*DISP_WINDOW_NAME "MSG_MACROENGINE"
*FILE_COMMENT " "
*FILE_MD5 ""
*FILE_MEMO " "
*FILE_OPERATOR "MiniFlex"
*FILE_PART_ID "MEAS_PBEA_00223"
*FILE_SAMPLE "Grafittpapir_test_glassholder"
*FILE_TYPE "RAS_RAW"
*FILE_USERGROUP "System User"
*FILE_VERSION "1.0000000000"
*HW_ATTACHMENT_ID "ATT1031"
*HW_ATTACHMENT_NAME "6サンプルチェンジャ|ASC-6"
*HW_COUNTER_ID-0 "CUT0025"
*HW_COUNTER_ID-1 "CUT0020"
*HW_COUNTER_ID-2 "CUT0020"
*HW_COUNTER_ID-3 "CMC0021"
*HW_COUNTER_NAME-0 "D/teX Ultra|D/teX Ultra"
*HW_COUNTER_NAME-1 "None|None"
*HW_COUNTER_NAME-2 "None|None"
*HW_COUNTER_NAME-3 "検出器モノクロメータ|Detector monochromator"
*HW_COUNTER_SELECT_NAME "D/teX Ultra|D/teX Ultra"
*HW_GONIOMETER_ID "GON0070"
*HW_GONIOMETER_NAME "MiniFlex 300/600|MiniFlex 300/600"
*HW_GONIOMETER_RADIUS-0 "79.0"
*HW_GONIOMETER_RADIUS-1 "91.5"
*HW_GONIOMETER_RADIUS-2 "150.0"
*HW_GONIOMETER_RADIUS-3 "0"
*HW_GONIOMETER_RADIUS-4 "103.4"
*HW_GONIOMETER_RADIUS-5 "150.0"
*HW_GONIOMETER_RADIUS-6 "46.6"
*HW_GONIOMETER_RADIUS-7 "160.0"
*HW_I_OPT_ID-0 "ISL0021"
*HW_I_OPT_ID-1 "ISO0021"
*HW_I_OPT_NAME-0 "発散スリット|Divergence slit"
*HW_I_OPT_NAME-1 "入射平行スリット|Incident parallel slit"
*HW_R_ATTENUATER_AUTOMODE "0"
*HW_R_OPT_ID-0 "RSS0021"
*HW_R_OPT_ID-1 "RSO0021"
*HW_R_OPT_ID-2 "RRS0021"
*HW_R_OPT_NAME-0 "散乱スリット|Scattering slit"
*HW_R_OPT_NAME-1 "受光平行スリット|Receiving soller slit"
*HW_R_OPT_NAME-2 "受光スリット|Receiving slit"
*HW_SAMPLE_HOLDER_ID "SMP0000"
*HW_SAMPLE_HOLDER_NAME "無し|None"
*HW_XG_CURRENT_MAX "15"
*HW_XG_CURRENT_MIN "2"
*HW_XG_CURRENT_RESOLUTION "1"
*HW_XG_CURRENT_UNIT "mA"
*HW_XG_FOCUS "1mm x 10mm"
*HW_XG_FOCUS_TYPE "Normal"
*HW_XG_ID "1060"
*HW_XG_NAME "300W/600W 封入管-B|300W/600W Sealed tube-B"
*HW_XG_TARGET_ATOMIC_NUMBER "29.0000000000"
*HW_XG_TARGET_NAME "Cu"
*HW_XG_TYPE "Hermetic"
*HW_XG_VOLTAGE_MAX "40"
*HW_XG_VOLTAGE_MIN "20"
*HW_XG_VOLTAGE_RESOLUTION "1"
*HW_XG_VOLTAGE_UNIT "kV"
*HW_XG_WATT_MAX "1"
*HW_XG_WATT_UNIT "kW"
*HW_XG_WAVE_LENGTH_ALPHA1 "1.540593"
*HW_XG_WAVE_LENGTH_ALPHA2 "1.544414"
*HW_XG_WAVE_LENGTH_BETA "1.392250"
*MEAS_COND_AXIS_NAME-0 "Theta/2-Theta"
*MEAS_COND_AXIS_NAME-1 "Spin"
*MEAS_COND_AXIS_NAME-2 "Change"
*MEAS_COND_AXIS_NAME-3 "Soller(inc.)"
*MEAS_COND_AXIS_NAME-4 "IHS"
*MEAS_COND_AXIS_NAME-5 "DS"
*MEAS_COND_AXIS_NAME-6 "SS"
*MEAS_COND_AXIS_NAME-7 "Soller(rec.)"
*MEAS_COND_AXIS_NAME-8 "RS"
*MEAS_COND_AXIS_NAME-9 "Filter"
*MEAS_COND_AXIS_NAME-10 "Monochromator"
*MEAS_COND_AXIS_NAME-11 "PHA"
*MEAS_COND_AXIS_NAME_INTERNAL-0 "TwoThetaTheta"
*MEAS_COND_AXIS_NAME_INTERNAL-1 "Spin"
*MEAS_COND_AXIS_NAME_INTERNAL-2 "Change"
*MEAS_COND_AXIS_NAME_INTERNAL-3 "IncidentSollerSlit"
*MEAS_COND_AXIS_NAME_INTERNAL-4 "IncidentAxdSlit"
*MEAS_COND_AXIS_NAME_INTERNAL-5 "IncidentSlitBox"
*MEAS_COND_AXIS_NAME_INTERNAL-6 "ReceivingSlitBox1"
*MEAS_COND_AXIS_NAME_INTERNAL-7 "ReceivingSollerSlit"
*MEAS_COND_AXIS_NAME_INTERNAL-8 "ReceivingSlitBox2"
*MEAS_COND_AXIS_NAME_INTERNAL-9 "Filter"
*MEAS_COND_AXIS_NAME_INTERNAL-10 "CounterMonochromator"
*MEAS_COND_AXIS_NAME_INTERNAL-11 "PHA"
*MEAS_COND_AXIS_NAME_MAGICNO-0 "268632064.0000000000"
*MEAS_COND_AXIS_NAME_MAGICNO-1 "16842752.0000000000"
*MEAS_COND_AXIS_NAME_MAGICNO-2 "16842752.0000000000"
*MEAS_COND_AXIS_NAME_MAGICNO-3 "20971521.0000000000"
*MEAS_COND_AXIS_NAME_MAGICNO-4 "22020097.0000000000"
*MEAS_COND_AXIS_NAME_MAGICNO-5 "22020097.0000000000"
*MEAS_COND_AXIS_NAME_MAGICNO-6 "23068673.0000000000"
*MEAS_COND_AXIS_NAME_MAGICNO-7 "20971521.0000000000"
*MEAS_COND_AXIS_NAME_MAGICNO-8 "23068673.0000000000"
*MEAS_COND_AXIS_NAME_MAGICNO-9 "20971521.0000000000"
*MEAS_COND_AXIS_NAME_MAGICNO-10 "20971521.0000000000"
*MEAS_COND_AXIS_NAME_MAGICNO-11 "0.0000000000"
*MEAS_COND_AXIS_OFFSET-0 "0.0000000000"
*MEAS_COND_AXIS_OFFSET-1 "-"
*MEAS_COND_AXIS_OFFSET-2 "-"
*MEAS_COND_AXIS_OFFSET-3 "-"
*MEAS_COND_AXIS_OFFSET-4 "-"
*MEAS_COND_AXIS_OFFSET-5 "-"
*MEAS_COND_AXIS_OFFSET-6 "-"
*MEAS_COND_AXIS_OFFSET-7 "-"
*MEAS_COND_AXIS_OFFSET-8 "-"
*MEAS_COND_AXIS_OFFSET-9 "-"
*MEAS_COND_AXIS_OFFSET-10 "-"
*MEAS_COND_AXIS_OFFSET-11 "-"
*MEAS_COND_AXIS_POSITION-0 "10.0000000000"
*MEAS_COND_AXIS_POSITION-1 "0.0000000000"
*MEAS_COND_AXIS_POSITION-2 "1.0000000000"
*MEAS_COND_AXIS_POSITION-3 "2.5deg"
*MEAS_COND_AXIS_POSITION-4 "10.0mm"
*MEAS_COND_AXIS_POSITION-5 "0.625deg"
*MEAS_COND_AXIS_POSITION-6 "13.0mm(Open)"
*MEAS_COND_AXIS_POSITION-7 "2.5deg"
*MEAS_COND_AXIS_POSITION-8 "13.0mm"
*MEAS_COND_AXIS_POSITION-9 "K-beta(x2)"
*MEAS_COND_AXIS_POSITION-10 "None"
*MEAS_COND_AXIS_POSITION-11 "41.0000000000"
*MEAS_COND_AXIS_UNIT-0 "deg"
*MEAS_COND_AXIS_UNIT-1 ""
*MEAS_COND_AXIS_UNIT-2 ""
*MEAS_COND_AXIS_UNIT-3 ""
*MEAS_COND_AXIS_UNIT-4 ""
*MEAS_COND_AXIS_UNIT-5 ""
*MEAS_COND_AXIS_UNIT-6 ""
*MEAS_COND_AXIS_UNIT-7 ""
*MEAS_COND_AXIS_UNIT-8 ""
*MEAS_COND_AXIS_UNIT-9 ""
*MEAS_COND_AXIS_UNIT-10 ""
*MEAS_COND_AXIS_UNIT-11 "div"
*MEAS_COND_CORRECTION_SLIT_COUNTERMONO "None"
*MEAS_COND_CORRECTION_SLIT_DS "0.625deg"
*MEAS_COND_CORRECTION_SLIT_FILTER "None"
*MEAS_COND_CORRECTION_SLIT_IHS "10.0mm"
*MEAS_COND_CORRECTION_SLIT_RS "13.0mm"
*MEAS_COND_CORRECTION_SLIT_SOLLER_INC "2.5deg"
*MEAS_COND_CORRECTION_SLIT_SOLLER_REC "2.5deg"
*MEAS_COND_CORRECTION_SLIT_SS "13.0mm"
*MEAS_COND_COUNTER_CNTLOSS_CORR "0.0000000000"
*MEAS_COND_COUNTER_PHABASE "41.0000000000"
*MEAS_COND_COUNTER_PHAWINDOW "14.0000000000"
*MEAS_COND_COUNTER_PHA_UNIT "div"
*MEAS_COND_COUNTER_TAUDIFF "0.2500000000"
*MEAS_COND_COUNTER_TAUINT "0.7500000000"
*MEAS_COND_IRRADIATION_MODE "OFF"
*MEAS_COND_IRRADIATION_WIDTH ""
*MEAS_COND_OPT_ATTR " "
*MEAS_COND_OPT_NAME ""
*MEAS_COND_UNSYMMETRIC_MODE "OFF"
*MEAS_COND_XG_CURRENT "15.0000000000"
*MEAS_COND_XG_VOLTAGE "40.0000000000"
*MEAS_COND_XG_WAVE_TYPE "Ka"
*MEAS_DATA_COUNT "4001.0000000000"
*MEAS_SCAN_AXIS_X "Theta/2-Theta"
*MEAS_SCAN_AXIS_X_INTERNAL "TwoThetaTheta"
*MEAS_SCAN_END_TIME "02/23/17 12:57:38"
*MEAS_SCAN_MODE "CONTINUOUS"
*MEAS_SCAN_MONITOR "0"
*MEAS_SCAN_RESOLUTION_X "0.005"
*MEAS_SCAN_SPEED "100.000"
*MEAS_SCAN_SPEED_UNIT "deg/min"
*MEAS_SCAN_SPEED_USER "100.000"
*MEAS_SCAN_START "10.0000000000"
*MEAS_SCAN_START_TIME "02/23/17 12:56:31"
*MEAS_SCAN_STEP "0.0200000000"
*MEAS_SCAN_STOP "90.0000000000"
*MEAS_SCAN_UNIT_X "deg"
*MEAS_SCAN_UNIT_Y "counts"
*SLIT_SYSTEM "0"
*RAS_HEADER_END
*RAS_INT_START
10.000 24.000 1.000
10.060 24.000 1.000
10.120 25.000 1.000
10.180 22.000 1.000
10.240 23.000 1.000
10.300 23.000 1.000
10.360 12.000 1.000
10.420 20.000 1.000
10.480 11.000 1.000
10.540 20.000 1.000
10.600 28.000 1.000
10.660 21.000 1.000
10.720 18.000 1.000
10.780 24.000 1.000
10.840 23.000 1.000
10.900 16.000 1.000
10.960 19.000 1.000
11.020 22.000 1.000
11.080 15.000 1.000
11.140 21.000 1.000
11.200 17.000 1.000
11.260 16.000 1.000
11.320 20.000 1.000
11.380 14.000 1.000
11.440 17.000 1.000
11.500 16.000 1.000
11.560 18.000 1.000
11.620 18.000 1.000
11.680 13.000 1.000
11.740 18.000 1.000
11.800 16.000 1.000
11.860 13.000 1.000
11.920 16.000 1.000
11.980 13.000 1.000
12.040 12.000 1.000
12.100 16.000 1.000
12.160 14.000 1.000
12.220 16.000 1.000
12.280 16.000 1.000
12.340 18.000 1.000
12.400 15.000 1.000
12.460 15.000 1.000
12.520 14.000 1.000
12.580 15.000 1.000
12.640 10.000 1.000
12.700 15.000 1.000
12.760 13.000 1.000
12.820 9.000 1.000
12.880 15.000 1.000
12.940 16.000 1.000
13.000 14.000 1.000
13.060 15.000 1.000
13.120 11.000 1.000
13.180 19.000 1.000
13.240 17.000 1.000
13.300 12.000 1.000
13.360 10.000 1.000
13.420 11.000 1.000
13.480 13.000 1.000
13.540 14.000 1.000
13.600 14.000 1.000
13.660 14.000 1.000
13.720 9.000 1.000
13.780 12.000 1.000
13.840 14.000 1.000
13.900 14.000 1.000
13.960 13.000 1.000
14.020 19.000 1.000
14.080 11.000 1.000
14.140 11.000 1.000
14.200 12.000 1.000
14.260 12.000 1.000
14.320 8.000 1.000
14.380 12.000 1.000
14.440 8.000 1.000
14.500 10.000 1.000
14.560 8.000 1.000
14.620 14.000 1.000
14.680 13.000 1.000
14.740 19.000 1.000
14.800 11.000 1.000
14.860 10.000 1.000
14.920 9.000 1.000
14.980 11.000 1.000
15.040 14.000 1.000
15.100 15.000 1.000
15.160 9.000 1.000
15.220 8.000 1.000
15.280 15.000 1.000
15.340 11.000 1.000
15.400 8.000 1.000
15.460 11.000 1.000
15.520 12.000 1.000
15.580 17.000 1.000
15.640 13.000 1.000
15.700 13.000 1.000
15.760 12.000 1.000
15.820 10.000 1.000
15.880 13.000 1.000
15.940 10.000 1.000
16.000 12.000 1.000
16.060 11.000 1.000
16.120 12.000 1.000
16.180 12.000 1.000
16.240 11.000 1.000
16.300 11.000 1.000
16.360 11.000 1.000
16.420 7.000 1.000
16.480 9.000 1.000
16.540 7.000 1.000
16.600 11.000 1.000
16.660 12.000 1.000
16.720 14.000 1.000
16.780 7.000 1.000
16.840 9.000 1.000
16.900 13.000 1.000
16.960 11.000 1.000
17.020 7.000 1.000
17.080 8.000 1.000
17.140 10.000 1.000
17.200 11.000 1.000
17.260 12.000 1.000
17.320 17.000 1.000
17.380 7.000 1.000
17.440 11.000 1.000
17.500 15.000 1.000
17.560 13.000 1.000
17.620 15.000 1.000
17.680 12.000 1.000
17.740 15.000 1.000
17.800 13.000 1.000
17.860 8.000 1.000
17.920 18.000 1.000
17.980 14.000 1.000
18.040 13.000 1.000
18.100 12.000 1.000
18.160 9.000 1.000
18.220 10.000 1.000
18.280 13.000 1.000
18.340 14.000 1.000
18.400 14.000 1.000
18.460 16.000 1.000
18.520 13.000 1.000
18.580 18.000 1.000
18.640 15.000 1.000
18.700 14.000 1.000
18.760 15.000 1.000
18.820 12.000 1.000
18.880 13.000 1.000
18.940 12.000 1.000
19.000 16.000 1.000
19.060 13.000 1.000
19.120 11.000 1.000
19.180 15.000 1.000
19.240 17.000 1.000
19.300 20.000 1.000
19.360 14.000 1.000
19.420 16.000 1.000
19.480 20.000 1.000
19.540 26.000 1.000
19.600 19.000 1.000
19.660 30.000 1.000
19.720 21.000 1.000
19.780 20.000 1.000
19.840 22.000 1.000
19.900 14.000 1.000
19.960 15.000 1.000
20.020 18.000 1.000
20.080 12.000 1.000
20.140 17.000 1.000
20.200 19.000 1.000
20.260 17.000 1.000
20.320 20.000 1.000
20.380 17.000 1.000
20.440 17.000 1.000
20.500 18.000 1.000
20.560 21.000 1.000
20.620 18.000 1.000
20.680 23.000 1.000
20.740 18.000 1.000
20.800 18.000 1.000
20.860 18.000 1.000
20.920 17.000 1.000
20.980 18.000 1.000
21.040 21.000 1.000
21.100 21.000 1.000
21.160 17.000 1.000
21.220 27.000 1.000
21.280 18.000 1.000
21.340 20.000 1.000
21.400 15.000 1.000
21.460 18.000 1.000
21.520 27.000 1.000
21.580 17.000 1.000
21.640 21.000 1.000
21.700 18.000 1.000
21.760 19.000 1.000
21.820 24.000 1.000
21.880 18.000 1.000
21.940 12.000 1.000
22.000 25.000 1.000
22.060 19.000 1.000
22.120 26.000 1.000
22.180 29.000 1.000
22.240 25.000 1.000
22.300 22.000 1.000
22.360 20.000 1.000
22.420 27.000 1.000
22.480 23.000 1.000
22.540 23.000 1.000
22.600 28.000 1.000
22.660 29.000 1.000
22.720 23.000 1.000
22.780 29.000 1.000
22.840 25.000 1.000
22.900 28.000 1.000
22.960 30.000 1.000
23.020 32.000 1.000
23.080 33.000 1.000
23.140 31.000 1.000
23.200 37.000 1.000
23.260 37.000 1.000
23.320 30.000 1.000
23.380 41.000 1.000
23.440 34.000 1.000
23.500 39.000 1.000
23.560 34.000 1.000
23.620 50.000 1.000
23.680 48.000 1.000
23.740 46.000 1.000
23.800 36.000 1.000
23.860 40.000 1.000
23.920 54.000 1.000
23.980 48.000 1.000
24.040 50.000 1.000
24.100 57.000 1.000
24.160 62.000 1.000
24.220 64.000 1.000
24.280 57.000 1.000
24.340 76.000 1.000
24.400 74.000 1.000
24.460 67.000 1.000
24.520 95.000 1.000
24.580 93.000 1.000
24.640 94.000 1.000
24.700 120.000 1.000
24.760 103.000 1.000
24.820 110.000 1.000
24.880 133.000 1.000
24.940 152.000 1.000
25.000 166.000 1.000
25.060 171.000 1.000
25.120 170.000 1.000
25.180 192.000 1.000
25.240 221.000 1.000
25.300 257.000 1.000
25.360 235.000 1.000
25.420 268.000 1.000
25.480 285.000 1.000
25.540 305.000 1.000
25.600 326.000 1.000
25.660 346.000 1.000
25.720 388.000 1.000
25.780 399.000 1.000
25.840 412.000 1.000
25.900 436.000 1.000
25.960 493.000 1.000
26.020 554.000 1.000
26.080 755.000 1.000
26.140 1002.000 1.000
26.200 1361.000 1.000
26.260 1645.000 1.000
26.320 1390.000 1.000
26.380 980.000 1.000
26.440 487.000 1.000
26.500 272.000 1.000
26.560 202.000 1.000
26.620 171.000 1.000
26.680 127.000 1.000
26.740 117.000 1.000
26.800 114.000 1.000
26.860 88.000 1.000
26.920 86.000 1.000
26.980 68.000 1.000
27.040 69.000 1.000
27.100 59.000 1.000
27.160 72.000 1.000
27.220 68.000 1.000
27.280 51.000 1.000
27.340 47.000 1.000
27.400 47.000 1.000
27.460 47.000 1.000
27.520 47.000 1.000
27.580 34.000 1.000
27.640 44.000 1.000
27.700 35.000 1.000
27.760 34.000 1.000
27.820 34.000 1.000
27.880 34.000 1.000
27.940 32.000 1.000
28.000 36.000 1.000
28.060 33.000 1.000
28.120 30.000 1.000
28.180 31.000 1.000
28.240 33.000 1.000
28.300 35.000 1.000
28.360 27.000 1.000
28.420 34.000 1.000
28.480 34.000 1.000
28.540 17.000 1.000
28.600 28.000 1.000
28.660 25.000 1.000
28.720 18.000 1.000
28.780 27.000 1.000
28.840 23.000 1.000
28.900 16.000 1.000
28.960 19.000 1.000
29.020 16.000 1.000
29.080 20.000 1.000
29.140 19.000 1.000
29.200 28.000 1.000
29.260 25.000 1.000
29.320 14.000 1.000
29.380 17.000 1.000
29.440 16.000 1.000
29.500 13.000 1.000
29.560 14.000 1.000
29.620 20.000 1.000
29.680 17.000 1.000
29.740 18.000 1.000
29.800 16.000 1.000
29.860 21.000 1.000
29.920 13.000 1.000
29.980 8.000 1.000
30.040 11.000 1.000
30.100 16.000 1.000
30.160 15.000 1.000
30.220 18.000 1.000
30.280 11.000 1.000
30.340 12.000 1.000
30.400 13.000 1.000
30.460 11.000 1.000
30.520 16.000 1.000
30.580 17.000 1.000
30.640 17.000 1.000
30.700 17.000 1.000
30.760 12.000 1.000
30.820 12.000 1.000
30.880 11.000 1.000
30.940 11.000 1.000
31.000 8.000 1.000
31.060 14.000 1.000
31.120 12.000 1.000
31.180 12.000 1.000
31.240 8.000 1.000
31.300 16.000 1.000
31.360 10.000 1.000
31.420 15.000 1.000
31.480 15.000 1.000
31.540 16.000 1.000
31.600 8.000 1.000
31.660 11.000 1.000
31.720 8.000 1.000
31.780 11.000 1.000
31.840 8.000 1.000
31.900 10.000 1.000
31.960 10.000 1.000
32.020 7.000 1.000
32.080 11.000 1.000
32.140 8.000 1.000
32.200 8.000 1.000
32.260 10.000 1.000
32.320 6.000 1.000
32.380 9.000 1.000
32.440 4.000 1.000
32.500 10.000 1.000
32.560 7.000 1.000
32.620 10.000 1.000
32.680 7.000 1.000
32.740 6.000 1.000
32.800 8.000 1.000
32.860 7.000 1.000
32.920 11.000 1.000
32.980 14.000 1.000
33.040 7.000 1.000
33.100 13.000 1.000
33.160 3.000 1.000
33.220 4.000 1.000
33.280 8.000 1.000
33.340 3.000 1.000
33.400 8.000 1.000
33.460 3.000 1.000
33.520 9.000 1.000
33.580 12.000 1.000
33.640 10.000 1.000
33.700 12.000 1.000
33.760 4.000 1.000
33.820 6.000 1.000
33.880 4.000 1.000
33.940 11.000 1.000
34.000 11.000 1.000
34.060 9.000 1.000
34.120 8.000 1.000
34.180 6.000 1.000
34.240 13.000 1.000
34.300 6.000 1.000
34.360 10.000 1.000
34.420 8.000 1.000
34.480 13.000 1.000
34.540 13.000 1.000
34.600 14.000 1.000
34.660 16.000 1.000
34.720 10.000 1.000
34.780 15.000 1.000
34.840 13.000 1.000
34.900 11.000 1.000
34.960 14.000 1.000
35.020 9.000 1.000
35.080 9.000 1.000
35.140 10.000 1.000
35.200 11.000 1.000
35.260 13.000 1.000
35.320 9.000 1.000
35.380 5.000 1.000
35.440 8.000 1.000
35.500 9.000 1.000
35.560 9.000 1.000
35.620 6.000 1.000
35.680 13.000 1.000
35.740 11.000 1.000
35.800 13.000 1.000
35.860 9.000 1.000
35.920 12.000 1.000
35.980 9.000 1.000
36.040 9.000 1.000
36.100 10.000 1.000
36.160 14.000 1.000
36.220 14.000 1.000
36.280 8.000 1.000
36.340 7.000 1.000
36.400 10.000 1.000
36.460 7.000 1.000
36.520 11.000 1.000
36.580 8.000 1.000
36.640 10.000 1.000
36.700 13.000 1.000
36.760 14.000 1.000
36.820 10.000 1.000
36.880 9.000 1.000
36.940 10.000 1.000
37.000 9.000 1.000
37.060 9.000 1.000
37.120 10.000 1.000
37.180 7.000 1.000
37.240 11.000 1.000
37.300 9.000 1.000
37.360 6.000 1.000
37.420 9.000 1.000
37.480 9.000 1.000
37.540 8.000 1.000
37.600 9.000 1.000
37.660 5.000 1.000
37.720 11.000 1.000
37.780 11.000 1.000
37.840 12.000 1.000
37.900 6.000 1.000
37.960 7.000 1.000
38.020 10.000 1.000
38.080 3.000 1.000
38.140 4.000 1.000
38.200 6.000 1.000
38.260 7.000 1.000
38.320 6.000 1.000
38.380 9.000 1.000
38.440 12.000 1.000
38.500 7.000 1.000
38.560 6.000 1.000
38.620 5.000 1.000
38.680 10.000 1.000
38.740 7.000 1.000
38.800 10.000 1.000
38.860 7.000 1.000
38.920 9.000 1.000
38.980 4.000 1.000
39.040 13.000 1.000
39.100 9.000 1.000
39.160 7.000 1.000
39.220 10.000 1.000
39.280 12.000 1.000
39.340 11.000 1.000
39.400 8.000 1.000
39.460 12.000 1.000
39.520 11.000 1.000
39.580 8.000 1.000
39.640 17.000 1.000
39.700 7.000 1.000
39.760 7.000 1.000
39.820 7.000 1.000
39.880 6.000 1.000
39.940 10.000 1.000
40.000 3.000 1.000
40.060 12.000 1.000
40.120 8.000 1.000
40.180 9.000 1.000
40.240 6.000 1.000
40.300 10.000 1.000
40.360 12.000 1.000
40.420 6.000 1.000
40.480 4.000 1.000
40.540 11.000 1.000
40.600 9.000 1.000
40.660 5.000 1.000
40.720 5.000 1.000
40.780 11.000 1.000
40.840 7.000 1.000
40.900 9.000 1.000
40.960 7.000 1.000
41.020 11.000 1.000
41.080 4.000 1.000
41.140 5.000 1.000
41.200 11.000 1.000
41.260 8.000 1.000
41.320 9.000 1.000
41.380 6.000 1.000
41.440 9.000 1.000
41.500 8.000 1.000
41.560 7.000 1.000
41.620 7.000 1.000
41.680 6.000 1.000
41.740 12.000 1.000
41.800 12.000 1.000
41.860 10.000 1.000
41.920 11.000 1.000
41.980 6.000 1.000
42.040 8.000 1.000
42.100 14.000 1.000
42.160 10.000 1.000
42.220 21.000 1.000
42.280 8.000 1.000
42.340 6.000 1.000
42.400 8.000 1.000
42.460 8.000 1.000
42.520 14.000 1.000
42.580 11.000 1.000
42.640 8.000 1.000
42.700 8.000 1.000
42.760 16.000 1.000
42.820 16.000 1.000
42.880 15.000 1.000
42.940 10.000 1.000
43.000 15.000 1.000
43.060 13.000 1.000
43.120 10.000 1.000
43.180 11.000 1.000
43.240 13.000 1.000
43.300 18.000 1.000
43.360 14.000 1.000
43.420 14.000 1.000
43.480 11.000 1.000
43.540 13.000 1.000
43.600 14.000 1.000
43.660 14.000 1.000
43.720 17.000 1.000
43.780 9.000 1.000
43.840 11.000 1.000
43.900 13.000 1.000
43.960 13.000 1.000
44.020 9.000 1.000
44.080 9.000 1.000
44.140 16.000 1.000
44.200 12.000 1.000
44.260 10.000 1.000
44.320 4.000 1.000
44.380 11.000 1.000
44.440 5.000 1.000
44.500 6.000 1.000
44.560 14.000 1.000
44.620 17.000 1.000
44.680 12.000 1.000
44.740 15.000 1.000
44.800 13.000 1.000
44.860 13.000 1.000
44.920 7.000 1.000
44.980 10.000 1.000
45.040 9.000 1.000
45.100 4.000 1.000
45.160 7.000 1.000
45.220 12.000 1.000
45.280 8.000 1.000
45.340 7.000 1.000
45.400 2.000 1.000
45.460 10.000 1.000
45.520 8.000 1.000
45.580 7.000 1.000
45.640 10.000 1.000
45.700 9.000 1.000
45.760 7.000 1.000
45.820 6.000 1.000
45.880 9.000 1.000
45.940 5.000 1.000
46.000 10.000 1.000
46.060 9.000 1.000
46.120 10.000 1.000
46.180 13.000 1.000
46.240 7.000 1.000
46.300 12.000 1.000
46.360 12.000 1.000
46.420 10.000 1.000
46.480 8.000 1.000
46.540 10.000 1.000
46.600 8.000 1.000
46.660 10.000 1.000
46.720 7.000 1.000
46.780 7.000 1.000
46.840 7.000 1.000
46.900 9.000 1.000
46.960 10.000 1.000
47.020 7.000 1.000
47.080 7.000 1.000
47.140 7.000 1.000
47.200 10.000 1.000
47.260 3.000 1.000
47.320 9.000 1.000
47.380 15.000 1.000
47.440 6.000 1.000
47.500 10.000 1.000
47.560 6.000 1.000
47.620 7.000 1.000
47.680 10.000 1.000
47.740 12.000 1.000
47.800 10.000 1.000
47.860 6.000 1.000
47.920 10.000 1.000
47.980 6.000 1.000
48.040 4.000 1.000
48.100 5.000 1.000
48.160 8.000 1.000
48.220 11.000 1.000
48.280 11.000 1.000
48.340 9.000 1.000
48.400 6.000 1.000
48.460 6.000 1.000
48.520 10.000 1.000
48.580 8.000 1.000
48.640 8.000 1.000
48.700 4.000 1.000
48.760 5.000 1.000
48.820 8.000 1.000
48.880 5.000 1.000
48.940 5.000 1.000
49.000 7.000 1.000
49.060 4.000 1.000
49.120 10.000 1.000
49.180 7.000 1.000
49.240 12.000 1.000
49.300 12.000 1.000
49.360 7.000 1.000
49.420 4.000 1.000
49.480 11.000 1.000
49.540 8.000 1.000
49.600 9.000 1.000
49.660 9.000 1.000
49.720 9.000 1.000
49.780 6.000 1.000
49.840 5.000 1.000
49.900 14.000 1.000
49.960 6.000 1.000
50.020 4.000 1.000
50.080 11.000 1.000
50.140 17.000 1.000
50.200 9.000 1.000
50.260 6.000 1.000
50.320 15.000 1.000
50.380 8.000 1.000
50.440 13.000 1.000
50.500 16.000 1.000
50.560 11.000 1.000
50.620 8.000 1.000
50.680 9.000 1.000
50.740 6.000 1.000
50.800 14.000 1.000
50.860 10.000 1.000
50.920 12.000 1.000
50.980 7.000 1.000
51.040 12.000 1.000
51.100 10.000 1.000
51.160 9.000 1.000
51.220 12.000 1.000
51.280 9.000 1.000
51.340 6.000 1.000
51.400 13.000 1.000
51.460 13.000 1.000
51.520 10.000 1.000
51.580 10.000 1.000
51.640 9.000 1.000
51.700 17.000 1.000
51.760 7.000 1.000
51.820 12.000 1.000
51.880 14.000 1.000
51.940 10.000 1.000
52.000 9.000 1.000
52.060 9.000 1.000
52.120 15.000 1.000
52.180 13.000 1.000
52.240 13.000 1.000
52.300 18.000 1.000
52.360 11.000 1.000
52.420 13.000 1.000
52.480 10.000 1.000
52.540 11.000 1.000
52.600 11.000 1.000
52.660 9.000 1.000
52.720 12.000 1.000
52.780 13.000 1.000
52.840 23.000 1.000
52.900 15.000 1.000
52.960 19.000 1.000
53.020 11.000 1.000
53.080 21.000 1.000
53.140 19.000 1.000
53.200 13.000 1.000
53.260 22.000 1.000
53.320 18.000 1.000
53.380 12.000 1.000
53.440 20.000 1.000
53.500 17.000 1.000
53.560 25.000 1.000
53.620 15.000 1.000
53.680 17.000 1.000
53.740 17.000 1.000
53.800 20.000 1.000
53.860 23.000 1.000
53.920 22.000 1.000
53.980 28.000 1.000
54.040 26.000 1.000
54.100 25.000 1.000
54.160 33.000 1.000
54.220 41.000 1.000
54.280 54.000 1.000
54.340 43.000 1.000
54.400 40.000 1.000
54.460 34.000 1.000
54.520 31.000 1.000
54.580 23.000 1.000
54.640 16.000 1.000
54.700 17.000 1.000
54.760 10.000 1.000
54.820 12.000 1.000
54.880 11.000 1.000
54.940 12.000 1.000
55.000 13.000 1.000
55.060 12.000 1.000
55.120 7.000 1.000
55.180 8.000 1.000
55.240 9.000 1.000
55.300 7.000 1.000
55.360 17.000 1.000
55.420 10.000 1.000
55.480 6.000 1.000
55.540 11.000 1.000
55.600 12.000 1.000
55.660 8.000 1.000
55.720 9.000 1.000
55.780 14.000 1.000
55.840 5.000 1.000
55.900 7.000 1.000
55.960 9.000 1.000
56.020 15.000 1.000
56.080 9.000 1.000
56.140 7.000 1.000
56.200 8.000 1.000
56.260 6.000 1.000
56.320 5.000 1.000
56.380 12.000 1.000
56.440 6.000 1.000
56.500 15.000 1.000
56.560 4.000 1.000
56.620 6.000 1.000
56.680 7.000 1.000
56.740 7.000 1.000
56.800 7.000 1.000
56.860 11.000 1.000
56.920 5.000 1.000
56.980 13.000 1.000
57.040 7.000 1.000
57.100 8.000 1.000
57.160 6.000 1.000
57.220 15.000 1.000
57.280 6.000 1.000
57.340 7.000 1.000
57.400 11.000 1.000
57.460 11.000 1.000
57.520 6.000 1.000
57.580 13.000 1.000
57.640 8.000 1.000
57.700 11.000 1.000
57.760 4.000 1.000
57.820 6.000 1.000
57.880 6.000 1.000
57.940 10.000 1.000
58.000 13.000 1.000
58.060 6.000 1.000
58.120 6.000 1.000
58.180 8.000 1.000
58.240 9.000 1.000
58.300 9.000 1.000
58.360 5.000 1.000
58.420 7.000 1.000
58.480 2.000 1.000
58.540 5.000 1.000
58.600 5.000 1.000
58.660 8.000 1.000
58.720 9.000 1.000
58.780 5.000 1.000
58.840 4.000 1.000
58.900 9.000 1.000
58.960 7.000 1.000
59.020 6.000 1.000
59.080 5.000 1.000
59.140 8.000 1.000
59.200 9.000 1.000
59.260 4.000 1.000
59.320 6.000 1.000
59.380 11.000 1.000
59.440 7.000 1.000
59.500 4.000 1.000
59.560 9.000 1.000
59.620 5.000 1.000
59.680 12.000 1.000
59.740 6.000 1.000
59.800 6.000 1.000
59.860 9.000 1.000
59.920 9.000 1.000
59.980 6.000 1.000
60.040 3.000 1.000
60.100 6.000 1.000
60.160 12.000 1.000
60.220 7.000 1.000
60.280 8.000 1.000
60.340 6.000 1.000
60.400 7.000 1.000
60.460 8.000 1.000
60.520 8.000 1.000
60.580 4.000 1.000
60.640 9.000 1.000
60.700 7.000 1.000
60.760 4.000 1.000
60.820 10.000 1.000
60.880 4.000 1.000
60.940 3.000 1.000
61.000 4.000 1.000
61.060 10.000 1.000
61.120 6.000 1.000
61.180 6.000 1.000
61.240 5.000 1.000
61.300 8.000 1.000
61.360 7.000 1.000
61.420 9.000 1.000
61.480 18.000 1.000
61.540 9.000 1.000
61.600 14.000 1.000
61.660 9.000 1.000
61.720 11.000 1.000
61.780 13.000 1.000
61.840 10.000 1.000
61.900 13.000 1.000
61.960 14.000 1.000
62.020 11.000 1.000
62.080 11.000 1.000
62.140 8.000 1.000
62.200 4.000 1.000
62.260 8.000 1.000
62.320 7.000 1.000
62.380 8.000 1.000
62.440 7.000 1.000
62.500 2.000 1.000
62.560 7.000 1.000
62.620 9.000 1.000
62.680 6.000 1.000
62.740 5.000 1.000
62.800 9.000 1.000
62.860 9.000 1.000
62.920 7.000 1.000
62.980 3.000 1.000
63.040 4.000 1.000
63.100 5.000 1.000
63.160 4.000 1.000
63.220 5.000 1.000
63.280 3.000 1.000
63.340 5.000 1.000
63.400 6.000 1.000
63.460 6.000 1.000
63.520 3.000 1.000
63.580 4.000 1.000
63.640 6.000 1.000
63.700 8.000 1.000
63.760 6.000 1.000
63.820 6.000 1.000
63.880 12.000 1.000
63.940 6.000 1.000
64.000 5.000 1.000
64.060 6.000 1.000
64.120 6.000 1.000
64.180 5.000 1.000
64.240 6.000 1.000
64.300 11.000 1.000
64.360 5.000 1.000
64.420 5.000 1.000
64.480 6.000 1.000
64.540 7.000 1.000
64.600 5.000 1.000
64.660 4.000 1.000
64.720 6.000 1.000
64.780 1.000 1.000
64.840 5.000 1.000
64.900 6.000 1.000
64.960 3.000 1.000
65.020 7.000 1.000
65.080 6.000 1.000
65.140 3.000 1.000
65.200 6.000 1.000
65.260 6.000 1.000
65.320 4.000 1.000
65.380 4.000 1.000
65.440 4.000 1.000
65.500 8.000 1.000
65.560 7.000 1.000
65.620 6.000 1.000
65.680 5.000 1.000
65.740 3.000 1.000
65.800 7.000 1.000
65.860 6.000 1.000
65.920 6.000 1.000
65.980 13.000 1.000
66.040 6.000 1.000
66.100 8.000 1.000
66.160 4.000 1.000
66.220 5.000 1.000
66.280 7.000 1.000
66.340 6.000 1.000
66.400 4.000 1.000
66.460 6.000 1.000
66.520 8.000 1.000
66.580 5.000 1.000
66.640 9.000 1.000
66.700 8.000 1.000
66.760 6.000 1.000
66.820 2.000 1.000
66.880 4.000 1.000
66.940 7.000 1.000
67.000 11.000 1.000
67.060 6.000 1.000
67.120 5.000 1.000
67.180 6.000 1.000
67.240 7.000 1.000
67.300 8.000 1.000
67.360 3.000 1.000
67.420 9.000 1.000
67.480 2.000 1.000
67.540 7.000 1.000
67.600 9.000 1.000
67.660 6.000 1.000
67.720 6.000 1.000
67.780 9.000 1.000
67.840 4.000 1.000
67.900 4.000 1.000
67.960 7.000 1.000
68.020 3.000 1.000
68.080 8.000 1.000
68.140 4.000 1.000
68.200 4.000 1.000
68.260 9.000 1.000
68.320 5.000 1.000
68.380 6.000 1.000
68.440 4.000 1.000
68.500 4.000 1.000
68.560 3.000 1.000
68.620 13.000 1.000
68.680 6.000 1.000
68.740 11.000 1.000
68.800 4.000 1.000
68.860 3.000 1.000
68.920 9.000 1.000
68.980 6.000 1.000
69.040 5.000 1.000
69.100 2.000 1.000
69.160 9.000 1.000
69.220 4.000 1.000
69.280 7.000 1.000
69.340 3.000 1.000
69.400 6.000 1.000
69.460 10.000 1.000
69.520 4.000 1.000
69.580 5.000 1.000
69.640 2.000 1.000
69.700 6.000 1.000
69.760 8.000 1.000
69.820 7.000 1.000
69.880 7.000 1.000
69.940 5.000 1.000
70.000 6.000 1.000
70.060 2.000 1.000
70.120 7.000 1.000
70.180 7.000 1.000
70.240 8.000 1.000
70.300 4.000 1.000
70.360 4.000 1.000
70.420 4.000 1.000
70.480 4.000 1.000
70.540 8.000 1.000
70.600 5.000 1.000
70.660 7.000 1.000
70.720 3.000 1.000
70.780 9.000 1.000
70.840 7.000 1.000
70.900 7.000 1.000
70.960 8.000 1.000
71.020 6.000 1.000
71.080 7.000 1.000
71.140 8.000 1.000
71.200 7.000 1.000
71.260 6.000 1.000
71.320 8.000 1.000
71.380 4.000 1.000
71.440 7.000 1.000
71.500 3.000 1.000
71.560 8.000 1.000
71.620 6.000 1.000
71.680 8.000 1.000
71.740 3.000 1.000
71.800 3.000 1.000
71.860 3.000 1.000
71.920 7.000 1.000
71.980 10.000 1.000
72.040 4.000 1.000
72.100 9.000 1.000
72.160 4.000 1.000
72.220 4.000 1.000
72.280 8.000 1.000
72.340 8.000 1.000
72.400 2.000 1.000
72.460 13.000 1.000
72.520 13.000 1.000
72.580 4.000 1.000
72.640 7.000 1.000
72.700 6.000 1.000
72.760 9.000 1.000
72.820 7.000 1.000
72.880 7.000 1.000
72.940 8.000 1.000
73.000 9.000 1.000
73.060 4.000 1.000
73.120 6.000 1.000
73.180 7.000 1.000
73.240 6.000 1.000
73.300 6.000 1.000
73.360 5.000 1.000
73.420 9.000 1.000
73.480 8.000 1.000
73.540 4.000 1.000
73.600 2.000 1.000
73.660 2.000 1.000
73.720 6.000 1.000
73.780 10.000 1.000
73.840 3.000 1.000
73.900 6.000 1.000
73.960 9.000 1.000
74.020 4.000 1.000
74.080 13.000 1.000
74.140 9.000 1.000
74.200 4.000 1.000
74.260 7.000 1.000
74.320 5.000 1.000
74.380 6.000 1.000
74.440 4.000 1.000
74.500 2.000 1.000
74.560 4.000 1.000
74.620 2.000 1.000
74.680 8.000 1.000
74.740 4.000 1.000
74.800 8.000 1.000
74.860 9.000 1.000
74.920 13.000 1.000
74.980 3.000 1.000
75.040 4.000 1.000
75.100 4.000 1.000
75.160 9.000 1.000
75.220 5.000 1.000
75.280 8.000 1.000
75.340 5.000 1.000
75.400 9.000 1.000
75.460 8.000 1.000
75.520 8.000 1.000
75.580 3.000 1.000
75.640 1.000 1.000
75.700 9.000 1.000
75.760 8.000 1.000
75.820 3.000 1.000
75.880 6.000 1.000
75.940 10.000 1.000
76.000 6.000 1.000
76.060 6.000 1.000
76.120 5.000 1.000
76.180 8.000 1.000
76.240 6.000 1.000
76.300 9.000 1.000
76.360 9.000 1.000
76.420 3.000 1.000
76.480 10.000 1.000
76.540 3.000 1.000
76.600 7.000 1.000
76.660 3.000 1.000
76.720 3.000 1.000
76.780 10.000 1.000
76.840 7.000 1.000
76.900 4.000 1.000
76.960 2.000 1.000
77.020 4.000 1.000
77.080 6.000 1.000
77.140 5.000 1.000
77.200 7.000 1.000
77.260 7.000 1.000
77.320 6.000 1.000
77.380 6.000 1.000
77.440 12.000 1.000
77.500 6.000 1.000
77.560 4.000 1.000
77.620 8.000 1.000
77.680 8.000 1.000
77.740 6.000 1.000
77.800 5.000 1.000
77.860 6.000 1.000
77.920 3.000 1.000
77.980 4.000 1.000
78.040 7.000 1.000
78.100 6.000 1.000
78.160 7.000 1.000
78.220 6.000 1.000
78.280 5.000 1.000
78.340 4.000 1.000
78.400 6.000 1.000
78.460 5.000 1.000
78.520 7.000 1.000
78.580 3.000 1.000
78.640 5.000 1.000
78.700 6.000 1.000
78.760 10.000 1.000
78.820 8.000 1.000
78.880 5.000 1.000
78.940 8.000 1.000
79.000 5.000 1.000
79.060 5.000 1.000
79.120 5.000 1.000
79.180 7.000 1.000
79.240 7.000 1.000
79.300 6.000 1.000
79.360 4.000 1.000
79.420 3.000 1.000
79.480 3.000 1.000
79.540 2.000 1.000
79.600 7.000 1.000
79.660 7.000 1.000
79.720 13.000 1.000
79.780 8.000 1.000
79.840 7.000 1.000
79.900 10.000 1.000
79.960 6.000 1.000
80.020 4.000 1.000
80.080 10.000 1.000
80.140 4.000 1.000
80.200 2.000 1.000
80.260 5.000 1.000
80.320 5.000 1.000
80.380 4.000 1.000
80.440 2.000 1.000
80.500 4.000 1.000
80.560 4.000 1.000
80.620 6.000 1.000
80.680 3.000 1.000
80.740 1.000 1.000
80.800 2.000 1.000
80.860 6.000 1.000
80.920 6.000 1.000
80.980 3.000 1.000
81.040 6.000 1.000
81.100 6.000 1.000
81.160 8.000 1.000
81.220 5.000 1.000
81.280 9.000 1.000
81.340 7.000 1.000
81.400 7.000 1.000
81.460 7.000 1.000
81.520 2.000 1.000
81.580 8.000 1.000
81.640 3.000 1.000
81.700 4.000 1.000
81.760 8.000 1.000
81.820 2.000 1.000
81.880 1.000 1.000
81.940 10.000 1.000
82.000 7.000 1.000
82.060 4.000 1.000
82.120 5.000 1.000
82.180 2.000 1.000
82.240 3.000 1.000
82.300 5.000 1.000
82.360 7.000 1.000
82.420 7.000 1.000
82.480 3.000 1.000
82.540 2.000 1.000
82.600 3.000 1.000
82.660 2.000 1.000
82.720 3.000 1.000
82.780 6.000 1.000
82.840 6.000 1.000
82.900 2.000 1.000
82.960 5.000 1.000
83.020 6.000 1.000
83.080 4.000 1.000
83.140 5.000 1.000
83.200 5.000 1.000
83.260 5.000 1.000
83.320 3.000 1.000
83.380 4.000 1.000
83.440 9.000 1.000
83.500 7.000 1.000
83.560 5.000 1.000
83.620 4.000 1.000
83.680 6.000 1.000
83.740 6.000 1.000
83.800 6.000 1.000
83.860 7.000 1.000
83.920 4.000 1.000
83.980 5.000 1.000
84.040 4.000 1.000
84.100 5.000 1.000
84.160 10.000 1.000
84.220 8.000 1.000
84.280 3.000 1.000
84.340 7.000 1.000
84.400 4.000 1.000
84.460 4.000 1.000
84.520 3.000 1.000
84.580 10.000 1.000
84.640 3.000 1.000
84.700 3.000 1.000
84.760 4.000 1.000
84.820 8.000 1.000
84.880 4.000 1.000
84.940 3.000 1.000
85.000 10.000 1.000
85.060 5.000 1.000
85.120 6.000 1.000
85.180 7.000 1.000
85.240 6.000 1.000
85.300 10.000 1.000
85.360 4.000 1.000
85.420 4.000 1.000
85.480 5.000 1.000
85.540 7.000 1.000
85.600 2.000 1.000
85.660 5.000 1.000
85.720 5.000 1.000
85.780 4.000 1.000
85.840 5.000 1.000
85.900 9.000 1.000
85.960 9.000 1.000
86.020 7.000 1.000
86.080 7.000 1.000
86.140 6.000 1.000
86.200 8.000 1.000
86.260 4.000 1.000
86.320 10.000 1.000
86.380 7.000 1.000
86.440 11.000 1.000
86.500 5.000 1.000
86.560 5.000 1.000
86.620 8.000 1.000
86.680 6.000 1.000
86.740 4.000 1.000
86.800 8.000 1.000
86.860 9.000 1.000
86.920 8.000 1.000
86.980 7.000 1.000
87.040 10.000 1.000
87.100 3.000 1.000
87.160 8.000 1.000
87.220 5.000 1.000
87.280 7.000 1.000
87.340 4.000 1.000
87.400 3.000 1.000
87.460 5.000 1.000
87.520 4.000 1.000
87.580 2.000 1.000
87.640 7.000 1.000
87.700 5.000 1.000
87.760 4.000 1.000
87.820 4.000 1.000
87.880 4.000 1.000
87.940 4.000 1.000
88.000 5.000 1.000
88.060 8.000 1.000
88.120 8.000 1.000
88.180 7.000 1.000
88.240 3.000 1.000
88.300 5.000 1.000
88.360 2.000 1.000
88.420 1.000 1.000
88.480 3.000 1.000
88.540 1.000 1.000
88.600 3.000 1.000
88.660 2.000 1.000
88.720 4.000 1.000
88.780 4.000 1.000
88.840 4.000 1.000
88.900 3.000 1.000
88.960 5.000 1.000
89.020 6.000 1.000
89.080 5.000 1.000
89.140 10.000 1.000
89.200 5.000 1.000
89.260 2.000 1.000
89.320 6.000 1.000
89.380 6.000 1.000
89.440 5.000 1.000
89.500 4.000 1.000
89.560 3.000 1.000
89.620 5.000 1.000
89.680 5.000 1.000
89.740 6.000 1.000
89.800 6.000 1.000
89.860 6.000 1.000
89.920 6.000 1.000
89.980 2.000 1.000
90.000 2.000 1.000
*RAS_INT_END
*RAS_DATA_END