File: Lab/XRD/20170223/Grafittpapir_test-1-1248-1.ras
*RAS_DATA_START
*RAS_HEADER_START
*CORR_POS_DB_NAME "DTEX_11112016"
*CORR_POS_GONIO_RADIUS ""
*CORR_POS_NODE_INDEX01 ""
*CORR_POS_NODE_INDEX02 ""
*CORR_POS_NODE_INDEX03 ""
*CORR_POS_NODE_INDEX04 ""
*CORR_POS_NODE_INDEX05 ""
*CORR_POS_NODE_INDEX06 ""
*CORR_POS_NODE_INDEX07 ""
*CORR_POS_NODE_INDEX08 ""
*CORR_POS_NODE_INDEX09 ""
*CORR_POS_NODE_INDEX10 ""
*CORR_POS_NODE_INDEX11 ""
*CORR_POS_NODE_LABEL01 "Si(111)"
*CORR_POS_NODE_LABEL02 "Si(220)"
*CORR_POS_NODE_LABEL03 "Si(311)"
*CORR_POS_NODE_LABEL04 "Si(400)"
*CORR_POS_NODE_LABEL05 "Si(331)"
*CORR_POS_NODE_LABEL06 "Si(422)"
*CORR_POS_NODE_LABEL07 "Si(511)"
*CORR_POS_NODE_LABEL08 "Si(440)"
*CORR_POS_NODE_LABEL09 "Si(531)"
*CORR_POS_NODE_LABEL10 "Si(620)"
*CORR_POS_NODE_LABEL11 "Si(533)"
*CORR_POS_NODE_POS_CALC01 "28.4137"
*CORR_POS_NODE_POS_CALC02 "47.2707"
*CORR_POS_NODE_POS_CALC03 "56.0883"
*CORR_POS_NODE_POS_CALC04 "69.0934"
*CORR_POS_NODE_POS_CALC05 "76.3385"
*CORR_POS_NODE_POS_CALC06 "87.9915"
*CORR_POS_NODE_POS_CALC07 "94.9137"
*CORR_POS_NODE_POS_CALC08 "106.67"
*CORR_POS_NODE_POS_CALC09 "114.054"
*CORR_POS_NODE_POS_CALC10 "127.508"
*CORR_POS_NODE_POS_CALC11 "136.858"
*CORR_POS_NODE_POS_MEAS01 "28.3712"
*CORR_POS_NODE_POS_MEAS02 "47.2304"
*CORR_POS_NODE_POS_MEAS03 "56.0465"
*CORR_POS_NODE_POS_MEAS04 "69.0523"
*CORR_POS_NODE_POS_MEAS05 "76.2993"
*CORR_POS_NODE_POS_MEAS06 "87.9512"
*CORR_POS_NODE_POS_MEAS07 "94.8772"
*CORR_POS_NODE_POS_MEAS08 "106.636"
*CORR_POS_NODE_POS_MEAS09 "114.028"
*CORR_POS_NODE_POS_MEAS10 "127.48"
*CORR_POS_NODE_POS_MEAS11 "136.839"
*CORR_POS_OPT_ATTR "集中法"
*CORR_POS_PARAM_MU ""
*CORR_POS_PARAM_PL ""
*CORR_POS_SEMODEL_TYPE "0"
*CORR_POS_STANDARD_TYPE ""
*CORR_POS_VALUE_ANALYZER "None"
*CORR_POS_VALUE_CMONO "None"
*CORR_POS_VALUE_IMONO "None"
*CORR_POS_VALUE_IS "0.625deg"
*CORR_POS_VALUE_ISL "10.0mm"
*CORR_POS_VALUE_ISOLLER "2.5deg"
*CORR_POS_VALUE_RS1 "13.0mm"
*CORR_POS_VALUE_RS2 "13.0mm"
*CORR_POS_VALUE_RSOLLER "2.5deg"
*CORR_POS_XG_FOCUS_L ""
*CORR_POS_XG_WAVE_TYPE ""
*CORR_POS_XG_WAVE_VALUE ""
*DISP_FMT_X "%.2f"
*DISP_FMT_Y "%.0f"
*DISP_FULLSCALE "4407.6000000000"
*DISP_LINE_COLOR "255.0000000000"
*DISP_LINE_STYLE "0.0000000000"
*DISP_LINE_WIDTH "0.2500000000"
*DISP_NOTE "Collected Data-1"
*DISP_OFFSET_Y "0.0000000000"
*DISP_PEAKSEARCH_UNIT_Y "COUNTS"
*DISP_RANGE_BOTTOM "0.0000000000"
*DISP_RANGE_LEFT "10.0000000000"
*DISP_RANGE_LOGCUTOFF "0.0100000000"
*DISP_RANGE_RIGHT "90.0000000000"
*DISP_RANGE_TOP "4407.6000000000"
*DISP_SCALE_MODE_Y "0.0000000000"
*DISP_TAB_NAME "Theta/2-Theta"
*DISP_TITLE_Y "Intensity"
*DISP_UNIT_Y "counts"
*DISP_WINDOW_NAME "MSG_MACROENGINE"
*FILE_COMMENT " "
*FILE_MD5 ""
*FILE_MEMO " "
*FILE_OPERATOR "MiniFlex"
*FILE_PART_ID "MEAS_PBEA_00223"
*FILE_SAMPLE "Grafittpapir_test"
*FILE_TYPE "RAS_RAW"
*FILE_USERGROUP "System User"
*FILE_VERSION "1.0000000000"
*HW_ATTACHMENT_ID "ATT1031"
*HW_ATTACHMENT_NAME "6サンプルチェンジャ|ASC-6"
*HW_COUNTER_ID-0 "CUT0025"
*HW_COUNTER_ID-1 "CUT0020"
*HW_COUNTER_ID-2 "CUT0020"
*HW_COUNTER_ID-3 "CMC0021"
*HW_COUNTER_NAME-0 "D/teX Ultra|D/teX Ultra"
*HW_COUNTER_NAME-1 "None|None"
*HW_COUNTER_NAME-2 "None|None"
*HW_COUNTER_NAME-3 "検出器モノクロメータ|Detector monochromator"
*HW_COUNTER_SELECT_NAME "D/teX Ultra|D/teX Ultra"
*HW_GONIOMETER_ID "GON0070"
*HW_GONIOMETER_NAME "MiniFlex 300/600|MiniFlex 300/600"
*HW_GONIOMETER_RADIUS-0 "79.0"
*HW_GONIOMETER_RADIUS-1 "91.5"
*HW_GONIOMETER_RADIUS-2 "150.0"
*HW_GONIOMETER_RADIUS-3 "0"
*HW_GONIOMETER_RADIUS-4 "103.4"
*HW_GONIOMETER_RADIUS-5 "150.0"
*HW_GONIOMETER_RADIUS-6 "46.6"
*HW_GONIOMETER_RADIUS-7 "160.0"
*HW_I_OPT_ID-0 "ISL0021"
*HW_I_OPT_ID-1 "ISO0021"
*HW_I_OPT_NAME-0 "発散スリット|Divergence slit"
*HW_I_OPT_NAME-1 "入射平行スリット|Incident parallel slit"
*HW_R_ATTENUATER_AUTOMODE "0"
*HW_R_OPT_ID-0 "RSS0021"
*HW_R_OPT_ID-1 "RSO0021"
*HW_R_OPT_ID-2 "RRS0021"
*HW_R_OPT_NAME-0 "散乱スリット|Scattering slit"
*HW_R_OPT_NAME-1 "受光平行スリット|Receiving soller slit"
*HW_R_OPT_NAME-2 "受光スリット|Receiving slit"
*HW_SAMPLE_HOLDER_ID "SMP0000"
*HW_SAMPLE_HOLDER_NAME "無し|None"
*HW_XG_CURRENT_MAX "15"
*HW_XG_CURRENT_MIN "2"
*HW_XG_CURRENT_RESOLUTION "1"
*HW_XG_CURRENT_UNIT "mA"
*HW_XG_FOCUS "1mm x 10mm"
*HW_XG_FOCUS_TYPE "Normal"
*HW_XG_ID "1060"
*HW_XG_NAME "300W/600W 封入管-B|300W/600W Sealed tube-B"
*HW_XG_TARGET_ATOMIC_NUMBER "29.0000000000"
*HW_XG_TARGET_NAME "Cu"
*HW_XG_TYPE "Hermetic"
*HW_XG_VOLTAGE_MAX "40"
*HW_XG_VOLTAGE_MIN "20"
*HW_XG_VOLTAGE_RESOLUTION "1"
*HW_XG_VOLTAGE_UNIT "kV"
*HW_XG_WATT_MAX "1"
*HW_XG_WATT_UNIT "kW"
*HW_XG_WAVE_LENGTH_ALPHA1 "1.540593"
*HW_XG_WAVE_LENGTH_ALPHA2 "1.544414"
*HW_XG_WAVE_LENGTH_BETA "1.392250"
*MEAS_COND_AXIS_NAME-0 "Theta/2-Theta"
*MEAS_COND_AXIS_NAME-1 "Spin"
*MEAS_COND_AXIS_NAME-2 "Change"
*MEAS_COND_AXIS_NAME-3 "Soller(inc.)"
*MEAS_COND_AXIS_NAME-4 "IHS"
*MEAS_COND_AXIS_NAME-5 "DS"
*MEAS_COND_AXIS_NAME-6 "SS"
*MEAS_COND_AXIS_NAME-7 "Soller(rec.)"
*MEAS_COND_AXIS_NAME-8 "RS"
*MEAS_COND_AXIS_NAME-9 "Filter"
*MEAS_COND_AXIS_NAME-10 "Monochromator"
*MEAS_COND_AXIS_NAME-11 "PHA"
*MEAS_COND_AXIS_NAME_INTERNAL-0 "TwoThetaTheta"
*MEAS_COND_AXIS_NAME_INTERNAL-1 "Spin"
*MEAS_COND_AXIS_NAME_INTERNAL-2 "Change"
*MEAS_COND_AXIS_NAME_INTERNAL-3 "IncidentSollerSlit"
*MEAS_COND_AXIS_NAME_INTERNAL-4 "IncidentAxdSlit"
*MEAS_COND_AXIS_NAME_INTERNAL-5 "IncidentSlitBox"
*MEAS_COND_AXIS_NAME_INTERNAL-6 "ReceivingSlitBox1"
*MEAS_COND_AXIS_NAME_INTERNAL-7 "ReceivingSollerSlit"
*MEAS_COND_AXIS_NAME_INTERNAL-8 "ReceivingSlitBox2"
*MEAS_COND_AXIS_NAME_INTERNAL-9 "Filter"
*MEAS_COND_AXIS_NAME_INTERNAL-10 "CounterMonochromator"
*MEAS_COND_AXIS_NAME_INTERNAL-11 "PHA"
*MEAS_COND_AXIS_NAME_MAGICNO-0 "268632064.0000000000"
*MEAS_COND_AXIS_NAME_MAGICNO-1 "16842752.0000000000"
*MEAS_COND_AXIS_NAME_MAGICNO-2 "16842752.0000000000"
*MEAS_COND_AXIS_NAME_MAGICNO-3 "20971521.0000000000"
*MEAS_COND_AXIS_NAME_MAGICNO-4 "22020097.0000000000"
*MEAS_COND_AXIS_NAME_MAGICNO-5 "22020097.0000000000"
*MEAS_COND_AXIS_NAME_MAGICNO-6 "23068673.0000000000"
*MEAS_COND_AXIS_NAME_MAGICNO-7 "20971521.0000000000"
*MEAS_COND_AXIS_NAME_MAGICNO-8 "23068673.0000000000"
*MEAS_COND_AXIS_NAME_MAGICNO-9 "20971521.0000000000"
*MEAS_COND_AXIS_NAME_MAGICNO-10 "20971521.0000000000"
*MEAS_COND_AXIS_NAME_MAGICNO-11 "0.0000000000"
*MEAS_COND_AXIS_OFFSET-0 "0.0000000000"
*MEAS_COND_AXIS_OFFSET-1 "-"
*MEAS_COND_AXIS_OFFSET-2 "-"
*MEAS_COND_AXIS_OFFSET-3 "-"
*MEAS_COND_AXIS_OFFSET-4 "-"
*MEAS_COND_AXIS_OFFSET-5 "-"
*MEAS_COND_AXIS_OFFSET-6 "-"
*MEAS_COND_AXIS_OFFSET-7 "-"
*MEAS_COND_AXIS_OFFSET-8 "-"
*MEAS_COND_AXIS_OFFSET-9 "-"
*MEAS_COND_AXIS_OFFSET-10 "-"
*MEAS_COND_AXIS_OFFSET-11 "-"
*MEAS_COND_AXIS_POSITION-0 "10.0000000000"
*MEAS_COND_AXIS_POSITION-1 "0.0000000000"
*MEAS_COND_AXIS_POSITION-2 "1.0000000000"
*MEAS_COND_AXIS_POSITION-3 "2.5deg"
*MEAS_COND_AXIS_POSITION-4 "10.0mm"
*MEAS_COND_AXIS_POSITION-5 "0.625deg"
*MEAS_COND_AXIS_POSITION-6 "13.0mm(Open)"
*MEAS_COND_AXIS_POSITION-7 "2.5deg"
*MEAS_COND_AXIS_POSITION-8 "13.0mm"
*MEAS_COND_AXIS_POSITION-9 "K-beta(x2)"
*MEAS_COND_AXIS_POSITION-10 "None"
*MEAS_COND_AXIS_POSITION-11 "41.0000000000"
*MEAS_COND_AXIS_UNIT-0 "deg"
*MEAS_COND_AXIS_UNIT-1 ""
*MEAS_COND_AXIS_UNIT-2 ""
*MEAS_COND_AXIS_UNIT-3 ""
*MEAS_COND_AXIS_UNIT-4 ""
*MEAS_COND_AXIS_UNIT-5 ""
*MEAS_COND_AXIS_UNIT-6 ""
*MEAS_COND_AXIS_UNIT-7 ""
*MEAS_COND_AXIS_UNIT-8 ""
*MEAS_COND_AXIS_UNIT-9 ""
*MEAS_COND_AXIS_UNIT-10 ""
*MEAS_COND_AXIS_UNIT-11 "div"
*MEAS_COND_CORRECTION_SLIT_COUNTERMONO "None"
*MEAS_COND_CORRECTION_SLIT_DS "0.625deg"
*MEAS_COND_CORRECTION_SLIT_FILTER "None"
*MEAS_COND_CORRECTION_SLIT_IHS "10.0mm"
*MEAS_COND_CORRECTION_SLIT_RS "13.0mm"
*MEAS_COND_CORRECTION_SLIT_SOLLER_INC "2.5deg"
*MEAS_COND_CORRECTION_SLIT_SOLLER_REC "2.5deg"
*MEAS_COND_CORRECTION_SLIT_SS "13.0mm"
*MEAS_COND_COUNTER_CNTLOSS_CORR "0.0000000000"
*MEAS_COND_COUNTER_PHABASE "41.0000000000"
*MEAS_COND_COUNTER_PHAWINDOW "14.0000000000"
*MEAS_COND_COUNTER_PHA_UNIT "div"
*MEAS_COND_COUNTER_TAUDIFF "0.2500000000"
*MEAS_COND_COUNTER_TAUINT "0.7500000000"
*MEAS_COND_IRRADIATION_MODE "OFF"
*MEAS_COND_IRRADIATION_WIDTH ""
*MEAS_COND_OPT_ATTR " "
*MEAS_COND_OPT_NAME ""
*MEAS_COND_UNSYMMETRIC_MODE "OFF"
*MEAS_COND_XG_CURRENT "15.0000000000"
*MEAS_COND_XG_VOLTAGE "40.0000000000"
*MEAS_COND_XG_WAVE_TYPE "Ka"
*MEAS_DATA_COUNT "4001.0000000000"
*MEAS_SCAN_AXIS_X "Theta/2-Theta"
*MEAS_SCAN_AXIS_X_INTERNAL "TwoThetaTheta"
*MEAS_SCAN_END_TIME "02/23/17 12:50:58"
*MEAS_SCAN_MODE "CONTINUOUS"
*MEAS_SCAN_MONITOR "0"
*MEAS_SCAN_RESOLUTION_X "0.005"
*MEAS_SCAN_SPEED "50.000"
*MEAS_SCAN_SPEED_UNIT "deg/min"
*MEAS_SCAN_SPEED_USER "50.000"
*MEAS_SCAN_START "10.0000000000"
*MEAS_SCAN_START_TIME "02/23/17 12:49:00"
*MEAS_SCAN_STEP "0.0200000000"
*MEAS_SCAN_STOP "90.0000000000"
*MEAS_SCAN_UNIT_X "deg"
*MEAS_SCAN_UNIT_Y "counts"
*SLIT_SYSTEM "0"
*RAS_HEADER_END
*RAS_INT_START
10.000 43.000 1.000
10.060 45.000 1.000
10.120 40.000 1.000
10.180 48.000 1.000
10.240 49.000 1.000
10.300 43.000 1.000
10.360 34.000 1.000
10.420 41.000 1.000
10.480 37.000 1.000
10.540 39.000 1.000
10.600 43.000 1.000
10.660 43.000 1.000
10.720 47.000 1.000
10.780 37.000 1.000
10.840 33.000 1.000
10.900 47.000 1.000
10.960 40.000 1.000
11.020 37.000 1.000
11.080 34.000 1.000
11.140 42.000 1.000
11.200 34.000 1.000
11.260 37.000 1.000
11.320 32.000 1.000
11.380 36.000 1.000
11.440 40.000 1.000
11.500 27.000 1.000
11.560 43.000 1.000
11.620 40.000 1.000
11.680 27.000 1.000
11.740 35.000 1.000
11.800 34.000 1.000
11.860 39.000 1.000
11.920 33.000 1.000
11.980 35.000 1.000
12.040 28.000 1.000
12.100 33.000 1.000
12.160 33.000 1.000
12.220 38.000 1.000
12.280 29.000 1.000
12.340 38.000 1.000
12.400 33.000 1.000
12.460 33.000 1.000
12.520 39.000 1.000
12.580 31.000 1.000
12.640 23.000 1.000
12.700 30.000 1.000
12.760 31.000 1.000
12.820 37.000 1.000
12.880 28.000 1.000
12.940 34.000 1.000
13.000 24.000 1.000
13.060 28.000 1.000
13.120 36.000 1.000
13.180 35.000 1.000
13.240 38.000 1.000
13.300 31.000 1.000
13.360 23.000 1.000
13.420 32.000 1.000
13.480 36.000 1.000
13.540 28.000 1.000
13.600 36.000 1.000
13.660 24.000 1.000
13.720 29.000 1.000
13.780 28.000 1.000
13.840 23.000 1.000
13.900 26.000 1.000
13.960 27.000 1.000
14.020 25.000 1.000
14.080 29.000 1.000
14.140 27.000 1.000
14.200 25.000 1.000
14.260 27.000 1.000
14.320 35.000 1.000
14.380 29.000 1.000
14.440 27.000 1.000
14.500 27.000 1.000
14.560 26.000 1.000
14.620 26.000 1.000
14.680 25.000 1.000
14.740 28.000 1.000
14.800 21.000 1.000
14.860 25.000 1.000
14.920 25.000 1.000
14.980 24.000 1.000
15.040 24.000 1.000
15.100 23.000 1.000
15.160 21.000 1.000
15.220 28.000 1.000
15.280 20.000 1.000
15.340 31.000 1.000
15.400 26.000 1.000
15.460 24.000 1.000
15.520 22.000 1.000
15.580 20.000 1.000
15.640 23.000 1.000
15.700 24.000 1.000
15.760 24.000 1.000
15.820 21.000 1.000
15.880 22.000 1.000
15.940 29.000 1.000
16.000 26.000 1.000
16.060 19.000 1.000
16.120 19.000 1.000
16.180 25.000 1.000
16.240 25.000 1.000
16.300 29.000 1.000
16.360 24.000 1.000
16.420 22.000 1.000
16.480 21.000 1.000
16.540 19.000 1.000
16.600 26.000 1.000
16.660 26.000 1.000
16.720 31.000 1.000
16.780 25.000 1.000
16.840 31.000 1.000
16.900 23.000 1.000
16.960 24.000 1.000
17.020 21.000 1.000
17.080 24.000 1.000
17.140 22.000 1.000
17.200 18.000 1.000
17.260 22.000 1.000
17.320 24.000 1.000
17.380 20.000 1.000
17.440 21.000 1.000
17.500 30.000 1.000
17.560 27.000 1.000
17.620 27.000 1.000
17.680 23.000 1.000
17.740 24.000 1.000
17.800 22.000 1.000
17.860 22.000 1.000
17.920 21.000 1.000
17.980 25.000 1.000
18.040 37.000 1.000
18.100 26.000 1.000
18.160 25.000 1.000
18.220 31.000 1.000
18.280 29.000 1.000
18.340 29.000 1.000
18.400 26.000 1.000
18.460 18.000 1.000
18.520 27.000 1.000
18.580 24.000 1.000
18.640 25.000 1.000
18.700 30.000 1.000
18.760 23.000 1.000
18.820 27.000 1.000
18.880 27.000 1.000
18.940 22.000 1.000
19.000 27.000 1.000
19.060 23.000 1.000
19.120 32.000 1.000
19.180 25.000 1.000
19.240 27.000 1.000
19.300 30.000 1.000
19.360 29.000 1.000
19.420 29.000 1.000
19.480 26.000 1.000
19.540 31.000 1.000
19.600 40.000 1.000
19.660 41.000 1.000
19.720 46.000 1.000
19.780 39.000 1.000
19.840 38.000 1.000
19.900 41.000 1.000
19.960 45.000 1.000
20.020 38.000 1.000
20.080 43.000 1.000
20.140 37.000 1.000
20.200 39.000 1.000
20.260 42.000 1.000
20.320 43.000 1.000
20.380 35.000 1.000
20.440 41.000 1.000
20.500 38.000 1.000
20.560 34.000 1.000
20.620 33.000 1.000
20.680 39.000 1.000
20.740 41.000 1.000
20.800 40.000 1.000
20.860 45.000 1.000
20.920 41.000 1.000
20.980 40.000 1.000
21.040 34.000 1.000
21.100 35.000 1.000
21.160 40.000 1.000
21.220 31.000 1.000
21.280 39.000 1.000
21.340 49.000 1.000
21.400 46.000 1.000
21.460 49.000 1.000
21.520 45.000 1.000
21.580 39.000 1.000
21.640 44.000 1.000
21.700 46.000 1.000
21.760 45.000 1.000
21.820 45.000 1.000
21.880 40.000 1.000
21.940 39.000 1.000
22.000 45.000 1.000
22.060 35.000 1.000
22.120 36.000 1.000
22.180 49.000 1.000
22.240 32.000 1.000
22.300 40.000 1.000
22.360 45.000 1.000
22.420 54.000 1.000
22.480 41.000 1.000
22.540 57.000 1.000
22.600 59.000 1.000
22.660 49.000 1.000
22.720 55.000 1.000
22.780 52.000 1.000
22.840 59.000 1.000
22.900 59.000 1.000
22.960 49.000 1.000
23.020 50.000 1.000
23.080 57.000 1.000
23.140 59.000 1.000
23.200 55.000 1.000
23.260 65.000 1.000
23.320 73.000 1.000
23.380 57.000 1.000
23.440 69.000 1.000
23.500 74.000 1.000
23.560 72.000 1.000
23.620 93.000 1.000
23.680 79.000 1.000
23.740 85.000 1.000
23.800 100.000 1.000
23.860 85.000 1.000
23.920 95.000 1.000
23.980 101.000 1.000
24.040 102.000 1.000
24.100 98.000 1.000
24.160 114.000 1.000
24.220 111.000 1.000
24.280 121.000 1.000
24.340 129.000 1.000
24.400 133.000 1.000
24.460 135.000 1.000
24.520 170.000 1.000
24.580 161.000 1.000
24.640 179.000 1.000
24.700 179.000 1.000
24.760 185.000 1.000
24.820 189.000 1.000
24.880 221.000 1.000
24.940 244.000 1.000
25.000 259.000 1.000
25.060 275.000 1.000
25.120 279.000 1.000
25.180 327.000 1.000
25.240 346.000 1.000
25.300 385.000 1.000
25.360 419.000 1.000
25.420 452.000 1.000
25.480 462.000 1.000
25.540 518.000 1.000
25.600 567.000 1.000
25.660 622.000 1.000
25.720 629.000 1.000
25.780 668.000 1.000
25.840 746.000 1.000
25.900 770.000 1.000
25.960 824.000 1.000
26.020 836.000 1.000
26.080 921.000 1.000
26.140 960.000 1.000
26.200 1055.000 1.000
26.260 1318.000 1.000
26.320 1778.000 1.000
26.380 2700.000 1.000
26.440 3531.000 1.000
26.500 3447.000 1.000
26.560 2239.000 1.000
26.620 1153.000 1.000
26.680 673.000 1.000
26.740 434.000 1.000
26.800 384.000 1.000
26.860 320.000 1.000
26.920 270.000 1.000
26.980 233.000 1.000
27.040 227.000 1.000
27.100 182.000 1.000
27.160 155.000 1.000
27.220 165.000 1.000
27.280 147.000 1.000
27.340 123.000 1.000
27.400 133.000 1.000
27.460 120.000 1.000
27.520 90.000 1.000
27.580 92.000 1.000
27.640 92.000 1.000
27.700 93.000 1.000
27.760 90.000 1.000
27.820 71.000 1.000
27.880 97.000 1.000
27.940 71.000 1.000
28.000 73.000 1.000
28.060 79.000 1.000
28.120 52.000 1.000
28.180 70.000 1.000
28.240 65.000 1.000
28.300 63.000 1.000
28.360 65.000 1.000
28.420 64.000 1.000
28.480 64.000 1.000
28.540 53.000 1.000
28.600 56.000 1.000
28.660 56.000 1.000
28.720 42.000 1.000
28.780 46.000 1.000
28.840 51.000 1.000
28.900 39.000 1.000
28.960 35.000 1.000
29.020 32.000 1.000
29.080 30.000 1.000
29.140 39.000 1.000
29.200 47.000 1.000
29.260 34.000 1.000
29.320 52.000 1.000
29.380 50.000 1.000
29.440 52.000 1.000
29.500 39.000 1.000
29.560 39.000 1.000
29.620 46.000 1.000
29.680 39.000 1.000
29.740 32.000 1.000
29.800 36.000 1.000
29.860 31.000 1.000
29.920 33.000 1.000
29.980 34.000 1.000
30.040 26.000 1.000
30.100 35.000 1.000
30.160 30.000 1.000
30.220 27.000 1.000
30.280 36.000 1.000
30.340 24.000 1.000
30.400 20.000 1.000
30.460 30.000 1.000
30.520 29.000 1.000
30.580 31.000 1.000
30.640 28.000 1.000
30.700 29.000 1.000
30.760 28.000 1.000
30.820 39.000 1.000
30.880 31.000 1.000
30.940 20.000 1.000
31.000 27.000 1.000
31.060 21.000 1.000
31.120 29.000 1.000
31.180 30.000 1.000
31.240 17.000 1.000
31.300 23.000 1.000
31.360 28.000 1.000
31.420 17.000 1.000
31.480 23.000 1.000
31.540 19.000 1.000
31.600 29.000 1.000
31.660 24.000 1.000
31.720 16.000 1.000
31.780 35.000 1.000
31.840 22.000 1.000
31.900 25.000 1.000
31.960 24.000 1.000
32.020 19.000 1.000
32.080 18.000 1.000
32.140 25.000 1.000
32.200 18.000 1.000
32.260 16.000 1.000
32.320 20.000 1.000
32.380 21.000 1.000
32.440 15.000 1.000
32.500 12.000 1.000
32.560 23.000 1.000
32.620 12.000 1.000
32.680 16.000 1.000
32.740 17.000 1.000
32.800 22.000 1.000
32.860 17.000 1.000
32.920 19.000 1.000
32.980 15.000 1.000
33.040 28.000 1.000
33.100 20.000 1.000
33.160 18.000 1.000
33.220 14.000 1.000
33.280 18.000 1.000
33.340 15.000 1.000
33.400 21.000 1.000
33.460 25.000 1.000
33.520 18.000 1.000
33.580 18.000 1.000
33.640 13.000 1.000
33.700 12.000 1.000
33.760 16.000 1.000
33.820 15.000 1.000
33.880 15.000 1.000
33.940 14.000 1.000
34.000 16.000 1.000
34.060 14.000 1.000
34.120 18.000 1.000
34.180 16.000 1.000
34.240 16.000 1.000
34.300 14.000 1.000
34.360 18.000 1.000
34.420 20.000 1.000
34.480 21.000 1.000
34.540 17.000 1.000
34.600 23.000 1.000
34.660 23.000 1.000
34.720 17.000 1.000
34.780 25.000 1.000
34.840 29.000 1.000
34.900 28.000 1.000
34.960 26.000 1.000
35.020 29.000 1.000
35.080 30.000 1.000
35.140 23.000 1.000
35.200 23.000 1.000
35.260 18.000 1.000
35.320 21.000 1.000
35.380 25.000 1.000
35.440 20.000 1.000
35.500 16.000 1.000
35.560 22.000 1.000
35.620 26.000 1.000
35.680 20.000 1.000
35.740 24.000 1.000
35.800 22.000 1.000
35.860 24.000 1.000
35.920 23.000 1.000
35.980 23.000 1.000
36.040 22.000 1.000
36.100 22.000 1.000
36.160 20.000 1.000
36.220 20.000 1.000
36.280 17.000 1.000
36.340 17.000 1.000
36.400 21.000 1.000
36.460 22.000 1.000
36.520 17.000 1.000
36.580 16.000 1.000
36.640 25.000 1.000
36.700 27.000 1.000
36.760 23.000 1.000
36.820 15.000 1.000
36.880 13.000 1.000
36.940 18.000 1.000
37.000 23.000 1.000
37.060 19.000 1.000
37.120 21.000 1.000
37.180 27.000 1.000
37.240 22.000 1.000
37.300 20.000 1.000
37.360 12.000 1.000
37.420 12.000 1.000
37.480 19.000 1.000
37.540 19.000 1.000
37.600 12.000 1.000
37.660 21.000 1.000
37.720 23.000 1.000
37.780 14.000 1.000
37.840 25.000 1.000
37.900 16.000 1.000
37.960 20.000 1.000
38.020 16.000 1.000
38.080 19.000 1.000
38.140 21.000 1.000
38.200 19.000 1.000
38.260 16.000 1.000
38.320 13.000 1.000
38.380 19.000 1.000
38.440 16.000 1.000
38.500 16.000 1.000
38.560 14.000 1.000
38.620 19.000 1.000
38.680 23.000 1.000
38.740 18.000 1.000
38.800 17.000 1.000
38.860 14.000 1.000
38.920 12.000 1.000
38.980 14.000 1.000
39.040 16.000 1.000
39.100 20.000 1.000
39.160 19.000 1.000
39.220 15.000 1.000
39.280 17.000 1.000
39.340 24.000 1.000
39.400 15.000 1.000
39.460 15.000 1.000
39.520 11.000 1.000
39.580 15.000 1.000
39.640 11.000 1.000
39.700 21.000 1.000
39.760 15.000 1.000
39.820 16.000 1.000
39.880 12.000 1.000
39.940 21.000 1.000
40.000 15.000 1.000
40.060 19.000 1.000
40.120 14.000 1.000
40.180 12.000 1.000
40.240 14.000 1.000
40.300 17.000 1.000
40.360 10.000 1.000
40.420 22.000 1.000
40.480 20.000 1.000
40.540 21.000 1.000
40.600 28.000 1.000
40.660 26.000 1.000
40.720 16.000 1.000
40.780 17.000 1.000
40.840 16.000 1.000
40.900 25.000 1.000
40.960 17.000 1.000
41.020 13.000 1.000
41.080 15.000 1.000
41.140 23.000 1.000
41.200 17.000 1.000
41.260 21.000 1.000
41.320 13.000 1.000
41.380 15.000 1.000
41.440 14.000 1.000
41.500 23.000 1.000
41.560 20.000 1.000
41.620 16.000 1.000
41.680 24.000 1.000
41.740 15.000 1.000
41.800 19.000 1.000
41.860 11.000 1.000
41.920 27.000 1.000
41.980 15.000 1.000
42.040 26.000 1.000
42.100 17.000 1.000
42.160 19.000 1.000
42.220 18.000 1.000
42.280 22.000 1.000
42.340 20.000 1.000
42.400 16.000 1.000
42.460 17.000 1.000
42.520 26.000 1.000
42.580 16.000 1.000
42.640 22.000 1.000
42.700 24.000 1.000
42.760 33.000 1.000
42.820 38.000 1.000
42.880 41.000 1.000
42.940 45.000 1.000
43.000 45.000 1.000
43.060 53.000 1.000
43.120 38.000 1.000
43.180 30.000 1.000
43.240 31.000 1.000
43.300 27.000 1.000
43.360 22.000 1.000
43.420 25.000 1.000
43.480 14.000 1.000
43.540 21.000 1.000
43.600 22.000 1.000
43.660 18.000 1.000
43.720 28.000 1.000
43.780 26.000 1.000
43.840 19.000 1.000
43.900 17.000 1.000
43.960 22.000 1.000
44.020 27.000 1.000
44.080 22.000 1.000
44.140 23.000 1.000
44.200 22.000 1.000
44.260 19.000 1.000
44.320 22.000 1.000
44.380 21.000 1.000
44.440 21.000 1.000
44.500 23.000 1.000
44.560 23.000 1.000
44.620 28.000 1.000
44.680 24.000 1.000
44.740 19.000 1.000
44.800 26.000 1.000
44.860 15.000 1.000
44.920 23.000 1.000
44.980 20.000 1.000
45.040 25.000 1.000
45.100 20.000 1.000
45.160 19.000 1.000
45.220 14.000 1.000
45.280 13.000 1.000
45.340 19.000 1.000
45.400 18.000 1.000
45.460 27.000 1.000
45.520 17.000 1.000
45.580 19.000 1.000
45.640 16.000 1.000
45.700 20.000 1.000
45.760 19.000 1.000
45.820 18.000 1.000
45.880 18.000 1.000
45.940 18.000 1.000
46.000 14.000 1.000
46.060 16.000 1.000
46.120 21.000 1.000
46.180 17.000 1.000
46.240 16.000 1.000
46.300 21.000 1.000
46.360 20.000 1.000
46.420 16.000 1.000
46.480 19.000 1.000
46.540 23.000 1.000
46.600 17.000 1.000
46.660 25.000 1.000
46.720 14.000 1.000
46.780 18.000 1.000
46.840 16.000 1.000
46.900 25.000 1.000
46.960 21.000 1.000
47.020 19.000 1.000
47.080 16.000 1.000
47.140 19.000 1.000
47.200 19.000 1.000
47.260 15.000 1.000
47.320 21.000 1.000
47.380 20.000 1.000
47.440 12.000 1.000
47.500 22.000 1.000
47.560 17.000 1.000
47.620 17.000 1.000
47.680 11.000 1.000
47.740 24.000 1.000
47.800 17.000 1.000
47.860 19.000 1.000
47.920 16.000 1.000
47.980 9.000 1.000
48.040 19.000 1.000
48.100 15.000 1.000
48.160 12.000 1.000
48.220 8.000 1.000
48.280 15.000 1.000
48.340 13.000 1.000
48.400 17.000 1.000
48.460 21.000 1.000
48.520 29.000 1.000
48.580 22.000 1.000
48.640 16.000 1.000
48.700 18.000 1.000
48.760 22.000 1.000
48.820 16.000 1.000
48.880 16.000 1.000
48.940 16.000 1.000
49.000 17.000 1.000
49.060 13.000 1.000
49.120 11.000 1.000
49.180 16.000 1.000
49.240 15.000 1.000
49.300 17.000 1.000
49.360 12.000 1.000
49.420 18.000 1.000
49.480 19.000 1.000
49.540 20.000 1.000
49.600 19.000 1.000
49.660 16.000 1.000
49.720 12.000 1.000
49.780 17.000 1.000
49.840 19.000 1.000
49.900 20.000 1.000
49.960 21.000 1.000
50.020 19.000 1.000
50.080 17.000 1.000
50.140 18.000 1.000
50.200 15.000 1.000
50.260 14.000 1.000
50.320 23.000 1.000
50.380 25.000 1.000
50.440 19.000 1.000
50.500 26.000 1.000
50.560 19.000 1.000
50.620 23.000 1.000
50.680 12.000 1.000
50.740 18.000 1.000
50.800 22.000 1.000
50.860 17.000 1.000
50.920 18.000 1.000
50.980 28.000 1.000
51.040 17.000 1.000
51.100 13.000 1.000
51.160 17.000 1.000
51.220 13.000 1.000
51.280 19.000 1.000
51.340 15.000 1.000
51.400 19.000 1.000
51.460 19.000 1.000
51.520 19.000 1.000
51.580 14.000 1.000
51.640 19.000 1.000
51.700 18.000 1.000
51.760 19.000 1.000
51.820 24.000 1.000
51.880 16.000 1.000
51.940 25.000 1.000
52.000 33.000 1.000
52.060 25.000 1.000
52.120 21.000 1.000
52.180 23.000 1.000
52.240 29.000 1.000
52.300 23.000 1.000
52.360 30.000 1.000
52.420 25.000 1.000
52.480 27.000 1.000
52.540 28.000 1.000
52.600 33.000 1.000
52.660 27.000 1.000
52.720 24.000 1.000
52.780 28.000 1.000
52.840 33.000 1.000
52.900 31.000 1.000
52.960 42.000 1.000
53.020 26.000 1.000
53.080 24.000 1.000
53.140 33.000 1.000
53.200 31.000 1.000
53.260 26.000 1.000
53.320 35.000 1.000
53.380 35.000 1.000
53.440 34.000 1.000
53.500 40.000 1.000
53.560 35.000 1.000
53.620 37.000 1.000
53.680 34.000 1.000
53.740 33.000 1.000
53.800 48.000 1.000
53.860 47.000 1.000
53.920 35.000 1.000
53.980 35.000 1.000
54.040 37.000 1.000
54.100 53.000 1.000
54.160 43.000 1.000
54.220 53.000 1.000
54.280 60.000 1.000
54.340 66.000 1.000
54.400 75.000 1.000
54.460 87.000 1.000
54.520 88.000 1.000
54.580 86.000 1.000
54.640 64.000 1.000
54.700 61.000 1.000
54.760 51.000 1.000
54.820 43.000 1.000
54.880 37.000 1.000
54.940 37.000 1.000
55.000 22.000 1.000
55.060 27.000 1.000
55.120 22.000 1.000
55.180 29.000 1.000
55.240 16.000 1.000
55.300 18.000 1.000
55.360 27.000 1.000
55.420 18.000 1.000
55.480 23.000 1.000
55.540 15.000 1.000
55.600 18.000 1.000
55.660 17.000 1.000
55.720 17.000 1.000
55.780 21.000 1.000
55.840 20.000 1.000
55.900 12.000 1.000
55.960 18.000 1.000
56.020 16.000 1.000
56.080 18.000 1.000
56.140 8.000 1.000
56.200 17.000 1.000
56.260 18.000 1.000
56.320 17.000 1.000
56.380 18.000 1.000
56.440 19.000 1.000
56.500 19.000 1.000
56.560 12.000 1.000
56.620 17.000 1.000
56.680 13.000 1.000
56.740 13.000 1.000
56.800 12.000 1.000
56.860 15.000 1.000
56.920 16.000 1.000
56.980 18.000 1.000
57.040 17.000 1.000
57.100 23.000 1.000
57.160 13.000 1.000
57.220 17.000 1.000
57.280 17.000 1.000
57.340 17.000 1.000
57.400 17.000 1.000
57.460 16.000 1.000
57.520 14.000 1.000
57.580 20.000 1.000
57.640 17.000 1.000
57.700 25.000 1.000
57.760 17.000 1.000
57.820 18.000 1.000
57.880 17.000 1.000
57.940 17.000 1.000
58.000 14.000 1.000
58.060 7.000 1.000
58.120 12.000 1.000
58.180 10.000 1.000
58.240 14.000 1.000
58.300 15.000 1.000
58.360 17.000 1.000
58.420 12.000 1.000
58.480 15.000 1.000
58.540 14.000 1.000
58.600 13.000 1.000
58.660 18.000 1.000
58.720 15.000 1.000
58.780 12.000 1.000
58.840 12.000 1.000
58.900 15.000 1.000
58.960 16.000 1.000
59.020 16.000 1.000
59.080 11.000 1.000
59.140 16.000 1.000
59.200 6.000 1.000
59.260 14.000 1.000
59.320 16.000 1.000
59.380 11.000 1.000
59.440 8.000 1.000
59.500 14.000 1.000
59.560 17.000 1.000
59.620 17.000 1.000
59.680 12.000 1.000
59.740 14.000 1.000
59.800 14.000 1.000
59.860 15.000 1.000
59.920 15.000 1.000
59.980 10.000 1.000
60.040 18.000 1.000
60.100 16.000 1.000
60.160 11.000 1.000
60.220 10.000 1.000
60.280 13.000 1.000
60.340 16.000 1.000
60.400 16.000 1.000
60.460 15.000 1.000
60.520 16.000 1.000
60.580 15.000 1.000
60.640 15.000 1.000
60.700 12.000 1.000
60.760 11.000 1.000
60.820 17.000 1.000
60.880 16.000 1.000
60.940 17.000 1.000
61.000 17.000 1.000
61.060 15.000 1.000
61.120 20.000 1.000
61.180 15.000 1.000
61.240 11.000 1.000
61.300 24.000 1.000
61.360 22.000 1.000
61.420 17.000 1.000
61.480 20.000 1.000
61.540 21.000 1.000
61.600 37.000 1.000
61.660 21.000 1.000
61.720 36.000 1.000
61.780 18.000 1.000
61.840 23.000 1.000
61.900 21.000 1.000
61.960 28.000 1.000
62.020 26.000 1.000
62.080 20.000 1.000
62.140 23.000 1.000
62.200 18.000 1.000
62.260 17.000 1.000
62.320 22.000 1.000
62.380 19.000 1.000
62.440 15.000 1.000
62.500 16.000 1.000
62.560 17.000 1.000
62.620 9.000 1.000
62.680 15.000 1.000
62.740 12.000 1.000
62.800 10.000 1.000
62.860 18.000 1.000
62.920 14.000 1.000
62.980 12.000 1.000
63.040 13.000 1.000
63.100 17.000 1.000
63.160 16.000 1.000
63.220 17.000 1.000
63.280 15.000 1.000
63.340 10.000 1.000
63.400 14.000 1.000
63.460 13.000 1.000
63.520 9.000 1.000
63.580 10.000 1.000
63.640 9.000 1.000
63.700 10.000 1.000
63.760 18.000 1.000
63.820 18.000 1.000
63.880 11.000 1.000
63.940 13.000 1.000
64.000 15.000 1.000
64.060 13.000 1.000
64.120 10.000 1.000
64.180 13.000 1.000
64.240 13.000 1.000
64.300 12.000 1.000
64.360 11.000 1.000
64.420 10.000 1.000
64.480 14.000 1.000
64.540 14.000 1.000
64.600 16.000 1.000
64.660 11.000 1.000
64.720 10.000 1.000
64.780 12.000 1.000
64.840 13.000 1.000
64.900 4.000 1.000
64.960 13.000 1.000
65.020 12.000 1.000
65.080 14.000 1.000
65.140 13.000 1.000
65.200 15.000 1.000
65.260 15.000 1.000
65.320 18.000 1.000
65.380 11.000 1.000
65.440 12.000 1.000
65.500 15.000 1.000
65.560 17.000 1.000
65.620 17.000 1.000
65.680 11.000 1.000
65.740 15.000 1.000
65.800 10.000 1.000
65.860 14.000 1.000
65.920 14.000 1.000
65.980 13.000 1.000
66.040 12.000 1.000
66.100 9.000 1.000
66.160 13.000 1.000
66.220 8.000 1.000
66.280 16.000 1.000
66.340 12.000 1.000
66.400 9.000 1.000
66.460 15.000 1.000
66.520 11.000 1.000
66.580 11.000 1.000
66.640 9.000 1.000
66.700 7.000 1.000
66.760 12.000 1.000
66.820 13.000 1.000
66.880 14.000 1.000
66.940 13.000 1.000
67.000 13.000 1.000
67.060 15.000 1.000
67.120 12.000 1.000
67.180 13.000 1.000
67.240 14.000 1.000
67.300 17.000 1.000
67.360 12.000 1.000
67.420 14.000 1.000
67.480 7.000 1.000
67.540 14.000 1.000
67.600 9.000 1.000
67.660 14.000 1.000
67.720 7.000 1.000
67.780 17.000 1.000
67.840 11.000 1.000
67.900 16.000 1.000
67.960 10.000 1.000
68.020 10.000 1.000
68.080 8.000 1.000
68.140 7.000 1.000
68.200 12.000 1.000
68.260 12.000 1.000
68.320 7.000 1.000
68.380 13.000 1.000
68.440 10.000 1.000
68.500 10.000 1.000
68.560 12.000 1.000
68.620 19.000 1.000
68.680 10.000 1.000
68.740 13.000 1.000
68.800 11.000 1.000
68.860 16.000 1.000
68.920 14.000 1.000
68.980 10.000 1.000
69.040 15.000 1.000
69.100 15.000 1.000
69.160 14.000 1.000
69.220 10.000 1.000
69.280 15.000 1.000
69.340 8.000 1.000
69.400 11.000 1.000
69.460 15.000 1.000
69.520 13.000 1.000
69.580 9.000 1.000
69.640 6.000 1.000
69.700 14.000 1.000
69.760 10.000 1.000
69.820 14.000 1.000
69.880 19.000 1.000
69.940 8.000 1.000
70.000 14.000 1.000
70.060 12.000 1.000
70.120 10.000 1.000
70.180 19.000 1.000
70.240 8.000 1.000
70.300 13.000 1.000
70.360 12.000 1.000
70.420 10.000 1.000
70.480 14.000 1.000
70.540 12.000 1.000
70.600 9.000 1.000
70.660 12.000 1.000
70.720 12.000 1.000
70.780 17.000 1.000
70.840 7.000 1.000
70.900 10.000 1.000
70.960 7.000 1.000
71.020 14.000 1.000
71.080 14.000 1.000
71.140 10.000 1.000
71.200 11.000 1.000
71.260 10.000 1.000
71.320 9.000 1.000
71.380 9.000 1.000
71.440 13.000 1.000
71.500 10.000 1.000
71.560 13.000 1.000
71.620 11.000 1.000
71.680 5.000 1.000
71.740 11.000 1.000
71.800 15.000 1.000
71.860 12.000 1.000
71.920 5.000 1.000
71.980 16.000 1.000
72.040 10.000 1.000
72.100 11.000 1.000
72.160 14.000 1.000
72.220 16.000 1.000
72.280 12.000 1.000
72.340 11.000 1.000
72.400 16.000 1.000
72.460 11.000 1.000
72.520 15.000 1.000
72.580 15.000 1.000
72.640 16.000 1.000
72.700 9.000 1.000
72.760 18.000 1.000
72.820 14.000 1.000
72.880 17.000 1.000
72.940 15.000 1.000
73.000 17.000 1.000
73.060 10.000 1.000
73.120 20.000 1.000
73.180 16.000 1.000
73.240 9.000 1.000
73.300 13.000 1.000
73.360 23.000 1.000
73.420 8.000 1.000
73.480 11.000 1.000
73.540 13.000 1.000
73.600 11.000 1.000
73.660 15.000 1.000
73.720 14.000 1.000
73.780 19.000 1.000
73.840 20.000 1.000
73.900 21.000 1.000
73.960 14.000 1.000
74.020 9.000 1.000
74.080 12.000 1.000
74.140 14.000 1.000
74.200 17.000 1.000
74.260 15.000 1.000
74.320 14.000 1.000
74.380 12.000 1.000
74.440 16.000 1.000
74.500 16.000 1.000
74.560 16.000 1.000
74.620 16.000 1.000
74.680 8.000 1.000
74.740 17.000 1.000
74.800 9.000 1.000
74.860 10.000 1.000
74.920 12.000 1.000
74.980 11.000 1.000
75.040 11.000 1.000
75.100 13.000 1.000
75.160 12.000 1.000
75.220 12.000 1.000
75.280 14.000 1.000
75.340 9.000 1.000
75.400 11.000 1.000
75.460 7.000 1.000
75.520 16.000 1.000
75.580 11.000 1.000
75.640 9.000 1.000
75.700 17.000 1.000
75.760 12.000 1.000
75.820 7.000 1.000
75.880 15.000 1.000
75.940 12.000 1.000
76.000 12.000 1.000
76.060 9.000 1.000
76.120 19.000 1.000
76.180 14.000 1.000
76.240 21.000 1.000
76.300 9.000 1.000
76.360 12.000 1.000
76.420 12.000 1.000
76.480 13.000 1.000
76.540 15.000 1.000
76.600 10.000 1.000
76.660 14.000 1.000
76.720 18.000 1.000
76.780 12.000 1.000
76.840 8.000 1.000
76.900 11.000 1.000
76.960 14.000 1.000
77.020 21.000 1.000
77.080 17.000 1.000
77.140 9.000 1.000
77.200 16.000 1.000
77.260 9.000 1.000
77.320 15.000 1.000
77.380 16.000 1.000
77.440 11.000 1.000
77.500 13.000 1.000
77.560 21.000 1.000
77.620 12.000 1.000
77.680 17.000 1.000
77.740 13.000 1.000
77.800 11.000 1.000
77.860 14.000 1.000
77.920 15.000 1.000
77.980 16.000 1.000
78.040 17.000 1.000
78.100 15.000 1.000
78.160 8.000 1.000
78.220 14.000 1.000
78.280 15.000 1.000
78.340 12.000 1.000
78.400 11.000 1.000
78.460 16.000 1.000
78.520 10.000 1.000
78.580 16.000 1.000
78.640 13.000 1.000
78.700 12.000 1.000
78.760 10.000 1.000
78.820 13.000 1.000
78.880 12.000 1.000
78.940 13.000 1.000
79.000 13.000 1.000
79.060 16.000 1.000
79.120 10.000 1.000
79.180 11.000 1.000
79.240 16.000 1.000
79.300 15.000 1.000
79.360 10.000 1.000
79.420 14.000 1.000
79.480 7.000 1.000
79.540 12.000 1.000
79.600 13.000 1.000
79.660 16.000 1.000
79.720 6.000 1.000
79.780 11.000 1.000
79.840 7.000 1.000
79.900 13.000 1.000
79.960 11.000 1.000
80.020 12.000 1.000
80.080 10.000 1.000
80.140 12.000 1.000
80.200 10.000 1.000
80.260 14.000 1.000
80.320 11.000 1.000
80.380 10.000 1.000
80.440 8.000 1.000
80.500 8.000 1.000
80.560 8.000 1.000
80.620 9.000 1.000
80.680 11.000 1.000
80.740 14.000 1.000
80.800 9.000 1.000
80.860 5.000 1.000
80.920 8.000 1.000
80.980 13.000 1.000
81.040 11.000 1.000
81.100 11.000 1.000
81.160 15.000 1.000
81.220 7.000 1.000
81.280 8.000 1.000
81.340 9.000 1.000
81.400 10.000 1.000
81.460 11.000 1.000
81.520 10.000 1.000
81.580 11.000 1.000
81.640 12.000 1.000
81.700 10.000 1.000
81.760 12.000 1.000
81.820 15.000 1.000
81.880 9.000 1.000
81.940 15.000 1.000
82.000 16.000 1.000
82.060 10.000 1.000
82.120 8.000 1.000
82.180 9.000 1.000
82.240 10.000 1.000
82.300 13.000 1.000
82.360 18.000 1.000
82.420 14.000 1.000
82.480 12.000 1.000
82.540 7.000 1.000
82.600 8.000 1.000
82.660 11.000 1.000
82.720 10.000 1.000
82.780 18.000 1.000
82.840 13.000 1.000
82.900 14.000 1.000
82.960 8.000 1.000
83.020 16.000 1.000
83.080 6.000 1.000
83.140 11.000 1.000
83.200 11.000 1.000
83.260 13.000 1.000
83.320 8.000 1.000
83.380 13.000 1.000
83.440 11.000 1.000
83.500 15.000 1.000
83.560 8.000 1.000
83.620 11.000 1.000
83.680 10.000 1.000
83.740 13.000 1.000
83.800 13.000 1.000
83.860 12.000 1.000
83.920 11.000 1.000
83.980 13.000 1.000
84.040 10.000 1.000
84.100 17.000 1.000
84.160 9.000 1.000
84.220 9.000 1.000
84.280 11.000 1.000
84.340 12.000 1.000
84.400 14.000 1.000
84.460 8.000 1.000
84.520 18.000 1.000
84.580 9.000 1.000
84.640 10.000 1.000
84.700 14.000 1.000
84.760 11.000 1.000
84.820 8.000 1.000
84.880 11.000 1.000
84.940 10.000 1.000
85.000 11.000 1.000
85.060 9.000 1.000
85.120 14.000 1.000
85.180 16.000 1.000
85.240 12.000 1.000
85.300 11.000 1.000
85.360 7.000 1.000
85.420 12.000 1.000
85.480 20.000 1.000
85.540 16.000 1.000
85.600 11.000 1.000
85.660 12.000 1.000
85.720 15.000 1.000
85.780 10.000 1.000
85.840 12.000 1.000
85.900 6.000 1.000
85.960 5.000 1.000
86.020 12.000 1.000
86.080 16.000 1.000
86.140 14.000 1.000
86.200 14.000 1.000
86.260 10.000 1.000
86.320 15.000 1.000
86.380 17.000 1.000
86.440 14.000 1.000
86.500 15.000 1.000
86.560 19.000 1.000
86.620 13.000 1.000
86.680 15.000 1.000
86.740 15.000 1.000
86.800 13.000 1.000
86.860 13.000 1.000
86.920 16.000 1.000
86.980 11.000 1.000
87.040 15.000 1.000
87.100 16.000 1.000
87.160 18.000 1.000
87.220 10.000 1.000
87.280 9.000 1.000
87.340 17.000 1.000
87.400 11.000 1.000
87.460 11.000 1.000
87.520 8.000 1.000
87.580 16.000 1.000
87.640 11.000 1.000
87.700 7.000 1.000
87.760 10.000 1.000
87.820 8.000 1.000
87.880 12.000 1.000
87.940 8.000 1.000
88.000 14.000 1.000
88.060 15.000 1.000
88.120 14.000 1.000
88.180 11.000 1.000
88.240 7.000 1.000
88.300 7.000 1.000
88.360 7.000 1.000
88.420 8.000 1.000
88.480 14.000 1.000
88.540 11.000 1.000
88.600 7.000 1.000
88.660 8.000 1.000
88.720 9.000 1.000
88.780 9.000 1.000
88.840 9.000 1.000
88.900 6.000 1.000
88.960 12.000 1.000
89.020 6.000 1.000
89.080 10.000 1.000
89.140 5.000 1.000
89.200 13.000 1.000
89.260 12.000 1.000
89.320 7.000 1.000
89.380 11.000 1.000
89.440 10.000 1.000
89.500 7.000 1.000
89.560 5.000 1.000
89.620 10.000 1.000
89.680 11.000 1.000
89.740 16.000 1.000
89.800 10.000 1.000
89.860 8.000 1.000
89.920 10.000 1.000
89.980 7.000 1.000
90.000 6.000 1.000
*RAS_INT_END
*RAS_DATA_END