File: Lab/XRD/20170907/cu2o_014_step0.02_speed20-4-1329-1.ras
*RAS_DATA_START
*RAS_HEADER_START
*CORR_POS_DB_NAME "DTEX_11112016"
*CORR_POS_GONIO_RADIUS ""
*CORR_POS_NODE_INDEX01 ""
*CORR_POS_NODE_INDEX02 ""
*CORR_POS_NODE_INDEX03 ""
*CORR_POS_NODE_INDEX04 ""
*CORR_POS_NODE_INDEX05 ""
*CORR_POS_NODE_INDEX06 ""
*CORR_POS_NODE_INDEX07 ""
*CORR_POS_NODE_INDEX08 ""
*CORR_POS_NODE_INDEX09 ""
*CORR_POS_NODE_INDEX10 ""
*CORR_POS_NODE_INDEX11 ""
*CORR_POS_NODE_LABEL01 "Si(111)"
*CORR_POS_NODE_LABEL02 "Si(220)"
*CORR_POS_NODE_LABEL03 "Si(311)"
*CORR_POS_NODE_LABEL04 "Si(400)"
*CORR_POS_NODE_LABEL05 "Si(331)"
*CORR_POS_NODE_LABEL06 "Si(422)"
*CORR_POS_NODE_LABEL07 "Si(511)"
*CORR_POS_NODE_LABEL08 "Si(440)"
*CORR_POS_NODE_LABEL09 "Si(531)"
*CORR_POS_NODE_LABEL10 "Si(620)"
*CORR_POS_NODE_LABEL11 "Si(533)"
*CORR_POS_NODE_POS_CALC01 "28.4137"
*CORR_POS_NODE_POS_CALC02 "47.2707"
*CORR_POS_NODE_POS_CALC03 "56.0883"
*CORR_POS_NODE_POS_CALC04 "69.0934"
*CORR_POS_NODE_POS_CALC05 "76.3385"
*CORR_POS_NODE_POS_CALC06 "87.9915"
*CORR_POS_NODE_POS_CALC07 "94.9137"
*CORR_POS_NODE_POS_CALC08 "106.67"
*CORR_POS_NODE_POS_CALC09 "114.054"
*CORR_POS_NODE_POS_CALC10 "127.508"
*CORR_POS_NODE_POS_CALC11 "136.858"
*CORR_POS_NODE_POS_MEAS01 "28.3712"
*CORR_POS_NODE_POS_MEAS02 "47.2304"
*CORR_POS_NODE_POS_MEAS03 "56.0465"
*CORR_POS_NODE_POS_MEAS04 "69.0523"
*CORR_POS_NODE_POS_MEAS05 "76.2993"
*CORR_POS_NODE_POS_MEAS06 "87.9512"
*CORR_POS_NODE_POS_MEAS07 "94.8772"
*CORR_POS_NODE_POS_MEAS08 "106.636"
*CORR_POS_NODE_POS_MEAS09 "114.028"
*CORR_POS_NODE_POS_MEAS10 "127.48"
*CORR_POS_NODE_POS_MEAS11 "136.839"
*CORR_POS_OPT_ATTR "集中法"
*CORR_POS_PARAM_MU ""
*CORR_POS_PARAM_PL ""
*CORR_POS_SEMODEL_TYPE "0"
*CORR_POS_STANDARD_TYPE ""
*CORR_POS_VALUE_ANALYZER "None"
*CORR_POS_VALUE_CMONO "None"
*CORR_POS_VALUE_IMONO "None"
*CORR_POS_VALUE_IS "0.625deg"
*CORR_POS_VALUE_ISL "10.0mm"
*CORR_POS_VALUE_ISOLLER "2.5deg"
*CORR_POS_VALUE_RS1 "13.0mm"
*CORR_POS_VALUE_RS2 "13.0mm"
*CORR_POS_VALUE_RSOLLER "2.5deg"
*CORR_POS_XG_FOCUS_L ""
*CORR_POS_XG_WAVE_TYPE ""
*CORR_POS_XG_WAVE_VALUE ""
*DISP_FMT_X "%.2f"
*DISP_FMT_Y "%.0f"
*DISP_FULLSCALE "4942.8000000000"
*DISP_LINE_COLOR "255.0000000000"
*DISP_LINE_STYLE "0.0000000000"
*DISP_LINE_WIDTH "0.2500000000"
*DISP_NOTE "Collected Data-1"
*DISP_OFFSET_Y "0.0000000000"
*DISP_PEAKSEARCH_UNIT_Y "COUNTS"
*DISP_RANGE_BOTTOM "0.0000000000"
*DISP_RANGE_LEFT "20.0000000000"
*DISP_RANGE_LOGCUTOFF "0.0100000000"
*DISP_RANGE_RIGHT "90.0000000000"
*DISP_RANGE_TOP "4942.8000000000"
*DISP_SCALE_MODE_Y "0.0000000000"
*DISP_TAB_NAME "Theta/2-Theta"
*DISP_TITLE_Y "Intensity"
*DISP_UNIT_Y "COUNTS"
*DISP_WINDOW_NAME "MSG_MACROENGINE"
*FILE_COMMENT " "
*FILE_MD5 ""
*FILE_MEMO " "
*FILE_OPERATOR "MiniFlex"
*FILE_PART_ID "MEAS_PBEA_00223"
*FILE_SAMPLE "cu2o_014_step0.02_speed20"
*FILE_TYPE "RAS_RAW"
*FILE_USERGROUP "System User"
*FILE_VERSION "1.0000000000"
*HW_ATTACHMENT_ID "ATT1031"
*HW_ATTACHMENT_NAME "6サンプルチェンジャ|ASC-6"
*HW_COUNTER_ID-0 "CUT0025"
*HW_COUNTER_ID-1 "CUT0020"
*HW_COUNTER_ID-2 "CUT0020"
*HW_COUNTER_ID-3 "CMC0021"
*HW_COUNTER_NAME-0 "D/teX Ultra|D/teX Ultra"
*HW_COUNTER_NAME-1 "None|None"
*HW_COUNTER_NAME-2 "None|None"
*HW_COUNTER_NAME-3 "検出器モノクロメータ|Detector monochromator"
*HW_COUNTER_SELECT_NAME "D/teX Ultra|D/teX Ultra"
*HW_GONIOMETER_ID "GON0070"
*HW_GONIOMETER_NAME "MiniFlex 300/600|MiniFlex 300/600"
*HW_GONIOMETER_RADIUS-0 "79.0"
*HW_GONIOMETER_RADIUS-1 "91.5"
*HW_GONIOMETER_RADIUS-2 "150.0"
*HW_GONIOMETER_RADIUS-3 "0"
*HW_GONIOMETER_RADIUS-4 "103.4"
*HW_GONIOMETER_RADIUS-5 "150.0"
*HW_GONIOMETER_RADIUS-6 "46.6"
*HW_GONIOMETER_RADIUS-7 "160.0"
*HW_I_OPT_ID-0 "ISL0021"
*HW_I_OPT_ID-1 "ISO0021"
*HW_I_OPT_NAME-0 "発散スリット|Divergence slit"
*HW_I_OPT_NAME-1 "入射平行スリット|Incident parallel slit"
*HW_R_ATTENUATER_AUTOMODE "0"
*HW_R_OPT_ID-0 "RSS0021"
*HW_R_OPT_ID-1 "RSO0021"
*HW_R_OPT_ID-2 "RRS0021"
*HW_R_OPT_NAME-0 "散乱スリット|Scattering slit"
*HW_R_OPT_NAME-1 "受光平行スリット|Receiving soller slit"
*HW_R_OPT_NAME-2 "受光スリット|Receiving slit"
*HW_SAMPLE_HOLDER_ID "SMP0000"
*HW_SAMPLE_HOLDER_NAME "無し|None"
*HW_XG_CURRENT_MAX "15"
*HW_XG_CURRENT_MIN "2"
*HW_XG_CURRENT_RESOLUTION "1"
*HW_XG_CURRENT_UNIT "mA"
*HW_XG_FOCUS "1mm x 10mm"
*HW_XG_FOCUS_TYPE "Normal"
*HW_XG_ID "1060"
*HW_XG_NAME "300W/600W 封入管-B|300W/600W Sealed tube-B"
*HW_XG_TARGET_ATOMIC_NUMBER "29.0000000000"
*HW_XG_TARGET_NAME "Cu"
*HW_XG_TYPE "Hermetic"
*HW_XG_VOLTAGE_MAX "40"
*HW_XG_VOLTAGE_MIN "20"
*HW_XG_VOLTAGE_RESOLUTION "1"
*HW_XG_VOLTAGE_UNIT "kV"
*HW_XG_WATT_MAX "1"
*HW_XG_WATT_UNIT "kW"
*HW_XG_WAVE_LENGTH_ALPHA1 "1.540593"
*HW_XG_WAVE_LENGTH_ALPHA2 "1.544414"
*HW_XG_WAVE_LENGTH_BETA "1.392250"
*MEAS_COND_AXIS_NAME-0 "Theta/2-Theta"
*MEAS_COND_AXIS_NAME-1 "Spin"
*MEAS_COND_AXIS_NAME-2 "Change"
*MEAS_COND_AXIS_NAME-3 "Soller(inc.)"
*MEAS_COND_AXIS_NAME-4 "IHS"
*MEAS_COND_AXIS_NAME-5 "DS"
*MEAS_COND_AXIS_NAME-6 "SS"
*MEAS_COND_AXIS_NAME-7 "Soller(rec.)"
*MEAS_COND_AXIS_NAME-8 "RS"
*MEAS_COND_AXIS_NAME-9 "Filter"
*MEAS_COND_AXIS_NAME-10 "Monochromator"
*MEAS_COND_AXIS_NAME-11 "PHA"
*MEAS_COND_AXIS_NAME_INTERNAL-0 "TwoThetaTheta"
*MEAS_COND_AXIS_NAME_INTERNAL-1 "Spin"
*MEAS_COND_AXIS_NAME_INTERNAL-2 "Change"
*MEAS_COND_AXIS_NAME_INTERNAL-3 "IncidentSollerSlit"
*MEAS_COND_AXIS_NAME_INTERNAL-4 "IncidentAxdSlit"
*MEAS_COND_AXIS_NAME_INTERNAL-5 "IncidentSlitBox"
*MEAS_COND_AXIS_NAME_INTERNAL-6 "ReceivingSlitBox1"
*MEAS_COND_AXIS_NAME_INTERNAL-7 "ReceivingSollerSlit"
*MEAS_COND_AXIS_NAME_INTERNAL-8 "ReceivingSlitBox2"
*MEAS_COND_AXIS_NAME_INTERNAL-9 "Filter"
*MEAS_COND_AXIS_NAME_INTERNAL-10 "CounterMonochromator"
*MEAS_COND_AXIS_NAME_INTERNAL-11 "PHA"
*MEAS_COND_AXIS_NAME_MAGICNO-0 "268632064.0000000000"
*MEAS_COND_AXIS_NAME_MAGICNO-1 "16842752.0000000000"
*MEAS_COND_AXIS_NAME_MAGICNO-2 "16842752.0000000000"
*MEAS_COND_AXIS_NAME_MAGICNO-3 "20971521.0000000000"
*MEAS_COND_AXIS_NAME_MAGICNO-4 "22020097.0000000000"
*MEAS_COND_AXIS_NAME_MAGICNO-5 "22020097.0000000000"
*MEAS_COND_AXIS_NAME_MAGICNO-6 "23068673.0000000000"
*MEAS_COND_AXIS_NAME_MAGICNO-7 "20971521.0000000000"
*MEAS_COND_AXIS_NAME_MAGICNO-8 "23068673.0000000000"
*MEAS_COND_AXIS_NAME_MAGICNO-9 "20971521.0000000000"
*MEAS_COND_AXIS_NAME_MAGICNO-10 "20971521.0000000000"
*MEAS_COND_AXIS_NAME_MAGICNO-11 "0.0000000000"
*MEAS_COND_AXIS_OFFSET-0 "0.0000000000"
*MEAS_COND_AXIS_OFFSET-1 "-"
*MEAS_COND_AXIS_OFFSET-2 "-"
*MEAS_COND_AXIS_OFFSET-3 "-"
*MEAS_COND_AXIS_OFFSET-4 "-"
*MEAS_COND_AXIS_OFFSET-5 "-"
*MEAS_COND_AXIS_OFFSET-6 "-"
*MEAS_COND_AXIS_OFFSET-7 "-"
*MEAS_COND_AXIS_OFFSET-8 "-"
*MEAS_COND_AXIS_OFFSET-9 "-"
*MEAS_COND_AXIS_OFFSET-10 "-"
*MEAS_COND_AXIS_OFFSET-11 "-"
*MEAS_COND_AXIS_POSITION-0 "10.0000000000"
*MEAS_COND_AXIS_POSITION-1 "0.0000000000"
*MEAS_COND_AXIS_POSITION-2 "4.0000000000"
*MEAS_COND_AXIS_POSITION-3 "2.5deg"
*MEAS_COND_AXIS_POSITION-4 "2.0mm"
*MEAS_COND_AXIS_POSITION-5 "0.625deg"
*MEAS_COND_AXIS_POSITION-6 "13.0mm(Open)"
*MEAS_COND_AXIS_POSITION-7 "2.5deg"
*MEAS_COND_AXIS_POSITION-8 "13.0mm"
*MEAS_COND_AXIS_POSITION-9 "K-beta(x2)"
*MEAS_COND_AXIS_POSITION-10 "None"
*MEAS_COND_AXIS_POSITION-11 "41.0000000000"
*MEAS_COND_AXIS_UNIT-0 "deg"
*MEAS_COND_AXIS_UNIT-1 ""
*MEAS_COND_AXIS_UNIT-2 ""
*MEAS_COND_AXIS_UNIT-3 ""
*MEAS_COND_AXIS_UNIT-4 ""
*MEAS_COND_AXIS_UNIT-5 ""
*MEAS_COND_AXIS_UNIT-6 ""
*MEAS_COND_AXIS_UNIT-7 ""
*MEAS_COND_AXIS_UNIT-8 ""
*MEAS_COND_AXIS_UNIT-9 ""
*MEAS_COND_AXIS_UNIT-10 ""
*MEAS_COND_AXIS_UNIT-11 "div"
*MEAS_COND_CORRECTION_SLIT_COUNTERMONO "None"
*MEAS_COND_CORRECTION_SLIT_DS "0.625deg"
*MEAS_COND_CORRECTION_SLIT_FILTER "None"
*MEAS_COND_CORRECTION_SLIT_IHS "2.0mm"
*MEAS_COND_CORRECTION_SLIT_RS "13.0mm"
*MEAS_COND_CORRECTION_SLIT_SOLLER_INC "2.5deg"
*MEAS_COND_CORRECTION_SLIT_SOLLER_REC "2.5deg"
*MEAS_COND_CORRECTION_SLIT_SS "13.0mm"
*MEAS_COND_COUNTER_CNTLOSS_CORR "0.0000000000"
*MEAS_COND_COUNTER_PHABASE "41.0000000000"
*MEAS_COND_COUNTER_PHAWINDOW "14.0000000000"
*MEAS_COND_COUNTER_PHA_UNIT "div"
*MEAS_COND_COUNTER_TAUDIFF "0.2500000000"
*MEAS_COND_COUNTER_TAUINT "0.7500000000"
*MEAS_COND_IRRADIATION_MODE "OFF"
*MEAS_COND_IRRADIATION_WIDTH ""
*MEAS_COND_OPT_ATTR " "
*MEAS_COND_OPT_NAME ""
*MEAS_COND_UNSYMMETRIC_MODE "OFF"
*MEAS_COND_XG_CURRENT "15.0000000000"
*MEAS_COND_XG_VOLTAGE "40.0000000000"
*MEAS_COND_XG_WAVE_TYPE "Ka"
*MEAS_DATA_COUNT "3501.0000000000"
*MEAS_SCAN_AXIS_X "Theta/2-Theta"
*MEAS_SCAN_AXIS_X_INTERNAL "TwoThetaTheta"
*MEAS_SCAN_END_TIME "09/07/17 13:33:43"
*MEAS_SCAN_MODE "CONTINUOUS"
*MEAS_SCAN_MONITOR "0"
*MEAS_SCAN_RESOLUTION_X "0.005"
*MEAS_SCAN_SPEED "20.000"
*MEAS_SCAN_SPEED_UNIT "deg/min"
*MEAS_SCAN_SPEED_USER "20.000"
*MEAS_SCAN_START "20.0000000000"
*MEAS_SCAN_START_TIME "09/07/17 13:29:41"
*MEAS_SCAN_STEP "0.0200000000"
*MEAS_SCAN_STOP "90.0000000000"
*MEAS_SCAN_UNIT_X "deg"
*MEAS_SCAN_UNIT_Y "counts"
*SLIT_SYSTEM "0"
*RAS_HEADER_END
*RAS_INT_START
20.000 156.000 1.000
20.060 156.000 1.000
20.120 124.000 1.000
20.180 134.000 1.000
20.240 144.000 1.000
20.300 142.000 1.000
20.360 138.000 1.000
20.420 143.000 1.000
20.480 137.000 1.000
20.540 132.000 1.000
20.600 129.000 1.000
20.660 138.000 1.000
20.720 129.000 1.000
20.780 134.000 1.000
20.840 139.000 1.000
20.900 149.000 1.000
20.960 133.000 1.000
21.020 133.000 1.000
21.080 139.000 1.000
21.140 138.000 1.000
21.200 127.000 1.000
21.260 135.000 1.000
21.320 149.000 1.000
21.380 135.000 1.000
21.440 134.000 1.000
21.500 127.000 1.000
21.560 143.000 1.000
21.620 128.000 1.000
21.680 135.000 1.000
21.740 147.000 1.000
21.800 140.000 1.000
21.860 158.000 1.000
21.920 151.000 1.000
21.980 141.000 1.000
22.040 148.000 1.000
22.100 151.000 1.000
22.160 151.000 1.000
22.220 164.000 1.000
22.280 147.000 1.000
22.340 155.000 1.000
22.400 145.000 1.000
22.460 151.000 1.000
22.520 144.000 1.000
22.580 152.000 1.000
22.640 144.000 1.000
22.700 160.000 1.000
22.760 159.000 1.000
22.820 146.000 1.000
22.880 161.000 1.000
22.940 158.000 1.000
23.000 136.000 1.000
23.060 172.000 1.000
23.120 158.000 1.000
23.180 181.000 1.000
23.240 164.000 1.000
23.300 161.000 1.000
23.360 177.000 1.000
23.420 192.000 1.000
23.480 215.000 1.000
23.540 153.000 1.000
23.600 187.000 1.000
23.660 196.000 1.000
23.720 185.000 1.000
23.780 206.000 1.000
23.840 189.000 1.000
23.900 215.000 1.000
23.960 218.000 1.000
24.020 223.000 1.000
24.080 213.000 1.000
24.140 232.000 1.000
24.200 241.000 1.000
24.260 258.000 1.000
24.320 257.000 1.000
24.380 236.000 1.000
24.440 241.000 1.000
24.500 256.000 1.000
24.560 271.000 1.000
24.620 301.000 1.000
24.680 285.000 1.000
24.740 348.000 1.000
24.800 346.000 1.000
24.860 326.000 1.000
24.920 362.000 1.000
24.980 382.000 1.000
25.040 412.000 1.000
25.100 428.000 1.000
25.160 483.000 1.000
25.220 544.000 1.000
25.280 525.000 1.000
25.340 578.000 1.000
25.400 642.000 1.000
25.460 699.000 1.000
25.520 710.000 1.000
25.580 705.000 1.000
25.640 824.000 1.000
25.700 842.000 1.000
25.760 953.000 1.000
25.820 958.000 1.000
25.880 1029.000 1.000
25.940 1052.000 1.000
26.000 1142.000 1.000
26.060 1197.000 1.000
26.120 1268.000 1.000
26.180 1449.000 1.000
26.240 1782.000 1.000
26.300 2396.000 1.000
26.360 3390.000 1.000
26.420 4119.000 1.000
26.480 3680.000 1.000
26.540 2231.000 1.000
26.600 1266.000 1.000
26.660 788.000 1.000
26.720 626.000 1.000
26.780 515.000 1.000
26.840 450.000 1.000
26.900 400.000 1.000
26.960 364.000 1.000
27.020 352.000 1.000
27.080 287.000 1.000
27.140 281.000 1.000
27.200 285.000 1.000
27.260 284.000 1.000
27.320 265.000 1.000
27.380 226.000 1.000
27.440 242.000 1.000
27.500 243.000 1.000
27.560 213.000 1.000
27.620 195.000 1.000
27.680 205.000 1.000
27.740 187.000 1.000
27.800 173.000 1.000
27.860 176.000 1.000
27.920 176.000 1.000
27.980 166.000 1.000
28.040 163.000 1.000
28.100 167.000 1.000
28.160 181.000 1.000
28.220 152.000 1.000
28.280 175.000 1.000
28.340 151.000 1.000
28.400 154.000 1.000
28.460 148.000 1.000
28.520 148.000 1.000
28.580 154.000 1.000
28.640 157.000 1.000
28.700 142.000 1.000
28.760 145.000 1.000
28.820 145.000 1.000
28.880 128.000 1.000
28.940 134.000 1.000
29.000 142.000 1.000
29.060 127.000 1.000
29.120 129.000 1.000
29.180 136.000 1.000
29.240 142.000 1.000
29.300 141.000 1.000
29.360 157.000 1.000
29.420 152.000 1.000
29.480 192.000 1.000
29.540 193.000 1.000
29.600 231.000 1.000
29.660 208.000 1.000
29.720 203.000 1.000
29.780 165.000 1.000
29.840 170.000 1.000
29.900 132.000 1.000
29.960 134.000 1.000
30.020 119.000 1.000
30.080 132.000 1.000
30.140 142.000 1.000
30.200 119.000 1.000
30.260 125.000 1.000
30.320 134.000 1.000
30.380 113.000 1.000
30.440 119.000 1.000
30.500 105.000 1.000
30.560 114.000 1.000
30.620 114.000 1.000
30.680 119.000 1.000
30.740 129.000 1.000
30.800 128.000 1.000
30.860 132.000 1.000
30.920 117.000 1.000
30.980 113.000 1.000
31.040 120.000 1.000
31.100 123.000 1.000
31.160 114.000 1.000
31.220 118.000 1.000
31.280 117.000 1.000
31.340 116.000 1.000
31.400 124.000 1.000
31.460 122.000 1.000
31.520 118.000 1.000
31.580 112.000 1.000
31.640 107.000 1.000
31.700 108.000 1.000
31.760 107.000 1.000
31.820 113.000 1.000
31.880 115.000 1.000
31.940 118.000 1.000
32.000 124.000 1.000
32.060 115.000 1.000
32.120 114.000 1.000
32.180 131.000 1.000
32.240 123.000 1.000
32.300 111.000 1.000
32.360 109.000 1.000
32.420 116.000 1.000
32.480 107.000 1.000
32.540 118.000 1.000
32.600 108.000 1.000
32.660 106.000 1.000
32.720 107.000 1.000
32.780 110.000 1.000
32.840 123.000 1.000
32.900 112.000 1.000
32.960 114.000 1.000
33.020 103.000 1.000
33.080 107.000 1.000
33.140 117.000 1.000
33.200 113.000 1.000
33.260 121.000 1.000
33.320 109.000 1.000
33.380 107.000 1.000
33.440 108.000 1.000
33.500 112.000 1.000
33.560 84.000 1.000
33.620 109.000 1.000
33.680 117.000 1.000
33.740 114.000 1.000
33.800 87.000 1.000
33.860 111.000 1.000
33.920 117.000 1.000
33.980 108.000 1.000
34.040 101.000 1.000
34.100 118.000 1.000
34.160 101.000 1.000
34.220 95.000 1.000
34.280 111.000 1.000
34.340 124.000 1.000
34.400 115.000 1.000
34.460 117.000 1.000
34.520 106.000 1.000
34.580 122.000 1.000
34.640 125.000 1.000
34.700 112.000 1.000
34.760 107.000 1.000
34.820 132.000 1.000
34.880 115.000 1.000
34.940 108.000 1.000
35.000 112.000 1.000
35.060 151.000 1.000
35.120 146.000 1.000
35.180 126.000 1.000
35.240 132.000 1.000
35.300 119.000 1.000
35.360 140.000 1.000
35.420 137.000 1.000
35.480 143.000 1.000
35.540 136.000 1.000
35.600 132.000 1.000
35.660 142.000 1.000
35.720 140.000 1.000
35.780 142.000 1.000
35.840 162.000 1.000
35.900 174.000 1.000
35.960 202.000 1.000
36.020 182.000 1.000
36.080 188.000 1.000
36.140 237.000 1.000
36.200 313.000 1.000
36.260 462.000 1.000
36.320 802.000 1.000
36.380 1288.000 1.000
36.440 1615.000 1.000
36.500 1594.000 1.000
36.560 1189.000 1.000
36.620 760.000 1.000
36.680 435.000 1.000
36.740 272.000 1.000
36.800 212.000 1.000
36.860 174.000 1.000
36.920 177.000 1.000
36.980 170.000 1.000
37.040 152.000 1.000
37.100 161.000 1.000
37.160 135.000 1.000
37.220 148.000 1.000
37.280 128.000 1.000
37.340 132.000 1.000
37.400 125.000 1.000
37.460 115.000 1.000
37.520 114.000 1.000
37.580 106.000 1.000
37.640 114.000 1.000
37.700 120.000 1.000
37.760 107.000 1.000
37.820 116.000 1.000
37.880 116.000 1.000
37.940 122.000 1.000
38.000 120.000 1.000
38.060 122.000 1.000
38.120 107.000 1.000
38.180 125.000 1.000
38.240 115.000 1.000
38.300 122.000 1.000
38.360 124.000 1.000
38.420 117.000 1.000
38.480 116.000 1.000
38.540 106.000 1.000
38.600 106.000 1.000
38.660 109.000 1.000
38.720 104.000 1.000
38.780 113.000 1.000
38.840 105.000 1.000
38.900 115.000 1.000
38.960 109.000 1.000
39.020 111.000 1.000
39.080 107.000 1.000
39.140 96.000 1.000
39.200 108.000 1.000
39.260 111.000 1.000
39.320 109.000 1.000
39.380 112.000 1.000
39.440 121.000 1.000
39.500 108.000 1.000
39.560 108.000 1.000
39.620 109.000 1.000
39.680 100.000 1.000
39.740 117.000 1.000
39.800 109.000 1.000
39.860 98.000 1.000
39.920 107.000 1.000
39.980 91.000 1.000
40.040 110.000 1.000
40.100 106.000 1.000
40.160 96.000 1.000
40.220 116.000 1.000
40.280 133.000 1.000
40.340 112.000 1.000
40.400 103.000 1.000
40.460 105.000 1.000
40.520 109.000 1.000
40.580 92.000 1.000
40.640 114.000 1.000
40.700 114.000 1.000
40.760 121.000 1.000
40.820 119.000 1.000
40.880 108.000 1.000
40.940 114.000 1.000
41.000 115.000 1.000
41.060 99.000 1.000
41.120 121.000 1.000
41.180 114.000 1.000
41.240 106.000 1.000
41.300 104.000 1.000
41.360 93.000 1.000
41.420 117.000 1.000
41.480 136.000 1.000
41.540 99.000 1.000
41.600 125.000 1.000
41.660 116.000 1.000
41.720 125.000 1.000
41.780 136.000 1.000
41.840 133.000 1.000
41.900 143.000 1.000
41.960 136.000 1.000
42.020 169.000 1.000
42.080 182.000 1.000
42.140 228.000 1.000
42.200 318.000 1.000
42.260 423.000 1.000
42.320 509.000 1.000
42.380 511.000 1.000
42.440 457.000 1.000
42.500 400.000 1.000
42.560 248.000 1.000
42.620 209.000 1.000
42.680 175.000 1.000
42.740 146.000 1.000
42.800 138.000 1.000
42.860 140.000 1.000
42.920 154.000 1.000
42.980 136.000 1.000
43.040 167.000 1.000
43.100 148.000 1.000
43.160 157.000 1.000
43.220 138.000 1.000
43.280 164.000 1.000
43.340 159.000 1.000
43.400 133.000 1.000
43.460 151.000 1.000
43.520 155.000 1.000
43.580 125.000 1.000
43.640 117.000 1.000
43.700 120.000 1.000
43.760 132.000 1.000
43.820 117.000 1.000
43.880 113.000 1.000
43.940 140.000 1.000
44.000 116.000 1.000
44.060 120.000 1.000
44.120 112.000 1.000
44.180 119.000 1.000
44.240 125.000 1.000
44.300 104.000 1.000
44.360 111.000 1.000
44.420 109.000 1.000
44.480 140.000 1.000
44.540 108.000 1.000
44.600 117.000 1.000
44.660 101.000 1.000
44.720 133.000 1.000
44.780 118.000 1.000
44.840 120.000 1.000
44.900 108.000 1.000
44.960 104.000 1.000
45.020 110.000 1.000
45.080 112.000 1.000
45.140 119.000 1.000
45.200 111.000 1.000
45.260 103.000 1.000
45.320 118.000 1.000
45.380 108.000 1.000
45.440 103.000 1.000
45.500 103.000 1.000
45.560 106.000 1.000
45.620 103.000 1.000
45.680 106.000 1.000
45.740 126.000 1.000
45.800 100.000 1.000
45.860 102.000 1.000
45.920 74.000 1.000
45.980 105.000 1.000
46.040 100.000 1.000
46.100 112.000 1.000
46.160 126.000 1.000
46.220 105.000 1.000
46.280 123.000 1.000
46.340 107.000 1.000
46.400 95.000 1.000
46.460 92.000 1.000
46.520 102.000 1.000
46.580 113.000 1.000
46.640 99.000 1.000
46.700 103.000 1.000
46.760 102.000 1.000
46.820 95.000 1.000
46.880 97.000 1.000
46.940 101.000 1.000
47.000 100.000 1.000
47.060 92.000 1.000
47.120 109.000 1.000
47.180 103.000 1.000
47.240 102.000 1.000
47.300 97.000 1.000
47.360 102.000 1.000
47.420 99.000 1.000
47.480 110.000 1.000
47.540 96.000 1.000
47.600 100.000 1.000
47.660 99.000 1.000
47.720 99.000 1.000
47.780 107.000 1.000
47.840 94.000 1.000
47.900 91.000 1.000
47.960 104.000 1.000
48.020 103.000 1.000
48.080 84.000 1.000
48.140 90.000 1.000
48.200 98.000 1.000
48.260 101.000 1.000
48.320 101.000 1.000
48.380 112.000 1.000
48.440 108.000 1.000
48.500 106.000 1.000
48.560 109.000 1.000
48.620 96.000 1.000
48.680 108.000 1.000
48.740 106.000 1.000
48.800 91.000 1.000
48.860 104.000 1.000
48.920 94.000 1.000
48.980 106.000 1.000
49.040 105.000 1.000
49.100 103.000 1.000
49.160 103.000 1.000
49.220 106.000 1.000
49.280 105.000 1.000
49.340 93.000 1.000
49.400 119.000 1.000
49.460 111.000 1.000
49.520 116.000 1.000
49.580 108.000 1.000
49.640 89.000 1.000
49.700 103.000 1.000
49.760 99.000 1.000
49.820 94.000 1.000
49.880 97.000 1.000
49.940 104.000 1.000
50.000 99.000 1.000
50.060 93.000 1.000
50.120 94.000 1.000
50.180 93.000 1.000
50.240 99.000 1.000
50.300 89.000 1.000
50.360 107.000 1.000
50.420 98.000 1.000
50.480 118.000 1.000
50.540 110.000 1.000
50.600 113.000 1.000
50.660 110.000 1.000
50.720 103.000 1.000
50.780 103.000 1.000
50.840 119.000 1.000
50.900 119.000 1.000
50.960 108.000 1.000
51.020 105.000 1.000
51.080 106.000 1.000
51.140 112.000 1.000
51.200 105.000 1.000
51.260 95.000 1.000
51.320 97.000 1.000
51.380 106.000 1.000
51.440 94.000 1.000
51.500 91.000 1.000
51.560 107.000 1.000
51.620 103.000 1.000
51.680 117.000 1.000
51.740 111.000 1.000
51.800 104.000 1.000
51.860 98.000 1.000
51.920 118.000 1.000
51.980 107.000 1.000
52.040 101.000 1.000
52.100 109.000 1.000
52.160 131.000 1.000
52.220 107.000 1.000
52.280 92.000 1.000
52.340 100.000 1.000
52.400 125.000 1.000
52.460 112.000 1.000
52.520 132.000 1.000
52.580 115.000 1.000
52.640 124.000 1.000
52.700 128.000 1.000
52.760 127.000 1.000
52.820 119.000 1.000
52.880 134.000 1.000
52.940 105.000 1.000
53.000 118.000 1.000
53.060 108.000 1.000
53.120 114.000 1.000
53.180 115.000 1.000
53.240 123.000 1.000
53.300 118.000 1.000
53.360 124.000 1.000
53.420 135.000 1.000
53.480 131.000 1.000
53.540 134.000 1.000
53.600 112.000 1.000
53.660 136.000 1.000
53.720 114.000 1.000
53.780 140.000 1.000
53.840 126.000 1.000
53.900 139.000 1.000
53.960 130.000 1.000
54.020 139.000 1.000
54.080 143.000 1.000
54.140 149.000 1.000
54.200 164.000 1.000
54.260 181.000 1.000
54.320 182.000 1.000
54.380 203.000 1.000
54.440 194.000 1.000
54.500 212.000 1.000
54.560 192.000 1.000
54.620 181.000 1.000
54.680 158.000 1.000
54.740 142.000 1.000
54.800 125.000 1.000
54.860 124.000 1.000
54.920 99.000 1.000
54.980 105.000 1.000
55.040 95.000 1.000
55.100 112.000 1.000
55.160 103.000 1.000
55.220 95.000 1.000
55.280 114.000 1.000
55.340 93.000 1.000
55.400 93.000 1.000
55.460 92.000 1.000
55.520 115.000 1.000
55.580 103.000 1.000
55.640 107.000 1.000
55.700 85.000 1.000
55.760 102.000 1.000
55.820 85.000 1.000
55.880 79.000 1.000
55.940 109.000 1.000
56.000 112.000 1.000
56.060 115.000 1.000
56.120 84.000 1.000
56.180 96.000 1.000
56.240 98.000 1.000
56.300 95.000 1.000
56.360 90.000 1.000
56.420 100.000 1.000
56.480 97.000 1.000
56.540 93.000 1.000
56.600 98.000 1.000
56.660 92.000 1.000
56.720 85.000 1.000
56.780 94.000 1.000
56.840 88.000 1.000
56.900 108.000 1.000
56.960 92.000 1.000
57.020 94.000 1.000
57.080 87.000 1.000
57.140 86.000 1.000
57.200 91.000 1.000
57.260 102.000 1.000
57.320 69.000 1.000
57.380 85.000 1.000
57.440 102.000 1.000
57.500 97.000 1.000
57.560 96.000 1.000
57.620 86.000 1.000
57.680 81.000 1.000
57.740 83.000 1.000
57.800 83.000 1.000
57.860 90.000 1.000
57.920 99.000 1.000
57.980 77.000 1.000
58.040 102.000 1.000
58.100 95.000 1.000
58.160 87.000 1.000
58.220 93.000 1.000
58.280 92.000 1.000
58.340 83.000 1.000
58.400 96.000 1.000
58.460 92.000 1.000
58.520 79.000 1.000
58.580 90.000 1.000
58.640 85.000 1.000
58.700 93.000 1.000
58.760 97.000 1.000
58.820 101.000 1.000
58.880 79.000 1.000
58.940 98.000 1.000
59.000 92.000 1.000
59.060 89.000 1.000
59.120 101.000 1.000
59.180 83.000 1.000
59.240 98.000 1.000
59.300 92.000 1.000
59.360 92.000 1.000
59.420 92.000 1.000
59.480 99.000 1.000
59.540 96.000 1.000
59.600 92.000 1.000
59.660 88.000 1.000
59.720 101.000 1.000
59.780 102.000 1.000
59.840 98.000 1.000
59.900 98.000 1.000
59.960 88.000 1.000
60.020 93.000 1.000
60.080 96.000 1.000
60.140 81.000 1.000
60.200 86.000 1.000
60.260 99.000 1.000
60.320 100.000 1.000
60.380 104.000 1.000
60.440 112.000 1.000
60.500 90.000 1.000
60.560 103.000 1.000
60.620 92.000 1.000
60.680 100.000 1.000
60.740 100.000 1.000
60.800 109.000 1.000
60.860 105.000 1.000
60.920 112.000 1.000
60.980 108.000 1.000
61.040 128.000 1.000
61.100 127.000 1.000
61.160 150.000 1.000
61.220 178.000 1.000
61.280 222.000 1.000
61.340 276.000 1.000
61.400 318.000 1.000
61.460 297.000 1.000
61.520 303.000 1.000
61.580 281.000 1.000
61.640 257.000 1.000
61.700 215.000 1.000
61.760 172.000 1.000
61.820 138.000 1.000
61.880 130.000 1.000
61.940 123.000 1.000
62.000 125.000 1.000
62.060 104.000 1.000
62.120 111.000 1.000
62.180 105.000 1.000
62.240 104.000 1.000
62.300 104.000 1.000
62.360 102.000 1.000
62.420 100.000 1.000
62.480 101.000 1.000
62.540 94.000 1.000
62.600 106.000 1.000
62.660 100.000 1.000
62.720 102.000 1.000
62.780 92.000 1.000
62.840 88.000 1.000
62.900 77.000 1.000
62.960 105.000 1.000
63.020 91.000 1.000
63.080 96.000 1.000
63.140 79.000 1.000
63.200 93.000 1.000
63.260 74.000 1.000
63.320 79.000 1.000
63.380 91.000 1.000
63.440 79.000 1.000
63.500 94.000 1.000
63.560 81.000 1.000
63.620 87.000 1.000
63.680 104.000 1.000
63.740 97.000 1.000
63.800 101.000 1.000
63.860 74.000 1.000
63.920 112.000 1.000
63.980 99.000 1.000
64.040 85.000 1.000
64.100 84.000 1.000
64.160 86.000 1.000
64.220 95.000 1.000
64.280 102.000 1.000
64.340 92.000 1.000
64.400 89.000 1.000
64.460 102.000 1.000
64.520 95.000 1.000
64.580 76.000 1.000
64.640 85.000 1.000
64.700 91.000 1.000
64.760 91.000 1.000
64.820 77.000 1.000
64.880 80.000 1.000
64.940 81.000 1.000
65.000 81.000 1.000
65.060 86.000 1.000
65.120 84.000 1.000
65.180 82.000 1.000
65.240 85.000 1.000
65.300 87.000 1.000
65.360 86.000 1.000
65.420 109.000 1.000
65.480 88.000 1.000
65.540 94.000 1.000
65.600 84.000 1.000
65.660 79.000 1.000
65.720 91.000 1.000
65.780 85.000 1.000
65.840 94.000 1.000
65.900 90.000 1.000
65.960 98.000 1.000
66.020 91.000 1.000
66.080 86.000 1.000
66.140 83.000 1.000
66.200 92.000 1.000
66.260 81.000 1.000
66.320 88.000 1.000
66.380 86.000 1.000
66.440 88.000 1.000
66.500 93.000 1.000
66.560 95.000 1.000
66.620 81.000 1.000
66.680 84.000 1.000
66.740 102.000 1.000
66.800 86.000 1.000
66.860 85.000 1.000
66.920 76.000 1.000
66.980 84.000 1.000
67.040 86.000 1.000
67.100 94.000 1.000
67.160 96.000 1.000
67.220 92.000 1.000
67.280 90.000 1.000
67.340 77.000 1.000
67.400 92.000 1.000
67.460 88.000 1.000
67.520 96.000 1.000
67.580 83.000 1.000
67.640 98.000 1.000
67.700 95.000 1.000
67.760 76.000 1.000
67.820 89.000 1.000
67.880 82.000 1.000
67.940 88.000 1.000
68.000 93.000 1.000
68.060 71.000 1.000
68.120 96.000 1.000
68.180 93.000 1.000
68.240 84.000 1.000
68.300 103.000 1.000
68.360 78.000 1.000
68.420 82.000 1.000
68.480 86.000 1.000
68.540 78.000 1.000
68.600 78.000 1.000
68.660 74.000 1.000
68.720 91.000 1.000
68.780 83.000 1.000
68.840 93.000 1.000
68.900 87.000 1.000
68.960 84.000 1.000
69.020 71.000 1.000
69.080 80.000 1.000
69.140 69.000 1.000
69.200 80.000 1.000
69.260 80.000 1.000
69.320 86.000 1.000
69.380 89.000 1.000
69.440 88.000 1.000
69.500 92.000 1.000
69.560 78.000 1.000
69.620 84.000 1.000
69.680 94.000 1.000
69.740 83.000 1.000
69.800 80.000 1.000
69.860 100.000 1.000
69.920 79.000 1.000
69.980 74.000 1.000
70.040 81.000 1.000
70.100 87.000 1.000
70.160 85.000 1.000
70.220 79.000 1.000
70.280 85.000 1.000
70.340 84.000 1.000
70.400 84.000 1.000
70.460 87.000 1.000
70.520 88.000 1.000
70.580 75.000 1.000
70.640 84.000 1.000
70.700 88.000 1.000
70.760 93.000 1.000
70.820 83.000 1.000
70.880 75.000 1.000
70.940 85.000 1.000
71.000 89.000 1.000
71.060 72.000 1.000
71.120 105.000 1.000
71.180 93.000 1.000
71.240 81.000 1.000
71.300 85.000 1.000
71.360 92.000 1.000
71.420 91.000 1.000
71.480 73.000 1.000
71.540 90.000 1.000
71.600 75.000 1.000
71.660 83.000 1.000
71.720 87.000 1.000
71.780 89.000 1.000
71.840 79.000 1.000
71.900 91.000 1.000
71.960 91.000 1.000
72.020 95.000 1.000
72.080 90.000 1.000
72.140 88.000 1.000
72.200 90.000 1.000
72.260 90.000 1.000
72.320 93.000 1.000
72.380 94.000 1.000
72.440 88.000 1.000
72.500 88.000 1.000
72.560 102.000 1.000
72.620 96.000 1.000
72.680 98.000 1.000
72.740 106.000 1.000
72.800 94.000 1.000
72.860 82.000 1.000
72.920 105.000 1.000
72.980 101.000 1.000
73.040 95.000 1.000
73.100 102.000 1.000
73.160 111.000 1.000
73.220 135.000 1.000
73.280 111.000 1.000
73.340 144.000 1.000
73.400 170.000 1.000
73.460 168.000 1.000
73.520 221.000 1.000
73.580 207.000 1.000
73.640 197.000 1.000
73.700 207.000 1.000
73.760 188.000 1.000
73.820 187.000 1.000
73.880 168.000 1.000
73.940 142.000 1.000
74.000 120.000 1.000
74.060 127.000 1.000
74.120 124.000 1.000
74.180 116.000 1.000
74.240 100.000 1.000
74.300 93.000 1.000
74.360 90.000 1.000
74.420 97.000 1.000
74.480 80.000 1.000
74.540 96.000 1.000
74.600 85.000 1.000
74.660 96.000 1.000
74.720 89.000 1.000
74.780 78.000 1.000
74.840 90.000 1.000
74.900 70.000 1.000
74.960 94.000 1.000
75.020 107.000 1.000
75.080 83.000 1.000
75.140 85.000 1.000
75.200 86.000 1.000
75.260 96.000 1.000
75.320 76.000 1.000
75.380 88.000 1.000
75.440 86.000 1.000
75.500 99.000 1.000
75.560 79.000 1.000
75.620 74.000 1.000
75.680 101.000 1.000
75.740 80.000 1.000
75.800 95.000 1.000
75.860 98.000 1.000
75.920 98.000 1.000
75.980 83.000 1.000
76.040 91.000 1.000
76.100 86.000 1.000
76.160 77.000 1.000
76.220 84.000 1.000
76.280 88.000 1.000
76.340 86.000 1.000
76.400 88.000 1.000
76.460 72.000 1.000
76.520 78.000 1.000
76.580 85.000 1.000
76.640 87.000 1.000
76.700 84.000 1.000
76.760 71.000 1.000
76.820 97.000 1.000
76.880 87.000 1.000
76.940 96.000 1.000
77.000 95.000 1.000
77.060 90.000 1.000
77.120 106.000 1.000
77.180 84.000 1.000
77.240 96.000 1.000
77.300 86.000 1.000
77.360 86.000 1.000
77.420 115.000 1.000
77.480 119.000 1.000
77.540 101.000 1.000
77.600 107.000 1.000
77.660 99.000 1.000
77.720 111.000 1.000
77.780 95.000 1.000
77.840 86.000 1.000
77.900 90.000 1.000
77.960 91.000 1.000
78.020 83.000 1.000
78.080 82.000 1.000
78.140 83.000 1.000
78.200 76.000 1.000
78.260 83.000 1.000
78.320 84.000 1.000
78.380 85.000 1.000
78.440 87.000 1.000
78.500 82.000 1.000
78.560 88.000 1.000
78.620 89.000 1.000
78.680 82.000 1.000
78.740 74.000 1.000
78.800 76.000 1.000
78.860 79.000 1.000
78.920 86.000 1.000
78.980 79.000 1.000
79.040 78.000 1.000
79.100 68.000 1.000
79.160 88.000 1.000
79.220 79.000 1.000
79.280 77.000 1.000
79.340 76.000 1.000
79.400 74.000 1.000
79.460 86.000 1.000
79.520 82.000 1.000
79.580 100.000 1.000
79.640 79.000 1.000
79.700 82.000 1.000
79.760 69.000 1.000
79.820 76.000 1.000
79.880 84.000 1.000
79.940 82.000 1.000
80.000 74.000 1.000
80.060 71.000 1.000
80.120 77.000 1.000
80.180 79.000 1.000
80.240 90.000 1.000
80.300 76.000 1.000
80.360 87.000 1.000
80.420 73.000 1.000
80.480 67.000 1.000
80.540 79.000 1.000
80.600 92.000 1.000
80.660 81.000 1.000
80.720 76.000 1.000
80.780 55.000 1.000
80.840 85.000 1.000
80.900 76.000 1.000
80.960 75.000 1.000
81.020 77.000 1.000
81.080 76.000 1.000
81.140 77.000 1.000
81.200 82.000 1.000
81.260 95.000 1.000
81.320 82.000 1.000
81.380 90.000 1.000
81.440 85.000 1.000
81.500 95.000 1.000
81.560 83.000 1.000
81.620 83.000 1.000
81.680 89.000 1.000
81.740 72.000 1.000
81.800 84.000 1.000
81.860 86.000 1.000
81.920 77.000 1.000
81.980 68.000 1.000
82.040 73.000 1.000
82.100 68.000 1.000
82.160 76.000 1.000
82.220 76.000 1.000
82.280 76.000 1.000
82.340 75.000 1.000
82.400 86.000 1.000
82.460 83.000 1.000
82.520 84.000 1.000
82.580 87.000 1.000
82.640 80.000 1.000
82.700 87.000 1.000
82.760 72.000 1.000
82.820 77.000 1.000
82.880 82.000 1.000
82.940 84.000 1.000
83.000 85.000 1.000
83.060 85.000 1.000
83.120 72.000 1.000
83.180 82.000 1.000
83.240 83.000 1.000
83.300 79.000 1.000
83.360 75.000 1.000
83.420 81.000 1.000
83.480 80.000 1.000
83.540 75.000 1.000
83.600 68.000 1.000
83.660 86.000 1.000
83.720 87.000 1.000
83.780 79.000 1.000
83.840 78.000 1.000
83.900 70.000 1.000
83.960 89.000 1.000
84.020 92.000 1.000
84.080 83.000 1.000
84.140 82.000 1.000
84.200 80.000 1.000
84.260 102.000 1.000
84.320 72.000 1.000
84.380 78.000 1.000
84.440 76.000 1.000
84.500 74.000 1.000
84.560 92.000 1.000
84.620 91.000 1.000
84.680 71.000 1.000
84.740 83.000 1.000
84.800 73.000 1.000
84.860 90.000 1.000
84.920 74.000 1.000
84.980 83.000 1.000
85.040 69.000 1.000
85.100 88.000 1.000
85.160 80.000 1.000
85.220 83.000 1.000
85.280 73.000 1.000
85.340 77.000 1.000
85.400 78.000 1.000
85.460 71.000 1.000
85.520 82.000 1.000
85.580 95.000 1.000
85.640 75.000 1.000
85.700 71.000 1.000
85.760 78.000 1.000
85.820 82.000 1.000
85.880 80.000 1.000
85.940 83.000 1.000
86.000 83.000 1.000
86.060 65.000 1.000
86.120 87.000 1.000
86.180 78.000 1.000
86.240 95.000 1.000
86.300 72.000 1.000
86.360 98.000 1.000
86.420 80.000 1.000
86.480 89.000 1.000
86.540 86.000 1.000
86.600 79.000 1.000
86.660 78.000 1.000
86.720 88.000 1.000
86.780 69.000 1.000
86.840 96.000 1.000
86.900 94.000 1.000
86.960 82.000 1.000
87.020 85.000 1.000
87.080 87.000 1.000
87.140 79.000 1.000
87.200 77.000 1.000
87.260 79.000 1.000
87.320 78.000 1.000
87.380 74.000 1.000
87.440 75.000 1.000
87.500 63.000 1.000
87.560 64.000 1.000
87.620 84.000 1.000
87.680 68.000 1.000
87.740 77.000 1.000
87.800 90.000 1.000
87.860 80.000 1.000
87.920 73.000 1.000
87.980 88.000 1.000
88.040 72.000 1.000
88.100 107.000 1.000
88.160 83.000 1.000
88.220 57.000 1.000
88.280 74.000 1.000
88.340 69.000 1.000
88.400 70.000 1.000
88.460 77.000 1.000
88.520 85.000 1.000
88.580 74.000 1.000
88.640 70.000 1.000
88.700 78.000 1.000
88.760 83.000 1.000
88.820 68.000 1.000
88.880 78.000 1.000
88.940 71.000 1.000
89.000 71.000 1.000
89.060 80.000 1.000
89.120 77.000 1.000
89.180 80.000 1.000
89.240 85.000 1.000
89.300 86.000 1.000
89.360 75.000 1.000
89.420 80.000 1.000
89.480 71.000 1.000
89.540 77.000 1.000
89.600 80.000 1.000
89.660 71.000 1.000
89.720 77.000 1.000
89.780 72.000 1.000
89.840 86.000 1.000
89.900 78.000 1.000
89.960 69.000 1.000
90.000 72.000 1.000
*RAS_INT_END
*RAS_DATA_END